Workbook

Sheet About the Company
B1: AMBUJA CEMENTS LIMITED
B2: Cement & Building Materials | Part of The Adani Group | BSE: 500425 | NSE: AMBUJACEM | www.ambujacement.com
B4: ◆ COMPANY OVERVIEW
B5: Company Name | C5: Ambuja Cements Limited | D5: Formerly Known As | E5: Ambuja Cements India Ltd. / Gujarat Ambuja Cements Ltd.
B6: CIN | C6: L26942GJ1981PLC004717 | D6: Stock Exchange(s) | E6: BSE (500425) | NSE (AMBUJACEM)
B7: Incorporated | C7: 1981, Gujarat | D7: Listing Year | E7: Listed on BSE & NSE; part of CNX Nifty 50 index
B8: Registered Office | C8: Adani Corporate House, Shantigram, S.G. Highway, Ahmedabad – 382213 | D8: Market Cap | E8: ₹1,32,602 crore (as on 31 March 2025)
B9: Reporting Period | C9: FY 2024-25 (April 1, 2024 – March 31, 2025) | D9: Report Type | E9: 7th Integrated Annual Report (IFRS Foundation IR Framework)
B10: ◆ PARENT / PROMOTER STRUCTURE
B11: Ultimate Parent Group | C11: Adani Group — Founded 1988 by Gautam Adani, HQ Ahmedabad; India's largest diversified infrastructure conglomerate
B12: Direct Parent Entity | C12: Holderind Investments Ltd. (Promoter) — 47.72% stake; Harmonia Trade and Investment Ltd. — 19.23%; Adani Enterprises Ltd. (Promoter Group) — 0.35%
B13: Total Promoter Holding | C13: 67.33% held by Adani promoter group (as on 31 March 2025)
B14: Adani Group Position | C14: Ambuja Cements is the cement and building materials flagship within the Adani Portfolio's 'Materials, Metals & Mining' vertical; sits alongside ACC, Sanghi, and Orient Cement under Adani's cement umbrella targeting 140 MTPA by FY 2027-28
B15: ◆ NATURE OF BUSINESS
B16: Primary Business | C16: Manufacturing and marketing of cement and building materials — one of India's largest cement producers
B17: Industry / Sector | C17: Cement & Building Materials | Construction Materials | Consumer discretionary / Industrials
B18: Product Portfolio | C18: Ambuja Cement (flagship) | Ambuja Plus (high-strength) | Ambuja Compocem (dense concrete) | Ambuja Kawach (water-repellent) | Ambuja Cool Walls (eco-friendly, 5°C cooler) | Ready-Mix Concrete | Blended Cement (>82% of portfolio); 4 products GRIHA-certified
B19: Blended Cement Mix | C19: Over 82% of portfolio is blended cement; Clinker Factor at 64%
B20: Geographic Presence | C20: Present in 31 States and UTs across 635+ districts in India; 1,10,000+ channel partners
B21: Manufacturing Network | C21: 24 Integrated Plants | 22 Grinding Units | 11 Bulk Cement Terminals | 102 Ready-Mix Concrete Plants | 11 Captive Ships
B22: ◆ SUBSIDIARIES & KEY GROUP ENTITIES
B23: Entity | C23: Type / Stake | D23: HQ / Location | E23: Nature of Business
B24: ACC Limited | C24: Subsidiary — 50.05% stake | D24: Mumbai, India | E24: India's one of largest cement producers; fully integrated with Ambuja under Adani Cement umbrella
B25: Sanghi Industries Limited | C25: Subsidiary — 58.08% stake | D25: Gujarat, India | E25: Cement manufacturing; large integrated plant at Sanghipuram, Gujarat; key addition post-acquisition
B26: Orient Cement Limited | C26: Subsidiary — 46.66% stake (w.e.f. April 2025) | D26: Hyderabad, India | E26: Cement manufacturing — acquisition completed April 2025; added 8.5 MTPA capacity
B27: Ambuja Cements (Rajasthan) Ltd. | C27: Wholly Owned Subsidiary | D27: Rajasthan, India | E27: Cement plant operations; limestone mining in Rajasthan
B28: Chemical Limes Mundwa Pvt. Ltd. | C28: Wholly Owned Subsidiary | D28: Rajasthan, India | E28: Limestone mining and lime products
B29: M.G.T. Cements Pvt. Ltd. | C29: Wholly Owned Subsidiary | D29: India | E29: Cement grinding operations
B30: Dang Cement Industries Pvt. Ltd. | C30: Wholly Owned Subsidiary | D30: India | E30: Cement plant operations
B31: Dirk India Pvt. Ltd. | C31: Subsidiary | D31: India | E31: Specialty construction chemicals and products
B32: Ambuja Shipping Services Ltd. | C32: Subsidiary | D32: India | E32: Captive maritime logistics — operates 11 captive ships for coastal cement dispatch
B33: ◆ KEY FINANCIAL HIGHLIGHTS — FY 2024-25 (Consolidated)
B34: Revenue from Operations | C34: ₹37,699 Crore | D34: Adj. EBITDA | E34: ₹8,645 Crore
B35: Profit After Tax (PAT) | C35: ₹5,158 Crore | D35: Market Capitalisation | E35: ₹1,32,602 Crore (as on 31 Mar 2025)
B36: Debt Status | C36: Debt-free (despite significant capex in FY25) | D36: Cement Capacity (FY25) | E36: 88.9 MTPA during FY25 → 100+ MTPA post Orient acquisition (April 2025)
B37: Tax Contribution | C37: ₹16,648 Crore paid to national exchequer | D37: Global Rank | E37: 9th largest cement company globally after crossing 100 MTPA milestone
B38: ◆ OPERATIONAL HIGHLIGHTS — FY 2024-25
B39: Cement Capacity Target | C39: 118 MTPA by FY2026 | 140 MTPA by FY2028 | D39: Plants of the Future | E39: Digital transformation programme across all plants — AI, IoT, automation, advanced analytics
B40: Integrated Units | C40: 24 Integrated Plants | 22 Grinding Units | 11 Bulk Terminals | 102 RMC Plants | D40: Captive Ships | E40: 11 captive ships for bulk sea-freight dispatch; strategic coastal logistics
B41: Distribution Network | C41: 1,10,000+ channel partners across India; 31 States & UTs; 635+ districts | D41: Ready-Mix Concrete | E41: 102 RMC plants serving urban infra and institutional customers
...

Sheet Promoter
A1: Ambuja Cements Limited — Promoter Shareholding Pattern (Q4 FY2024-25)
A2: Category of Shareholder | B2: No. of Shareholders | C2: Shares Held | D2: Stake %
A3: A1) Indian Promoters
A4: Any Other (specify) | B4: 1 | C4: 87,00,000 | D4: 0.35%
A5: Adani Enterprises Limited | B5: 1 | C5: 87,00,000 | D5: 0.35%
A6: Sub Total A1 — Indian | B6: 1 | C6: 87,00,000 | D6: 0.35%
A7: A2) Foreign Promoters
A8: Any Other (specify) | B8: 3 | C8: 1,66,33,81,052 | D8: 66.98%
A9: Endeavour Trade and Investment Limited | B9: 1 | C9: 7,02,442 | D9: 0.03%
A10: Harmonia Trade and Investment Ltd | B10: 1 | C10: 47,74,78,249 | D10: 19.23%
A11: Holderind Investments Ltd | B11: 1 | C11: 1,18,52,00,361 | D11: 47.72%
A12: Sub Total A2 — Foreign | B12: 3 | C12: 1,66,33,81,052 | D12: 66.98%
A13: TOTAL PROMOTER (A = A1 + A2) | B13: 4 | C13: 1,67,20,81,052 | D13: 67.33%

Sheet Public
A1: Ambuja Cements Limited — Public Shareholding Detail (Q4 FY2024-25)
A2: Category of Shareholder | B2: No. of Shareholders | C2: Shares Held | D2: Stake %
A3: B1) Domestic Institutional Investors (DII)
A4: Mutual Funds | B4: 53 | C4: 21,68,21,219 | D4: 8.73%
A5: Mirae Asset Large Cap Fund | B5: 1 | C5: 3,29,82,563 | D5: 1.33%
A6: Mirae Asset Large Cap Fund (SIP Tranche) | B6: 1 | C6: 4,34,16,130 | D6: 1.75%
A7: HDFC Large Cap Fund | B7: 1 | C7: 5,15,40,443 | D7: 2.08%
A8: Alternate Investment Funds | B8: 12 | C8: 8,46,032 | D8: 0.03%
A9: Banks | B9: 17 | C9: 1,27,315 | D9: 0.01%
A10: Insurance Companies | B10: 21 | C10: 21,96,57,802 | D10: 8.84%
A11: Life Insurance Corporation of India | B11: 1 | C11: 18,07,93,420 | D11: 7.28%
A12: Provident Funds / Pension Funds | B12: 1 | C12: 4,99,24,778 | D12: 2.01%
A13: NPS Trust — SBI Pension Fund (State Govt) | B13: 1 | C13: 4,99,24,778 | D13: 2.01%
A14: Sovereign Wealth Funds | B14: 2 | C14: 51,53,529 | D14: 0.21%
A15: NBFCs (RBI Registered) | B15: 8 | C15: 67,668 | D15: 0.00%
... A17: Sub Total B1 — DII | B17: 119 | C17: 49,26,19,343 | D17: 19.84%
A18: B2) Foreign Institutional Investors (FII)
A19: FPI — Category I | B19: 455 | C19: 14,00,84,991 | D19: 5.64%
A20: FPI — Category II | B20: 27 | C20: 46,63,938 | D20: 0.19%
A21: Foreign Institutional Investors (Other) | B21: 9 | C21: 61,275 | D21: 0.00%
A22: Sub Total B2 — FII | B22: 491 | C22: 14,48,10,204 | D22: 5.83%
A23: B3) Central Government / President of India
A24: Central Government / President of India | B24: 1 | C24: 37,747 | D24: 0.00%
A25: Sub Total B3 | B25: 1 | C25: 37,747 | D25: 0.00%
A26: B4) Non-Institutions (Retail & Others)
A27: IEPF | B27: 1 | C27: 50,34,848 | D27: 0.20%
A28: Resident Individuals (up to ₹2 lakh capital) | B28: 5,91,674 | C28: 11,36,89,930 | D28: 4.58%
A29: Resident Individuals (above ₹2 lakh capital) | B29: 39 | C29: 2,28,56,436 | D29: 0.92%
A30: Non-Resident Indians (NRIs) | B30: 12,527 | C30: 1,12,51,148 | D30: 0.45%
A31: Bodies Corporate | B31: 1,771 | C31: 1,64,41,809 | D31: 0.66%
A32: Any Other (Trusts, Clearing Members, HUF etc.) | B32: 6,788 | C32: 46,36,597 | D32: 0.19%
A33: Foreign Nationals | B33: 5 | C33: 18,459 | D33: 0.00%
A34: Sub Total B4 — Retail & Others | B34: 6,12,805 | C34: 17,39,29,227 | D34: 7.00%
A35: TOTAL PUBLIC (B = B1 + B2 + B3 + B4) | B35: 6,13,416 | C35: 81,13,96,521 | D35: 32.67%

Sheet Consolidated P&L
A1: AMBUJA CEMENTS LIMITED
A2: Consolidated Statement of Profit and Loss
A3: (₹ in Crore)
A4: Particulars | B4: Dec 31, 2019 | C4: Dec 31, 2020 | D4: Dec 31, 2021 | E4: Mar 31, 2023 (15 months) | F4: Mar 31, 2024 | G4: Mar 31, 2025
A5: INCOME
A6: a) Revenue from operations | B6: 27103.55 | C6: 24516.17 | D6: 28965.46 | E6: 38937.03 | F6: 33159.64 | G6: 33697.7
A7: b) Government grants incl. duty credits | B7: - | C7: - | D7: - | E7: - | F7: - | G7: 1347.06
A8: c) Other income | B8: 580.74 | C8: 449.59 | D8: 352.44 | E8: 737.71 | F8: 1166.4 | G8: 2654.25
A9: Total Income | B9: 27684.29 | C9: 24965.76 | D9: 29317.9 | E9: 39674.74 | F9: 34326.04 | G9: 37699.01
A10: EXPENSES
A11: a) Cost of materials consumed | B11: 3231.22 | C11: 2532.87 | D11: 3183.41 | E11: 4749.65 | F11: 4321.96 | G11: 5708.07
A12: b) Purchase of stock-in-trade | B12: 308.82 | C12: 334.92 | D12: 309.21 | E12: 481.12 | F12: 576.83 | G12: 763.66
A13: c) Changes in inventories of FG, WIP | B13: 143.64 | C13: 256.45 | D13: -530.34 | E13: -119.86 | F13: 23.99 | G13: 55.69
A14: d) Employee benefits expense | B14: 1570.75 | C14: 1540.4 | D14: 1529.15 | E14: 1856.53 | F14: 1352.79 | G14: 1403.41
A15: e) Finance costs | B15: 169.87 | C15: 140.22 | D15: 145.66 | E15: 194.9 | F15: 276.38 | G15: 215.94
A16: f) Depreciation and amortisation expense | B16: 1152.52 | C16: 1161.78 | D16: 1152.49 | E16: 1644.67 | F16: 1623.38 | G16: 2478.34
A17: g) Power and fuel | B17: 5722.19 | C17: 4827.64 | D17: 6787.52 | E17: 11761.9 | F17: 8109.31 | G17: 8347.84
A18: h) Freight and forwarding expense | B18: 7127.97 | C18: 6271.54 | D18: 7132.9 | E18: 9523.72 | F18: 8000.64 | G18: 8301.19
A19: i) Other expenses | B19: 4410.44 | C19: 3768.92 | D19: 4387.84 | E19: 5608.5 | F19: 4388.97 | G19: 4515.13
A20: Sub-total | B20: 23837.42 | C20: 20834.74 | D20: 24097.84 | E20: 35701.13 | F20: 28674.25 | G20: 31789.27
A21: j) Self/Captive consumption of cement | B21: -8.47 | C21: -22.14 | D21: -44.63 | E21: -46.9 | F21: -14.36 | G21: -20.88
A22: Total Expenses | B22: 23828.95 | C22: 20812.6 | D22: 24053.21 | E22: 35654.23 | F22: 28659.89 | G22: 31768.39
... A25: 5 Profit before exceptional items and tax (3+4) | B25: 3875.31 | C25: 4167.6 | D25: 5284.92 | E25: 4048.53 | F25: 5689.05 | G25: 5943.84
A26: 6 Exceptional items Expense / (Income) | B26: - | C26: 176.01 | D26: 120.45 | E26: 319.04 | F26: -211.57 | G26: 21.47
A27: 7 Profit before tax (5-6) | B27: 3875.31 | C27: 3991.59 | D27: 5164.47 | E27: 3729.49 | F27: 5900.62 | G27: 5922.37
A28: TAX EXPENSE
A29: a) Current tax (net) | B29: 1264.7 | C29: 1200.42 | D29: 1326.98 | E29: 770.6 | F29: 1260.11 | G29: 1274.53
A30: b) Tax adjustments - earlier years (net) | B30: - | C30: - | D30: - | E30: - | F30: -266.89 | G30: -769.87
A31: c) Deferred tax charge / (credit) | B31: -172.55 | C31: -315.67 | D31: 126.45 | E31: -65.49 | F31: 169.39 | G31: 259.3
A32: Total tax expense (8) | B32: 1092.15 | C32: 884.75 | D32: 1453.43 | E32: 705.11 | F32: 1162.61 | G32: 763.96
A33: 9 Profit after tax / for the year (7-8) | B33: 2783.16 | C33: 3106.84 | D33: 3711.04 | E33: 3024.38 | F33: 4738.01 | G33: 5158.41
A34: OTHER COMPREHENSIVE INCOME
A35: a) Remeasurement gains/(losses) on defined benefit plans | B35: -82.78 | C35: -15.39 | D35: 14.86 | E35: 38.61 | F35: 40.29 | G35: -52.29
A36: b) Share of remeasurement - JV/associates | B36: 0.18 | C36: -0.05 | D36: - | E36: -0.07 | F36: -0.17 | G36: -0.02
A37: Income tax effect on above | B37: 28.92 | C37: -6.18 | D37: -3.75 | E37: -9.67 | F37: -10.15 | G37: 12.43
A38: Foreign currency translation reserve | B38: - | C38: - | D38: - | E38: - | F38: - | G38: 0.25
A39: Total OCI (net of tax) (10) | B39: -53.68 | C39: -21.62 | D39: 11.11 | E39: 28.87 | F39: 29.97 | G39: -39.63
A40: 11 Total comprehensive income for the year (9+10) | B40: 2729.48 | C40: 3085.22 | D40: 3722.15 | E40: 3053.25 | F40: 4767.98 | G40: 5118.78
A41: ATTRIBUTABLE TO
A42: 12 Profit for the year attributable to:
...

Sheet DCF Valuation
C1: 1 | D1: 2 | E1: 3 | F1: 4 | G1: 5 | H1: 6 | I1: 7 | J1: 8 | K1: 9 | L1: 10
A2: INR Cr | B2: LTM | C2: Y1E | D2: Y2E | E2: Y3E | F2: Y4E | G2: Y5E | H2: Y6E | I2: Y7E | J2: Y8E | K2: Y9E | L2: Y10E | N2: Terminal Year | P2: Terminal growth rate % | Q2: 0.055
A3: Sales | B3: ='Growth Scenario'!B18 -> 33697.7 | C3: ='Growth Scenario'!C18 -> 35911.189 | D3: ='Growth Scenario'!D18 -> 38238.101 | E3: ='Growth Scenario'!E18 -> 40681.741 | F3: ='Growth Scenario'!F18 -> 43245.323 | G3: ='Growth Scenario'!G18 -> 45931.946 | H3: ='Growth Scenario'!H18 -> 48744.58 | I3: ='Growth Scenario'!I18 -> 51686.043 | ... L3: ='Growth Scenario'!L18 -> 61308.959 | N3: =L3*(1+$Q$2) -> 64680.952 | P3: Cost of Capital % | Q3: =Wacc!E27 -> 0.13506582
A4: Sales Growth | C4: ='Growth Scenario'!C19 -> 0.065686654 | D4: ='Growth Scenario'!D19 -> 0.064796283 | E4: ='Growth Scenario'!E19 -> 0.063905911 | F4: ='Growth Scenario'!F19 -> 0.063015539 | G4: ='Growth Scenario'!G19 -> 0.062125167 | H4: ='Growth Scenario'!H19 -> 0.061234796 | I4: ='Growth Scenario'!I19 -> 0.060344424 | J4: ='Growth Scenario'!J19 -> 0.059454052 | ... L4: ='Growth Scenario'!L19 -> 0.057673309 | N4: =$Q$2 -> 0.055 | P4: Terminal reinvestment rate % | Q4: =Q2*Q3 -> 0.0074286202
A5: EBIT | C5: =C3*C6 -> 5156.8963 | D5: =D3*D6 -> 5491.044 | E5: =E3*E6 -> 5841.9541 | F5: =F3*F6 -> 6210.088 | G5: =G3*G6 -> 6595.8908 | H5: =H3*H6 -> 6999.7888 | I5: =I3*I6 -> 7422.187 | J5: =J3*J6 -> 7863.4661 | ... L5: =L3*L6 -> 8804.0511 | N5: =N6*N3 -> 9288.2739
A6: EBIT Margin % | C6: =MEDIAN(Assumptions!B29:F29) -> 0.14360138 | D6: =C6 -> 0.14360138 | E6: =D6 -> 0.14360138 | F6: =E6 -> 0.14360138 | G6: =F6 -> 0.14360138 | H6: =G6 -> 0.14360138 | I6: =H6 -> 0.14360138 | J6: =I6 -> 0.14360138 | K6: =J6 -> 0.14360138 | L6: =K6 -> 0.14360138 | N6: =L6 -> 0.14360138 | P6: Enterprise value = Equity Value + Minority interest
A7: Less: Tax on EBIT | C7: =Assumptions!$B$35*'DCF Valuation'!C5 -> 1289.2241 | D7: =Assumptions!$B$35*'DCF Valuation'!D5 -> 1372.761 | E7: =Assumptions!$B$35*'DCF Valuation'!E5 -> 1460.4885 | F7: =Assumptions!$B$35*'DCF Valuation'!F5 -> 1552.522 | G7: =Assumptions!$B$35*'DCF Valuation'!G5 -> 1648.9727 | H7: =Assumptions!$B$35*'DCF Valuation'!H5 -> 1749.9472 | I7: =Assumptions!$B$35*'DCF Valuation'!I5 -> 1855.5468 | J7: =Assumptions!$B$35*'DCF Valuation'!J5 -> 1965.8665 | ... L7: =Assumptions!$B$35*'DCF Valuation'!L5 -> 2201.0128 | N7: =Assumptions!$B$35*N5 -> 2322.0685
A8: EBIT(1-T) | C8: =C5-C7 -> 3867.6722 | D8: =D5-D7 -> 4118.283 | E8: =E5-E7 -> 4381.4656 | F8: =F5-F7 -> 4657.566 | G8: =G5-G7 -> 4946.9181 | H8: =H5-H7 -> 5249.8416 | I8: =I5-I7 -> 5566.6403 | J8: =J5-J7 -> 5897.5996 | ... L8: =L5-L7 -> 6603.0383 | N8: =N5-N7 -> 6966.2054
A9: Less: Net Capital Expenditure | C9: =C3*'Fixed Asset Scheduled'!$B$11 -> 2202.5304 | D9: =D3*'Fixed Asset Scheduled'!$B$11 -> 2345.2461 | E9: =E3*'Fixed Asset Scheduled'!$B$11 -> 2495.1212 | F9: =F3*'Fixed Asset Scheduled'!$B$11 -> 2652.3526 | G9: =G3*'Fixed Asset Scheduled'!$B$11 -> 2817.1305 | H9: =H3*'Fixed Asset Scheduled'!$B$11 -> 2989.6369 | I9: =I3*'Fixed Asset Scheduled'!$B$11 -> 3170.0448 | J9: =J3*'Fixed Asset Scheduled'!$B$11 -> 3358.5168 | ... L9: =L3*'Fixed Asset Scheduled'!$B$11 -> 3760.2443
A10: Non Cash Working Capital | B10: ='Change in working capital'!F5 -> 3078.85 | C10: ='Change in working capital'!$B$9*'DCF Valuation'!C3 -> 1790.424 | D10: ='Change in working capital'!$B$9*'DCF Valuation'!D3 -> 1906.4368 | E10: ='Change in working capital'!$B$9*'DCF Valuation'!E3 -> 2028.2694 | F10: ='Change in working capital'!$B$9*'DCF Valuation'!F3 -> 2156.0819 | G10: ='Change in working capital'!$B$9*'DCF Valuation'!G3 -> 2290.0288 | H10: ='Change in working capital'!$B$9*'DCF Valuation'!H3 -> 2430.2582 | I10: ='Change in working capital'!$B$9*'DCF Valuation'!I3 -> 2576.9108 | J10: ='Change in working capital'!$B$9*'DCF Valuation'!J3 -> 2730.1186 | ... L10: ='Change in working capital'!$B$9*'DCF Valuation'!L3 -> 3056.6805
A11: Less: Change in Working Capital | C11: =C10-B10 -> -1288.426 | D11: =D10-C10 -> 116.01282 | E11: =E10-D10 -> 121.83258 | F11: =F10-E10 -> 127.81249 | G11: =G10-F10 -> 133.94695 | H11: =H10-G10 -> 140.22945 | I11: =I10-H10 -> 146.65253 | J11: =J10-I10 -> 153.20779 | ... L11: =L10-K10 -> 166.67611
A12: Reinvestment | C12: =C9+C11 -> 914.10433 | D12: =D9+D11 -> 2461.259 | E12: =E9+E11 -> 2616.9538 | F12: =F9+F11 -> 2780.1651 | G12: =G9+G11 -> 2951.0774 | H12: =H9+H11 -> 3129.8663 | I12: =I9+I11 -> 3316.6973 | J12: =J9+J11 -> 3511.7246 | ... L12: =L9+L11 -> 3926.9204 | N12: =N8*N14 -> 51.749294
A13: Free Cash Flow To Firm (FCFF) | C13: =C8-C12 -> 2953.5679 | D13: =D8-(D12) -> 1657.024 | E13: =E8-(E12) -> 1764.5118 | F13: =F8-(F12) -> 1877.4009 | G13: =G8-(G12) -> 1995.8406 | H13: =H8-(H12) -> 2119.9753 | I13: =I8-(I12) -> 2249.9429 | J13: =J8-(J12) -> 2385.875 | K13: =K8-(K12) -> 2527.895 | L13: =L8-(L12) -> 2676.1179 | N13: =N8-N12 -> 6914.4561
A14: Implied Reinvestment rate % | C14: =C13/C8 -> 0.76365517 | D14: =D13/D8 -> 0.40235798 | E14: =E13/E8 -> 0.40272182 | F14: =F13/F8 -> 0.40308627 | G14: =G13/G8 -> 0.40345132 | H14: =H13/H8 -> 0.40381699 | I14: =I13/I8 -> 0.40418328 | J14: =J13/J8 -> 0.40455018 | ... L14: =L13/L8 -> 0.40528583 | N14: =$Q$4 -> 0.0074286202
A16: Terminal Value | L16: =N13/($Q$3-$Q$2) -> 86359.647
A18: Present Value Interest Factor(PVIF) | C18: =1/(1+$Q$3)^C1 -> 0.88100618 | D18: =1/(1+$Q$3)^D1 -> 0.77617188 | E18: =1/(1+$Q$3)^E1 -> 0.68381222 | F18: =1/(1+$Q$3)^F1 -> 0.60244279 | G18: =1/(1+$Q$3)^G1 -> 0.53075582 | H18: =1/(1+$Q$3)^H1 -> 0.46759916 | I18: =1/(1+$Q$3)^I1 -> 0.41195774 | J18: =1/(1+$Q$3)^J1 -> 0.36293732 | ... L18: =1/(1+$Q$3)^L1 -> 0.28170174
A20: Present value of FCFF | C20: =SUMPRODUCT(C18:L18,C13:L13) -> 11631.437
A21: Present value of Terminal value | C21: =L16*L18 -> 24327.663
A23: Value of operating assets | C23: =C20+C21 -> 35959.1
A24: Add: Cash | C24: ='Consolidated Balance sheet'!G26+'Consolidated Balance sheet'!G27 -> 6172.16
A25: Less: Debt | C25: ='Consolidated Balance sheet'!G47+'Consolidated Balance sheet'!G56+'Consolidated Balance sheet'!G48+'Consolidated Balance sheet'!G57 -> 788.5
A26: Less: Minority Interest (NCI - Book Value) | C26: ='Consolidated Balance sheet'!G42 -> 10368.17
A27: Equity Value | C27: =C23+C24-C25-C26 -> 30974.59
A29: No. of Shares outstanding (Cr) | C29: ='Consolidated Balance sheet'!G38/2 -> 246.31
A30: intrinsic value per share | C30: =C27/C29 -> 125.7545
A32: Note: TV uses Terminal FCFF (reinvestment-adjusted). Cash includes bank balances. Debt includes lease liabilities. NCI at book value.

Sheet Consolidated Balance sheet
A1: AMBUJA CEMENTS LIMITED
A2: Consolidated Balance Sheet
A3: Particulars | B3: Dec 31, 2019 | C3: Dec 31, 2020 | D3: Dec 31, 2021 | E3: Mar 31, 2023 | F3: Mar 31, 2024 | G3: Mar 31, 2025
A4: ASSETS
A5: 1 Non-current assets
A6: a) Property, plant and equipment | B6: 12605.99 | C6: 11885.36 | D6: 13661.89 | E6: 14729.35 | F6: 19956.67 | G6: 24656.29
A7: b) Right-of-use assets | B7: - | C7: 503.87 | D7: 497.87 | E7: 588.15 | F7: 758.34 | G7: 1464.76
A8: c) Capital work-in-progress | B8: 1554.43 | C8: 2421.85 | D8: 2196.38 | E8: 2525.87 | F8: 2658.45 | G8: 9820.4
A9: d) Goodwill | B9: 7881.49 | C9: 7876.11 | D9: 7869.69 | E9: 7869.69 | F9: 8219.27 | G9: 10856.07
A10: e) Other intangible assets | B10: 213.86 | C10: 220.63 | D10: 224.11 | E10: 364.3 | F10: 3454.19 | G10: 5600.63
A11: Other intangible assets under development | B11: - | C11: - | D11: - | E11: - | F11: - | G11: 65.31
A12: f) Investments in associates and joint ventures | B12: 145.87 | C12: 154.6 | D12: 170.51 | E12: 186.05 | F12: 62.26 | G12: 60.39
A13: g) Financial assets | B13: - | C13: - | D13: - | E13: - | F13: - | G13: -
A14: i) Investments | B14: 3.7 | C14: 12.7 | D14: 27.6 | E14: 27.6 | F14: 27.6 | G14: 28.96
A15: ii) Loans | B15: 208.63 | C15: 212.28 | D15: 11.56 | E15: 9.89 | F15: 11.58 | G15: 4.95
A16: iii) Other financial assets | B16: 841.68 | C16: 1184.09 | D16: 1255.12 | E16: 3133.72 | F16: 1167.39 | G16: 3721.7
A17: h) Non-current tax assets (net) | B17: 1041.99 | C17: 1100.29 | D17: 1125.86 | E17: 1128.08 | F17: 1250.36 | G17: 1748.48
A18: i) Deferred tax assets (net) | B18: 4.16 | C18: 2.91 | D18: 2.91 | E18: - | F18: 36.94 | G18: 4.37
A19: j) Other non-current assets | B19: 1361.53 | C19: 1341.18 | D19: 1141.36 | E19: 1909.39 | F19: 2842.6 | G19: 3195.95
A20: Total - Non-current assets | B20: 25863.33 | C20: 26915.87 | D20: 28184.86 | E20: 32472.09 | F20: 40445.65 | G20: 61228.26
A21: 2 Current assets
A22: a) Inventories | B22: 2096.5 | C22: 1648.58 | D22: 2738.04 | E22: 3272.79 | F22: 3608.55 | G22: 4248.01
A23: b) Financial assets | B23: - | C23: - | D23: - | E23: - | F23: - | G23: -
A24: i) Investments | B24: - | C24: - | D24: - | E24: - | F24: 758.69 | G24: 1822.16
A25: ii) Trade receivables | B25: 1068.56 | C25: 561.13 | D25: 645.83 | E25: 1154.36 | F25: 1213.14 | G25: 1590.3
A26: iii) Cash and cash equivalents | B26: 9011.88 | C26: 8571.56 | D26: 11358.49 | E26: 543.87 | F26: 3007.1 | G26: 5043.32
A27: iv) Bank balances other than cash and cash equivalents | B27: 342.67 | C27: 364.07 | D27: 335.8 | E27: 2417.17 | F27: 8061.77 | G27: 1128.84
A28: v) Loans | B28: 32.28 | C28: 62.06 | D28: 9.91 | E28: 8.61 | F28: 6.24 | G28: 7.7
A29: vi) Other financial assets | B29: 496.62 | C29: 346.35 | D29: 474.25 | E29: 7901.58 | F29: 5715 | G29: 1888.24
A30: c) Current tax assets (net) | B30: - | C30: 71.26 | D30: - | E30: - | F30: - | G30: 16.18
A31: d) Other current assets | B31: 1235.25 | C31: 1153.69 | D31: 1434.66 | E31: 3948.86 | F31: 2459.74 | G31: 3965.63
A32: Sub-total | B32: 14283.76 | C32: 12778.7 | D32: 16996.98 | E32: 19247.24 | F32: 24830.23 | G32: 19710.38
A33: e) Non-current assets classified as held for sale | B33: 35.25 | C33: 26.13 | D33: 25.44 | E33: 2.13 | F33: 21.93 | G33: 6.77
A34: Total - Current assets | B34: 14319.01 | C34: 12804.83 | D34: 17022.42 | E34: 19249.37 | F34: 24852.16 | G34: 19717.15
A35: TOTAL - ASSETS | B35: 40182.34 | C35: 39720.7 | D35: 45207.28 | E35: 51721.46 | F35: 65297.81 | G35: 80945.41
A36: EQUITY AND LIABILITIES
A37: Equity | B37: - | C37: - | D37: - | E37: - | F37: - | G37: -
A38: a) Equity share capital | B38: 397.13 | C38: 397.13 | D38: 397.13 | E38: 397.13 | F38: 439.54 | G38: 492.62
A39: b) Other equity | B39: 23680.86 | C39: 22360.47 | D39: 24956.61 | E39: 26301.04 | F39: 38235.87 | G39: 52950.63
A40: c) Money received against share warrants | B40: - | C40: - | D40: - | E40: 5000.03 | F40: 2779.65 | G40: -
...

Sheet Consolidated Cash Flow
A1: AMBUJA CEMENTS LIMITED
A2: Consolidated Statement of Cash Flows
A3: (₹ in Crore)
A4: Particulars | B4: Dec 31, 2020 | C4: Dec 31, 2021 | D4: Mar 31, 2023 (15 months) | E4: Mar 31, 2024 | F4: Mar 31, 2025
A5: A) CASH FLOWS FROM OPERATING ACTIVITIES
A6: Profit before tax | B6: 3991.59 | C6: 5164.47 | D6: 3729.49 | E6: 5900.62 | F6: 5922.37
A7: Adjustments to reconcile profit before tax to net cash flows: | B7: - | C7: - | D7: - | E7: - | F7: -
A8: Depreciation and amortisation expense | B8: 1161.78 | C8: 1152.49 | D8: 1644.67 | E8: 1623.38 | F8: 2478.34
A9: Exceptional item / Provision for restructuring cost | B9: 176.01 | C9: 113.11 | D9: 147.13 | E9: - | F9: -
A10: Exceptional Items - Expense / (Income) | B10: - | C10: - | D10: - | E10: -211.57 | F10: 21.47
A11: Expected credit loss on non current financial assets | B11: 128.92 | C11: - | D11: - | E11: - | F11: -
A12: (Gain) / Loss on PP&E sold, discarded and written off (net) | B12: 32.86 | C12: 25.27 | D12: -96.09 | E12: -115.81 | F12: -35.79
A13: Loss on buy back of shares of joint venture | B13: 0.26 | C13: - | D13: - | E13: - | F13: -
A14: Gain on sale of current financial assets measured at FVTPL | B14: -26.65 | C14: -17.8 | D14: -52.25 | E14: -46.31 | F14: -116.72
A15: Gain on sale of investment in subsidiary company | B15: -12.91 | C15: - | D15: -16.52 | E15: - | F15: -
A16: Net gain on fair valuation of liquid mutual fund measured at FVTPL | B16: -0.47 | C16: -0.37 | D16: -0.21 | E16: -16.76 | F16: -27.19
A17: Finance costs | B17: 140.22 | C17: 142.32 | D17: 190.54 | E17: 276.38 | F17: 215.94
A18: Interest income | B18: -401.42 | C18: -302.3 | D18: -538.26 | E18: -936.9 | F18: -2433.91
A19: Provision for slow and non moving spares (net) | B19: 25.39 | C19: 29.85 | D19: -2.57 | E19: -6.05 | F19: 17.56
A20: Impairment loss / (Reversal) on trade receivable (net) | B20: 51.48 | C20: -8.79 | D20: 7.22 | E20: 18.8 | F20: 9.37
A21: Discounting income on interest free loan / Unwinding of discounting charge | B21: -3.25 | C21: 3.34 | D21: - | E21: - | F21: -
A22: Unrealised exchange (gain) / loss (net) | B22: 8.29 | C22: 3.36 | D22: 37.44 | E22: 2.47 | F22: 6.16
A23: Fair value movement in derivative instruments | B23: 1.3 | C23: 5.92 | D23: -7.31 | E23: 5.46 | F23: 0.47
A24: Interest on income tax written back | B24: -5.77 | C24: - | D24: - | E24: - | F24: -
A25: Provisions no longer required written back | B25: -11.86 | C25: -18.53 | D25: -46.84 | E25: -110.01 | F25: -
A26: Compensation Expenses under Employees Stock Options Scheme | B26: 3.66 | C26: 8.01 | D26: 2.94 | E26: - | F26: -
A27: Inventories written off | B27: 1.66 | C27: 2.4 | D27: - | E27: - | F27: -
A28: Impairment of goodwill in subsidiary company | B28: - | C28: 6.42 | D28: - | E28: - | F28: -
A29: Provisions / (Reversal) for doubtful advances (net) | B29: - | C29: -0.13 | D29: - | E29: - | F29: -
A30: Bad debts and claims written off / written back (net) | B30: 1.07 | C30: - | D30: - | E30: - | F30: -
A31: Unrealised share of profit in associates and joint ventures | B31: -14.44 | C31: -20.23 | D31: -28.02 | E31: -22.9 | F31: -13.22
A32: Other non cash items | B32: -2.41 | C32: -0.63 | D32: -25.04 | E32: 6.49 | F32: -26.1
A33: Operating profit before working capital changes | B33: 5245.31 | C33: 6288.18 | D33: 4946.32 | E33: 6367.29 | F33: 6018.75
A34: Changes in Working Capital | B34: - | C34: - | D34: - | E34: - | F34: -
A35: Decrease / (Increase) in Trade receivables, loans & advances and other assets | B35: 244.5 | C35: -268.03 | D35: - | E35: - | F35: -
A36: Decrease / (Increase) in Inventories | B36: 420.49 | C36: -1121.71 | D36: - | E36: - | F36: -
A37: (Increase) / Decrease in Inventories | B37: - | C37: - | D37: -466.99 | E37: -228.29 | F37: -512.89
A38: (Increase) / Decrease in Trade Receivables | B38: - | C38: - | D38: -547.07 | E38: 24.35 | F38: -382.32
A39: (Increase) / Decrease in Other Financial Assets | B39: - | C39: - | D39: - | E39: - | F39: -305.02
A40: (Increase) / Decrease in Other Assets | B40: - | C40: - | D40: -2720.44 | E40: 975.24 | F40: -995.13
...

Sheet Wacc
B2: Capital Structure
B3: Total Debt | C3: ='Consolidated Balance sheet'!G47+'Consolidated Balance sheet'!G56 -> 26.82 | D3: (Borrowings + Lease Liabilities)
B4: Total Equity | C4: ='Relative Valuations'!C3*G4 -> 107637.47 | D4: no of shares outstanding | F4: CMP (Rs.): | G4: 437 | H4: Source: BSE/NSE (FY2025)
B5: Total Mix (Debt + Equity) | C5: =C4+C3 -> 107664.29 | D5: equity share capital/face valueper share
B6: % of Debt | C6: =C3/C5 -> 0.00024910767
B7: % of Equity | C7: =C4/C5 -> 0.99975089
B8: Debt to Equity | C8: =C3/C4 -> 0.00024916974
B10: Cost of Equity (CAPM)
B11: Risk-free Rate (Rf) | C11: 0.0625 | E11: Source: RBI 10-year Government Securities yield (FY2025)
B12: Beta (β) | C12: =BETA!H3 -> 1.0923358
B13: Market Risk Premium (Rm - Rf) | C13: 0.065 | E13: Source: India Equity Risk Premium (Damodaran estimate)
B14: Cost of Equity [Ke = Rf + β×(Rm-Rf)] | C14: =C11+(C12*C13) -> 0.13350183
B16: Cost of Debt
B17: Finance Cost (FY2025) | C17: ='Consolidated P&L'!G15 -> 215.94
B18: Total Debt (FY2025) | C18: =C3 -> 26.82
B19: Pre-tax Cost of Debt [Kd = FC/Debt] | C19: =IFERROR(C17/C18,0) -> 8.0514541
B20: Tax Rate | C20: =Assumptions!G34 -> 0.20363462
B21: Post-tax Cost of Debt [Kd*(1-T)] | C21: =C19*(1-C20) -> 6.4118994
B23: WACC
B24: Source | C24: Weight | D24: Cost | E24: Weighted Cost
B25: Debt | C25: =C6 -> 0.00024910767 | D25: =C21 -> 6.4118994 | E25: =D25*C25 -> 0.0015972533
B26: Equity | C26: =C7 -> 0.99975089 | D26: =C14 -> 0.13350183 | E26: =C26*D26 -> 0.13346857
B27: WACC | C27: =SUM(C25:C26) -> 1 | D27: (Check: weights = 100%) | E27: =E25+E26 -> 0.13506582 | G27: wacc = we*ke+wd*kd

Sheet BETA
A1: Date | B1: Close Price (Ambuja Cement) | C1: Date | D1: Close Price (Nifty) | F1: Rm Ambuja Cement) | G1: Rm Nifty | H1: Beta | I1: Covariance
A2: 43922 | B2: 156.64999389648438 | C2: 43922 | D2: 8253.7998046875
A3: 43924 | B3: 153 | C3: 43924 | D3: 8083.7998046875 | F3: =(B3-B2)/B2 -> -0.023300313 | G3: =(D3-D2)/D2 -> -0.020596574 | H3: =SLOPE(F3:F1515,G3:G1515) -> 1.0923358 | I3: =_xlfn.COVARIANCE.S(F3:F1515,G3:G1515)/_xlfn.VAR.S(G3:G1515) -> 1.0923358
A4: 43928 | B4: 159 | C4: 43928 | D4: 8792.2001953125 | F4: =(B4-B3)/B3 -> 0.039215686 | G4: =(D4-D3)/D3 -> 0.087632105
A5: 43929 | B5: 149.6999969482422 | C5: 43929 | D5: 8748.75 | F5: =(B5-B4)/B4 -> -0.058490585 | G5: =(D5-D4)/D4 -> -0.0049419024
A6: 43930 | B6: 158.8000030517578 | C6: 43930 | D6: 9111.9004 | F6: =(B6-B5)/B5 -> 0.060788285 | G6: =(D6-D5)/D5 -> 0.041508832 | I6: SUMMARY OUTPUT
A7: 43934 | B7: 165 | C7: 43934 | D7: 8993.8496 | F7: =(B7-B6)/B6 -> 0.039042801 | G7: =(D7-D6)/D6 -> -0.012955671
A8: 43936 | B8: 168.5500030517578 | C8: 43936 | D8: 8925.2998046875 | F8: =(B8-B7)/B7 -> 0.02151517 | G8: =(D8-D7)/D7 -> -0.0076218536 | I8: Regression Statistics
A9: 43937 | B9: 169.6999969482422 | C9: 43937 | D9: 8992.7998046875 | F9: =(B9-B8)/B8 -> 0.0068228649 | G9: =(D9-D8)/D8 -> 0.0075627712 | I9: Multiple R | J9: 0.5115617
A10: 43938 | B10: 172.9499969482422 | C10: 43938 | D10: 9266.75 | F10: =(B10-B9)/B9 -> 0.019151444 | G10: =(D10-D9)/D9 -> 0.030463282 | I10: R Square | J10: 0.26169537
A11: 43941 | B11: 170.3000030517578 | C11: 43941 | D11: 9261.8496 | F11: =(B11-B10)/B10 -> -0.015322312 | G11: =(D11-D10)/D10 -> -0.00052881438 | I11: Adjusted R Square | J11: 0.26120675
A12: 43942 | B12: 167.5500030517578 | C12: 43942 | D12: 8981.4501953125 | F12: =(B12-B11)/B11 -> -0.016147974 | G12: =(D12-D11)/D11 -> -0.030274667 | I12: Standard Error | J12: 0.018030476
A13: 43943 | B13: 176.5 | C13: 43943 | D13: 9187.2998046875 | F13: =(B13-B12)/B12 -> 0.053416871 | G13: =(D13-D12)/D12 -> 0.022919418 | I13: Observations | J13: 1513
A14: 43944 | B14: 171.4499969482422 | C14: 43944 | D14: 9313.9004 | F14: =(B14-B13)/B13 -> -0.028611915 | G14: =(D14-D13)/D13 -> 0.013779956
A15: 43945 | B15: 167.9499969482422 | C15: 43945 | D15: 9154.4004 | F15: =(B15-B14)/B14 -> -0.020414115 | G15: =(D15-D14)/D14 -> -0.017124942 | I15: ANOVA
A16: 43948 | B16: 172.3000030517578 | C16: 43948 | D16: 9282.2998046875 | F16: =(B16-B15)/B15 -> 0.025900602 | G16: =(D16-D15)/D15 -> 0.013971359 | J16: df | K16: SS | L16: MS | M16: F | N16: Significance F
A17: 43949 | B17: 167.6999969482422 | C17: 43949 | D17: 9380.9004 | F17: =(B17-B16)/B16 -> -0.026697655 | G17: =(D17-D16)/D16 -> 0.010622431 | I17: Regression | J17: 1 | K17: 0.17411625 | L17: 0.17411625 | M17: 535.5807 | N17: 1.1337563e-101
A18: 43950 | B18: 169.5 | C18: 43950 | D18: 9553.3496 | F18: =(B18-B17)/B17 -> 0.010733471 | G18: =(D18-D17)/D17 -> 0.018383014 | I18: Residual | J18: 1511 | K18: 0.49122317 | L18: 0.00032509806
A19: 43951 | B19: 171.64999389648438 | C19: 43951 | D19: 9859.9004 | F19: =(B19-B18)/B18 -> 0.01268433 | G19: =(D19-D18)/D18 -> 0.032088303 | I19: Total | J19: 1512 | K19: 0.66533942
A20: 43955 | B20: 162.35000610351562 | C20: 43955 | D20: 9293.5 | F20: =(B20-B19)/B19 -> -0.054179948 | G20: =(D20-D19)/D19 -> -0.057444839
A21: 43956 | B21: 164.8000030517578 | C21: 43956 | D21: 9205.5996 | F21: =(B21-B20)/B20 -> 0.015090834 | G21: =(D21-D20)/D20 -> -0.0094582655 | J21: Coefficients | K21: Standard Error | L21: t Stat | M21: P-value | N21: Lower 95% | O21: Upper 95% | P21: Lower 95.0% | Q21: Upper 95.0%
A22: 43957 | B22: 167.85000610351562 | C22: 43957 | D22: 9270.9004 | F22: =(B22-B21)/B21 -> 0.0185073 | G22: =(D22-D21)/D21 -> 0.0070935935 | I22: Intercept | J22: 8.2113966e-05 | K22: 0.00046486634 | L22: 0.17663995 | M22: 0.85981489 | N22: -0.00082973773 | O22: 0.00099396566 | P22: -0.00082973773 | Q22: 0.00099396566
A23: 43958 | B23: 168.60000610351562 | C23: 43958 | D23: 9199.0498046875 | F23: =(B23-B22)/B22 -> 0.0044682751 | G23: =(D23-D22)/D22 -> -0.0077501195 | I23: X Variable 1 | J23: 1.0923358 | K23: 0.047200184 | L23: 23.142617 | M23: 1.1337563e-101 | N23: 0.99975095 | O23: 1.1849206 | P23: 0.99975095 | Q23: 1.1849206
A24: 43959 | B24: 169.35000610351562 | C24: 43959 | D24: 9251.5 | F24: =(B24-B23)/B23 -> 0.0044483984 | G24: =(D24-D23)/D23 -> 0.0057016971
A25: 43962 | B25: 173.9499969482422 | C25: 43962 | D25: 9239.2001953125 | F25: =(B25-B24)/B24 -> 0.027162626 | G25: =(D25-D24)/D24 -> -0.001329493
A26: 43963 | B26: 175.1999969482422 | C26: 43963 | D26: 9196.5498046875 | F26: =(B26-B25)/B25 -> 0.0071859731 | G26: =(D26-D25)/D25 -> -0.0046162427
A27: 43964 | B27: 183 | C27: 43964 | D27: 9383.5498046875 | F27: =(B27-B26)/B26 -> 0.044520566 | G27: =(D27-D26)/D26 -> 0.020333713
A28: 43965 | B28: 182.5 | C28: 43965 | D28: 9142.75 | F28: =(B28-B27)/B27 -> -0.0027322404 | G28: =(D28-D27)/D27 -> -0.025661909
A29: 43966 | B29: 181.8000030517578 | C29: 43966 | D29: 9136.8496 | F29: =(B29-B28)/B28 -> -0.0038355997 | G29: =(D29-D28)/D28 -> -0.00064536279
A30: 43969 | B30: 172.14999389648438 | C30: 43969 | D30: 8823.25 | F30: =(B30-B29)/B29 -> -0.053080357 | G30: =(D30-D29)/D29 -> -0.03432251
A31: 43970 | B31: 174.60000610351562 | C31: 43970 | D31: 8879.0996 | F31: =(B31-B30)/B30 -> 0.014231846 | G31: =(D31-D30)/D30 -> 0.0063298228
A32: 43971 | B32: 179.64999389648438 | C32: 43971 | D32: 9066.5498046875 | F32: =(B32-B31)/B31 -> 0.028923182 | G32: =(D32-D31)/D31 -> 0.021111397
A33: 43972 | B33: 181 | C33: 43972 | D33: 9106.25 | F33: =(B33-B32)/B32 -> 0.007514646 | G33: =(D33-D32)/D32 -> 0.0043787545
A34: 43973 | B34: 186.9499969482422 | C34: 43973 | D34: 9039.25 | F34: =(B34-B33)/B33 -> 0.032872911 | G34: =(D34-D33)/D33 -> -0.0073575841
A35: 43977 | B35: 188.5500030517578 | C35: 43977 | D35: 9029.0498046875 | F35: =(B35-B34)/B34 -> 0.0085584709 | G35: =(D35-D34)/D34 -> -0.0011284338
A36: 43978 | B36: 187.4499969482422 | C36: 43978 | D36: 9314.9501953125 | F36: =(B36-B35)/B35 -> -0.0058340286 | G36: =(D36-D35)/D35 -> 0.031664505
A37: 43979 | B37: 191.3000030517578 | C37: 43979 | D37: 9490.0996 | F37: =(B37-B36)/B36 -> 0.020538843 | G37: =(D37-D36)/D36 -> 0.018803044
A38: 43980 | B38: 191.5500030517578 | C38: 43980 | D38: 9580.2998046875 | F38: =(B38-B37)/B37 -> 0.0013068479 | G38: =(D38-D37)/D37 -> 0.0095046627
A39: 43983 | B39: 188.9499969482422 | C39: 43983 | D39: 9826.1504 | F39: =(B39-B38)/B38 -> -0.013573511 | G39: =(D39-D38)/D38 -> 0.025662097
A40: 43984 | B40: 191.1999969482422 | C40: 43984 | D40: 9979.0996 | F40: =(B40-B39)/B39 -> 0.011907912 | G40: =(D40-D39)/D39 -> 0.015565528
...

Sheet Consolidated Quaterly Result
C1: Consolidated Quarterly Results (Rs. Crores)
D2: Quarter ended | G2: Years
C3: Particulars | D3: 46082 | E3: 45992 | F3: 45901 | G3: 46082 | H3: 45717
C4: Net Sales | D4: 10915.47 | E4: 10276.65 | F4: 9174.49 | G4: 40655.68 | H4: 35044.76
C5: Other Income | D5: 233.89 | E5: 87.32 | F5: 257.04 | G5: 834.34 | H5: 2654.24
C6: Total Income | D6: 11149.36 | E6: 10363.97 | F6: 9431.53 | G6: 41490.02 | H6: 37699
C7: Expenditure | D7: -10525.09 | E7: -9941.46 | F7: -8375.59 | G7: -37910.76 | H7: -31768.39
C8: Cost of Materials Consumed | D8: -1626.55 | E8: -1741.51 | F8: -1607.92 | G8: -6511.54 | H8: -5708.07
C9: Finance Costs | D9: -20.8 | E9: -58.85 | F9: -76.82 | G9: -223.61 | H9: -215.94
C10: Other Expenses | D10: -7051.01 | E10: -6634.82 | F10: -5699.98 | G10: -25771.59 | H10: -21143.28
C11: Employee benefit expense | D11: -395.9 | E11: -383.88 | F11: -405.13 | G11: -1602.65 | H11: -1403.41
C12: Purchases of stock-in-trade | D12: -162.77 | E12: -247.61 | F12: -81.39 | G12: -609.25 | H12: -763.66
C13: Changes in inventories of finished goods, work-in-progress and stock-in-trade | D13: -215.33 | E13: 84.24 | F13: 380.8 | G13: 378.29 | H13: -55.69
C14: Depreciation and amortisation expense | D14: -1052.73 | E14: -959.03 | F14: -885.15 | G14: -3570.41 | H14: -2478.34
... C25: Income Attributable to Consolidated Group | D25: 1857.43 | E25: 366.97 | F25: 2302.28 | G25: 5637.08 | H25: 5158.41
C26: EPS after Extraordinary items (in Rs) | D26: - | E26: - | F26: - | G26: - | H26: -
C27: Exceptional Item | D27: -102.51 | E27: -15.23 | F27: -222.8 | G27: -300.54 | H27: -21.47
C28: Profit after Interest but before Exceptional Items | D28: 624.27 | E28: 422.51 | F28: 1055.94 | G28: 3579.26 | H28: 5930.61
C29: Net Profit Loss for the period from continuing operations | D29: 1851.06 | E29: 361.84 | F29: 2297.89 | G29: 5617.03 | H29: 5145.19
C30: Profit (loss) from discontinuing operations before tax | D30: 0 | E30: 0 | F30: 0 | G30: 0 | H30: 0
C31: Tax expense of discontinuing operations | D31: 0 | E31: 0 | F31: 0 | G31: 0 | H31: 0
C32: Net profit (loss) from discontinuing operation after tax | D32: 0 | E32: 0 | F32: 0 | G32: 0 | H32: 0
C33: Other Comprehensive Income Net of Taxes | D33: 41.32 | E33: -4.58 | F33: 42.26 | G33: 74.13 | H33: -39.63
C34: Any Other Comprehensive Item | D34: 0 | E34: 0 | F34: 0 | G34: 0 | H34: 0
C35: Total Comprehensive Income for the Period | D35: 1898.75 | E35: 362.39 | F35: 2344.54 | G35: 5711.21 | H35: 5118.78
C36: Total Amount of items that will not be reclassified to profit and loss | D36: 0 | E36: 0 | F36: 0 | G36: 0 | H36: 0
C37: Income tax relating to items that will not be reclassified to profit or loss | D37: 0 | E37: 0 | F37: 0 | G37: 0 | H37: 0
C38: Total Amount of items that will be reclassified to profit and loss | D38: 0 | E38: 0 | F38: 0 | G38: 0 | H38: 0
... C45: Diluted for discontinued & continuing operation | D45: 0 | E45: 0 | F45: 0 | G45: 0 | H45: 0

Sheet Peers
E2: Ambuja Cement | J2: Ultra tech Cement
E3: Metric | F3: 45352 | G3: 45717 | H3: 46082 | J3: Metric | K3: 45352 | L3: 45717 | M3: 46082
E4: Debtor Days | F4: 13 | G4: 16 | H4: 17 | J4: Debtor Days | K4: 22 | L4: 28 | M4: 25
E5: Inventory Days | F5: 238 | G5: 238 | H5: 246 | J5: Inventory Days | K5: 255 | L5: 255 | M5: 206
E6: Days Payable | F6: 196 | G6: 167 | H6: 227 | J6: Days Payable | K6: 260 | L6: 248 | M6: 217
E7: Cash Conversion Cycle | F7: 56 | G7: 86 | H7: 37 | J7: Cash Conversion Cycle | K7: 17 | L7: 35 | M7: 13
E8: Working Capital Days | F8: 8 | G8: -25 | H8: -3 | J8: Working Capital Days | K8: -52 | L8: -64 | M8: -41
E9: ROCE % | F9: 0.13 | G9: 0.11 | H9: 0.06 | J9: ROCE % | K9: 0.15 | L9: 0.11 | M9: 0.13
E13: Shree Cement | J13: J.K Cement
E14: Metric | F14: 45352 | G14: 45717 | H14: 46082 | J14: Metric | K14: 45352 | L14: 45717 | M14: 46082
E15: Debtor Days | F15: 23 | G15: 27 | H15: 32 | J15: Debtor Days | K15: 18 | L15: 24 | M15: 20
E16: Inventory Days | F16: 670 | G16: 444 | H16: 469 | J16: Inventory Days | K16: 235 | L16: 213 | M16: 249
E17: Days Payable | F17: 229 | G17: 247 | H17: 274 | J17: Days Payable | K17: 185 | L17: 199 | M17: 198
E18: Cash Conversion Cycle | F18: 464 | G18: 223 | H18: 227 | J18: Cash Conversion Cycle | K18: 68 | L18: 38 | M18: 71
E19: Working Capital Days | F19: 7 | G19: -8 | H19: 135 | J19: Working Capital Days | K19: 2 | L19: -23 | M19: -21
E20: ROCE % | F20: 0.15 | G20: 0.07 | H20: 0.1 | J20: ROCE % | K20: 0.16 | L20: 0.14 | M20: 0.15

Sheet Ratio Analysis
A1: Ratio Analysis- Ambuja
A2: Years | B2: 43800 | C2: 44166 | D2: 44531 | E2: 44986 | F2: 45352 | G2: 45717 | H2: Trends | I2: Mean | J2: Median
A4: Sales Growth | C4: =('Consolidated P&L'!C6-'Consolidated P&L'!B6)/'Consolidated P&L'!B6 -> -0.095462771 | D4: =('Consolidated P&L'!D6-'Consolidated P&L'!C6)/'Consolidated P&L'!C6 -> 0.18148389 | E4: =('Consolidated P&L'!E6-'Consolidated P&L'!D6)/'Consolidated P&L'!D6 -> 0.34425726 | F4: =('Consolidated P&L'!F6-'Consolidated P&L'!E6)/'Consolidated P&L'!E6 -> -0.14837778 | G4: =('Consolidated P&L'!G6-'Consolidated P&L'!F6)/'Consolidated P&L'!F6 -> 0.016226352 | I4: =AVERAGE(C4:G4) -> 0.059625392 | J4: =MEDIAN(C4:G4) -> 0.016226352
A5: EBITDA Growth | D5: =(Assumptions!C9-Assumptions!B9)/Assumptions!B9 -> 0.23725426 | E5: =(Assumptions!D9-Assumptions!C9)/Assumptions!C9 -> -0.17683112 | F5: =(Assumptions!E9-Assumptions!D9)/Assumptions!D9 -> 0.25804113 | G5: =(Assumptions!F9-Assumptions!E9)/Assumptions!E9 -> -0.27915397 | I5: =AVERAGE(D5:G5) -> 0.0098275739 | J5: =MEDIAN(D5:G5) -> 0.030211572
A6: EBIT Growth | D6: =(Assumptions!C11-Assumptions!B11)/Assumptions!B11 -> 0.31181034 | E6: =(Assumptions!D11-Assumptions!C11)/Assumptions!C11 -> -0.31565761 | F6: =(Assumptions!E11-Assumptions!D11)/Assumptions!D11 -> 0.38794742 | G6: =(Assumptions!F11-Assumptions!E11)/Assumptions!E11 -> -0.55386967 | I6: =AVERAGE(D6:G6) -> -0.042442382 | J6: =MEDIAN(D6:G6) -> -0.0019236348
A7: Net Profit Growth | D7: =(Assumptions!C17-Assumptions!B17)/Assumptions!B17 -> 0.17541768 | E7: =(Assumptions!D17-Assumptions!C17)/Assumptions!C17 -> -0.070846431 | F7: =(Assumptions!E17-Assumptions!D17)/Assumptions!D17 -> 0.38452814 | G7: =(Assumptions!F17-Assumptions!E17)/Assumptions!E17 -> 0.1651313 | I7: =AVERAGE(D7:G7) -> 0.16355767 | J7: =MEDIAN(D7:G7) -> 0.17027449
A8: Dividend Growth | D8: =('Consolidated Cash Flow'!C83-'Consolidated Cash Flow'!B83)/'Consolidated Cash Flow'!B83 -> -0.94485088 | E8: =('Consolidated Cash Flow'!D83-'Consolidated Cash Flow'!C83)/'Consolidated Cash Flow'!C83 -> 5.1920831 | F8: =('Consolidated Cash Flow'!E83-'Consolidated Cash Flow'!D83)/'Consolidated Cash Flow'!D83 -> -0.60332263 | G8: =('Consolidated Cash Flow'!F83-'Consolidated Cash Flow'!E83)/'Consolidated Cash Flow'!E83 -> -0.0076146734 | I8: =AVERAGE(D8:G8) -> 0.90907374 | J8: =MEDIAN(D8:G8) -> -0.30546865
A9: Gross Margin | B9: =('Consolidated P&L'!B6-('Consolidated P&L'!B11+'Consolidated P&L'!B12+'Consolidated P&L'!B13+'Consolidated P&L'!B17+'Consolidated P&L'!B18)-'Consolidated P&L'!B14)/'Consolidated P&L'!B6 -> 0.33202145 | C9: =('Consolidated P&L'!C6-('Consolidated P&L'!C11+'Consolidated P&L'!C12+'Consolidated P&L'!C13+'Consolidated P&L'!C17+'Consolidated P&L'!C18)-'Consolidated P&L'!C14)/'Consolidated P&L'!C6 -> 0.35700315 | D9: =('Consolidated P&L'!D6-('Consolidated P&L'!D11+'Consolidated P&L'!D12+'Consolidated P&L'!D13+'Consolidated P&L'!D17+'Consolidated P&L'!D18)-'Consolidated P&L'!D14)/'Consolidated P&L'!D6 -> 0.36435154 | E9: =('Consolidated P&L'!E6-('Consolidated P&L'!E11+'Consolidated P&L'!E12+'Consolidated P&L'!E13+'Consolidated P&L'!E17+'Consolidated P&L'!E18)-'Consolidated P&L'!E14)/'Consolidated P&L'!E6 -> 0.27439098 | F9: =('Consolidated P&L'!F6-('Consolidated P&L'!F11+'Consolidated P&L'!F12+'Consolidated P&L'!F13+'Consolidated P&L'!F17+'Consolidated P&L'!F18)-'Consolidated P&L'!F14)/'Consolidated P&L'!F6 -> 0.32491668 | G9: =('Consolidated P&L'!G6-('Consolidated P&L'!G11+'Consolidated P&L'!G12+'Consolidated P&L'!G13+'Consolidated P&L'!G17+'Consolidated P&L'!G18)-'Consolidated P&L'!G14)/'Consolidated P&L'!G6 -> 0.27057752 | I9: =AVERAGE(B9:G9) -> 0.32054355 | J9: =MEDIAN(B9:G9) -> 0.32846906
A10: EBITDA Margin | B10: =('Consolidated P&L'!B6-'Consolidated P&L'!B22+'Consolidated P&L'!B15+'Consolidated P&L'!B16)/'Consolidated P&L'!B6 -> 0.16960841 | C10: =Assumptions!B9/'Consolidated P&L'!C6 -> 0.20327115 | D10: =Assumptions!C9/'Consolidated P&L'!D6 -> 0.21286629 | E10: =Assumptions!D9/'Consolidated P&L'!E6 -> 0.13035072 | F10: =Assumptions!E9/'Consolidated P&L'!F6 -> 0.19255788 | G10: =Assumptions!F9/'Consolidated P&L'!G6 -> 0.13658825 | I10: =AVERAGE(B10:G10) -> 0.17420712 | J10: =MEDIAN(B10:G10) -> 0.18108314
A11: EBIT Margin | B11: =('Consolidated P&L'!B6-'Consolidated P&L'!B22+'Consolidated P&L'!B15)/'Consolidated P&L'!B6 -> 0.12708557 | C11: =Assumptions!B11/'Consolidated P&L'!C6 -> 0.15588283 | D11: =Assumptions!C11/'Consolidated P&L'!D6 -> 0.17307787 | E11: =Assumptions!D11/'Consolidated P&L'!E6 -> 0.088111497 | F11: =Assumptions!E11/'Consolidated P&L'!F6 -> 0.14360138 | G11: =Assumptions!F11/'Consolidated P&L'!G6 -> 0.063041988 | I11: =AVERAGE(B11:G11) -> 0.12513352 | J11: =MEDIAN(B11:G11) -> 0.13534347
A12: EBT Margin | B12: ='Consolidated P&L'!B27/'Consolidated P&L'!B6 -> 0.14298164 | C12: ='Consolidated P&L'!C27/'Consolidated P&L'!C6 -> 0.16281458 | D12: ='Consolidated P&L'!D27/'Consolidated P&L'!D6 -> 0.17829753 | E12: ='Consolidated P&L'!E27/'Consolidated P&L'!E6 -> 0.095782601 | F12: ='Consolidated P&L'!F27/'Consolidated P&L'!F6 -> 0.17794584 | G12: ='Consolidated P&L'!G27/'Consolidated P&L'!G6 -> 0.17574998 | I12: =AVERAGE(B12:G12) -> 0.15559536 | J12: =MEDIAN(B12:G12) -> 0.16928228
A13: Net Profit Margin | B13: =('Consolidated P&L'!B33-'Consolidated P&L'!B44)/'Consolidated P&L'!B6 -> 0.077296148 | C13: =Assumptions!B17/'Consolidated P&L'!C6 -> 0.096484891 | D13: =Assumptions!C17/'Consolidated P&L'!D6 -> 0.095989499 | E13: =Assumptions!D17/'Consolidated P&L'!E6 -> 0.066348152 | F13: =Assumptions!E17/'Consolidated P&L'!F6 -> 0.10786577 | G13: =Assumptions!F17/'Consolidated P&L'!G6 -> 0.12367105 | I13: =AVERAGE(B13:G13) -> 0.094609252 | J13: =MEDIAN(B13:G13) -> 0.096237195
A15: Sales Expenses%Sales | B15: ='Consolidated P&L'!B22/'Consolidated P&L'!B6 -> 0.87918188 | C15: ='Consolidated P&L'!C22/'Consolidated P&L'!C6 -> 0.84893358 | D15: ='Consolidated P&L'!D22/'Consolidated P&L'!D6 -> 0.83041008 | E15: ='Consolidated P&L'!E22/'Consolidated P&L'!E6 -> 0.91568951 | F15: ='Consolidated P&L'!F22/'Consolidated P&L'!F6 -> 0.8643004 | G15: ='Consolidated P&L'!G22/'Consolidated P&L'!G6 -> 0.94274654 | I15: =AVERAGE(B15:G15) -> 0.88021033 | J15: =MEDIAN(B15:G15) -> 0.87174114
A16: Depriciation%Sales | B16: ='Consolidated P&L'!B16/'Consolidated P&L'!B6 -> 0.042522843 | C16: ='Consolidated P&L'!C16/'Consolidated P&L'!C6 -> 0.047388316 | D16: ='Consolidated P&L'!D16/'Consolidated P&L'!D6 -> 0.039788424 | E16: ='Consolidated P&L'!E16/'Consolidated P&L'!E6 -> 0.042239226 | F16: ='Consolidated P&L'!F16/'Consolidated P&L'!F6 -> 0.048956503 | G16: ='Consolidated P&L'!G16/'Consolidated P&L'!G6 -> 0.073546266 | I16: =AVERAGE(B16:G16) -> 0.049073596 | J16: =MEDIAN(B16:G16) -> 0.044955579
A17: Operating Income%Sales | B17: =('Consolidated P&L'!B6-'Consolidated P&L'!B22+'Consolidated P&L'!B15)/'Consolidated P&L'!B6 -> 0.12708557 | C17: =Assumptions!B11/'Consolidated P&L'!C6 -> 0.15588283 | D17: =Assumptions!C11/'Consolidated P&L'!D6 -> 0.17307787 | E17: =Assumptions!D11/'Consolidated P&L'!E6 -> 0.088111497 | F17: =Assumptions!E11/'Consolidated P&L'!F6 -> 0.14360138 | G17: =Assumptions!F11/'Consolidated P&L'!G6 -> 0.063041988 | I17: =AVERAGE(B17:G17) -> 0.12513352 | J17: =MEDIAN(B17:G17) -> 0.13534347
A19: Return on Capital Employed | B19: =('Consolidated P&L'!B6-'Consolidated P&L'!B22+'Consolidated P&L'!B15)/('Consolidated Balance sheet'!B35-'Consolidated Balance sheet'!B65) -> 0.11071184 | C19: =Assumptions!B11/('Consolidated Balance sheet'!C35-'Consolidated Balance sheet'!C65) -> 0.12546331 | D19: =Assumptions!C11/('Consolidated Balance sheet'!D35-'Consolidated Balance sheet'!D65) -> 0.14753885 | E19: =Assumptions!D11/('Consolidated Balance sheet'!E35-'Consolidated Balance sheet'!E65) -> 0.085326749 | F19: =Assumptions!E11/('Consolidated Balance sheet'!F35-'Consolidated Balance sheet'!F65) -> 0.08955926 | G19: =Assumptions!F11/('Consolidated Balance sheet'!G35-'Consolidated Balance sheet'!G65) -> 0.031659691 | I19: =AVERAGE(B19:G19) -> 0.098376615 | J19: =MEDIAN(B19:G19) -> 0.10013555
A20: Retained Earning % | C20: =(Assumptions!B17+('Consolidated Cash Flow'!B83))/Assumptions!B17 -> -0.54922974 | D20: =(Assumptions!C17+('Consolidated Cash Flow'!C83))/Assumptions!C17 -> 0.92731209 | E20: =(Assumptions!D17+('Consolidated Cash Flow'!D83))/Assumptions!D17 -> 0.51559186 | F20: =(Assumptions!E17+('Consolidated Cash Flow'!E83))/Assumptions!E17 -> 0.86121355 | G20: =(Assumptions!F17+('Consolidated Cash Flow'!F83))/Assumptions!F17 -> 0.88179046 | I20: =AVERAGE(C20:G20) -> 0.52733564 | J20: =MEDIAN(C20:G20) -> 0.86121355
A21: Return on Equity % | B21: =('Consolidated P&L'!B33-'Consolidated P&L'!B44)/'Consolidated Balance sheet'!B41 -> 0.087008924 | C21: =Assumptions!B17/'Consolidated Balance sheet'!C41 -> 0.10394066 | D21: =Assumptions!C17/'Consolidated Balance sheet'!D41 -> 0.10966351 | E21: =Assumptions!D17/'Consolidated Balance sheet'!E41 -> 0.081499896 | F21: =Assumptions!E17/'Consolidated Balance sheet'!F41 -> 0.086281144 | G21: =Assumptions!F17/'Consolidated Balance sheet'!G41 -> 0.077978603 | I21: =AVERAGE(B21:G21) -> 0.091062122 | J21: =MEDIAN(B21:G21) -> 0.086645034
A22: Self Sustained Growth Rate | C22: =C21*C20 -> -0.057087303 | D22: =D21*D20 -> 0.10169229 | E22: =E21*E20 -> 0.042020683 | F22: =F21*F20 -> 0.07430649 | G22: =G21*G20 -> 0.068760788 | I22: =AVERAGE(C22:G22) -> 0.045938591 | J22: =MEDIAN(C22:G22) -> 0.068760788
A23: Interest Coverage Ratio | B23: =('Consolidated P&L'!B6-'Consolidated P&L'!B22+'Consolidated P&L'!B15)/'Consolidated P&L'!B15 -> 20.277094 | C23: =Assumptions!B11/'Consolidated P&L'!C15 -> 27.254671 | D23: =Assumptions!C11/'Consolidated P&L'!D15 -> 34.417685 | E23: =Assumptions!D11/'Consolidated P&L'!E15 -> 17.602873 | F23: =Assumptions!E11/'Consolidated P&L'!F15 -> 17.229069 | G23: =Assumptions!F11/'Consolidated P&L'!G15 -> 9.837779 | I23: =AVERAGE(B23:G23) -> 21.103195 | J23: =MEDIAN(B23:G23) -> 18.939984
A25: Debtor Turnover Ratio | B25: ='Consolidated P&L'!B6/'Consolidated Balance sheet'!B25 -> 25.364556 | C25: ='Consolidated P&L'!C6/'Consolidated Balance sheet'!C25 -> 43.690713 | D25: ='Consolidated P&L'!D6/'Consolidated Balance sheet'!D25 -> 44.849976 | E25: ='Consolidated P&L'!E6/'Consolidated Balance sheet'!E25 -> 33.730405 | F25: ='Consolidated P&L'!F6/'Consolidated Balance sheet'!F25 -> 27.333729 | G25: ='Consolidated P&L'!G6/'Consolidated Balance sheet'!G25 -> 21.189524 | I25: =AVERAGE(B25:G25) -> 32.693151 | J25: =MEDIAN(B25:G25) -> 30.532067
A26: Creditor Turnover Ratio | B26: ='Consolidated P&L'!B6/('Consolidated Balance sheet'!B59+'Consolidated Balance sheet'!B60) -> 11.618064 | C26: ='Consolidated P&L'!C6/('Consolidated Balance sheet'!C59+'Consolidated Balance sheet'!C60) -> 11.076199 | D26: ='Consolidated P&L'!D6/('Consolidated Balance sheet'!D59+'Consolidated Balance sheet'!D60) -> 9.9441297 | E26: ='Consolidated P&L'!E6/('Consolidated Balance sheet'!E59+'Consolidated Balance sheet'!E60) -> 14.036876 | F26: ='Consolidated P&L'!F6/('Consolidated Balance sheet'!F59+'Consolidated Balance sheet'!F60) -> 10.666551 | G26: ='Consolidated P&L'!G6/('Consolidated Balance sheet'!G59+'Consolidated Balance sheet'!G60) -> 12.211701 | I26: =AVERAGE(B26:G26) -> 11.592253 | J26: =MEDIAN(B26:G26) -> 11.347132
A27: Inventory Turnover | B27: =IF('Consolidated Balance sheet'!B22=0,"",('Consolidated P&L'!B6/'Consolidated Balance sheet'!B22)) -> 12.927999 | C27: =IF('Consolidated Balance sheet'!C22=0,"",('Consolidated P&L'!C6/'Consolidated Balance sheet'!C22)) -> 14.871083 | D27: =IF('Consolidated Balance sheet'!D22=0,"",('Consolidated P&L'!D6/'Consolidated Balance sheet'!D22)) -> 10.578903 | E27: =IF('Consolidated Balance sheet'!E22=0,"",('Consolidated P&L'!E6/'Consolidated Balance sheet'!E22)) -> 11.897198 | F27: =IF('Consolidated Balance sheet'!F22=0,"",('Consolidated P&L'!F6/'Consolidated Balance sheet'!F22)) -> 9.1891868 | G27: =IF('Consolidated Balance sheet'!G22=0,"",'Consolidated P&L'!G6/'Consolidated Balance sheet'!G22) -> 7.9325849 | I27: =IFERROR(AVERAGE(B27:G27),"") -> 11.232826 | J27: =IFERROR(MEDIAN(B27:G27),"") -> 11.23805
A28: Fixed Asset Turnover | B28: ='Consolidated P&L'!B6/('Consolidated Balance sheet'!B6+'Consolidated Balance sheet'!B8) -> 1.9140357 | C28: ='Consolidated P&L'!C6/('Consolidated Balance sheet'!C6+'Consolidated Balance sheet'!C8) -> 1.7135535 | D28: ='Consolidated P&L'!D6/('Consolidated Balance sheet'!D6+'Consolidated Balance sheet'!D8) -> 1.8265208 | E28: ='Consolidated P&L'!E6/('Consolidated Balance sheet'!E6+'Consolidated Balance sheet'!E8) -> 2.2565363 | F28: ='Consolidated P&L'!F6/('Consolidated Balance sheet'!F6+'Consolidated Balance sheet'!F8) -> 1.4662597 | G28: ='Consolidated P&L'!G6/('Consolidated Balance sheet'!G6+'Consolidated Balance sheet'!G8) -> 0.97740531 | I28: =AVERAGE(B28:G28) -> 1.6923852 | J28: =MEDIAN(B28:G28) -> 1.7700372
A29: Capital Turnover Ratio | B29: ='Consolidated P&L'!B6/('Consolidated Balance sheet'!B43+'Consolidated Balance sheet'!B47+IF(ISNUMBER('Consolidated Balance sheet'!B56),'Consolidated Balance sheet'!B56,0)) -> 0.90799071 | C29: ='Consolidated P&L'!C6/('Consolidated Balance sheet'!C43+'Consolidated Balance sheet'!C47+IF(ISNUMBER('Consolidated Balance sheet'!C56),'Consolidated Balance sheet'!C56,0)) -> 0.84126327 | D29: ='Consolidated P&L'!D6/('Consolidated Balance sheet'!D43+'Consolidated Balance sheet'!D47+IF(ISNUMBER('Consolidated Balance sheet'!D56),'Consolidated Balance sheet'!D56,0)) -> 0.89008726 | E29: ='Consolidated P&L'!E6/('Consolidated Balance sheet'!E43+'Consolidated Balance sheet'!E47+IF(ISNUMBER('Consolidated Balance sheet'!E56),'Consolidated Balance sheet'!E56,0)) -> 1.0034215 | F29: ='Consolidated P&L'!F6/('Consolidated Balance sheet'!F43+'Consolidated Balance sheet'!F47+IF(ISNUMBER('Consolidated Balance sheet'!F56),'Consolidated Balance sheet'!F56,0)) -> 0.65168816 | G29: ='Consolidated P&L'!G6/('Consolidated Balance sheet'!G43+'Consolidated Balance sheet'!G47+IF(ISNUMBER('Consolidated Balance sheet'!G56),'Consolidated Balance sheet'!G56,0)) -> 0.52786073 | I29: =AVERAGE(B29:G29) -> 0.80371861 | J29: =MEDIAN(B29:G29) -> 0.86567527
A31: (In days)
A32: Debtors Day | B32: ='Consolidated Balance sheet'!B25/'Consolidated P&L'!B6*365 -> 14.390159 | C32: ='Consolidated Balance sheet'!C25/'Consolidated P&L'!C6*365 -> 8.3541781 | D32: ='Consolidated Balance sheet'!D25/'Consolidated P&L'!D6*365 -> 8.1382429 | E32: ='Consolidated Balance sheet'!E25/'Consolidated P&L'!E6*365 -> 10.821098 | F32: ='Consolidated Balance sheet'!F25/'Consolidated P&L'!F6*365 -> 13.353465 | G32: ='Consolidated Balance sheet'!G25/'Consolidated P&L'!G6*365 -> 17.225493 | I32: =AVERAGE(B32:G32) -> 12.047106 | J32: =MEDIAN(B32:G32) -> 12.087281
A33: Payable Days | B33: =('Consolidated Balance sheet'!B59+'Consolidated Balance sheet'!B60)/'Consolidated P&L'!B6*365 -> 31.416593 | C33: =('Consolidated Balance sheet'!C59+'Consolidated Balance sheet'!C60)/'Consolidated P&L'!C6*365 -> 32.953542 | D33: =('Consolidated Balance sheet'!D59+'Consolidated Balance sheet'!D60)/'Consolidated P&L'!D6*365 -> 36.705072 | E33: =('Consolidated Balance sheet'!E59+'Consolidated Balance sheet'!E60)/'Consolidated P&L'!E6*365 -> 26.002937 | F33: =('Consolidated Balance sheet'!F59+'Consolidated Balance sheet'!F60)/'Consolidated P&L'!F6*365 -> 34.219121 | G33: =('Consolidated Balance sheet'!G59+'Consolidated Balance sheet'!G60)/'Consolidated P&L'!G6*365 -> 29.889366 | I33: =AVERAGE(B33:G33) -> 31.864439 | J33: =MEDIAN(B33:G33) -> 32.185068
A34: Inventory Days | B34: =IF('Consolidated Balance sheet'!B22=0,0,'Consolidated Balance sheet'!B22/'Consolidated P&L'!B6*365) -> 28.233294 | C34: =IF('Consolidated Balance sheet'!C22=0,0,'Consolidated Balance sheet'!C22/'Consolidated P&L'!C6*365) -> 24.544278 | D34: =IF('Consolidated Balance sheet'!D22=0,0,'Consolidated Balance sheet'!D22/'Consolidated P&L'!D6*365) -> 34.502632 | E34: =IF('Consolidated Balance sheet'!E22=0,0,'Consolidated Balance sheet'!E22/'Consolidated P&L'!E6*365) -> 30.679493 | F34: =IF('Consolidated Balance sheet'!F22=0,0,'Consolidated Balance sheet'!F22/'Consolidated P&L'!F6*365) -> 39.720599 | G34: =IF('Consolidated Balance sheet'!G22=0,0,'Consolidated Balance sheet'!G22/'Consolidated P&L'!G6*365) -> 46.012744 | I34: =AVERAGE(B34:G34) -> 33.94884 | J34: =MEDIAN(B34:G34) -> 32.591063
A35: Cash Conversion Cycle | B35: =B32+B34-B33 -> 11.20686 | C35: =C32+C34-C33 -> -0.055086092 | D35: =D32+D34-D33 -> 5.9358025 | E35: =E32+E34-E33 -> 15.497654 | F35: =F32+F34-F33 -> 18.854942 | G35: =G32+G34-G33 -> 33.348871 | I35: =AVERAGE(B35:G35) -> 14.131507 | J35: =MEDIAN(B35:G35) -> 13.352257
A37: CFO/Sales | C37: ='Consolidated Cash Flow'!B48/'Consolidated P&L'!C6 -> 0.1971095 | D37: ='Consolidated Cash Flow'!C48/'Consolidated P&L'!D6 -> 0.18329279 | E37: ='Consolidated Cash Flow'!D48/'Consolidated P&L'!E6 -> 0.018874578 | F37: ='Consolidated Cash Flow'!E48/'Consolidated P&L'!F6 -> 0.1702618 | G37: ='Consolidated Cash Flow'!F48/'Consolidated P&L'!G6 -> 0.066394739 | I37: =AVERAGE(C37:G37) -> 0.12718668 | J37: =MEDIAN(C37:G37) -> 0.1702618
A38: CFO/Total Assets | C38: ='Consolidated Cash Flow'!B48/'Consolidated Balance sheet'!C35 -> 0.12165873 | D38: ='Consolidated Cash Flow'!C48/'Consolidated Balance sheet'!D35 -> 0.11744038 | E38: ='Consolidated Cash Flow'!D48/'Consolidated Balance sheet'!E35 -> 0.014209189 | F38: ='Consolidated Cash Flow'!E48/'Consolidated Balance sheet'!F35 -> 0.086462624 | G38: ='Consolidated Cash Flow'!F48/'Consolidated Balance sheet'!G35 -> 0.027640233 | I38: =AVERAGE(C38:G38) -> 0.073482231 | J38: =MEDIAN(C38:G38) -> 0.086462624
A39: CFO/Total Debt | C39: =IF('Consolidated Balance sheet'!C47+IF(ISNUMBER('Consolidated Balance sheet'!C56),'Consolidated Balance sheet'!C56,0)=0,"",'Consolidated Cash Flow'!B48/('Consolidated Balance sheet'!C47+IF(ISNUMBER('Consolidated Balance sheet'!C56),'Consolidated Balance sheet'!C56,0))) -> 110.83417 | D39: =IF('Consolidated Balance sheet'!D47+IF(ISNUMBER('Consolidated Balance sheet'!D56),'Consolidated Balance sheet'!D56,0)=0,"",'Consolidated Cash Flow'!C48/('Consolidated Balance sheet'!D47+IF(ISNUMBER('Consolidated Balance sheet'!D56),'Consolidated Balance sheet'!D56,0))) -> 122.04966 | E39: =IF('Consolidated Balance sheet'!E47+'Consolidated Balance sheet'!E56=0,"",'Consolidated Cash Flow'!D48/('Consolidated Balance sheet'!E47+'Consolidated Balance sheet'!E56)) -> 15.403899 | F39: =IF('Consolidated Balance sheet'!F47+'Consolidated Balance sheet'!F56=0,"",'Consolidated Cash Flow'!E48/('Consolidated Balance sheet'!F47+'Consolidated Balance sheet'!F56)) -> 153.50245 | G39: =IF('Consolidated Balance sheet'!G47+'Consolidated Balance sheet'!G56=0,"",'Consolidated Cash Flow'!F48/('Consolidated Balance sheet'!G47+'Consolidated Balance sheet'!G56)) -> 83.420955 | I39: =IFERROR(AVERAGE(C39:G39),"") -> 97.042226 | J39: =IFERROR(MEDIAN(C39:G39),"") -> 110.83417

Sheet Fixed Asset Scheduled
A1: Particular | B1: Dec 31, 2020 | C1: Dec 31, 2021 | D1: Mar 31, 2023 | E1: Mar 31, 2024 | F1: Mar 31, 2025
A2: Beginning balance | B2: ='Consolidated Balance sheet'!B6 -> 12605.99 | C2: =B6 -> 11885.36 | D2: =C6 -> 13661.89 | E2: =D6 -> 14729.35 | F2: =E6 -> 19956.67
A3: Add: Net Purchases | B3: =B6+B5-B2 -> 441.15 | C3: =C6+C5-C2 -> 2929.02 | D3: =D6+D5-D2 -> 2712.13 | E3: =E6+E5-E2 -> 6850.7 | F3: =F6+F5-F2 -> 7177.96
A4: Total Fixed Assets | B4: =B2+B3 -> 13047.14 | C4: =C2+C3 -> 14814.38 | D4: =D2+D3 -> 16374.02 | E4: =E2+E3 -> 21580.05 | F4: =F2+F3 -> 27134.63
A5: Less: Depreciation | B5: =Assumptions!B10 -> 1161.78 | C5: =Assumptions!C10 -> 1152.49 | D5: =Assumptions!D10 -> 1644.67 | E5: =Assumptions!E10 -> 1623.38 | F5: =Assumptions!F10 -> 2478.34
A6: Closing Balance(Fixed Asests ) | B6: ='Consolidated Balance sheet'!C6 -> 11885.36 | C6: ='Consolidated Balance sheet'!D6 -> 13661.89 | D6: ='Consolidated Balance sheet'!E6 -> 14729.35 | E6: ='Consolidated Balance sheet'!F6 -> 19956.67 | F6: ='Consolidated Balance sheet'!G6 -> 24656.29
