Workbook

Sheet About the Company
C2: DLF LIMITED
C4: Corporate Profile | Annual Report FY 2024-25 | Equity Research Note
A8: ABOUT THE COMPANY (DLF LIMITED)
A9: Business Overview, Chairman's Message & Key Corporate Facts
A11: MESSAGE FROM THE CHAIRMAN In his message to shareholders, Chairman Mr. Rajiv Singh noted that both the Residential and Rental businesses delivered strong growth in FY 2024-25, supported by record sales bookings on new launches such as The Dahlias and Privana, and continued capital investment in new office and retail build-outs across Gurugram, Chennai, Delhi and Goa. He reaffirmed the Company's commitment to good governance, transparency and sustainable, long-term value creation for all stakeholders, while reiterating DLF's vision of contributing to India's 'Viksit Bharat' goal by 2047. WHO WE ARE DLF Limited is one of India's largest and most reputed real estate development companies, with a track record spanning over six decades since its incorporation in 1963. Headquartered in Gurugram, Haryana, the Company has built and delivered a diversified portfolio of residential, commercial and retail developments across the country and is recognised as one of India's most trusted real estate brands. DLF is listed on both BSE Limited and the National Stock Exchange of India Limited. BUSINESS SEGMENTS / SERVICES OFFERED DLF's operations are organised around two core business verticals. The Development Business focuses on the design, construction and sale of residential products, including high-rise condominiums, low-rise independent floors, plotted developments and shop-cum-offices. The Rental (Annuity) Business comprises Offices, Retail and Hospitality assets, largely held and operated through DLF Cyber City Developers Limited (DCCDL), a 66.66%-owned subsidiary and joint venture platform with Reco Greens Pte. Limited, an affiliate of GIC, Singapore. KEY MARKETS / SEGMENTS SERVED Residential Real Estate: Super-luxury and luxury housing, plotted developments and independent floors across Gurugram, Delhi, Chennai, Goa and Panchkula. Commercial Offices: Grade-A office parks and business districts serving Global Capability Centres (GCCs), BFSI and technology occupiers. Retail: Shopping malls and lifestyle destinations, including DLF Promenade, DLF Mall of India and Midtown Plaza. Hospitality: Premium hotels and clubs, including The Lodhi, New Delhi, and DLF's golf and recreation clubs.
A34: KEY SUBSIDIARIES, JOINT VENTURES & ASSOCIATES
A35: S. No. | B35: Company Name | D35: Nature of Business | F35: Holding (%)
A36: 1 | B36: DLF Home Developers Limited | D36: Residential Real Estate Development | F36: 100.00
A37: 2 | B37: DLF Cyber City Developers Limited (DCCDL) | D37: Office, Retail & Hospitality (Rental Business / JV with GIC, Singapore) | F37: 66.66
A38: 3 | B38: DLF Universal Limited | D38: Real Estate Development | F38: 100.00
A39: 4 | B39: DLF Utilities Limited | D39: Utility & Infrastructure Services | F39: 100.00
A40: 5 | B40: DLF Projects Limited | D40: Project & Construction Management | F40: 100.00
A41: 6 | B41: DLF Property Developers Limited | D41: Real Estate Development | F41: 100.00
A42: 7 | B42: DLF Luxury Homes Limited | D42: Premium Residential Development | F42: 100.00
A43: 8 | B43: Lodhi Property Company Limited | D43: Hospitality (The Lodhi, New Delhi) | F43: 100.00
A44: 9 | B44: DLF Info City Hyderabad Limited | D44: IT Park / Commercial Development | F44: 100.00
A45: 10 | B45: DLF Info Park (Pune) Limited | D45: IT Park / Commercial Development | F45: 100.00
A46: 11 | B46: DLF Southern Towns Private Limited | D46: Residential Development (South India) | F46: 100.00
A47: 12 | B47: DLF Residential Partners Limited | D47: Residential Development | F47: 100.00
... A49: 14 | B49: DLF Homes Panchkula Private Limited | D49: Residential Development | F49: 99.94
A51: REGISTERED OFFICE & CORPORATE INFORMATION
A52: Registered Office | C52: Shopping Mall, 3rd Floor, Arjun Marg, Phase-I, DLF City, Gurugram – 122 002, Haryana, India
A53: Corporate Office | C53: DLF Gateway Tower, R Block, DLF City, Phase-III, Gurugram – 122 002, Haryana, India
A54: Corporate Identity Number (CIN) | C54: L70101HR1963PLC002484
A55: Listed At | C55: BSE Limited (BSE) and National Stock Exchange of India Limited (NSE)
A57: KEY OPERATING METRICS
A58: Metric | C58: Value | D58: Details
A59: Track Record | C59: 8 Decades | D59: Real estate operations since incorporation in 1963
A60: Real Estate Projects Developed | C60: 178 | D60: Across residential, commercial and retail segments
A61: Cumulative Area Developed | C61: 349 msf | D61: Since inception
A62: Development Potential | C62: 205 msf | D62: Combined Devco & Rentco pipeline
A63: Operational Rental Portfolio | C63: 45 msf | D63: Offices, Retail & Hospitality (through DCCDL)
A64: Pan-India Presence | C64: 132 locations | D64: Across India; no international operations (per BRSR disclosure)

Sheet Promoter
A1: DLF LIMITED | SHAREHOLDING PATTERN — PROMOTER & PROMOTER GROUP (CATEGORY A)
A2: Per Regulation 31, SEBI (LODR) Regulations, 2015 | Capital Structure Annexure — Equity Research
A4: Category of Shareholder | B4: Entity Type | C4: No. of Shareholders | D4: No. of Fully Paid-up Equity Shares Held | E4: Total Shares Held | F4: Shareholding (% of Total) | G4: Voting Rights Held (Class: Equity) | H4: Voting Rights (% of Total) | I4: Shares on Fully Diluted Basis | J4: Shareholding % (Diluted Basis) | K4: Shares Held in Dematerialised Form
A5: A5) Indian
A6: Individuals/Hindu undivided Family | C6: 5 | D6: 23531900 | E6: 23531900 | F6: 0.95 | G6: 23531900 | H6: 0.95 | I6: 23531900 | J6: 0.95 | K6: 23531900
A7: PIA SINGH | B7: Promoter Group | C7: 1 | D7: 21420500 | E7: 21420500 | F7: 0.87 | G7: 21420500 | H7: 0.87 | I7: 21420500 | J7: 0.87 | K7: 21420500
A8: RENUKA TALWAR | B8: Promoter Group | C8: 1 | D8: 1540000 | E8: 1540000 | F8: 0.06 | G8: 1540000 | H8: 0.06 | I8: 1540000 | J8: 0.06 | K8: 1540000
A9: RAJIV SINGH | B9: Promoter | C9: 1 | D9: 256320 | E9: 256320 | F9: 0.01 | G9: 256320 | H9: 0.01 | I9: 256320 | J9: 0.01 | K9: 256320
A10: KAVITA SINGH | B10: Promoter Group | C10: 1 | D10: 314080 | E10: 314080 | F10: 0.01 | G10: 314080 | H10: 0.01 | I10: 314080 | J10: 0.01 | K10: 314080
A11: ANUSHKA SINGH | B11: Promoter Group | C11: 1 | D11: 1000 | E11: 1000 | F11: 0 | G11: 1000 | H11: 0 | I11: 1000 | J11: 0 | K11: 1000
A12: K. P. SINGH (HUF) [KARTA- KUSHAL PAL SINGH] | B12: Promoter Group | C12: - | D12: - | E12: - | F12: 0 | G12: - | H12: 0 | I12: - | J12: 0 | K12: -
A13: Any Other (specify) | C13: 7 | D13: 1810103485 | E13: 1810103485 | F13: 73.13 | G13: 1810103485 | H13: 73.13 | I13: 1810103485 | J13: 73.13 | K13: 1810103485
A14: RAJDHANI INVESTMENTS AND AGENCIES PRIVATE LIMITED | B14: Promoter | C14: 1 | D14: 1523133505 | E14: 1523133505 | F14: 61.53 | G14: 1523133505 | H14: 61.53 | I14: 1523133505 | J14: 61.53 | K14: 1523133505
A15: UNIVERSAL MANAGEMENT AND SALES LLP | B15: Promoter Group | C15: 1 | D15: 5455560 | E15: 5455560 | F15: 0.22 | G15: 5455560 | H15: 0.22 | I15: 5455560 | J15: 0.22 | K15: 5455560
A16: JHANDEWALAN ANCILLARIES LLP | B16: Promoter Group | C16: 1 | D16: 47388000 | E16: 47388000 | F16: 1.91 | G16: 47388000 | H16: 1.91 | I16: 47388000 | J16: 1.91 | K16: 47388000
A17: BEVERLY BUILDERS LLP | B17: Promoter Group | C17: - | D17: - | E17: - | F17: 0 | G17: - | H17: 0 | I17: - | J17: 0 | K17: -
A18: PARVATI ESTATES LLP | B18: Promoter Group | C18: 1 | D18: 6380000 | E18: 6380000 | F18: 0.26 | G18: 6380000 | H18: 0.26 | I18: 6380000 | J18: 0.26 | K18: 6380000
A19: PREM TRADERS LLP | B19: Promoter Group | C19: 1 | D19: 90059200 | E19: 90059200 | F19: 3.64 | G19: 90059200 | H19: 3.64 | I19: 90059200 | J19: 3.64 | K19: 90059200
A20: RAISINA AGENCIES LLP | B20: Promoter Group | C20: 1 | D20: 65889120 | E20: 65889120 | F20: 2.66 | G20: 65889120 | H20: 2.66 | I20: 65889120 | J20: 2.66 | K20: 65889120
A21: MALLIKA HOUSING COMPANY LLP | B21: Promoter Group | C21: 1 | D21: 71798100 | E21: 71798100 | F21: 2.9 | G21: 71798100 | H21: 2.9 | I21: 71798100 | J21: 2.9 | K21: 71798100
A22: PREM'S WILL TRUST (TRUSTEE- KUSHAL PAL SINGH, RAJIV SINGH AND PIA SINGH) | B22: Promoter Group | C22: - | D22: - | E22: - | F22: 0 | G22: - | H22: 0 | I22: - | J22: 0 | K22: -
A23: REALEST BUILDERS AND SERVICES PRIVATE LIMITED | B23: Promoter Group | C23: - | D23: - | E23: - | F23: 0 | G23: - | H23: 0 | I23: - | J23: 0 | K23: -
A24: AGS BUILDTECH PRIVATE LIMITED | B24: Promoter Group | C24: - | D24: - | E24: - | F24: 0 | G24: - | H24: 0 | I24: - | J24: 0 | K24: -
A25: A.S.G. REALCON PRIVATE LIMITED | B25: Promoter Group | C25: - | D25: - | E25: - | F25: 0 | G25: - | H25: 0 | I25: - | J25: 0 | K25: -
A26: HITECH PROPERTY DEVELOPERS PRIVATE LIMITED | B26: Promoter Group | C26: - | D26: - | E26: - | F26: 0 | G26: - | H26: 0 | I26: - | J26: 0 | K26: -
A27: SIDHANT REAL ESTATE DEVELOPERS AND SERVICES PRIVATE LIMITED | B27: Promoter Group | C27: - | D27: - | E27: - | F27: 0 | G27: - | H27: 0 | I27: - | J27: 0 | K27: -
A28: TRINITY HOUSING AND CONSTRUCTION COMPANY | B28: Promoter Group | C28: - | D28: - | E28: - | F28: 0 | G28: - | H28: 0 | I28: - | J28: 0 | K28: -
A29: UTTAM BUILDERS AND DEVELOPERS PRIVATE LIMITED | B29: Promoter Group | C29: - | D29: - | E29: - | F29: 0 | G29: - | H29: 0 | I29: - | J29: 0 | K29: -
A30: UTTAM REAL ESTATES COMPANY | B30: Promoter Group | C30: - | D30: - | E30: - | F30: 0 | G30: - | H30: 0 | I30: - | J30: 0 | K30: -
A31: MADHUKAR HOUSING AND DEVELOPMENT COMPANY | B31: Promoter Group | C31: - | D31: - | E31: - | F31: 0 | G31: - | H31: 0 | I31: - | J31: 0 | K31: -
A32: RENKON PARTNERS | B32: Promoter Group | C32: - | D32: - | E32: - | F32: 0 | G32: - | H32: 0 | I32: - | J32: 0 | K32: -
A33: GENERAL MARKETING CORPORATION | B33: Promoter Group | C33: - | D33: - | E33: - | F33: 0 | G33: - | H33: 0 | I33: - | J33: 0 | K33: -
... A61: R.R. FAMILY TRUST (TRUSTEE – RENUKA TALWAR AND PIA SINGH) | B61: Promoter Group | C61: - | D61: - | E61: - | F61: 0 | G61: - | H61: 0 | I61: - | J61: 0 | K61: -
A62: Sub Total A1 | C62: 12 | D62: 1833635385 | E62: 1833635385 | F62: 74.08 | G62: 1833635385 | H62: 74.08 | I62: 1833635385 | J62: 74.08 | K62: 1833635385
A63: A6) Foreign
A64: Individuals (NonResident Individuals/ Foreign Individuals) | C64: 1 | D64: 1000 | E64: 1000 | F64: 0 | G64: 1000 | H64: 0 | I64: 1000 | J64: 0 | K64: 1000
A65: KUSHAL PAL SINGH | B65: Promoter | C65: - | D65: - | E65: - | F65: 0 | G65: - | H65: 0 | I65: - | J65: 0 | K65: -
A66: SAVITRI DEVI SINGH | B66: Promoter Group | C66: 1 | D66: 1000 | E66: 1000 | F66: 0 | G66: 1000 | H66: 0 | I66: 1000 | J66: 0 | K66: 1000
A67: Any Other (specify) | C67: - | D67: - | E67: - | F67: 0 | G67: - | H67: 0 | I67: - | J67: 0 | K67: -
A68: BECKON INVESTMENTS GROUP LIMITED | B68: Promoter Group | C68: - | D68: - | E68: - | F68: 0 | G68: - | H68: 0 | I68: - | J68: 0 | K68: -
...

Sheet Public
A1: DLF LIMITED | SHAREHOLDING PATTERN — PUBLIC SHAREHOLDING (CATEGORY B)
A2: Per Regulation 31, SEBI (LODR) Regulations, 2015 | Capital Structure Annexure — Equity Research
A4: Category & Name of Shareholder | B4: No. of Shareholders | C4: No. of Fully Paid-up Equity Shares Held | D4: Total Shares Held | E4: Shareholding (% of Total) | F4: No. of Voting Rights | G4: Voting Rights (% of Total) | H4: Shares on Fully Diluted Basis | I4: Shareholding % (Diluted Basis) | J4: Shares Held in Dematerialised Form | K4: Sub-Category I (No. of Shares) | L4: Sub-Category II (No. of Shares) | M4: Sub-Category III (No. of Shares)
A5: Institutions
A6: B2) Institutions (Domestic) | B6: 0 | C6: 0 | D6: - | E6: 0 | F6: - | G6: 0 | H6: - | I6: 0 | J6: - | K6: - | L6: - | M6: -
A7: Mutual Funds/ | B7: 42 | C7: 127406762 | D7: 127406762 | E7: 5.15 | F7: 127406762 | G7: 5.15 | H7: 127406762 | I7: 5.15 | J7: 127406762 | K7: - | L7: - | M7: -
A8: SBI EQUITY HYBRID FUND | B8: 1 | C8: 26622038 | D8: 26622038 | E8: 1.08 | F8: 26622038 | G8: 1.08 | H8: 26622038 | I8: 1.08 | J8: 26622038 | K8: - | L8: - | M8: -
A9: ICICI PRUDENTIAL LARGE CAP FUND | B9: 1 | C9: 35900187 | D9: 35900187 | E9: 1.45 | F9: 35900187 | G9: 1.45 | H9: 35900187 | I9: 1.45 | J9: 35900187 | K9: - | L9: - | M9: -
A10: Venture Capital Funds | B10: 0 | C10: 0 | D10: - | E10: 0 | F10: - | G10: 0 | H10: - | I10: 0 | J10: - | K10: - | L10: - | M10: -
A11: Alternate Investment Funds | B11: 15 | C11: 2032639 | D11: 2032639 | E11: 0.08 | F11: 2032639 | G11: 0.08 | H11: 2032639 | I11: 0.08 | J11: 2032639 | K11: - | L11: - | M11: -
A12: Banks | B12: 2 | C12: 465931 | D12: 465931 | E12: 0.02 | F12: 465931 | G12: 0.02 | H12: 465931 | I12: 0.02 | J12: 465931 | K12: - | L12: - | M12: -
A13: Insurance Companies | B13: 15 | C13: 22533357 | D13: 22533357 | E13: 0.91 | F13: 22533357 | G13: 0.91 | H13: 22533357 | I13: 0.91 | J13: 22533357 | K13: - | L13: - | M13: -
A14: Provident Funds/ Pension Funds | B14: 1 | C14: 18967466 | D14: 18967466 | E14: 0.77 | F14: 18967466 | G14: 0.77 | H14: 18967466 | I14: 0.77 | J14: 18967466 | K14: - | L14: - | M14: -
A15: Asset reconstruction companies | B15: 0 | C15: 0 | D15: - | E15: 0 | F15: - | G15: 0 | H15: - | I15: 0 | J15: - | K15: - | L15: - | M15: -
A16: Sovereign Wealth Funds | B16: 0 | C16: 0 | D16: - | E16: 0 | F16: - | G16: 0 | H16: - | I16: 0 | J16: - | K16: - | L16: - | M16: -
A17: NBFCs registered with RBI | B17: 2 | C17: 367540 | D17: 367540 | E17: 0.01 | F17: 367540 | G17: 0.01 | H17: 367540 | I17: 0.01 | J17: 367540 | K17: - | L17: - | M17: -
A18: Other Financial Institutions | B18: 0 | C18: 0 | D18: - | E18: 0 | F18: - | G18: 0 | H18: - | I18: 0 | J18: - | K18: - | L18: - | M18: -
A19: Any Other(Institutions (Domestic)) | B19: 0 | C19: 0 | D19: - | E19: 0 | F19: - | G19: 0 | H19: - | I19: 0 | J19: - | K19: - | L19: - | M19: -
A20: Sub Total B1 | B20: 77 | C20: 171773695 | D20: 171773695 | E20: 6.94 | F20: 171773695 | G20: 6.94 | H20: 171773695 | I20: 6.94 | J20: 171773695 | K20: - | L20: - | M20: -
A21: B17) Institutions (Foreign)
A22: Foreign Direct Investment | B22: 0 | C22: 0 | D22: - | E22: 0 | F22: - | G22: 0 | H22: - | I22: 0 | J22: - | K22: - | L22: - | M22: -
A23: Foreign Venture Capital Investors | B23: 0 | C23: 0 | D23: - | E23: 0 | F23: - | G23: 0 | H23: - | I23: 0 | J23: - | K23: - | L23: - | M23: -
A24: Sovereign Wealth Funds | B24: 0 | C24: 0 | D24: - | E24: 0 | F24: - | G24: 0 | H24: - | I24: 0 | J24: - | K24: - | L24: - | M24: -
A25: Foreign Portfolio Investors Category I | B25: 689 | C25: 326976953 | D25: 326976953 | E25: 13.21 | F25: 326976953 | G25: 13.21 | H25: 326976953 | I25: 13.21 | J25: 326976953 | K25: - | L25: - | M25: -
A26: INVESCO GLOBAL FUND | B26: 1 | C26: 32185164 | D26: 32185164 | E26: 1.3 | F26: 32185164 | G26: 1.3 | H26: 32185164 | I26: 1.3 | J26: 32185164 | K26: - | L26: - | M26: -
A27: Foreign Portfolio Investors Category II | B27: 37 | C27: 8194544 | D27: 8194544 | E27: 0.33 | F27: 8194544 | G27: 0.33 | H27: 8194544 | I27: 0.33 | J27: 8194544 | K27: - | L27: - | M27: -
A28: Overseas Depositories (holding DRs) (balancing figure) | B28: 0 | C28: 0 | D28: - | E28: 0 | F28: - | G28: 0 | H28: - | I28: 0 | J28: - | K28: - | L28: - | M28: -
A29: Any Other(Institutions (Foreign)) | B29: 0 | C29: 0 | D29: - | E29: 0 | F29: - | G29: 0 | H29: - | I29: 0 | J29: - | K29: - | L29: - | M29: -
A30: Sub Total B2 | B30: 726 | C30: 335171497 | D30: 335171497 | E30: 13.54 | F30: 335171497 | G30: 13.54 | H30: 335171497 | I30: 13.54 | J30: 335171497 | K30: - | L30: - | M30: -
A31: B27) Central Government/ State Government(s)/ President of India
A32: Central Government / President of India | B32: 0 | C32: 0 | D32: - | E32: 0 | F32: - | G32: 0 | H32: - | I32: 0 | J32: - | K32: - | L32: - | M32: -
A33: State Government / Governor | B33: 0 | C33: 0 | D33: - | E33: 0 | F33: - | G33: 0 | H33: - | I33: 0 | J33: - | K33: - | L33: - | M33: -
A34: Shareholding by Companies or Bodies Corporate where Central / State Government is a promoter | B34: 3 | C34: 2883 | D34: 2883 | E34: 0 | F34: 2883 | G34: 0 | H34: 2883 | I34: 0 | J34: 2883 | K34: - | L34: - | M34: -
A35: Sub Total B3 | B35: 3 | C35: 2883 | D35: 2883 | E35: 0 | F35: 2883 | G35: 0 | H35: 2883 | I35: 0 | J35: 2883 | K35: - | L35: - | M35: -
A36: B32) Non-Institutions
A37: Associate companies / Subsidiaries | B37: 0 | C37: 0 | D37: - | E37: 0 | F37: - | G37: 0 | H37: - | I37: 0 | J37: - | K37: - | L37: - | M37: -
A38: Directors and their relatives (excluding independent directors and nominee directors) | B38: 2 | C38: 357453 | D38: 357453 | E38: 0.01 | F38: 357453 | G38: 0.01 | H38: 357453 | I38: 0.01 | J38: 357453 | K38: - | L38: - | M38: -
A39: Key Managerial Personnel | B39: 1 | C39: 10254 | D39: 10254 | E39: 0 | F39: 10254 | G39: 0 | H39: 10254 | I39: 0 | J39: 10254 | K39: - | L39: - | M39: -
A40: Relatives of promoters (other than 'immediate relatives' of promoters disclosed under 'Promoter and Promoter Group' category) | B40: 0 | C40: 0 | D40: - | E40: 0 | F40: - | G40: 0 | H40: - | I40: 0 | J40: - | K40: - | L40: - | M40: -
A41: Trusts where any person belonging to 'Promoter and Promoter Group' category is 'trustee', 'beneficiary', or 'author of the trust' | B41: 0 | C41: 0 | D41: - | E41: 0 | F41: - | G41: 0 | H41: - | I41: 0 | J41: - | K41: - | L41: - | M41: -
...

Sheet Consolidated P&L
A1: Consolidated Profit & Loss Account
A2: (Rs. Cr.) | B2: Mar 22 | C2: Mar 23 | D2: Mar 24 | E2: Mar 25 | F2: Mar 26
A3: INCOME
A4: Revenue From Operations [Gross] | B4: 5708.99 | C4: 5681.97 | D4: 6249.21 | E4: 7946.6 | F4: 8194.02
A5: Revenue From Operations [Net] | B5: 5708.99 | C5: 5681.97 | D5: 6249.21 | E5: 7946.6 | F5: 8194.02
A6: Other Operating Revenues | B6: 8.4 | C6: 12.86 | D6: 177.79 | E6: 47.06 | F6: 0
A7: Total Operating Revenues | B7: 5717.39 | C7: 5694.83 | D7: 6427 | E7: 7993.66 | F7: 8194.02
A8: Other Income | B8: 420.46 | C8: 317.31 | D8: 531.34 | E8: 1002.23 | F8: 1622.02
A9: Total Revenue | B9: 6137.84 | C9: 6012.14 | D9: 6958.34 | E9: 8995.89 | F9: 9816.04
A10: EXPENSES
A11: Cost Of Materials Consumed | B11: 0 | C11: 0 | D11: 0 | E11: 0 | F11: 4848.57
A12: Operating And Direct Expenses | B12: 2744.96 | C12: 2433.96 | D12: 2793.76 | E12: 4131.58 | F12: 0
A13: Employee Benefit Expenses | B13: 353.99 | C13: 547.88 | D13: 545.95 | E13: 591.96 | F13: 640.3
A14: Finance Costs | B14: 624.55 | C14: 392.14 | D14: 356.45 | E14: 397.2 | F14: 199.07
A15: Depreciation And Amortisation Expenses | B15: 149.44 | C15: 148.63 | D15: 147.95 | E15: 150.66 | F15: 142.41
A16: Other Expenses | B16: 875.88 | C16: 987.11 | D16: 963.69 | E16: 1161.48 | F16: 1256.79
A17: Total Expenses | B17: 4748.82 | C17: 4509.72 | D17: 4807.8 | E17: 6432.88 | F17: 7087.14
A18: Profit/Loss Before Exceptional, ExtraOrdinary Items And Tax | B18: 1389.03 | C18: 1502.42 | D18: 2150.55 | E18: 2563.01 | F18: 2728.9
A19: Exceptional Items | B19: -224.43 | C19: 0 | D19: 0 | E19: -302.39 | F19: 202.92
A20: Profit/Loss Before Tax | B20: 1164.59 | C20: 1502.42 | D20: 2150.55 | E20: 2260.62 | F20: 2931.82
A21: Tax Expenses-Continued Operations
A22: Current Tax | B22: 59.48 | C22: 56.88 | D22: 124.67 | E22: 89.45 | F22: 309.97
A23: Deferred Tax | B23: 261.5 | C23: 407.23 | D23: 384.05 | E23: -1110.89 | F23: 0
A24: Tax For Earlier Years | B24: 0 | C24: -62.61 | D24: 11.42 | E24: 587.55 | F24: 0
A25: Total Tax Expenses | B25: 320.97 | C25: 401.5 | D25: 520.13 | E25: -433.89 | F25: 309.97
A26: Profit/Loss After Tax And Before ExtraOrdinary Items | B26: 843.62 | C26: 1100.92 | D26: 1630.42 | E26: 2694.51 | F26: 2621.85
A27: Profit/Loss From Continuing Operations | B27: 843.62 | C27: 1100.92 | D27: 1630.42 | E27: 2694.51 | F27: 2621.85
A28: Profit/Loss For The Period | B28: 843.62 | C28: 1100.92 | D28: 1630.42 | E28: 2694.51 | F28: 2621.85
A29: Minority Interest | B29: 0.54 | C29: 1.88 | D29: 3.56 | E29: 0.8 | F29: 0
A30: Share Of Profit/Loss Of Associates | B30: 656.7 | C30: 933.03 | D30: 1093.13 | E30: 1672.31 | F30: 1792.83
A31: Consolidated Profit/Loss After MI And Associates | B31: 1500.85 | C31: 2035.83 | D31: 2727.11 | E31: 4367.62 | F31: 4414.68
A32: EARNINGS PER SHARE
A33: Basic EPS (Rs.) | B33: 6 | C33: 8 | D33: 11 | E33: 18 | F33: 18
A34: Diluted EPS (Rs.) | B34: 6 | C34: 8 | D34: 11 | E34: 18 | F34: 18
A35: DIVIDEND AND DIVIDEND PERCENTAGE
A36: Equity Share Dividend | B36: 495.06 | C36: 742.59 | D36: 990.12 | E36: 1237.66 | F36: 0

Sheet Consolidated Balance Sheet
A1: Consolidated Balance Sheet
A2: (Rs. Cr.) | B2: Mar 22 | C2: Mar 23 | D2: Mar 24 | E2: Mar 25 | F2: Mar 26
A3: EQUITIES AND LIABILITIES
A4: SHAREHOLDER'S FUNDS
A5: Equity Share Capital | B5: 495.06 | C5: 495.06 | D5: 495.06 | E5: 495.06 | F5: 495.06
A6: Total Share Capital | B6: 495.06 | C6: 495.06 | D6: 495.06 | E6: 495.06 | F6: 495.06
A7: Reserves and Surplus | B7: 35867.22 | C7: 37192.47 | D7: 38935.75 | E7: 42055.16 | F7: 44978.31
A8: Total Reserves and Surplus | B8: 35867.22 | C8: 37192.47 | D8: 38935.75 | E8: 42055.16 | F8: 44978.31
A9: Total Shareholders Funds | B9: 36362.28 | C9: 37687.53 | D9: 39430.81 | E9: 42550.22 | F9: 45473.37
A10: Minority Interest | B10: 19.47 | C10: 4.36 | D10: 0.8 | E10: 0 | F10: 0
A11: NON-CURRENT LIABILITIES
A12: Long Term Borrowings | B12: 2189.46 | C12: 1049.66 | D12: 2438.99 | E12: 1672.07 | F12: 0
A13: Deferred Tax Liabilities [Net] | B13: 2141.56 | C13: 2574.33 | D13: 2790.19 | E13: 1514.78 | F13: 2143.18
A14: Other Long Term Liabilities | B14: 1337.89 | C14: 1377.33 | D14: 1406.56 | E14: 1452.41 | F14: 1549.48
A15: Long Term Provisions | B15: 48.88 | C15: 50.01 | D15: 54 | E15: 52.89 | F15: 107.75
A16: Total Non-Current Liabilities | B16: 5717.79 | C16: 5051.33 | D16: 6689.73 | E16: 4692.16 | F16: 3800.41
A17: CURRENT LIABILITIES
A18: Short Term Borrowings | B18: 1770.54 | C18: 2053.43 | D18: 2159.73 | E18: 2181.96 | F18: 44.95
A19: Trade Payables | B19: 1528.73 | C19: 1643.7 | D19: 1787.82 | E19: 2261.03 | F19: 1719.59
A20: Other Current Liabilities | B20: 7059.5 | C20: 7451.88 | D20: 10118.82 | E20: 17748.64 | F20: 23757.07
A21: Short Term Provisions | B21: 45.09 | C21: 35.76 | D21: 74.68 | E21: 41.37 | F21: 79.38
A22: Total Current Liabilities | B22: 10403.85 | C22: 11184.76 | D22: 14141.05 | E22: 22233 | F22: 25600.99
A23: Total Capital And Liabilities | B23: 52503.4 | C23: 53927.99 | D23: 60262.4 | E23: 69475.37 | F23: 74874.77
A24: ASSETS
A25: NON-CURRENT ASSETS
A26: Tangible Assets | B26: 3771.75 | C26: 3699.49 | D26: 2799.41 | E26: 2427.8 | F26: 2955.79
A27: Intangible Assets | B27: 146.39 | C27: 141.65 | D27: 136.35 | E27: 130.23 | F27: 216.78
A28: Capital Work-In-Progress | B28: 81.05 | C28: 61.12 | D28: 68.1 | E28: 77.14 | F28: 158.72
A29: Intangible Assets Under Development | B29: 0 | C29: 0 | D29: 2.6 | E29: 8.55 | F29: 0
A30: Fixed Assets | B30: 3999.19 | C30: 3902.25 | D30: 3006.46 | E30: 2643.73 | F30: 3331.29
A31: Non-Current Investments | B31: 19536.42 | C31: 19010.41 | D31: 19756.88 | E31: 20980.61 | F31: 21119.22
A32: Deferred Tax Assets [Net] | B32: 1336.54 | C32: 1355.76 | D32: 1193.47 | E32: 1002.97 | F32: 1410.15
A33: Long Term Loans And Advances | B33: 229.92 | C33: 205.65 | D33: 204.67 | E33: 190.14 | F33: 663.31
A34: Other Non-Current Assets | B34: 2366.19 | C34: 2738.97 | D34: 2599.92 | E34: 2508.39 | F34: 6686.14
A35: Total Non-Current Assets | B35: 28412.52 | C35: 28157.3 | D35: 27705.66 | E35: 28270.08 | F35: 34154.36
A36: CURRENT ASSETS
A37: Current Investments | B37: 243.06 | C37: 470.72 | D37: 380.81 | E37: 355 | F37: 572.97
A38: Inventories | B38: 20106.99 | C38: 19361.23 | D38: 21154.13 | E38: 24621.48 | F38: 24717.48
A39: Trade Receivables | B39: 563.6 | C39: 549.23 | D39: 538.07 | E39: 802.21 | F39: 847.38
A40: Cash And Cash Equivalents | B40: 931.62 | C40: 2274.72 | D40: 4384.35 | E40: 4338.08 | F40: 7746.4
...

Sheet Cash flow Statement
A1: Consolidated Cash Flow
A2: (Rs. Cr.) | B2: Mar 22 | C2: Mar 23 | D2: Mar 24 | E2: Mar 25 | F2: Mar 26
A3: Net Profit Before Tax | B3: 1164.59 | C3: 1502.42 | D3: 2150.55 | E3: 2260.62 | F3: 2931.82
A4: Net Cash From Operating Activities | B4: 2831.82 | C4: 2375.26 | D4: 2538.81 | E4: 5235.22 | F4: 6347.37
A5: Net Cash (used in)/from Investing Activities | B5: 262.97 | C5: -462.62 | D5: -1528.67 | E5: -3543.05 | F5: 721.1
A6: Net Cash (used in)/from Financing Activities | B6: -3828.19 | C6: -2013.15 | D6: 176.61 | E6: -2402.56 | F6: -5546.76
A7: Net (decrease)/increase In Cash and Cash Equivalents | B7: -733.4 | C7: -100.51 | D7: 1186.75 | E7: -710.38 | F7: 1521.71
A8: Opening Cash & Cash Equivalents | B8: 1039.25 | C8: 307.86 | D8: 207.08 | E8: 1461.89 | F8: 751.51
A9: Closing Cash & Cash Equivalents | B9: 305.85 | C9: 207.35 | D9: 1393.83 | E9: 751.51 | F9: 2273.22

Sheet Beta
A1: Date | B1: NIFTY50_Close | C1: DLF_Close | E1: Rm nifty | F1: Rm Dlf | G1: slope | H1: covariance
A2: 43922 | B2: 8253.7998 | C2: 132.55
A3: 43924 | B3: 8083.7998 | C3: 132.10001 | E3: =(B3-B2)/B2 -> -0.020596574 | F3: =(C3-C2)/C2 -> -0.0033949222 | G3: =SLOPE(F3:F1532,E3:E1532) -> 1.5661234 | H3: =_xlfn.COVARIANCE.S(F3:F1532,E3:E1532)/_xlfn.VAR.S(E3:E1532) -> 1.5661234 | I3: SUMMARY OUTPUT
A4: 43928 | B4: 8792.2002 | C4: 141.55 | E4: =(B4-B3)/B3 -> 0.087632105 | F4: =(C4-C3)/C3 -> 0.071536688
A5: 43929 | B5: 8748.75 | C5: 138 | E5: =(B5-B4)/B4 -> -0.0049419024 | F5: =(C5-C4)/C4 -> -0.025079498 | I5: Regression Statistics
A6: 43930 | B6: 9111.9004 | C6: 149.10001 | E6: =(B6-B5)/B5 -> 0.041508832 | F6: =(C6-C5)/C5 -> 0.080434827 | I6: Multiple R | J6: 0.66199222
A7: 43934 | B7: 8993.8496 | C7: 139.75 | E7: =(B7-B6)/B6 -> -0.012955671 | F7: =(C7-C6)/C6 -> -0.062709629 | I7: R Square | J7: 0.4382337
A8: 43936 | B8: 8925.2998 | C8: 140.3 | E8: =(B8-B7)/B7 -> -0.0076218536 | F8: =(C8-C7)/C7 -> 0.0039356211 | I8: Adjusted R Square | J8: 0.43786605
A9: 43937 | B9: 8992.7998 | C9: 134 | E9: =(B9-B8)/B8 -> 0.0075627712 | F9: =(C9-C8)/C8 -> -0.044903798 | I9: Standard Error | J9: 0.017391265
A10: 43938 | B10: 9266.75 | C10: 136.89999 | E10: =(B10-B9)/B9 -> 0.030463282 | F10: =(C10-C9)/C9 -> 0.021641745 | I10: Observations | J10: 1530
A11: 43941 | B11: 9261.8496 | C11: 134.39999 | E11: =(B11-B10)/B10 -> -0.00052881438 | F11: =(C11-C10)/C10 -> -0.018261506
A12: 43942 | B12: 8981.4502 | C12: 132.64999 | E12: =(B12-B11)/B11 -> -0.030274667 | F12: =(C12-C11)/C11 -> -0.013020834 | I12: ANOVA
A13: 43943 | B13: 9187.2998 | C13: 133.55 | E13: =(B13-B12)/B12 -> 0.022919418 | F13: =(C13-C12)/C12 -> 0.0067848413 | J13: df | K13: SS | L13: MS | M13: F | N13: Significance F
A14: 43944 | B14: 9313.9004 | C14: 137 | E14: =(B14-B13)/B13 -> 0.013779956 | F14: =(C14-C13)/C13 -> 0.025832998 | I14: Regression | J14: 1 | K14: 0.36052535 | L14: 0.36052535 | M14: 1191.9923 | N14: 1.4097146e-193
A15: 43945 | B15: 9154.4004 | C15: 128.2 | E15: =(B15-B14)/B14 -> -0.017124942 | F15: =(C15-C14)/C14 -> -0.064233599 | I15: Residual | J15: 1528 | K15: 0.46215293 | L15: 0.0003024561
A16: 43948 | B16: 9282.2998 | C16: 133 | E16: =(B16-B15)/B15 -> 0.013971359 | F16: =(C16-C15)/C15 -> 0.037441522 | I16: Total | J16: 1529 | K16: 0.82267827
A17: 43949 | B17: 9380.9004 | C17: 138 | E17: =(B17-B16)/B16 -> 0.010622431 | F17: =(C17-C16)/C16 -> 0.037593985
A18: 43950 | B18: 9553.3496 | C18: 141.64999 | E18: =(B18-B17)/B17 -> 0.018383014 | F18: =(C18-C17)/C17 -> 0.026449231 | J18: Coefficients | K18: Standard Error | L18: t Stat | M18: P-value | N18: Lower 95% | O18: Upper 95% | P18: Lower 95.0% | Q18: Upper 95.0%
A19: 43951 | B19: 9859.9004 | C19: 146.85001 | E19: =(B19-B18)/B18 -> 0.032088303 | F19: =(C19-C18)/C18 -> 0.036710289 | I19: Intercept | J19: 8.9787125e-05 | K19: 0.00044586647 | L19: 0.20137671 | M19: 0.84043082 | N19: -0.00078478786 | O19: 0.00096436211 | P19: -0.00078478786 | Q19: 0.00096436211
A20: 43955 | B20: 9293.5 | C20: 133.05 | E20: =(B20-B19)/B19 -> -0.057444839 | F20: =(C20-C19)/C19 -> -0.093973459 | I20: X Variable 1 | J20: 1.5661234 | K20: 0.045361693 | L20: 34.525241 | M20: 1.4097146e-193 | N20: 1.4771456 | O20: 1.6551012 | P20: 1.4771456 | Q20: 1.6551012
A21: 43956 | B21: 9205.5996 | C21: 126.8 | E21: =(B21-B20)/B20 -> -0.0094582655 | F21: =(C21-C20)/C20 -> -0.04697482
A22: 43957 | B22: 9270.9004 | C22: 129.89999 | E22: =(B22-B21)/B21 -> 0.0070935935 | F22: =(C22-C21)/C21 -> 0.024447877
A23: 43958 | B23: 9199.0498 | C23: 129.14999 | E23: =(B23-B22)/B22 -> -0.0077501195 | F23: =(C23-C22)/C22 -> -0.0057736723
A24: 43959 | B24: 9251.5 | C24: 130.14999 | E24: =(B24-B23)/B23 -> 0.0057016971 | F24: =(C24-C23)/C23 -> 0.0077429349
A25: 43962 | B25: 9239.2002 | C25: 133.35001 | E25: =(B25-B24)/B24 -> -0.001329493 | F25: =(C25-C24)/C24 -> 0.02458711
A26: 43963 | B26: 9196.5498 | C26: 136.95 | E26: =(B26-B25)/B25 -> -0.0046162427 | F26: =(C26-C25)/C25 -> 0.026996556
A27: 43964 | B27: 9383.5498 | C27: 141.10001 | E27: =(B27-B26)/B26 -> 0.020333713 | F27: =(C27-C26)/C26 -> 0.030303098
A28: 43965 | B28: 9142.75 | C28: 137.05 | E28: =(B28-B27)/B27 -> -0.025661909 | F28: =(C28-C27)/C27 -> -0.028703068
A29: 43966 | B29: 9136.8496 | C29: 138.8 | E29: =(B29-B28)/B28 -> -0.00064536279 | F29: =(C29-C28)/C28 -> 0.012769062
A30: 43969 | B30: 8823.25 | C30: 132.45 | E30: =(B30-B29)/B29 -> -0.03432251 | F30: =(C30-C29)/C29 -> -0.045749323
A31: 43970 | B31: 8879.0996 | C31: 131.45 | E31: =(B31-B30)/B30 -> 0.0063298228 | F31: =(C31-C30)/C30 -> -0.007550019
A32: 43971 | B32: 9066.5498 | C32: 139.25 | E32: =(B32-B31)/B31 -> 0.021111397 | F32: =(C32-C31)/C31 -> 0.059338176
... A1532: 46185 | B1532: 23622.9 | C1532: 587.04999 | E1532: =(B1532-B1531)/B1531 -> 0.01991662 | F1532: =(C1532-C1531)/C1531 -> 0.042717563

Sheet Wacc
A1: Capital Structure
A2: Total Debt | B2: ='Consolidated Balance Sheet'!E12+'Consolidated Balance Sheet'!E18 -> 3854.03 | D2: Total Debt (FY2025) = Long Term Borrowings + Short Term Borrowings (Mar 25, Consolidated Balance Sheet)
A3: Total Equity | B3: =E6*606.05 -> 149620 | D3: Total Equity = Market Cap = (Total Share Capital / Face Value 2) x Current Price (Beta sheet latest close)
A4: Total Mix (Debt + Equity) | B4: =B2+B3 -> 153474.03
A5: % of Debt | B5: =B2/B4 -> 0.025111936 | C5: share outstanding | D5: mkt capitalisation/current share price
A6: % of Equity | B6: =B3/B4 -> 0.97488806 | D6: 149620/606.05 | E6: =149620/606.05 -> 246.87732
A7: Debt to Equity | B7: =B2/B3 -> 0.025758789
A9: Cost of Equity (CAPM)
A10: Risk-free Rate (Rf) | B10: 0.0625 | D10: Source: RBI 10-year Government Securities yield (FY2025)
A11: Beta (β) | B11: =Beta!G3 -> 1.5661234
A12: Market Risk Premium (Rm - Rf) | B12: 0.065 | D12: Source: India Equity Risk Premium (Damodaran estimate)
A13: Cost of Equity [Ke = Rf + β×(Rm-Rf)] | B13: =B10+B11*(B12) -> 0.16429802
A15: Cost of Debt
A16: Finance Cost (FY2025) | B16: ='Consolidated P&L'!E14 -> 397.2 | D16: Finance Costs, FY2025 / Mar 25 (Consolidated P&L)
A17: Total Debt (FY2025) | B17: =B2 -> 3854.03 | D17: Same as Total Debt (Capital Structure)
A18: Pre-tax Cost of Debt [Kd = FC/Debt] | B18: =IFERROR(B16/B17,0) -> 0.10306095
A19: Tax Rate | B19: =Assumptions!F15/Assumptions!F14 -> 0.11358789 | D19: Effective Tax Rate = Tax / EBT, FY2026 / Mar 26 (FY2025 excluded: one-off deferred tax credit distorts it to -16.9%)
A20: Post-tax Cost of Debt [Kd*(1-T)] | B20: =B18*(1-B19) -> 0.091354475
A22: WACC
A23: Source | B23: Weight | C23: Cost | D23: Weighted Cost
A24: Debt | B24: =B5 -> 0.025111936 | C24: =B20 -> 0.091354475 | D24: =B24*C24 -> 0.0022940877
A25: Equity | B25: =B6 -> 0.97488806 | C25: =B13 -> 0.16429802 | D25: =B25*C25 -> 0.16017218
A26: WACC | B26: =SUM(B24:B25) -> 1 | C26: (Check: weights = 100%) | D26: =SUM(D24:D25) -> 0.16246627 | F26: wacc = we*ke+wd*kd

Sheet Assumptions
A1: DLF
A2: Particulars (in RS Cr.) | B2: Mar 22 | C2: Mar 23 | D2: Mar 24 | E2: Mar 25 | F2: 46082
A3: Revenue from operations | B3: ='Consolidated P&L'!B7 -> 5717.39 | C3: ='Consolidated P&L'!C7 -> 5694.83 | D3: ='Consolidated P&L'!D7 -> 6427 | E3: ='Consolidated P&L'!E7 -> 7993.66 | F3: ='Consolidated P&L'!F7 -> 8194.02 | H3: Median of revenue growth
A4: Revenue growth in % | C4: =('Consolidated P&L'!C7-'Consolidated P&L'!B7)/'Consolidated P&L'!B7 -> -0.0039458564 | D4: =('Consolidated P&L'!D7-'Consolidated P&L'!C7)/'Consolidated P&L'!C7 -> 0.12856749 | E4: =('Consolidated P&L'!E7-'Consolidated P&L'!D7)/'Consolidated P&L'!D7 -> 0.24376225 | F4: =('Consolidated P&L'!F7-'Consolidated P&L'!E7)/'Consolidated P&L'!E7 -> 0.025064864 | G4: =AVERAGE(C4:F4) -> 0.098362188 | H4: =MEDIAN(C4:F4) -> 0.076816177
A5: Less: Material cost | B5: ='Consolidated P&L'!B12+'Consolidated P&L'!B11 -> 2744.96 | C5: ='Consolidated P&L'!C12+'Consolidated P&L'!C11 -> 2433.96 | D5: ='Consolidated P&L'!D12+'Consolidated P&L'!D11 -> 2793.76 | E5: ='Consolidated P&L'!E12+'Consolidated P&L'!E11 -> 4131.58 | F5: ='Consolidated P&L'!F12+'Consolidated P&L'!F11 -> 4848.57
A6: Less: Employee costs | B6: ='Consolidated P&L'!B13 -> 353.99 | C6: ='Consolidated P&L'!C13 -> 547.88 | D6: ='Consolidated P&L'!D13 -> 545.95 | E6: ='Consolidated P&L'!E13 -> 591.96 | F6: ='Consolidated P&L'!F13 -> 640.3
A7: Less: Other Expenses | B7: ='Consolidated P&L'!B16 -> 875.88 | C7: ='Consolidated P&L'!C16 -> 987.11 | D7: ='Consolidated P&L'!D16 -> 963.69 | E7: ='Consolidated P&L'!E16 -> 1161.48 | F7: ='Consolidated P&L'!F16 -> 1256.79
A8: Total Expenses | B8: =B5+B6+B7 -> 3974.83 | C8: =C5+C6+C7 -> 3968.95 | D8: =D5+D6+D7 -> 4303.4 | E8: =E5+E6+E7 -> 5885.02 | F8: =F5+F6+F7 -> 6745.66
A9: EBITDA | B9: =B3-B8 -> 1742.56 | C9: =C3-C8 -> 1725.88 | D9: =D3-D8 -> 2123.6 | E9: =E3-E8 -> 2108.64 | F9: =F3-F8 -> 1448.36
A10: Less: Depreciation And Amortization | B10: ='Consolidated P&L'!B15 -> 149.44 | C10: ='Consolidated P&L'!C15 -> 148.63 | D10: ='Consolidated P&L'!D15 -> 147.95 | E10: ='Consolidated P&L'!E15 -> 150.66 | F10: ='Consolidated P&L'!F15 -> 142.41
A11: EBIT | B11: =B9-B10 -> 1593.12 | C11: =C9-C10 -> 1577.25 | D11: =D9-D10 -> 1975.65 | E11: =E9-E10 -> 1957.98 | F11: =F9-F10 -> 1305.95
A12: ADD: Non operating income/ Other Income | B12: ='Consolidated P&L'!B8 -> 420.46 | C12: ='Consolidated P&L'!C8 -> 317.31 | D12: ='Consolidated P&L'!D8 -> 531.34 | E12: ='Consolidated P&L'!E8 -> 1002.23 | F12: ='Consolidated P&L'!F8 -> 1622.02
A13: Less: Interest Expenses | B13: ='Consolidated P&L'!B14 -> 624.55 | C13: ='Consolidated P&L'!C14 -> 392.14 | D13: ='Consolidated P&L'!D14 -> 356.45 | E13: ='Consolidated P&L'!E14 -> 397.2 | F13: ='Consolidated P&L'!F14 -> 199.07
A14: EBT | B14: =B11+B12-B13 -> 1389.03 | C14: =C11+C12-C13 -> 1502.42 | D14: =D11+D12-D13 -> 2150.54 | E14: =E11+E12-E13 -> 2563.01 | F14: =F11+F12-F13 -> 2728.9
A15: Less: TAX | B15: ='Consolidated P&L'!B25 -> 320.97 | C15: ='Consolidated P&L'!C25 -> 401.5 | D15: ='Consolidated P&L'!D25 -> 520.13 | E15: ='Consolidated P&L'!E25 -> -433.89 | F15: ='Consolidated P&L'!F25 -> 309.97
A16: Less:Non Controlling Interest/Minority Interest | B16: ='Consolidated P&L'!B29 -> 0.54 | C16: ='Consolidated P&L'!C29 -> 1.88 | D16: ='Consolidated P&L'!D29 -> 3.56 | E16: ='Consolidated P&L'!E29 -> 0.8 | F16: ='Consolidated P&L'!F29 -> 0
A17: Net Profit- Pat | B17: =B14-B15-B16 -> 1067.52 | C17: =C14-C15-C16 -> 1099.04 | D17: =D14-D15-D16 -> 1626.85 | E17: =E14-E15-E16 -> 2996.1 | F17: =F14-F15-F16 -> 2418.93
A21: Historical Growth
A22: Average Growth | B22: =AVERAGE(C4:F4) -> 0.098362188
A23: CAGR | B23: =(F3/B3)^(1/5)-1 -> 0.074632177 | C23: =_xlfn.RRI(5,B3,F3) -> 0.074632177 | D23: RRI
A25: Margins
A26: EBITDA | B26: =B9/B3 -> 0.30478243 | C26: =C9/C3 -> 0.30306085 | D26: =D9/D3 -> 0.33041855 | E26: =E9/E3 -> 0.26378905 | F26: =F9/F3 -> 0.17675817
A27: EBIT | B27: =B11/B3 -> 0.27864463 | C27: =C11/C3 -> 0.27696174 | D27: =D11/D3 -> 0.30739848 | E27: =E11/E3 -> 0.24494162 | F27: =F11/F3 -> 0.15937842
A28: EBT | B28: =B14/B3 -> 0.24294827 | C28: =C14/C3 -> 0.26382175 | D28: =D14/D3 -> 0.33461024 | E28: =E14/E3 -> 0.32063035 | F28: =F14/F3 -> 0.33303556
A29: Net Proftt | B29: =B17/B3 -> 0.18671457 | C29: =C17/C3 -> 0.19298908 | D29: =D17/D3 -> 0.25312743 | E29: =E17/E3 -> 0.37480954 | F29: =F17/F3 -> 0.29520675
A31: Tax Rate
A32: Effective tax rate | B32: =B15/B14 -> 0.23107492 | C32: =C15/C14 -> 0.26723553 | D32: =D15/D14 -> 0.24186018 | E32: =E15/E14 -> -0.16928923 | F32: =F15/F14 -> 0.11358789 | H32: Effective tax rate | I32: =AVERAGE(B32:F32) -> 0.13689386
A33: Marginal Tax rate | B33: 0.25 | C33: 0.25 | D33: 0.25 | E33: 0.25 | F33: 0.25 | I33: =AVERAGE(B33:F33) -> 0.25
A35: Return On Capital
A36: EBIT*(1-T) | B36: =B11*(1-B33) -> 1194.84 | C36: =C11*(1-C33) -> 1182.9375 | D36: =D11*(1-D33) -> 1481.7375 | E36: =E11*(1-E33) -> 1468.485 | F36: =F11*(1-F33) -> 979.4625
A37: Book Equity | B37: ='Consolidated Balance Sheet'!B9 -> 36362.28 | C37: ='Consolidated Balance Sheet'!C9 -> 37687.53 | D37: ='Consolidated Balance Sheet'!D9 -> 39430.81 | E37: ='Consolidated Balance Sheet'!E9 -> 42550.22 | F37: ='Consolidated Balance Sheet'!F9 -> 45473.37
A38: Book Debt | B38: ='Consolidated Balance Sheet'!B12+'Consolidated Balance Sheet'!B18 -> 3960 | C38: ='Consolidated Balance Sheet'!C12+'Consolidated Balance Sheet'!C18 -> 3103.09 | D38: ='Consolidated Balance Sheet'!D12+'Consolidated Balance Sheet'!D18 -> 4598.72 | E38: ='Consolidated Balance Sheet'!E12+'Consolidated Balance Sheet'!E18 -> 3854.03 | F38: ='Consolidated Balance Sheet'!F12+'Consolidated Balance Sheet'!F18 -> 44.95
A39: Cash and Cash equivalents | B39: ='Consolidated Balance Sheet'!B40 -> 931.62 | C39: ='Consolidated Balance Sheet'!C40 -> 2274.72 | D39: ='Consolidated Balance Sheet'!D40 -> 4384.35 | E39: ='Consolidated Balance Sheet'!E40 -> 4338.08 | F39: ='Consolidated Balance Sheet'!F40 -> 7746.4
A40: Capital Employed | B40: =B37+B38+B39 -> 41253.9 | C40: =C37+C38+C39 -> 43065.34 | D40: =D37+D38+D39 -> 48413.88 | E40: =E37+E38+E39 -> 50742.33 | F40: =F37+F38+F39 -> 53264.72
A42: Pre-Tax Return on capital | B42: =B11/B40 -> 0.03861744 | C42: =C11/C40 -> 0.03662458 | D42: =D11/D40 -> 0.040807512 | E42: =E11/E40 -> 0.038586718 | F42: =F11/F40 -> 0.024518105
A43: Post Tax return On capital | B43: =B36/B40 -> 0.02896308 | C43: =C36/C40 -> 0.027468435 | D43: =D36/D40 -> 0.030605634 | E43: =E36/E40 -> 0.028940039 | F43: =F36/F40 -> 0.018388579
A45: Growth In EBIT | C45: =FCFF!B12*F43 -> 0.0063714534

Sheet Ratio Analysis
A1: Ratio Analysis- DLF
A2: Years | B2: 44621 | C2: 44986 | D2: 45352 | E2: 45717 | F2: 46082 | G2: Trends | H2: Mean | I2: Median
A4: Sales Growth | C4: =('Consolidated P&L'!C7-'Consolidated P&L'!B7)/'Consolidated P&L'!B7 -> -0.0039458564 | D4: =('Consolidated P&L'!D7-'Consolidated P&L'!C7)/'Consolidated P&L'!C7 -> 0.12856749 | E4: =('Consolidated P&L'!E7-'Consolidated P&L'!D7)/'Consolidated P&L'!D7 -> 0.24376225 | F4: =('Consolidated P&L'!F7-'Consolidated P&L'!E7)/'Consolidated P&L'!E7 -> 0.025064864 | H4: =AVERAGE(C4:F4) -> 0.098362188 | I4: =MEDIAN(C4:F4) -> 0.076816177
A5: EBITDA Growth | C5: =(('Consolidated P&L'!C7-'Consolidated P&L'!C12-'Consolidated P&L'!C13-'Consolidated P&L'!C16)-('Consolidated P&L'!B7-'Consolidated P&L'!B12-'Consolidated P&L'!B13-'Consolidated P&L'!B16))/('Consolidated P&L'!B7-'Consolidated P&L'!B12-'Consolidated P&L'!B13-'Consolidated P&L'!B16) -> -0.0095721238 | D5: =(('Consolidated P&L'!D7-'Consolidated P&L'!D12-'Consolidated P&L'!D13-'Consolidated P&L'!D16)-('Consolidated P&L'!C7-'Consolidated P&L'!C12-'Consolidated P&L'!C13-'Consolidated P&L'!C16))/('Consolidated P&L'!C7-'Consolidated P&L'!C12-'Consolidated P&L'!C13-'Consolidated P&L'!C16) -> 0.23044476 | E5: =(('Consolidated P&L'!E7-'Consolidated P&L'!E12-'Consolidated P&L'!E13-'Consolidated P&L'!E16)-('Consolidated P&L'!D7-'Consolidated P&L'!D12-'Consolidated P&L'!D13-'Consolidated P&L'!D16))/('Consolidated P&L'!D7-'Consolidated P&L'!D12-'Consolidated P&L'!D13-'Consolidated P&L'!D16) -> -0.0070446412 | F5: =(('Consolidated P&L'!F7-'Consolidated P&L'!F12-'Consolidated P&L'!F13-'Consolidated P&L'!F16)-('Consolidated P&L'!E7-'Consolidated P&L'!E12-'Consolidated P&L'!E13-'Consolidated P&L'!E16))/('Consolidated P&L'!E7-'Consolidated P&L'!E12-'Consolidated P&L'!E13-'Consolidated P&L'!E16) -> 1.9862518 | H5: =AVERAGE(C5:F5) -> 0.55001995 | I5: =MEDIAN(C5:F5) -> 0.11170006
A6: EBIT Growth | C6: =(('Consolidated P&L'!C7-'Consolidated P&L'!C12-'Consolidated P&L'!C13-'Consolidated P&L'!C16-'Consolidated P&L'!C15)-('Consolidated P&L'!B7-'Consolidated P&L'!B12-'Consolidated P&L'!B13-'Consolidated P&L'!B16-'Consolidated P&L'!B15))/('Consolidated P&L'!B7-'Consolidated P&L'!B12-'Consolidated P&L'!B13-'Consolidated P&L'!B16-'Consolidated P&L'!B15) -> -0.0099615848 | D6: =(('Consolidated P&L'!D7-'Consolidated P&L'!D12-'Consolidated P&L'!D13-'Consolidated P&L'!D16-'Consolidated P&L'!D15)-('Consolidated P&L'!C7-'Consolidated P&L'!C12-'Consolidated P&L'!C13-'Consolidated P&L'!C16-'Consolidated P&L'!C15))/('Consolidated P&L'!C7-'Consolidated P&L'!C12-'Consolidated P&L'!C13-'Consolidated P&L'!C16-'Consolidated P&L'!C15) -> 0.25259154 | E6: =(('Consolidated P&L'!E7-'Consolidated P&L'!E12-'Consolidated P&L'!E13-'Consolidated P&L'!E16-'Consolidated P&L'!E15)-('Consolidated P&L'!D7-'Consolidated P&L'!D12-'Consolidated P&L'!D13-'Consolidated P&L'!D16-'Consolidated P&L'!D15))/('Consolidated P&L'!D7-'Consolidated P&L'!D12-'Consolidated P&L'!D13-'Consolidated P&L'!D16-'Consolidated P&L'!D15) -> -0.0089438919 | F6: =(('Consolidated P&L'!F7-'Consolidated P&L'!F12-'Consolidated P&L'!F13-'Consolidated P&L'!F16-'Consolidated P&L'!F15)-('Consolidated P&L'!E7-'Consolidated P&L'!E12-'Consolidated P&L'!E13-'Consolidated P&L'!E16-'Consolidated P&L'!E15))/('Consolidated P&L'!E7-'Consolidated P&L'!E12-'Consolidated P&L'!E13-'Consolidated P&L'!E16-'Consolidated P&L'!E15) -> 2.1433007 | H6: =AVERAGE(C6:F6) -> 0.5942467 | I6: =MEDIAN(C6:F6) -> 0.12182382
A7: Net Profit Growth | C7: =('Consolidated P&L'!C31-'Consolidated P&L'!B31)/'Consolidated P&L'!B31 -> 0.35645134 | D7: =('Consolidated P&L'!D31-'Consolidated P&L'!C31)/'Consolidated P&L'!C31 -> 0.33955684 | E7: =('Consolidated P&L'!E31-'Consolidated P&L'!D31)/'Consolidated P&L'!D31 -> 0.60155623 | F7: =('Consolidated P&L'!F31-'Consolidated P&L'!E31)/'Consolidated P&L'!E31 -> 0.010774747 | H7: =AVERAGE(C7:F7) -> 0.32708479 | I7: =MEDIAN(C7:F7) -> 0.34800409
A8: Dividend Growth | C8: =('Consolidated P&L'!C36-'Consolidated P&L'!B36)/'Consolidated P&L'!B36 -> 0.5 | D8: =('Consolidated P&L'!D36-'Consolidated P&L'!C36)/'Consolidated P&L'!C36 -> 0.33333333 | E8: =('Consolidated P&L'!E36-'Consolidated P&L'!D36)/'Consolidated P&L'!D36 -> 0.2500101 | H8: =AVERAGE(C8:E8) -> 0.36111448 | I8: =MEDIAN(C8:E8) -> 0.33333333
A10: Gross Margin | B10: =('Consolidated P&L'!B7-'Consolidated P&L'!B12-'Consolidated P&L'!B13)/'Consolidated P&L'!B7 -> 0.4579782 | C10: =('Consolidated P&L'!C7-'Consolidated P&L'!C12-'Consolidated P&L'!C13)/'Consolidated P&L'!C7 -> 0.47639526 | D10: =('Consolidated P&L'!D7-'Consolidated P&L'!D12-'Consolidated P&L'!D13)/'Consolidated P&L'!D7 -> 0.48036253 | E10: =('Consolidated P&L'!E7-'Consolidated P&L'!E12-'Consolidated P&L'!E13)/'Consolidated P&L'!E7 -> 0.4090892 | F10: =('Consolidated P&L'!F7-'Consolidated P&L'!F12-'Consolidated P&L'!F13)/'Consolidated P&L'!F7 -> 0.92185765 | H10: =AVERAGE(B10:F10) -> 0.54913657 | I10: =MEDIAN(B10:F10) -> 0.47639526
A11: EBITDA Margin | B11: =('Consolidated P&L'!B7-'Consolidated P&L'!B12-'Consolidated P&L'!B13-'Consolidated P&L'!B16)/'Consolidated P&L'!B7 -> 0.30478243 | C11: =('Consolidated P&L'!C7-'Consolidated P&L'!C12-'Consolidated P&L'!C13-'Consolidated P&L'!C16)/'Consolidated P&L'!C7 -> 0.30306085 | D11: =('Consolidated P&L'!D7-'Consolidated P&L'!D12-'Consolidated P&L'!D13-'Consolidated P&L'!D16)/'Consolidated P&L'!D7 -> 0.33041855 | E11: =('Consolidated P&L'!E7-'Consolidated P&L'!E12-'Consolidated P&L'!E13-'Consolidated P&L'!E16)/'Consolidated P&L'!E7 -> 0.26378905 | F11: =('Consolidated P&L'!F7-'Consolidated P&L'!F12-'Consolidated P&L'!F13-'Consolidated P&L'!F16)/'Consolidated P&L'!F7 -> 0.76847872 | H11: =AVERAGE(B11:F11) -> 0.39410592 | I11: =MEDIAN(B11:F11) -> 0.30478243
A12: EBIT Margin | B12: =('Consolidated P&L'!B7-'Consolidated P&L'!B12-'Consolidated P&L'!B13-'Consolidated P&L'!B16-'Consolidated P&L'!B15)/'Consolidated P&L'!B7 -> 0.27864463 | C12: =('Consolidated P&L'!C7-'Consolidated P&L'!C12-'Consolidated P&L'!C13-'Consolidated P&L'!C16-'Consolidated P&L'!C15)/'Consolidated P&L'!C7 -> 0.27696174 | D12: =('Consolidated P&L'!D7-'Consolidated P&L'!D12-'Consolidated P&L'!D13-'Consolidated P&L'!D16-'Consolidated P&L'!D15)/'Consolidated P&L'!D7 -> 0.30739848 | E12: =('Consolidated P&L'!E7-'Consolidated P&L'!E12-'Consolidated P&L'!E13-'Consolidated P&L'!E16-'Consolidated P&L'!E15)/'Consolidated P&L'!E7 -> 0.24494162 | F12: =('Consolidated P&L'!F7-'Consolidated P&L'!F12-'Consolidated P&L'!F13-'Consolidated P&L'!F16-'Consolidated P&L'!F15)/'Consolidated P&L'!F7 -> 0.75109897 | H12: =AVERAGE(B12:F12) -> 0.37180909 | I12: =MEDIAN(B12:F12) -> 0.27864463
A13: EBT Margin | B13: ='Consolidated P&L'!B20/'Consolidated P&L'!B7 -> 0.20369259 | C13: ='Consolidated P&L'!C20/'Consolidated P&L'!C7 -> 0.26382175 | D13: ='Consolidated P&L'!D20/'Consolidated P&L'!D7 -> 0.33461179 | E13: ='Consolidated P&L'!E20/'Consolidated P&L'!E7 -> 0.28280162 | F13: ='Consolidated P&L'!F20/'Consolidated P&L'!F7 -> 0.35779996 | H13: =AVERAGE(B13:F13) -> 0.28854554 | I13: =MEDIAN(B13:F13) -> 0.28280162
A14: Net Profit Margin | B14: ='Consolidated P&L'!B31/'Consolidated P&L'!B7 -> 0.26250614 | C14: ='Consolidated P&L'!C31/'Consolidated P&L'!C7 -> 0.35748741 | D14: ='Consolidated P&L'!D31/'Consolidated P&L'!D7 -> 0.42432083 | E14: ='Consolidated P&L'!E31/'Consolidated P&L'!E7 -> 0.54638551 | F14: ='Consolidated P&L'!F31/'Consolidated P&L'!F7 -> 0.53876852 | H14: =AVERAGE(B14:F14) -> 0.42589368 | I14: =MEDIAN(B14:F14) -> 0.42432083
A16: Sales Expenses%Sales | B16: ='Consolidated P&L'!B17/'Consolidated P&L'!B7 -> 0.83059228 | C16: ='Consolidated P&L'!C17/'Consolidated P&L'!C7 -> 0.79189721 | D16: ='Consolidated P&L'!D17/'Consolidated P&L'!D7 -> 0.74806286 | E16: ='Consolidated P&L'!E17/'Consolidated P&L'!E7 -> 0.80474776 | F16: ='Consolidated P&L'!F17/'Consolidated P&L'!F7 -> 0.86491612 | H16: =AVERAGE(B16:F16) -> 0.80804325 | I16: =MEDIAN(B16:F16) -> 0.80474776
A17: Depriciation%Sales | B17: ='Consolidated P&L'!B15/'Consolidated P&L'!B7 -> 0.026137801 | C17: ='Consolidated P&L'!C15/'Consolidated P&L'!C7 -> 0.026099111 | D17: ='Consolidated P&L'!D15/'Consolidated P&L'!D7 -> 0.023020072 | E17: ='Consolidated P&L'!E15/'Consolidated P&L'!E7 -> 0.018847437 | F17: ='Consolidated P&L'!F15/'Consolidated P&L'!F7 -> 0.017379748 | H17: =AVERAGE(B17:F17) -> 0.022296833 | I17: =MEDIAN(B17:F17) -> 0.023020072
A18: Operating Income%Sales | B18: =('Consolidated P&L'!B7-'Consolidated P&L'!B12-'Consolidated P&L'!B13-'Consolidated P&L'!B16-'Consolidated P&L'!B15)/'Consolidated P&L'!B7 -> 0.27864463 | C18: =('Consolidated P&L'!C7-'Consolidated P&L'!C12-'Consolidated P&L'!C13-'Consolidated P&L'!C16-'Consolidated P&L'!C15)/'Consolidated P&L'!C7 -> 0.27696174 | D18: =('Consolidated P&L'!D7-'Consolidated P&L'!D12-'Consolidated P&L'!D13-'Consolidated P&L'!D16-'Consolidated P&L'!D15)/'Consolidated P&L'!D7 -> 0.30739848 | E18: =('Consolidated P&L'!E7-'Consolidated P&L'!E12-'Consolidated P&L'!E13-'Consolidated P&L'!E16-'Consolidated P&L'!E15)/'Consolidated P&L'!E7 -> 0.24494162 | F18: =('Consolidated P&L'!F7-'Consolidated P&L'!F12-'Consolidated P&L'!F13-'Consolidated P&L'!F16-'Consolidated P&L'!F15)/'Consolidated P&L'!F7 -> 0.75109897 | H18: =AVERAGE(B18:F18) -> 0.37180909 | I18: =MEDIAN(B18:F18) -> 0.27864463
A20: Return on Capital Employed | B20: =('Consolidated P&L'!B7-'Consolidated P&L'!B12-'Consolidated P&L'!B13-'Consolidated P&L'!B16-'Consolidated P&L'!B15)/('Consolidated Balance Sheet'!B9+'Consolidated Balance Sheet'!B12+'Consolidated Balance Sheet'!B18) -> 0.039509671 | C20: =('Consolidated P&L'!C7-'Consolidated P&L'!C12-'Consolidated P&L'!C13-'Consolidated P&L'!C16-'Consolidated P&L'!C15)/('Consolidated Balance Sheet'!C9+'Consolidated Balance Sheet'!C12+'Consolidated Balance Sheet'!C18) -> 0.038666978 | D20: =('Consolidated P&L'!D7-'Consolidated P&L'!D12-'Consolidated P&L'!D13-'Consolidated P&L'!D16-'Consolidated P&L'!D15)/('Consolidated Balance Sheet'!D9+'Consolidated Balance Sheet'!D12+'Consolidated Balance Sheet'!D18) -> 0.044871022 | E20: =('Consolidated P&L'!E7-'Consolidated P&L'!E12-'Consolidated P&L'!E13-'Consolidated P&L'!E16-'Consolidated P&L'!E15)/('Consolidated Balance Sheet'!E9+'Consolidated Balance Sheet'!E12+'Consolidated Balance Sheet'!E18) -> 0.04219398 | F20: =('Consolidated P&L'!F7-'Consolidated P&L'!F12-'Consolidated P&L'!F13-'Consolidated P&L'!F16-'Consolidated P&L'!F15)/('Consolidated Balance Sheet'!F9+'Consolidated Balance Sheet'!F12+'Consolidated Balance Sheet'!F18) -> 0.13520974 | H20: =AVERAGE(B20:F20) -> 0.060090277 | I20: =MEDIAN(B20:F20) -> 0.04219398
A21: Retained Earning % | B21: =('Consolidated P&L'!B31-'Consolidated P&L'!B36)/'Consolidated P&L'!B31 -> 0.67014692 | C21: =('Consolidated P&L'!C31-'Consolidated P&L'!C36)/'Consolidated P&L'!C31 -> 0.63523968 | D21: =('Consolidated P&L'!D31-'Consolidated P&L'!D36)/'Consolidated P&L'!D31 -> 0.63693434 | E21: =('Consolidated P&L'!E31-'Consolidated P&L'!E36)/'Consolidated P&L'!E31 -> 0.71662828 | F21: =('Consolidated P&L'!F31-'Consolidated P&L'!F36)/'Consolidated P&L'!F31 -> 1 | H21: =AVERAGE(B21:F21) -> 0.73178984 | I21: =MEDIAN(B21:F21) -> 0.67014692
A22: Return on Equity % | B22: ='Consolidated P&L'!B31/'Consolidated Balance Sheet'!B9 -> 0.041274915 | C22: ='Consolidated P&L'!C31/'Consolidated Balance Sheet'!C9 -> 0.054018663 | D22: ='Consolidated P&L'!D31/'Consolidated Balance Sheet'!D9 -> 0.069161907 | E22: ='Consolidated P&L'!E31/'Consolidated Balance Sheet'!E9 -> 0.10264624 | F22: ='Consolidated P&L'!F31/'Consolidated Balance Sheet'!F9 -> 0.097082754 | H22: =AVERAGE(B22:F22) -> 0.072836895 | I22: =MEDIAN(B22:F22) -> 0.069161907
A23: Self Sustained Growth Rate | B23: =B22*B21 -> 0.027660257 | C23: =C22*C21 -> 0.034314799 | D23: =D22*D21 -> 0.044051593 | E23: =E22*E21 -> 0.073559197 | F23: =F22*F21 -> 0.097082754 | H23: =AVERAGE(B23:F23) -> 0.05533372 | I23: =MEDIAN(B23:F23) -> 0.044051593
A24: Interest Coverage Ratio | B24: =('Consolidated P&L'!B7-'Consolidated P&L'!B12-'Consolidated P&L'!B13-'Consolidated P&L'!B16-'Consolidated P&L'!B15)/'Consolidated P&L'!B14 -> 2.5508286 | C24: =('Consolidated P&L'!C7-'Consolidated P&L'!C12-'Consolidated P&L'!C13-'Consolidated P&L'!C16-'Consolidated P&L'!C15)/'Consolidated P&L'!C14 -> 4.0221605 | D24: =('Consolidated P&L'!D7-'Consolidated P&L'!D12-'Consolidated P&L'!D13-'Consolidated P&L'!D16-'Consolidated P&L'!D15)/'Consolidated P&L'!D14 -> 5.5425726 | E24: =('Consolidated P&L'!E7-'Consolidated P&L'!E12-'Consolidated P&L'!E13-'Consolidated P&L'!E16-'Consolidated P&L'!E15)/'Consolidated P&L'!E14 -> 4.9294562 | F24: =('Consolidated P&L'!F7-'Consolidated P&L'!F12-'Consolidated P&L'!F13-'Consolidated P&L'!F16-'Consolidated P&L'!F15)/'Consolidated P&L'!F14 -> 30.916361 | H24: =AVERAGE(B24:F24) -> 9.5922758 | I24: =MEDIAN(B24:F24) -> 4.9294562
A26: Debtor Turnover Ratio | B26: ='Consolidated P&L'!B7/'Consolidated Balance Sheet'!B39 -> 10.144411 | C26: ='Consolidated P&L'!C7/'Consolidated Balance Sheet'!C39 -> 10.368753 | D26: ='Consolidated P&L'!D7/'Consolidated Balance Sheet'!D39 -> 11.944543 | E26: ='Consolidated P&L'!E7/'Consolidated Balance Sheet'!E39 -> 9.9645479 | F26: ='Consolidated P&L'!F7/'Consolidated Balance Sheet'!F39 -> 9.6698294 | H26: =AVERAGE(B26:F26) -> 10.418417 | I26: =MEDIAN(B26:F26) -> 10.144411
A27: Creditor Turnover Ratio | B27: ='Consolidated P&L'!B7/'Consolidated Balance Sheet'!B19 -> 3.7399606 | C27: ='Consolidated P&L'!C7/'Consolidated Balance Sheet'!C19 -> 3.4646407 | D27: ='Consolidated P&L'!D7/'Consolidated Balance Sheet'!D19 -> 3.5948809 | E27: ='Consolidated P&L'!E7/'Consolidated Balance Sheet'!E19 -> 3.5354064 | F27: ='Consolidated P&L'!F7/'Consolidated Balance Sheet'!F19 -> 4.765101 | H27: =AVERAGE(B27:F27) -> 3.8199979 | I27: =MEDIAN(B27:F27) -> 3.5948809
A28: Inventory Turnover | B28: ='Consolidated P&L'!B7/'Consolidated Balance Sheet'!B38 -> 0.28434838 | C28: ='Consolidated P&L'!C7/'Consolidated Balance Sheet'!C38 -> 0.29413575 | D28: ='Consolidated P&L'!D7/'Consolidated Balance Sheet'!D38 -> 0.30381774 | E28: ='Consolidated P&L'!E7/'Consolidated Balance Sheet'!E38 -> 0.32466204 | F28: ='Consolidated P&L'!F7/'Consolidated Balance Sheet'!F38 -> 0.3315071 | H28: =AVERAGE(B28:F28) -> 0.3076942 | I28: =MEDIAN(B28:F28) -> 0.30381774
A29: Fixed Asset Turnover | B29: ='Consolidated P&L'!B7/'Consolidated Balance Sheet'!B30 -> 1.429637 | C29: ='Consolidated P&L'!C7/'Consolidated Balance Sheet'!C30 -> 1.4593709 | D29: ='Consolidated P&L'!D7/'Consolidated Balance Sheet'!D30 -> 2.1377301 | E29: ='Consolidated P&L'!E7/'Consolidated Balance Sheet'!E30 -> 3.0236295 | F29: ='Consolidated P&L'!F7/'Consolidated Balance Sheet'!F30 -> 2.4597138 | H29: =AVERAGE(B29:F29) -> 2.1020163 | I29: =MEDIAN(B29:F29) -> 2.1377301
A30: Capital Turnover Ratio | B30: ='Consolidated P&L'!B7/('Consolidated Balance Sheet'!B9+'Consolidated Balance Sheet'!B12+'Consolidated Balance Sheet'!B18) -> 0.14179233 | C30: ='Consolidated P&L'!C7/('Consolidated Balance Sheet'!C9+'Consolidated Balance Sheet'!C12+'Consolidated Balance Sheet'!C18) -> 0.13961126 | D30: ='Consolidated P&L'!D7/('Consolidated Balance Sheet'!D9+'Consolidated Balance Sheet'!D12+'Consolidated Balance Sheet'!D18) -> 0.14597022 | E30: ='Consolidated P&L'!E7/('Consolidated Balance Sheet'!E9+'Consolidated Balance Sheet'!E12+'Consolidated Balance Sheet'!E18) -> 0.17226138 | F30: ='Consolidated P&L'!F7/('Consolidated Balance Sheet'!F9+'Consolidated Balance Sheet'!F12+'Consolidated Balance Sheet'!F18) -> 0.18001587 | H30: =AVERAGE(B30:F30) -> 0.15593021 | I30: =MEDIAN(B30:F30) -> 0.14597022
A32: (In days)
A33: Debtors Day | B33: ='Consolidated Balance Sheet'!B39/'Consolidated P&L'!B7*365 -> 35.980404 | C33: ='Consolidated Balance Sheet'!C39/'Consolidated P&L'!C7*365 -> 35.20192 | D33: ='Consolidated Balance Sheet'!D39/'Consolidated P&L'!D7*365 -> 30.557889 | E33: ='Consolidated Balance Sheet'!E39/'Consolidated P&L'!E7*365 -> 36.62986 | F33: ='Consolidated Balance Sheet'!F39/'Consolidated P&L'!F7*365 -> 37.746271 | H33: =AVERAGE(B33:F33) -> 35.223269 | I33: =MEDIAN(B33:F33) -> 35.980404
A34: Payable Days | B34: ='Consolidated Balance Sheet'!B19/'Consolidated P&L'!B7*365 -> 97.59461 | C34: ='Consolidated Balance Sheet'!C19/'Consolidated P&L'!C7*365 -> 105.35003 | D34: ='Consolidated Balance Sheet'!D19/'Consolidated P&L'!D7*365 -> 101.53327 | E34: ='Consolidated Balance Sheet'!E19/'Consolidated P&L'!E7*365 -> 103.24131 | F34: ='Consolidated Balance Sheet'!F19/'Consolidated P&L'!F7*365 -> 76.598587 | H34: =AVERAGE(B34:F34) -> 96.863561 | I34: =MEDIAN(B34:F34) -> 101.53327
A35: Inventory Days | B35: ='Consolidated Balance Sheet'!B38/'Consolidated P&L'!B7*365 -> 1283.6367 | C35: ='Consolidated Balance Sheet'!C38/'Consolidated P&L'!C7*365 -> 1240.9236 | D35: ='Consolidated Balance Sheet'!D38/'Consolidated P&L'!D7*365 -> 1201.3782 | E35: ='Consolidated Balance Sheet'!E38/'Consolidated P&L'!E7*365 -> 1124.246 | F35: ='Consolidated Balance Sheet'!F38/'Consolidated P&L'!F7*365 -> 1101.0322 | H35: =AVERAGE(B35:F35) -> 1190.2433 | I35: =MEDIAN(B35:F35) -> 1201.3782
A36: Cash Conversion Cycle | B36: =B33+B35-B34 -> 1222.0224 | C36: =C33+C35-C34 -> 1170.7755 | D36: =D33+D35-D34 -> 1130.4028 | E36: =E33+E35-E34 -> 1057.6345 | F36: =F33+F35-F34 -> 1062.1799 | H36: =AVERAGE(B36:F36) -> 1128.603 | I36: =MEDIAN(B36:F36) -> 1130.4028
A38: CFO/Sales | B38: ='Cash flow Statement'!B4/'Consolidated P&L'!B7 -> 0.49529943 | C38: ='Cash flow Statement'!C4/'Consolidated P&L'!C7 -> 0.41709059 | D38: ='Cash flow Statement'!D4/'Consolidated P&L'!D7 -> 0.39502256 | E38: ='Cash flow Statement'!E4/'Consolidated P&L'!E7 -> 0.65492153 | F38: ='Cash flow Statement'!F4/'Consolidated P&L'!F7 -> 0.77463443 | H38: =AVERAGE(B38:F38) -> 0.54739371 | I38: =MEDIAN(B38:F38) -> 0.49529943
A39: CFO/Total Assets | B39: ='Cash flow Statement'!B4/'Consolidated Balance Sheet'!B44 -> 0.053935936 | C39: ='Cash flow Statement'!C4/'Consolidated Balance Sheet'!C44 -> 0.044045031 | D39: ='Cash flow Statement'!D4/'Consolidated Balance Sheet'!D44 -> 0.042129255 | E39: ='Cash flow Statement'!E4/'Consolidated Balance Sheet'!E44 -> 0.075353611 | F39: ='Cash flow Statement'!F4/'Consolidated Balance Sheet'!F44 -> 0.084773149 | H39: =AVERAGE(B39:F39) -> 0.060047396 | I39: =MEDIAN(B39:F39) -> 0.053935936
A40: CFO/Total Debt | B40: ='Cash flow Statement'!B4/('Consolidated Balance Sheet'!B12+'Consolidated Balance Sheet'!B18) -> 0.71510606 | C40: ='Cash flow Statement'!C4/('Consolidated Balance Sheet'!C12+'Consolidated Balance Sheet'!C18) -> 0.76544992 | D40: ='Cash flow Statement'!D4/('Consolidated Balance Sheet'!D12+'Consolidated Balance Sheet'!D18) -> 0.55206884 | E40: ='Cash flow Statement'!E4/('Consolidated Balance Sheet'!E12+'Consolidated Balance Sheet'!E18) -> 1.3583755 | F40: ='Cash flow Statement'!F4/('Consolidated Balance Sheet'!F12+'Consolidated Balance Sheet'!F18) -> 141.20957 | H40: =AVERAGE(B40:F40) -> 28.920113 | I40: =MEDIAN(B40:F40) -> 0.76544992

Sheet FCFF
A1: Particular | B1: 44621 | C1: 44986 | D1: 45352 | E1: 45717 | F1: 46082
A2: EBIT | B2: ='Consolidated P&L'!B7-'Consolidated P&L'!B12-'Consolidated P&L'!B13-'Consolidated P&L'!B16-'Consolidated P&L'!B15 -> 1593.12 | C2: ='Consolidated P&L'!C7-'Consolidated P&L'!C12-'Consolidated P&L'!C13-'Consolidated P&L'!C16-'Consolidated P&L'!C15 -> 1577.25 | D2: ='Consolidated P&L'!D7-'Consolidated P&L'!D12-'Consolidated P&L'!D13-'Consolidated P&L'!D16-'Consolidated P&L'!D15 -> 1975.65 | E2: ='Consolidated P&L'!E7-'Consolidated P&L'!E12-'Consolidated P&L'!E13-'Consolidated P&L'!E16-'Consolidated P&L'!E15 -> 1957.98 | F2: ='Consolidated P&L'!F7-'Consolidated P&L'!F12-'Consolidated P&L'!F13-'Consolidated P&L'!F16-'Consolidated P&L'!F15 -> 6154.52
A3: Less: Tax on EBIT | B3: =B2*$J$5 -> 218.08834 | C3: =C2*$J$5 -> 215.91584 | D3: =D2*$J$5 -> 270.45435 | E3: =E2*$J$5 -> 268.03544 | F3: =F2*$J$5 -> 842.51599
A4: EBIT * (1- Tax) NOPAT | B4: =B2-B3 -> 1375.0317 | C4: =C2-C3 -> 1361.3342 | D4: =D2-D3 -> 1705.1956 | E4: =E2-E3 -> 1689.9446 | F4: =F2-F3 -> 5312.004
A5: Less: Net Capital expenditure | C5: ='Fixed Asset Scheduled'!C8 -> -96.94 | D5: ='Fixed Asset Scheduled'!D8 -> -895.79 | E5: ='Fixed Asset Scheduled'!E8 -> -362.73 | F5: ='Fixed Asset Scheduled'!F8 -> 687.56 | I5: Avg of effective tax rate | J5: =Assumptions!I32 -> 0.13689386
A6: Less: Net Change in working Capital | C6: ='Change in working capital'!C6 -> -875.1 | D6: ='Change in working capital'!D6 -> 1637.62 | E6: ='Change in working capital'!E6 -> 3258.28 | F6: ='Change in working capital'!F6 -> 682.61
A7: Reinvestment | C7: =C5+C6 -> -972.04 | D7: =D5+D6 -> 741.83 | E7: =E5+E6 -> 2895.55 | F7: =F5+F6 -> 1370.17
A8: Free Cash Flow | C8: =C4-C7 -> 2333.3742 | D8: =D4-D7 -> 963.36565 | E8: =E4-E7 -> -1205.6054 | F8: =F4-F7 -> 3941.834
I9: Marginal tax rate | J9: =Assumptions!I33 -> 0.25
A10: Reinvestment Rate | C10: =C7/C4 -> -0.71403482 | D10: =D7/D4 -> 0.43504099 | E10: =E7/E4 -> 1.7133994 | F10: =F7/F4 -> 0.25793843
A12: Median Reinvestment rate /Sales percentage | B12: =MEDIAN(C10:F10) -> 0.34648971
A13: Average Reinvestment rate /Sales percentage | B13: =AVERAGE(C10:F10) -> 0.423086

Sheet Change in working capital
A1: Particular | B1: 44621 | C1: 44986 | D1: 45352 | E1: 45717 | F1: 46082
A2: Inventory | B2: ='Consolidated Balance Sheet'!B38 -> 20106.99 | C2: ='Consolidated Balance Sheet'!C38 -> 19361.23 | D2: ='Consolidated Balance Sheet'!D38 -> 21154.13 | E2: ='Consolidated Balance Sheet'!E38 -> 24621.48 | F2: ='Consolidated Balance Sheet'!F38 -> 24717.48
A3: Trade Receivables | B3: ='Consolidated Balance Sheet'!B39 -> 563.6 | C3: ='Consolidated Balance Sheet'!C39 -> 549.23 | D3: ='Consolidated Balance Sheet'!D39 -> 538.07 | E3: ='Consolidated Balance Sheet'!E39 -> 802.21 | F3: ='Consolidated Balance Sheet'!F39 -> 847.38
