Workbook

Sheet About the Company
A1: About the Company (DMART)
A3: Who We Are - Avenue Supermarts Limited (DMart) is one of India's largest supermarket chains, founded by veteran value investor Mr. Radhakishan Damani in the year 2000. The Company operates on an Everyday Low Cost / Everyday Low Price (EDLC/EDLP) model and follows a value-retailing format focused on the Foods, Non-Foods (FMCG) and General Merchandise & Apparel categories. Since opening its first store in Mumbai in 2002, DMart has grown to 415 stores across 10 states, 1 union territory and the NCR, with a total retail business area of 17.2 million sq. ft. Business Model - DMart predominantly owns the real estate for its stores, follows a cluster-based expansion strategy, and emphasises high inventory turnover with low operating costs. Operations are supported by 75 distribution centres and 10 packing centres as of 31st March 2025. Total bill cuts stood at 35.3 crore in FY 2024-25 (vs 30.3 crore in FY 2023-24), and annualised revenue per sq. ft. of retail business area was Rs.33,896 (vs Rs.32,941 in FY 2023-24). Geographic Presence (Stores by State, FY25) - Maharashtra (116), Gujarat (66), Telangana (45), Andhra Pradesh (41), Karnataka (40), Tamil Nadu (26), Madhya Pradesh (24), Rajasthan (22), Punjab (19), NCR (9), Chhattisgarh (6) and Daman (1). Vision - To be the lowest-priced retailer in its area of operation / city / region. Mission / Core Values - Built on the pillars of Action, Care and Truth – continuously identifying and offering new products at the best value, treating every stakeholder with respect, and operating with integrity and transparency. FY25 Key Highlights (Standalone) - Revenue from Operations: Rs.49,533 Cr (+16.7% YoY) | Profit After Tax: Rs.2,927 Cr (+8.6% YoY) | EPS (Basic): Rs.44.98 | EPS (Diluted): Rs.44.87 | Profit Before Tax: Rs.3,883 Cr | Stores: 415 (50 added during the year) | Retail Business Area: 17.2 mn sq. ft. FY25 Key Highlights (Consolidated) - Total Income: Rs.59,358 Cr (+16.9% YoY) | Profit Before Tax: Rs.3,673 Cr | Profit After Tax: Rs.2,707 Cr | EPS (Basic): Rs.41.61 | EPS (Diluted): Rs.41.50.
A18: Subsidiaries
A19: S.No | B19: Company Name | C19: Type | D19: FY25 Revenue / Status
A20: 1 | B20: Align Retail Trades Private Limited (ARTPL) | C20: Wholly Owned Subsidiary | D20: Revenue Rs.3,322.44 Cr; PAT Rs.37.56 Cr (FY25)
A21: 2 | B21: Avenue Food Plaza Private Limited (AFPPL) | C21: Wholly Owned Subsidiary | D21: Revenue Rs.226.50 Cr; Loss Rs.9.66 Cr (FY25)
A22: 3 | B22: Avenue E-Commerce Limited (AEL) - DMart Ready | C22: Subsidiary | D22: Revenue Rs.3,502.42 Cr; Loss Rs.247.37 Cr (FY25)
A23: 4 | B23: Nahar Seth & Jogani Developers Pvt. Ltd. (NSJDPL) | C23: Subsidiary | D23: Revenue Rs.0.83 Cr; PAT Rs.0.73 Cr (FY25)
A24: 5 | B24: Reflect Healthcare and Retail Pvt. Ltd. (RHRPL) | C24: Wholly Owned Subsidiary | D24: Revenue Rs.12.92 Cr; Loss Rs.2.45 Cr (FY25)
A25: Total Subsidiaries | B25: 5 (as on 31st March, 2025)
A27: Registered Office
A28: Anjaneya Co-op. Housing Society Ltd., Orchard Avenue, Opp. Hiranandani Foundation School, Powai, Mumbai - 400 076
A29: CIN: L51900MH2000PLC126473
A30: Website: www.dmartindia.com | Email: investorrelations@dmartindia.com
A32: Operational Footprint
A33: Company | B33: Metric | C33: Value | D33: Details
A34: Avenue Supermarts Ltd. | B34: Total Stores | C34: 415 | D34: Operational as of 31st March, 2025; 50 new stores added in FY25
A35: Avenue Supermarts Ltd. | B35: Retail Business Area | C35: 17.2 mn sq. ft. | D35: Across 10 states, 1 UT and NCR
A36: Avenue Supermarts Ltd. | B36: Distribution Centres | C36: 75 | D36: As of 31st March, 2025
A37: Avenue Supermarts Ltd. | B37: Packing Centres | C37: 10 | D37: As of 31st March, 2025
A38: Avenue Supermarts Ltd. | B38: States / UT Covered | C38: 11 | D38: Maharashtra, Gujarat, Telangana, Andhra Pradesh, Karnataka, Tamil Nadu, Madhya Pradesh, Rajasthan, Punjab, NCR, Chhattisgarh, Daman
A39: Avenue Supermarts Ltd. | B39: Annual Bill Cuts | C39: 35.3 crore | D39: FY 2024-25 (vs 30.3 crore in FY 2023-24)
A40: Avenue Supermarts Ltd. | B40: Revenue per sq.ft. | C40: Rs.33,896 | D40: Annualised, FY 2024-25 (vs Rs.32,941 in FY 2023-24)
A41: Avenue Supermarts Ltd. | B41: Stock Exchanges | C41: BSE & NSE | D41: Listed entity
A43: Board of Directors
A44: Name | C44: Designation
A45: Mr. Chandrashekhar Bhave | C45: Independent Director (Chairman)
A46: Mr. Ignatius Navil Noronha | C46: Managing Director & CEO
A47: Mr. Ramakant Baheti | C47: Whole-time Director & Group CFO
A48: Mr. Bhaskaran N | C48: Whole-time Director & COO - West
A49: Mr. Elvin Machado | C49: Whole-time Director
A50: Ms. Kalpana Unadkat | C50: Independent Director
A51: Mr. Harischandra M. Bharuka | C51: Independent Director
A52: Mrs. Manjri Chandak | C52: Non-Executive Director
A53: Mr. Niladri Deb | C53: Chief Financial Officer
A54: Mrs. Ashu Gupta | C54: Company Secretary & Compliance Officer

Sheet Promoter
A1: DMART (AVENUE SUPERMARTS LIMITED)
A2: Shareholding Pattern – Promoter & Promoter Group
A4: Sr. No. | B4: Name of Shareholder / Category | C4: Category | D4: No. of Shareholders | E4: No. of Shares Held | F4: % of Total Share Capital
B5: (A1) INDIAN
A6: 1 | B6: Individuals/Hindu undivided Family | C6: Individual | D6: 9 | E6: 242268786 | F6: 0.3716
A7: 2 | B7: Radhakishan Shivkishan Damani | C7: Promoter | D7: 1 | E7: 149848238 | F7: 0.2298
A8: 3 | B8: Gopikishan Shivkishan Damani | C8: Promoter | D8: 1 | E8: 36469012 | F8: 0.0559
A9: 4 | B9: Shrikantadevi Radhakishan Damani | C9: Promoter | D9: 1 | E9: 6500000 | F9: 0.01
A10: 5 | B10: Kirandevi Gopikishan Damani | C10: Promoter | D10: 1 | E10: 1100000 | F10: 0.0017
A11: 6 | B11: Jyoti Varun Kabra | C11: Promoter Group | D11: 1 | E11: 16114812 | F11: 0.0247
A12: 7 | B12: Manjri Chandak | C12: Promoter Group | D12: 1 | E12: 16064812 | F12: 0.0246
A13: 8 | B13: Madhu Abhay Chandak | C13: Promoter Group | D13: 1 | E13: 16064812 | F13: 0.0246
A14: 9 | B14: Rukmanidevi Mohanlal Bagri | C14: Promoter Group | D14: 1 | E14: 100000 | F14: 0.0002
A15: 10 | B15: Vijay Shankar Chandak | C15: Promoter Group | D15: 1 | E15: 7100 | F15: 0
A16: 11 | B16: Govind Kishan Mundhra | C16: Promoter Group | D16: 0 | E16: 0 | F16: 0
A17: 12 | B17: Pratinav Gopikishan Damani | C17: Promoter Group | D17: 0 | E17: 0 | F17: 0
... A20: 15 | B20: Gopikishan Shivkishan Damani HUF | C20: Promoter Group | D20: 0 | E20: 0 | F20: 0
B21: Any Other – Bodies Corporate / Trusts (Sub-total) | D21: 6 | E21: 243527470 | F21: 0.3735
A22: 16 | B22: Gopikishan S. Damani And Radhakishan S. Damani (On behalf of Gulmohar Pvt Beneficiary Trust) | C22: Promoter | D22: 1 | E22: 30955494 | F22: 0.0475
A23: 17 | B23: Gopikishan S. Damani And Radhakishan S. Damani (On behalf of Karnikar Pvt Beneficiary Trust) | C23: Promoter | D23: 1 | E23: 30955494 | F23: 0.0475
A24: 18 | B24: Radhakishan S. Damani And Shrikantadevi Damani (On behalf of Bottle Palm Pvt Beneficiary Trust) | C24: Promoter | D24: 1 | E24: 30955494 | F24: 0.0475
A25: 19 | B25: Radhakishan S. Damani And Shrikantadevi Damani (On behalf of Royal Palm Pvt Beneficiary Trust) | C25: Promoter | D25: 1 | E25: 30955494 | F25: 0.0475
A26: 20 | B26: Radhakishan S. Damani And Shrikantadevi Damani (On behalf of Mountain Glory Pvt Beneficiary Trust) | C26: Promoter | D26: 1 | E26: 30955494 | F26: 0.0475
A27: 21 | B27: Bright Star Investments Private Limited | C27: Promoter | D27: 1 | E27: 88750000 | F27: 0.1361
B28: Sub-Total (A1) – Indian Promoters | D28: 15 | E28: 485796256 | F28: 0.7451
B29: (A2) Foreign Promoters | D29: 0 | E29: 0 | F29: 0
B30: TOTAL PROMOTER & PROMOTER GROUP SHAREHOLDING (A) | D30: 15 | E30: 485796256 | F30: 0.7451
A32: Notes:

Sheet Public
A1: DMART (AVENUE SUPERMARTS LIMITED)
A2: Shareholding Pattern – Public Shareholders
A4: Sr. No. | B4: Name of Shareholder / Category | C4: Category | D4: No. of Shareholders | E4: No. of Shares Held | F4: % of Total Share Capital
B5: DOMESTIC INSTITUTIONS
A6: 1 | B6: Mutual Funds/ | D6: 31 | E6: 44145863 | F6: 0.0677
A7: 2 | B7: SBI Mutual Fund | D7: 1 | E7: 7649262 | F7: 0.0117
A8: 3 | B8: ICICI Prudential Fund | D8: 1 | E8: 17233956 | F8: 0.0264
A9: 4 | B9: Alternate Investment Funds | D9: 20 | E9: 440082 | F9: 0.0007
A10: 5 | B10: Banks | D10: 2 | E10: 14980 | F10: 0
A11: 6 | B11: Insurance Companies | D11: 18 | E11: 3051484 | F11: 0.0047
A12: 7 | B12: Provident Funds/ Pension Funds | D12: 1 | E12: 9543229 | F12: 0.0146
A13: 8 | B13: Nps Trust- A/C Sbi Pension Fund Scheme - State Govt | D13: 1 | E13: 9543229 | F13: 0.0146
A14: 9 | B14: Sovereign Wealth Funds | D14: 2 | E14: 480228 | F14: 0.0007
A15: 10 | B15: NBFCs registered with RBI | D15: 3 | E15: 867 | F15: 0
B16: Sub-Total (B1) – Domestic Institutions | D16: 77 | E16: 57676733 | F16: 0.0885
B17: FOREIGN INSTITUTIONS
A18: 11 | B18: Foreign Portfolio Investors Category I | D18: 577 | E18: 57161995 | F18: 0.0877
A19: 12 | B19: Foreign Portfolio Investors Category II | D19: 30 | E19: 1506574 | F19: 0.0023
B20: Sub-Total (B2) – Foreign Institutions | D20: 607 | E20: 58668569 | F20: 0.09
B21: GOVERNMENT HOLDING
A22: 13 | B22: Central Government / President of India | D22: 3 | E22: 14847 | F22: 0
B23: Sub-Total (B3) – Government Holding | D23: 3 | E23: 14847 | F23: 0
B24: NON-INSTITUTIONS
A25: 14 | B25: Directors and their relatives (excluding independent directors and nominee directors) | D25: 12 | E25: 4196494 | F25: 0.0064
A26: 15 | B26: Key Managerial Personnel | D26: 2 | E26: 94372 | F26: 0.0001
A27: 16 | B27: Relatives of promoters (other than 'immediate relatives' of promoters disclosed under 'Promoter and Promoter Group' category) | D27: 3 | E27: 750000 | F27: 0.0012
A28: 17 | B28: Resident Individuals holding nominal share capital up to Rs. 2 lakhs | D28: 552567 | E28: 17765451 | F28: 0.0272
A29: 18 | B29: Resident Individuals holding nominal share capital in excess of Rs. 2 lakhs | D29: 169 | E29: 24047555 | F29: 0.0369
A30: 19 | B30: Ignatius Navil Noronha | D30: 1 | E30: 12542572 | F30: 0.0192
A31: 20 | B31: Non Resident Indians (NRIs) | D31: 11308 | E31: 706754 | F31: 0.0011
A32: 21 | B32: Bodies Corporate | D32: 1307 | E32: 896140 | F32: 0.0014
A33: 22 | B33: Any Other (specify) | D33: 7694 | E33: 1345952 | F33: 0.0021
A34: 23 | B34: Trusts | D34: 14 | E34: 3956 | F34: 0
A35: 24 | B35: LLP | D35: 167 | E35: 52859 | F35: 0.0001
A36: 25 | B36: HUF | D36: 7468 | E36: 478130 | F36: 0.0007
A37: 26 | B37: Clearing Members | D37: 45 | E37: 811007 | F37: 0.0012
B38: Sub-Total (B4) – Non-Institutions | D38: 573062 | E38: 49802718 | F38: 0.0764
B39: TOTAL PUBLIC SHAREHOLDING (B) | D39: 573749 | E39: 166162867 | F39: 0.2549
A41: Notes:
A42: 1. Categories with nil shareholding as of the reporting date have been excluded for presentation clarity.
...

Sheet Consolidated Balance sheet
A1: PARTICULARS | B1: Mar 22 | C1: Mar 23 | D1: Mar 24 | E1: Mar 25 | F1: Mar 26
B2: 12 mths | C2: 12 mths | D2: 12 mths | E2: 12 mths | F2: 12 mths
B3: (Rs. Cr.) | C3: (Rs. Cr.) | D3: (Rs. Cr.) | E3: (Rs. Cr.) | F3: (Rs. Cr.)
A4: EQUITIES AND LIABILITIES
A5: SHAREHOLDER'S FUNDS
A6: Equity Share Capital | B6: 647.77 | C6: 648.26 | D6: 650.73 | E6: 650.73 | F6: 651.96
A7: Total Share Capital | B7: 647.77 | C7: 648.26 | D7: 650.73 | E7: 650.73 | F7: 651.96
A8: Reserves and Surplus | B8: 12990.43 | C8: 15383.6 | D8: 18010.21 | E8: 20777.02 | F8: 23812.08
A9: Total Reserves and Surplus | B9: 12990.43 | C9: 15383.6 | D9: 18010.21 | E9: 20777.02 | F9: 23812.08
A10: Employees Stock Options | B10: 39.44 | C10: 45.93 | D10: 36.88 | E10: 0 | F10: 0
A11: Total Shareholders Funds | B11: 13677.64 | C11: 16077.79 | D11: 18697.82 | E11: 21427.75 | F11: 24464.04
A12: Equity Share Application Money | B12: 0 | C12: 0.91 | D12: 0 | E12: 0 | F12: 0
A13: Minority Interest | B13: 0.25 | C13: 0.08 | D13: -0.48 | E13: -1.05 | F13: -1.68
A15: NON-CURRENT LIABILITIES
A16: Long Term Borrowings | B16: 0 | C16: 0 | D16: 0 | E16: 0 | F16: 1142.54
A17: Deferred Tax Liabilities [Net] | B17: 64.03 | C17: 76.96 | D17: 91.93 | E17: 112.48 | F17: 121.86
A18: Other Long Term Liabilities | B18: 507.56 | C18: 477.13 | D18: 399.61 | E18: 556.28 | F18: 0.54
A19: Long Term Provisions | B19: 4.87 | C19: 6.41 | D19: 9.18 | E19: 12.67 | F19: 14.7
A20: Total Non-Current Liabilities | B20: 576.46 | C20: 560.5 | D20: 500.72 | E20: 681.43 | F20: 1279.64
A22: CURRENT LIABILITIES
A23: Short Term Borrowings | B23: 0 | C23: 0 | D23: 0 | E23: 0 | F23: 1282.45
A24: Trade Payables | B24: 589.2 | C24: 753.79 | D24: 984.81 | E24: 1070.81 | F24: 1338.23
A25: Other Current Liabilities | B25: 592.65 | C25: 662.35 | D25: 933.29 | E25: 1092.21 | F25: 1050.16
A26: Short Term Provisions | B26: 36.44 | C26: 50.87 | D26: 61.04 | E26: 49.14 | F26: 111.42
A27: Total Current Liabilities | B27: 1218.29 | C27: 1467.01 | D27: 1979.14 | E27: 2212.16 | F27: 3782.26
A28: Total Capital And Liabilities | B28: 15472.64 | C28: 18106.29 | D28: 21177.2 | E28: 24320.29 | F28: 29524.26
A30: ASSETS
A31: NON-CURRENT ASSETS
A32: Tangible Assets | B32: 9168.14 | C32: 11239.03 | D32: 13306.38 | E32: 16099.21 | F32: 17594.21
A33: Intangible Assets | B33: 13.61 | C33: 23.18 | D33: 30.35 | E33: 28.98 | F33: 2417.83
A34: Capital Work-In-Progress | B34: 1129.34 | C34: 829.16 | D34: 935.22 | E34: 1099.35 | F34: 1299.96
A35: Fixed Assets | B35: 10311.09 | C35: 12091.37 | D35: 14271.95 | E35: 17227.54 | F35: 21312
A36: Non-Current Investments | B36: 0.01 | C36: 0.01 | D36: 0.01 | E36: 2.01 | F36: 2.01
A37: Deferred Tax Assets [Net] | B37: 1.66 | C37: 1.77 | D37: 4.72 | E37: 7.51 | F37: 6.71
A38: Other Non-Current Assets | B38: 1638.76 | C38: 486.48 | D38: 620.22 | E38: 612.76 | F38: 647.49
A39: Total Non-Current Assets | B39: 12029.79 | C39: 12657.9 | D39: 14975.17 | E39: 17928.09 | F39: 22046.48
A41: CURRENT ASSETS
A42: Current Investments | B42: 5.93 | C42: 202.19 | D42: 106.66 | E42: 1.25 | F42: 2
A43: Inventories | B43: 2742.66 | C43: 3243.48 | D43: 3927.31 | E43: 5044.37 | F43: 5900.64
A44: Trade Receivables | B44: 66.89 | C44: 62.16 | D44: 166.37 | E44: 153.79 | F44: 149.34
...

Sheet Consolidated P&l
A1: PARTICULARS | B1: Mar 22 | C1: Mar 23 | D1: Mar 24 | E1: Mar 25 | F1: Mar 26
B2: 12 mths | C2: 12 mths | D2: 12 mths | E2: 12 mths | F2: 12 mths
B3: (Rs. Cr.) | C3: (Rs. Cr.) | D3: (Rs. Cr.) | E3: (Rs. Cr.) | F3: (Rs. Cr.)
A4: INCOME
A5: Revenue From Operations [Gross] | B5: 33794.9 | C5: 47016.17 | D5: 55774.38 | E5: 65224.12 | F5: 68820.74
A6: Less: Excise/Service Tax/Other Levies | B6: 2936.5 | C6: 4310.75 | D6: 5105.34 | E6: 6024.82 | F6: 0
A7: Revenue From Operations [Net] | B7: 30858.4 | C7: 42705.42 | D7: 50669.04 | E7: 59199.3 | F7: 68820.74
A8: Other Operating Revenues | B8: 117.87 | C8: 134.14 | D8: 119.79 | E8: 158.75 | F8: 0
A9: Total Operating Revenues | B9: 30976.27 | C9: 42839.56 | D9: 50788.83 | E9: 59358.05 | F9: 68820.74
A10: Other Income | B10: 117.49 | C10: 129.34 | D10: 146.45 | E10: 124.31 | F10: 74.1
A11: Total Revenue | B11: 31093.76 | C11: 42968.9 | D11: 50935.28 | E11: 59482.36 | F11: 68894.84
A13: EXPENSES
A14: Purchase Of Stock-In Trade | B14: 26891.77 | C14: 36884.77 | D14: 43958.31 | E14: 51668.76 | F14: 59315.99
A15: Changes In Inventories Of FG, WIP And Stock-In Trade | B15: -494.38 | C15: -500.82 | D15: -683.77 | E15: -1117.06 | F15: -856.26
A16: Employee Benefit Expenses | B16: 616.21 | C16: 746.97 | D16: 906.12 | E16: 1165.9 | F16: 1541.48
A17: Finance Costs | B17: 53.79 | C17: 67.41 | D17: 58.13 | E17: 69.45 | F17: 142.05
A18: Depreciation And Amortisation Expenses | B18: 498.08 | C18: 638.87 | D18: 730.76 | E18: 869.52 | F18: 1037.02
A19: Other Expenses | B19: 1464.17 | C19: 2071.61 | D19: 2504.4 | E19: 3153.12 | F19: 3632.94
A20: Total Expenses | B20: 29029.64 | C20: 39908.81 | D20: 47473.95 | E20: 55809.69 | F20: 64813.22
A22: Profit/Loss Before Exceptional, ExtraOrdinary Items And Tax | B22: 2064.12 | C22: 3060.09 | D22: 3461.33 | E22: 3672.67 | F22: 4081.62
A23: Profit/Loss Before Tax | B23: 2064.12 | C23: 3060.09 | D23: 3461.33 | E23: 3672.67 | F23: 4081.62
A25: TAX EXPENSES - CONTINUED OPERATIONS
A26: Current Tax | B26: 546.33 | C26: 807.7 | D26: 913.09 | E26: 983.47 | F26: 1111.76
A27: Deferred Tax | B27: 12.1 | C27: 12.82 | D27: 12.02 | E27: 17.76 | F27: 0
A28: Tax For Earlier Years | B28: 13.29 | C28: -138.77 | D28: 0.61 | E28: -36.01 | F28: 0
A29: Total Tax Expenses | B29: 571.72 | C29: 681.75 | D29: 925.72 | E29: 965.22 | F29: 1111.76
A31: Profit/Loss After Tax And Before ExtraOrdinary Items | B31: 1492.4 | C31: 2378.34 | D31: 2535.61 | E31: 2707.45 | F31: 2969.86
A32: Profit/Loss From Continuing Operations | B32: 1492.4 | C32: 2378.34 | D32: 2535.61 | E32: 2707.45 | F32: 2969.86
A33: Profit/Loss For The Period | B33: 1492.4 | C33: 2378.34 | D33: 2535.61 | E33: 2707.45 | F33: 2969.86
A34: Minority Interest | B34: 0.15 | C34: 0.17 | D34: 0.56 | E34: 0.57 | F34: 0.63
A35: Consolidated Profit/Loss After MI And Associates | B35: 1492.55 | C35: 2378.51 | D35: 2536.17 | E35: 2708.02 | F35: 2970.49
A37: OTHER ADDITIONAL INFORMATION
A38: EARNINGS PER SHARE
A39: Basic EPS (Rs.) | B39: 23 | C39: 37 | D39: 39 | E39: 42 | F39: 46
A40: Diluted EPS (Rs.) | B40: 23 | C40: 36 | D40: 39 | E40: 42 | F40: 46

Sheet Consolidated Cash flow
A1: PARTICULARS | B1: Mar '22 | C1: Mar '23 | D1: Mar '24 | E1: Mar '25 | F1: Mar '26
B2: 12 mths | C2: 12 mths | D2: 12 mths | E2: 12 mths | F2: 12 mths
B3: (Rs. Cr.) | C3: (Rs. Cr.) | D3: (Rs. Cr.) | E3: (Rs. Cr.) | F3: (Rs. Cr.)
A4: Net Profit Before Tax | B4: 2064.12 | C4: 3060.09 | D4: 3461.33 | E4: 3672.67 | F4: 4081.62
A5: Net Cash From Operating Activities | B5: 1372.35 | C5: 2630.27 | D5: 2745.84 | E5: 2462.97 | F5: 3466.74
A6: Net Cash (used in)/from Investing Activities | B6: -1289.49 | C6: -2313.1 | D6: -2468.23 | E6: -2185.31 | F6: -4206.96
A7: Net Cash (used in)/from Financing Activities | B7: -179.24 | C7: -205.14 | D7: -147.64 | E7: -259.3 | F7: 288.18
A8: Net (decrease)/increase In Cash and Cash Equivalents | B8: -96.38 | C8: 112.03 | D8: 129.97 | E8: 18.36 | F8: -452.04
A9: Opening Cash & Cash Equivalents | B9: 191.5 | C9: 95.12 | D9: 207.15 | E9: 337.12 | F9: 355.48
A10: Closing Cash & Cash Equivalents | B10: 95.12 | C10: 207.15 | D10: 337.12 | E10: 355.48 | F10: -96.56

Sheet Beta
A1: Date | B1: NIFTY50_Close | C1: DMART_Close | E1: Rm Nifty | F1: Rm DMArt | G1: slope | H1: covariance
A2: 43922 | B2: 8253.7998 | C2: 2082.7
A3: 43924 | B3: 8083.7998 | C3: 2066.95 | E3: =(B3-B2)/B2 -> -0.020596574 | F3: =(C3-C2)/C2 -> -0.0075622991 | G3: =SLOPE(F3:F1519,E3:E1519) -> 0.64597459 | H3: =_xlfn.COVARIANCE.S(F3:F1519,E3:E1519)/_xlfn.VAR.S(E3:E1519) -> 0.64597459 | J3: SUMMARY OUTPUT
A4: 43928 | B4: 8792.2002 | C4: 2170.25 | E4: =(B4-B3)/B3 -> 0.087632105 | F4: =(C4-C3)/C3 -> 0.049977044
A5: 43929 | B5: 8748.75 | C5: 2278.75 | E5: =(B5-B4)/B4 -> -0.0049419024 | F5: =(C5-C4)/C4 -> 0.04999424 | H5: =0.67*H3+0.33 -> 0.76280297 | J5: Regression Statistics
A6: 43930 | B6: 9111.9004 | C6: 2392.6499 | E6: =(B6-B5)/B5 -> 0.041508832 | F6: =(C6-C5)/C5 -> 0.049983501 | J6: Multiple R | K6: 0.34312358
A7: 43934 | B7: 8993.8496 | C7: 2273.05 | E7: =(B7-B6)/B6 -> -0.012955671 | F7: =(C7-C6)/C6 -> -0.049986358 | J7: R Square | K7: 0.11773379
A8: 43936 | B8: 8925.2998 | C8: 2180.8999 | E8: =(B8-B7)/B7 -> -0.0076218536 | F8: =(C8-C7)/C7 -> -0.040540307 | J8: Adjusted R Square | K8: 0.11715144
A9: 43937 | B9: 8992.7998 | C9: 2137.8501 | E9: =(B9-B8)/B8 -> 0.0075627712 | F9: =(C9-C8)/C8 -> -0.019739468 | J9: Standard Error | K9: 0.017364408
A10: 43938 | B10: 9266.75 | C10: 2212.1001 | E10: =(B10-B9)/B9 -> 0.030463282 | F10: =(C10-C9)/C9 -> 0.034731154 | J10: Observations | K10: 1517
A11: 43941 | B11: 9261.8496 | C11: 2256.25 | E11: =(B11-B10)/B10 -> -0.00052881438 | F11: =(C11-C10)/C10 -> 0.019958366
A12: 43942 | B12: 8981.4502 | C12: 2238.2 | E12: =(B12-B11)/B11 -> -0.030274667 | F12: =(C12-C11)/C11 -> -0.0080000216 | J12: ANOVA
A13: 43943 | B13: 9187.2998 | C13: 2290.05 | E13: =(B13-B12)/B12 -> 0.022919418 | F13: =(C13-C12)/C12 -> 0.023165981 | K13: df | L13: SS | M13: MS | N13: F | O13: Significance F
A14: 43944 | B14: 9313.9004 | C14: 2303.5 | E14: =(B14-B13)/B13 -> 0.013779956 | F14: =(C14-C13)/C13 -> 0.0058732128 | J14: Regression | K14: 1 | L14: 0.06095847 | M14: 0.06095847 | N14: 202.16879 | O14: 3.6798025e-43
A15: 43945 | B15: 9154.4004 | C15: 2310.5 | E15: =(B15-B14)/B14 -> -0.017124942 | F15: =(C15-C14)/C14 -> 0.0030388539 | J15: Residual | K15: 1515 | L15: 0.45680682 | M15: 0.00030152266
A16: 43948 | B16: 9282.2998 | C16: 2323.95 | E16: =(B16-B15)/B15 -> 0.013971359 | F16: =(C16-C15)/C15 -> 0.0058212297 | J16: Total | K16: 1516 | L16: 0.51776529
A17: 43949 | B17: 9380.9004 | C17: 2305.8 | E17: =(B17-B16)/B16 -> 0.010622431 | F17: =(C17-C16)/C16 -> -0.0078099368
A18: 43950 | B18: 9553.3496 | C18: 2344.3501 | E18: =(B18-B17)/B17 -> 0.018383014 | F18: =(C18-C17)/C17 -> 0.01671873 | K18: Coefficients | L18: Standard Error | M18: t Stat | N18: P-value | O18: Lower 95% | P18: Upper 95% | Q18: Lower 95.0% | R18: Upper 95.0%
A19: 43951 | B19: 9859.9004 | C19: 2383.6499 | E19: =(B19-B18)/B18 -> 0.032088303 | F19: =(C19-C18)/C18 -> 0.016763624 | J19: Intercept | K19: 0.00012946393 | L19: 0.00044713791 | M19: 0.28953916 | N19: 0.77220843 | O19: -0.00074761096 | P19: 0.0010065388 | Q19: -0.00074761096 | R19: 0.0010065388
A20: 43955 | B20: 9293.5 | C20: 2281.3 | E20: =(B20-B19)/B19 -> -0.057444839 | F20: =(C20-C19)/C19 -> -0.042938291 | J20: X Variable 1 | K20: 0.64597459 | L20: 0.045431636 | M20: 14.218607 | N20: 3.6798025e-43 | O20: 0.55685902 | P20: 0.73509015 | Q20: 0.55685902 | R20: 0.73509015
A21: 43956 | B21: 9205.5996 | C21: 2198.95 | E21: =(B21-B20)/B20 -> -0.0094582655 | F21: =(C21-C20)/C20 -> -0.036097881
A22: 43957 | B22: 9270.9004 | C22: 2175.6001 | E22: =(B22-B21)/B21 -> 0.0070935935 | F22: =(C22-C21)/C21 -> -0.010618638
A23: 43958 | B23: 9199.0498 | C23: 2182.1001 | E23: =(B23-B22)/B22 -> -0.0077501195 | F23: =(C23-C22)/C22 -> 0.0029876814
A24: 43959 | B24: 9251.5 | C24: 2255 | E24: =(B24-B23)/B23 -> 0.0057016971 | F24: =(C24-C23)/C23 -> 0.033408139
A25: 43962 | B25: 9239.2002 | C25: 2313.55 | E25: =(B25-B24)/B24 -> -0.001329493 | F25: =(C25-C24)/C24 -> 0.025964545
A26: 43963 | B26: 9196.5498 | C26: 2303.3501 | E26: =(B26-B25)/B25 -> -0.0046162427 | F26: =(C26-C25)/C25 -> -0.0044087878
A27: 43964 | B27: 9383.5498 | C27: 2352.1499 | E27: =(B27-B26)/B26 -> 0.020333713 | F27: =(C27-C26)/C26 -> 0.021186447
A28: 43965 | B28: 9142.75 | C28: 2324.3999 | E28: =(B28-B27)/B27 -> -0.025661909 | F28: =(C28-C27)/C27 -> -0.011797717
A29: 43966 | B29: 9136.8496 | C29: 2333.8 | E29: =(B29-B28)/B28 -> -0.00064536279 | F29: =(C29-C28)/C28 -> 0.0040441176
A30: 43969 | B30: 8823.25 | C30: 2306.55 | E30: =(B30-B29)/B29 -> -0.03432251 | F30: =(C30-C29)/C29 -> -0.011676236
A31: 43970 | B31: 8879.0996 | C31: 2337.5 | E31: =(B31-B30)/B30 -> 0.0063298228 | F31: =(C31-C30)/C30 -> 0.013418287
A32: 43971 | B32: 9066.5498 | C32: 2454.3501 | E32: =(B32-B31)/B31 -> 0.021111397 | F32: =(C32-C31)/C31 -> 0.049989347
... A1519: 46167 | B1519: 24031.699 | C1519: 4097.2002 | E1519: =(B1519-B1518)/B1518 -> 0.013170643 | F1519: =(C1519-C1518)/C1518 -> -0.0048092797

Sheet Ratio analysis
A1: Ratio Analysis - DMart (Avenue Supermarts)
A2: Particulars | B2: Mar-22 | C2: Mar-23 | D2: Mar-24 | E2: Mar-25 | F2: Mar-26 | G2: Trends | H2: Mean | I2: Median
A3: GROWTH RATIOS
A4: Sales Growth | C4: =('Consolidated P&l'!C9-'Consolidated P&l'!B9)/'Consolidated P&l'!B9 -> 0.38297994 | D4: =('Consolidated P&l'!D9-'Consolidated P&l'!C9)/'Consolidated P&l'!C9 -> 0.1855591 | E4: =('Consolidated P&l'!E9-'Consolidated P&l'!D9)/'Consolidated P&l'!D9 -> 0.16872253 | F4: =('Consolidated P&l'!F9-'Consolidated P&l'!E9)/'Consolidated P&l'!E9 -> 0.15941713 | H4: =AVERAGE(C4:F4) -> 0.22416967 | I4: =MEDIAN(C4:F4) -> 0.17714081
A5: EBITDA Growth | C5: =(('Consolidated P&l'!C23+'Consolidated P&l'!C17+'Consolidated P&l'!C18)-('Consolidated P&l'!B23+'Consolidated P&l'!B17+'Consolidated P&l'!B18))/('Consolidated P&l'!B23+'Consolidated P&l'!B17+'Consolidated P&l'!B18) -> 0.43974939 | D5: =(('Consolidated P&l'!D23+'Consolidated P&l'!D17+'Consolidated P&l'!D18)-('Consolidated P&l'!C23+'Consolidated P&l'!C17+'Consolidated P&l'!C18))/('Consolidated P&l'!C23+'Consolidated P&l'!C17+'Consolidated P&l'!C18) -> 0.12846587 | E5: =(('Consolidated P&l'!E23+'Consolidated P&l'!E17+'Consolidated P&l'!E18)-('Consolidated P&l'!D23+'Consolidated P&l'!D17+'Consolidated P&l'!D18))/('Consolidated P&l'!D23+'Consolidated P&l'!D17+'Consolidated P&l'!D18) -> 0.085035598 | F5: =(('Consolidated P&l'!F23+'Consolidated P&l'!F17+'Consolidated P&l'!F18)-('Consolidated P&l'!E23+'Consolidated P&l'!E17+'Consolidated P&l'!E18))/('Consolidated P&l'!E23+'Consolidated P&l'!E17+'Consolidated P&l'!E18) -> 0.14074169 | H5: =AVERAGE(C5:F5) -> 0.19849814 | I5: =MEDIAN(C5:F5) -> 0.13460378
A6: EBIT Growth | C6: =(('Consolidated P&l'!C23+'Consolidated P&l'!C17)-('Consolidated P&l'!B23+'Consolidated P&l'!B17))/('Consolidated P&l'!B23+'Consolidated P&l'!B17) -> 0.47669164 | D6: =(('Consolidated P&l'!D23+'Consolidated P&l'!D17)-('Consolidated P&l'!C23+'Consolidated P&l'!C17))/('Consolidated P&l'!C23+'Consolidated P&l'!C17) -> 0.12532694 | E6: =(('Consolidated P&l'!E23+'Consolidated P&l'!E17)-('Consolidated P&l'!D23+'Consolidated P&l'!D17))/('Consolidated P&l'!D23+'Consolidated P&l'!D17) -> 0.063265387 | F6: =(('Consolidated P&l'!F23+'Consolidated P&l'!F17)-('Consolidated P&l'!E23+'Consolidated P&l'!E17))/('Consolidated P&l'!E23+'Consolidated P&l'!E17) -> 0.12868374 | H6: =AVERAGE(C6:F6) -> 0.19849193 | I6: =MEDIAN(C6:F6) -> 0.12700534
A7: Net Profit Growth | C7: =('Consolidated P&l'!C33-'Consolidated P&l'!B33)/'Consolidated P&l'!B33 -> 0.59363441 | D7: =('Consolidated P&l'!D33-'Consolidated P&l'!C33)/'Consolidated P&l'!C33 -> 0.066125953 | E7: =('Consolidated P&l'!E33-'Consolidated P&l'!D33)/'Consolidated P&l'!D33 -> 0.067770675 | F7: =('Consolidated P&l'!F33-'Consolidated P&l'!E33)/'Consolidated P&l'!E33 -> 0.096921457 | H7: =AVERAGE(C7:F7) -> 0.20611312 | I7: =MEDIAN(C7:F7) -> 0.082346066
A9: MARGIN RATIOS
A10: Gross Margin | B10: =('Consolidated P&l'!B9-'Consolidated P&l'!B14-'Consolidated P&l'!B15)/'Consolidated P&l'!B9 -> 0.14781896 | C10: =('Consolidated P&l'!C9-'Consolidated P&l'!C14-'Consolidated P&l'!C15)/'Consolidated P&l'!C9 -> 0.15069272 | D10: =('Consolidated P&l'!D9-'Consolidated P&l'!D14-'Consolidated P&l'!D15)/'Consolidated P&l'!D9 -> 0.14795163 | E10: =('Consolidated P&l'!E9-'Consolidated P&l'!E14-'Consolidated P&l'!E15)/'Consolidated P&l'!E9 -> 0.14835983 | F10: =('Consolidated P&l'!F9-'Consolidated P&l'!F14-'Consolidated P&l'!F15)/'Consolidated P&l'!F9 -> 0.15055069 | H10: =AVERAGE(B10:F10) -> 0.14907477 | I10: =MEDIAN(B10:F10) -> 0.14835983
A11: EBITDA Margin | B11: =('Consolidated P&l'!B23+'Consolidated P&l'!B17+'Consolidated P&l'!B18)/'Consolidated P&l'!B9 -> 0.08445142 | C11: =('Consolidated P&l'!C23+'Consolidated P&l'!C17+'Consolidated P&l'!C18)/'Consolidated P&l'!C9 -> 0.087918037 | D11: =('Consolidated P&l'!D23+'Consolidated P&l'!D17+'Consolidated P&l'!D18)/'Consolidated P&l'!D9 -> 0.083684149 | E11: =('Consolidated P&l'!E23+'Consolidated P&l'!E17+'Consolidated P&l'!E18)/'Consolidated P&l'!E9 -> 0.077691905 | F11: =('Consolidated P&l'!F23+'Consolidated P&l'!F17+'Consolidated P&l'!F18)/'Consolidated P&l'!F9 -> 0.076440474 | H11: =AVERAGE(B11:F11) -> 0.082037197 | I11: =MEDIAN(B11:F11) -> 0.083684149
A12: EBIT Margin | B12: =('Consolidated P&l'!B23+'Consolidated P&l'!B17)/'Consolidated P&l'!B9 -> 0.068372015 | C12: =('Consolidated P&l'!C23+'Consolidated P&l'!C17)/'Consolidated P&l'!C9 -> 0.073004951 | D12: =('Consolidated P&l'!D23+'Consolidated P&l'!D17)/'Consolidated P&l'!D9 -> 0.069295946 | E12: =('Consolidated P&l'!E23+'Consolidated P&l'!E17)/'Consolidated P&l'!E9 -> 0.063043176 | F12: =('Consolidated P&l'!F23+'Consolidated P&l'!F17)/'Consolidated P&l'!F9 -> 0.061372052 | H12: =AVERAGE(B12:F12) -> 0.067017628 | I12: =MEDIAN(B12:F12) -> 0.068372015
A13: EBT Margin | B13: ='Consolidated P&l'!B23/'Consolidated P&l'!B9 -> 0.066635525 | C13: ='Consolidated P&l'!C23/'Consolidated P&l'!C9 -> 0.071431406 | D13: ='Consolidated P&l'!D23/'Consolidated P&l'!D9 -> 0.068151403 | E13: ='Consolidated P&l'!E23/'Consolidated P&l'!E9 -> 0.061873158 | F13: ='Consolidated P&l'!F23/'Consolidated P&l'!F9 -> 0.059307993 | H13: =AVERAGE(B13:F13) -> 0.065479897 | I13: =MEDIAN(B13:F13) -> 0.066635525
A14: Net Profit Margin | B14: ='Consolidated P&l'!B33/'Consolidated P&l'!B9 -> 0.048178816 | C14: ='Consolidated P&l'!C33/'Consolidated P&l'!C9 -> 0.055517377 | D14: ='Consolidated P&l'!D33/'Consolidated P&l'!D9 -> 0.04992456 | E14: ='Consolidated P&l'!E33/'Consolidated P&l'!E9 -> 0.045612179 | F14: ='Consolidated P&l'!F33/'Consolidated P&l'!F9 -> 0.043153561 | H14: =AVERAGE(B14:F14) -> 0.048477299 | I14: =MEDIAN(B14:F14) -> 0.048178816
A16: EXPENSE ANALYSIS
A17: COGS % of Sales | B17: =('Consolidated P&l'!B14+'Consolidated P&l'!B15)/'Consolidated P&l'!B9 -> 0.85218104 | C17: =('Consolidated P&l'!C14+'Consolidated P&l'!C15)/'Consolidated P&l'!C9 -> 0.84930728 | D17: =('Consolidated P&l'!D14+'Consolidated P&l'!D15)/'Consolidated P&l'!D9 -> 0.85204837 | E17: =('Consolidated P&l'!E14+'Consolidated P&l'!E15)/'Consolidated P&l'!E9 -> 0.85164017 | F17: =('Consolidated P&l'!F14+'Consolidated P&l'!F15)/'Consolidated P&l'!F9 -> 0.84944931 | H17: =AVERAGE(B17:F17) -> 0.85092523 | I17: =MEDIAN(B17:F17) -> 0.85164017
A18: Depreciation % of Sales | B18: ='Consolidated P&l'!B18/'Consolidated P&l'!B9 -> 0.016079405 | C18: ='Consolidated P&l'!C18/'Consolidated P&l'!C9 -> 0.014913085 | D18: ='Consolidated P&l'!D18/'Consolidated P&l'!D9 -> 0.014388203 | E18: ='Consolidated P&l'!E18/'Consolidated P&l'!E9 -> 0.014648729 | F18: ='Consolidated P&l'!F18/'Consolidated P&l'!F9 -> 0.015068423 | H18: =AVERAGE(B18:F18) -> 0.015019569 | I18: =MEDIAN(B18:F18) -> 0.014913085
A19: Employee Cost % of Sales | B19: ='Consolidated P&l'!B16/'Consolidated P&l'!B9 -> 0.01989297 | C19: ='Consolidated P&l'!C16/'Consolidated P&l'!C9 -> 0.017436454 | D19: ='Consolidated P&l'!D16/'Consolidated P&l'!D9 -> 0.017840931 | E19: ='Consolidated P&l'!E16/'Consolidated P&l'!E9 -> 0.019641818 | F19: ='Consolidated P&l'!F16/'Consolidated P&l'!F9 -> 0.02239848 | H19: =AVERAGE(B19:F19) -> 0.01944213 | I19: =MEDIAN(B19:F19) -> 0.019641818
A20: Other Expenses % of Sales | B20: ='Consolidated P&l'!B19/'Consolidated P&l'!B9 -> 0.047267473 | C20: ='Consolidated P&l'!C19/'Consolidated P&l'!C9 -> 0.048357406 | D20: ='Consolidated P&l'!D19/'Consolidated P&l'!D9 -> 0.049310055 | E20: ='Consolidated P&l'!E19/'Consolidated P&l'!E9 -> 0.053120343 | F20: ='Consolidated P&l'!F19/'Consolidated P&l'!F9 -> 0.052788447 | H20: =AVERAGE(B20:F20) -> 0.050168745 | I20: =MEDIAN(B20:F20) -> 0.049310055
A21: Finance Cost % of Sales | B21: ='Consolidated P&l'!B17/'Consolidated P&l'!B9 -> 0.0017364905 | C21: ='Consolidated P&l'!C17/'Consolidated P&l'!C9 -> 0.0015735456 | D21: ='Consolidated P&l'!D17/'Consolidated P&l'!D9 -> 0.001144543 | E21: ='Consolidated P&l'!E17/'Consolidated P&l'!E9 -> 0.0011700182 | F21: ='Consolidated P&l'!F17/'Consolidated P&l'!F9 -> 0.002064058 | H21: =AVERAGE(B21:F21) -> 0.0015377311 | I21: =MEDIAN(B21:F21) -> 0.0015735456
A22: sales expenses% of sales
A23: Operating Income
A24: RETURN RATIOS
A25: Return on Equity (ROE) | B25: ='Consolidated P&l'!B33/'Consolidated Balance sheet'!B11 -> 0.10911239 | C25: ='Consolidated P&l'!C33/'Consolidated Balance sheet'!C11 -> 0.14792705 | D25: ='Consolidated P&l'!D33/'Consolidated Balance sheet'!D11 -> 0.13560993 | E25: ='Consolidated P&l'!E33/'Consolidated Balance sheet'!E11 -> 0.12635251 | F25: ='Consolidated P&l'!F33/'Consolidated Balance sheet'!F11 -> 0.12139696 | H25: =AVERAGE(B25:F25) -> 0.12807977 | I25: =MEDIAN(B25:F25) -> 0.12635251
A26: Return on Capital Employed (ROCE) | B26: =('Consolidated P&l'!B23+'Consolidated P&l'!B17)/('Consolidated Balance sheet'!B48-'Consolidated Balance sheet'!B27) -> 0.14857991 | C26: =('Consolidated P&l'!C23+'Consolidated P&l'!C17)/('Consolidated Balance sheet'!C48-'Consolidated Balance sheet'!C27) -> 0.18795885 | D26: =('Consolidated P&l'!D23+'Consolidated P&l'!D17)/('Consolidated Balance sheet'!D48-'Consolidated Balance sheet'!D27) -> 0.18332373 | E26: =('Consolidated P&l'!E23+'Consolidated P&l'!E17)/('Consolidated Balance sheet'!E48-'Consolidated Balance sheet'!E27) -> 0.16926443 | F26: =('Consolidated P&l'!F23+'Consolidated P&l'!F17)/('Consolidated Balance sheet'!F48-'Consolidated Balance sheet'!F27) -> 0.16407699 | H26: =AVERAGE(B26:F26) -> 0.17064078 | I26: =MEDIAN(B26:F26) -> 0.16926443
A27: Return on Assets (ROA) | B27: ='Consolidated P&l'!B33/'Consolidated Balance sheet'!B48 -> 0.096454128 | C27: ='Consolidated P&l'!C33/'Consolidated Balance sheet'!C48 -> 0.13135435 | D27: ='Consolidated P&l'!D33/'Consolidated Balance sheet'!D48 -> 0.11973301 | E27: ='Consolidated P&l'!E33/'Consolidated Balance sheet'!E48 -> 0.11132474 | F27: ='Consolidated P&l'!F33/'Consolidated Balance sheet'!F48 -> 0.1005905 | H27: =AVERAGE(B27:F27) -> 0.11189135 | I27: =MEDIAN(B27:F27) -> 0.11132474
A28: Retained Earnings % of Sales | B28: ='Consolidated P&l'!B33/'Consolidated P&l'!B9 -> 0.048178816 | C28: ='Consolidated P&l'!C33/'Consolidated P&l'!C9 -> 0.055517377 | D28: ='Consolidated P&l'!D33/'Consolidated P&l'!D9 -> 0.04992456 | E28: ='Consolidated P&l'!E33/'Consolidated P&l'!E9 -> 0.045612179 | F28: ='Consolidated P&l'!F33/'Consolidated P&l'!F9 -> 0.043153561 | H28: =AVERAGE(B28:F28) -> 0.048477299 | I28: =MEDIAN(B28:F28) -> 0.048178816
A29: Self Sustained Growth Rate | B29: =B25*B28 -> 0.0052569058 | C29: =C25*C28 -> 0.0082125216 | D29: =D25*D28 -> 0.0067702659 | E29: =E25*E28 -> 0.0057632133 | F29: =F25*F28 -> 0.005238711 | H29: =AVERAGE(B29:F29) -> 0.0062483235 | I29: =MEDIAN(B29:F29) -> 0.0057632133
A30: Interest Coverage Ratio | B30: =IF('Consolidated P&l'!B17=0,"",('Consolidated P&l'!B23+'Consolidated P&l'!B17)/'Consolidated P&l'!B17) -> 39.373675 | C30: =IF('Consolidated P&l'!C17=0,"",('Consolidated P&l'!C23+'Consolidated P&l'!C17)/'Consolidated P&l'!C17) -> 46.395194 | D30: =IF('Consolidated P&l'!D17=0,"",('Consolidated P&l'!D23+'Consolidated P&l'!D17)/'Consolidated P&l'!D17) -> 60.544641 | E30: =IF('Consolidated P&l'!E17=0,"",('Consolidated P&l'!E23+'Consolidated P&l'!E17)/'Consolidated P&l'!E17) -> 53.882217 | F30: =IF('Consolidated P&l'!F17=0,"",('Consolidated P&l'!F23+'Consolidated P&l'!F17)/'Consolidated P&l'!F17) -> 29.733685 | H30: =AVERAGE(B30:F30) -> 45.985883 | I30: =MEDIAN(B30:F30) -> 46.395194
A32: TURNOVER RATIOS
A33: Debtor Turnover | B33: ='Consolidated P&l'!B9/'Consolidated Balance sheet'!B44 -> 463.09269 | C33: ='Consolidated P&l'!C9/'Consolidated Balance sheet'!C44 -> 689.18211 | D33: ='Consolidated P&l'!D9/'Consolidated Balance sheet'!D44 -> 305.27637 | E33: ='Consolidated P&l'!E9/'Consolidated Balance sheet'!E44 -> 385.9682 | F33: ='Consolidated P&l'!F9/'Consolidated Balance sheet'!F44 -> 460.8326 | H33: =AVERAGE(B33:F33) -> 460.87039 | I33: =MEDIAN(B33:F33) -> 460.8326
A34: Creditor Turnover | B34: =('Consolidated P&l'!B14+'Consolidated P&l'!B15)/'Consolidated Balance sheet'!B24 -> 44.802088 | C34: =('Consolidated P&l'!C14+'Consolidated P&l'!C15)/'Consolidated Balance sheet'!C24 -> 48.268019 | D34: =('Consolidated P&l'!D14+'Consolidated P&l'!D15)/'Consolidated Balance sheet'!D24 -> 43.942019 | E34: =('Consolidated P&l'!E14+'Consolidated P&l'!E15)/'Consolidated Balance sheet'!E24 -> 47.208842 | F34: =('Consolidated P&l'!F14+'Consolidated P&l'!F15)/'Consolidated Balance sheet'!F24 -> 43.684367 | H34: =AVERAGE(B34:F34) -> 45.581067 | I34: =MEDIAN(B34:F34) -> 44.802088
A35: Inventory Turnover | B35: =('Consolidated P&l'!B14+'Consolidated P&l'!B15)/'Consolidated Balance sheet'!B43 -> 9.6247402 | C35: =('Consolidated P&l'!C14+'Consolidated P&l'!C15)/'Consolidated Balance sheet'!C43 -> 11.217566 | D35: =('Consolidated P&l'!D14+'Consolidated P&l'!D15)/'Consolidated Balance sheet'!D43 -> 11.018876 | E35: =('Consolidated P&l'!E14+'Consolidated P&l'!E15)/'Consolidated Balance sheet'!E43 -> 10.02141 | F35: =('Consolidated P&l'!F14+'Consolidated P&l'!F15)/'Consolidated Balance sheet'!F43 -> 9.9073541 | H35: =AVERAGE(B35:F35) -> 10.357989 | I35: =MEDIAN(B35:F35) -> 10.02141
A36: Fixed Asset Turnover | B36: ='Consolidated P&l'!B9/'Consolidated Balance sheet'!B35 -> 3.0041703 | C36: ='Consolidated P&l'!C9/'Consolidated Balance sheet'!C35 -> 3.5429864 | D36: ='Consolidated P&l'!D9/'Consolidated Balance sheet'!D35 -> 3.5586469 | E36: ='Consolidated P&l'!E9/'Consolidated Balance sheet'!E35 -> 3.4455326 | F36: ='Consolidated P&l'!F9/'Consolidated Balance sheet'!F35 -> 3.2292014 | H36: =AVERAGE(B36:F36) -> 3.3561075 | I36: =MEDIAN(B36:F36) -> 3.4455326
A37: Capital Turnover | B37: ='Consolidated P&l'!B9/'Consolidated Balance sheet'!B11 -> 2.2647379 | C37: ='Consolidated P&l'!C9/'Consolidated Balance sheet'!C11 -> 2.6645179 | D37: ='Consolidated P&l'!D9/'Consolidated Balance sheet'!D11 -> 2.7162969 | E37: ='Consolidated P&l'!E9/'Consolidated Balance sheet'!E11 -> 2.7701485 | F37: ='Consolidated P&l'!F9/'Consolidated Balance sheet'!F11 -> 2.8131388 | H37: =AVERAGE(B37:F37) -> 2.645768 | I37: =MEDIAN(B37:F37) -> 2.7162969
A39: (IN DAYS)
A40: Debtors Days | B40: =365/B33 -> 0.78817914 | C40: =365/C33 -> 0.52961328 | D40: =365/D33 -> 1.1956379 | E40: =365/E33 -> 0.94567375 | F40: =365/F33 -> 0.79204467 | H40: =AVERAGE(B40:F40) -> 0.85022975 | I40: =MEDIAN(B40:F40) -> 0.79204467
A41: Payable Days | B41: =365/B34 -> 8.1469418 | C41: =365/C34 -> 7.5619428 | D41: =365/D34 -> 8.3064003 | E41: =365/E34 -> 7.7316025 | F41: =365/F34 -> 8.3553918 | H41: =AVERAGE(B41:F41) -> 8.0204558 | I41: =MEDIAN(B41:F41) -> 8.1469418
A42: Inventory Days | B42: =365/B35 -> 37.923101 | C42: =365/C35 -> 32.538254 | D42: =365/D35 -> 33.124977 | E42: =365/E35 -> 36.42202 | F42: =365/F35 -> 36.84132 | H42: =AVERAGE(B42:F42) -> 35.369935 | I42: =MEDIAN(B42:F42) -> 36.42202
A43: Cash Conversion Cycle | B43: =B40+B42-B41 -> 30.564339 | C43: =C40+C42-C41 -> 25.505924 | D43: =D40+D42-D41 -> 26.014215 | E43: =E40+E42-E41 -> 29.636092 | F43: =F40+F42-F41 -> 29.277973 | H43: =AVERAGE(B43:F43) -> 28.199708 | I43: =MEDIAN(B43:F43) -> 29.277973
A45: CASH FLOW RATIOS
...

Sheet FCFF
A1: FCFF Analysis - DMart
A2: Particular | B2: Mar-22 | C2: Mar-23 | D2: Mar-24 | E2: Mar-25 | F2: Mar-26
A3: EBIT | B3: ='Consolidated P&l'!B23+'Consolidated P&l'!B17 -> 2117.91 | C3: ='Consolidated P&l'!C23+'Consolidated P&l'!C17 -> 3127.5 | D3: ='Consolidated P&l'!D23+'Consolidated P&l'!D17 -> 3519.46 | E3: ='Consolidated P&l'!E23+'Consolidated P&l'!E17 -> 3742.12 | F3: ='Consolidated P&l'!F23+'Consolidated P&l'!F17 -> 4223.67
A4: Less: Tax on EBIT | B4: =IF('Consolidated P&l'!B23=0,0,B3*('Consolidated P&l'!B29/'Consolidated P&l'!B23)) -> 586.61876 | C4: =IF('Consolidated P&l'!C23=0,0,C3*('Consolidated P&l'!C29/'Consolidated P&l'!C23)) -> 696.76811 | D4: =IF('Consolidated P&l'!D23=0,0,D3*('Consolidated P&l'!D29/'Consolidated P&l'!D23)) -> 941.26666 | E4: =IF('Consolidated P&l'!E23=0,0,E3*('Consolidated P&l'!E29/'Consolidated P&l'!E23)) -> 983.47226 | F4: =IF('Consolidated P&l'!F23=0,0,F3*('Consolidated P&l'!F29/'Consolidated P&l'!F23)) -> 1150.4519
A5: EBIT * (1 - Tax) = NOPAT | B5: =B3-B4 -> 1531.2912 | C5: =C3-C4 -> 2430.7319 | D5: =D3-D4 -> 2578.1933 | E5: =E3-E4 -> 2758.6477 | F5: =F3-F4 -> 3073.2181
A6: Less: Net Capital Expenditure | C6: ='Fixed Asset Scheduled'!C9 -> 1780.28 | D6: ='Fixed Asset Scheduled'!D9 -> 2180.58 | E6: ='Fixed Asset Scheduled'!E9 -> 2955.59 | F6: ='Fixed Asset Scheduled'!F9 -> 4084.46
A7: Less: Net Change in Working Capital | C7: ='Change in working capital'!C7 -> 331.5 | D7: ='Change in working capital'!D7 -> 557.02 | E7: ='Change in working capital'!E7 -> 1018.48 | F7: ='Change in working capital'!F7 -> 584.4
A8: Reinvestment | C8: =C6+C7 -> 2111.78 | D8: =D6+D7 -> 2737.6 | E8: =E6+E7 -> 3974.07 | F8: =F6+F7 -> 4668.86
A9: Free Cash Flow (FCFF) | C9: =C5-C8 -> 318.95189 | D9: =D5-D8 -> -159.40666 | E9: =E5-E8 -> -1215.4223 | F9: =F5-F8 -> -1595.6419
A11: Reinvestment Rate | C11: =IF(C5=0,"",C8/C5) -> 0.8687836 | D11: =IF(D5=0,"",D8/D5) -> 1.0618288 | E11: =IF(E5=0,"",E8/E5) -> 1.4405862 | F11: =IF(F5=0,"",F8/F5) -> 1.5192088
A13: Median Reinvestment Rate / Sales % | C13: =MEDIAN(C11:F11) -> 1.2512075
A14: Average Reinvestment Rate / Sales % | C14: =AVERAGE(C11:F11) -> 1.2226019

Sheet Fixed Asset Scheduled
A1: Fixed Asset Schedule - DMart
A2: Particular | B2: Mar-22 | C2: Mar-23 | D2: Mar-24 | E2: Mar-25 | F2: Mar-26
A3: Opening Balance (Fixed Assets) | B3: ='Consolidated Balance sheet'!B35 -> 10311.09 | C3: =B7 -> 10311.09 | D3: =C7 -> 12091.37 | E3: =D7 -> 14271.95 | F3: =E7 -> 17227.54
A4: Add: Net Purchases | C4: =C7+C6-C3 -> 2419.15 | D4: =D7+D6-D3 -> 2911.34 | E4: =E7+E6-E3 -> 3825.11 | F4: =F7+F6-F3 -> 5121.48
A5: Total Fixed Assets | B5: ='Consolidated Balance sheet'!B35 -> 10311.09 | C5: =C3+C4 -> 12730.24 | D5: =D3+D4 -> 15002.71 | E5: =E3+E4 -> 18097.06 | F5: =F3+F4 -> 22349.02
A6: Less: Depreciation | B6: ='Consolidated P&l'!B18 -> 498.08 | C6: ='Consolidated P&l'!C18 -> 638.87 | D6: ='Consolidated P&l'!D18 -> 730.76 | E6: ='Consolidated P&l'!E18 -> 869.52 | F6: ='Consolidated P&l'!F18 -> 1037.02
A7: Closing Balance (Fixed Assets) | B7: ='Consolidated Balance sheet'!B35 -> 10311.09 | C7: ='Consolidated Balance sheet'!C35 -> 12091.37 | D7: ='Consolidated Balance sheet'!D35 -> 14271.95 | E7: ='Consolidated Balance sheet'!E35 -> 17227.54 | F7: ='Consolidated Balance sheet'!F35 -> 21312
A9: Net Capital Expenditure | C9: =C4-C6 -> 1780.28 | D9: =D4-D6 -> 2180.58 | E9: =E4-E6 -> 2955.59 | F9: =F4-F6 -> 4084.46
A10: Net Capex / Sales % | C10: =C9/'Consolidated P&l'!C9 -> 0.041556916 | D10: =D9/'Consolidated P&l'!D9 -> 0.042934244 | E10: =E9/'Consolidated P&l'!E9 -> 0.049792572 | F10: =F9/'Consolidated P&l'!F9 -> 0.05934926
A12: Median Capex / Sales % | C12: =MEDIAN(C10:F10) -> 0.046363408
A13: Average Capex / Sales % | C13: =AVERAGE(C10:F10) -> 0.048408248

Sheet Change in working capital
A1: Change in Working Capital - DMart
A2: Particular | B2: Mar-22 | C2: Mar-23 | D2: Mar-24 | E2: Mar-25 | F2: Mar-26
A3: Inventories | B3: ='Consolidated Balance sheet'!B43 -> 2742.66 | C3: ='Consolidated Balance sheet'!C43 -> 3243.48 | D3: ='Consolidated Balance sheet'!D43 -> 3927.31 | E3: ='Consolidated Balance sheet'!E43 -> 5044.37 | F3: ='Consolidated Balance sheet'!F43 -> 5900.64
A4: Trade Receivables | B4: ='Consolidated Balance sheet'!B44 -> 66.89 | C4: ='Consolidated Balance sheet'!C44 -> 62.16 | D4: ='Consolidated Balance sheet'!D44 -> 166.37 | E4: ='Consolidated Balance sheet'!E44 -> 153.79 | F4: ='Consolidated Balance sheet'!F44 -> 149.34
A5: Trade Payables | B5: ='Consolidated Balance sheet'!B24 -> 589.2 | C5: ='Consolidated Balance sheet'!C24 -> 753.79 | D5: ='Consolidated Balance sheet'!D24 -> 984.81 | E5: ='Consolidated Balance sheet'!E24 -> 1070.81 | F5: ='Consolidated Balance sheet'!F24 -> 1338.23
A6: Non Cash Working Capital | B6: =B3+B4-B5 -> 2220.35 | C6: =C3+C4-C5 -> 2551.85 | D6: =D3+D4-D5 -> 3108.87 | E6: =E3+E4-E5 -> 4127.35 | F6: =F3+F4-F5 -> 4711.75
A7: Change in Working Capital | C7: =C6-B6 -> 331.5 | D7: =D6-C6 -> 557.02 | E7: =E6-D6 -> 1018.48 | F7: =F6-E6 -> 584.4
A8: Change in WC % of Sales | C8: =C7/'Consolidated P&l'!C9 -> 0.0077381747 | D8: =D7/'Consolidated P&l'!D9 -> 0.010967372 | E8: =E7/'Consolidated P&l'!E9 -> 0.017158246 | F8: =F7/'Consolidated P&l'!F9 -> 0.0084916262
A10: Median Non Cash WC / Sales | C10: =MEDIAN(B6:F6)/MEDIAN('Consolidated P&l'!B9:F9) -> 0.061211688
A11: Average Non Cash WC / Sales | C11: =AVERAGE(B6:F6)/AVERAGE('Consolidated P&l'!B9:F9) -> 0.066144243

Sheet Assumptions
A1: DMART
A2: Particulars (in RS Cr.) | B2: Mar 22 | C2: Mar 23 | D2: Mar 24 | E2: Mar 25 | F2: 46082
A3: Revenue from operations | B3: ='Consolidated P&l'!B9 -> 30976.27 | C3: ='Consolidated P&l'!C9 -> 42839.56 | D3: ='Consolidated P&l'!D9 -> 50788.83 | E3: ='Consolidated P&l'!E9 -> 59358.05 | F3: ='Consolidated P&l'!F9 -> 68820.74
A4: Revenue growth in % | C4: =(C3-B3)/B3 -> 0.38297994 | D4: =(D3-C3)/C3 -> 0.1855591 | E4: =(E3-D3)/D3 -> 0.16872253 | F4: =(F3-E3)/E3 -> 0.15941713
A5: Less: Material cost | B5: ='Consolidated P&l'!B14+'Consolidated P&l'!B15 -> 26397.39 | C5: ='Consolidated P&l'!C14+'Consolidated P&l'!C15 -> 36383.95 | D5: ='Consolidated P&l'!D14+'Consolidated P&l'!D15 -> 43274.54 | E5: ='Consolidated P&l'!E14+'Consolidated P&l'!E15 -> 50551.7 | F5: ='Consolidated P&l'!F14+'Consolidated P&l'!F15 -> 58459.73
A6: Less: Employee costs | B6: ='Consolidated P&l'!B16 -> 616.21 | C6: ='Consolidated P&l'!C16 -> 746.97 | D6: ='Consolidated P&l'!D16 -> 906.12 | E6: ='Consolidated P&l'!E16 -> 1165.9 | F6: ='Consolidated P&l'!F16 -> 1541.48
A7: Less: Other Expenses | B7: ='Consolidated P&l'!B19 -> 1464.17 | C7: ='Consolidated P&l'!C19 -> 2071.61 | D7: ='Consolidated P&l'!D19 -> 2504.4 | E7: ='Consolidated P&l'!E19 -> 3153.12 | F7: ='Consolidated P&l'!F19 -> 3632.94
A8: Total Expenses | B8: =B5+B6+B7 -> 28477.77 | C8: =C5+C6+C7 -> 39202.53 | D8: =D5+D6+D7 -> 46685.06 | E8: =E5+E6+E7 -> 54870.72 | F8: =F5+F6+F7 -> 63634.15
A9: EBITDA | B9: =B3-B8 -> 2498.5 | C9: =C3-C8 -> 3637.03 | D9: =D3-D8 -> 4103.77 | E9: =E3-E8 -> 4487.33 | F9: =F3-F8 -> 5186.59
A10: Less: Depreciation And Amortization | B10: ='Consolidated P&l'!B18 -> 498.08 | C10: ='Consolidated P&l'!C18 -> 638.87 | D10: ='Consolidated P&l'!D18 -> 730.76 | E10: ='Consolidated P&l'!E18 -> 869.52 | F10: ='Consolidated P&l'!F18 -> 1037.02
A11: EBIT | B11: =B9-B10 -> 2000.42 | C11: =C9-C10 -> 2998.16 | D11: =D9-D10 -> 3373.01 | E11: =E9-E10 -> 3617.81 | F11: =F9-F10 -> 4149.57
A12: ADD: Non operating income/ Other Income | B12: ='Consolidated P&l'!B10 -> 117.49 | C12: ='Consolidated P&l'!C10 -> 129.34 | D12: ='Consolidated P&l'!D10 -> 146.45 | E12: ='Consolidated P&l'!E10 -> 124.31 | F12: ='Consolidated P&l'!F10 -> 74.1
A13: Less: Interest Expenses | B13: ='Consolidated P&l'!B17 -> 53.79 | C13: ='Consolidated P&l'!C17 -> 67.41 | D13: ='Consolidated P&l'!D17 -> 58.13 | E13: ='Consolidated P&l'!E17 -> 69.45 | F13: ='Consolidated P&l'!F17 -> 142.05
A14: EBT | B14: =B11+B12-B13 -> 2064.12 | C14: =C11+C12-C13 -> 3060.09 | D14: =D11+D12-D13 -> 3461.33 | E14: =E11+E12-E13 -> 3672.67 | F14: =F11+F12-F13 -> 4081.62
A15: Less: TAX | B15: ='Consolidated P&l'!B29 -> 571.72 | C15: ='Consolidated P&l'!C29 -> 681.75 | D15: ='Consolidated P&l'!D29 -> 925.72 | E15: ='Consolidated P&l'!E29 -> 965.22 | F15: ='Consolidated P&l'!F29 -> 1111.76
A16: Less:Non Controlling Interest/Minority Interest | B16: ='Consolidated P&l'!B34 -> 0.15 | C16: ='Consolidated P&l'!C34 -> 0.17 | D16: ='Consolidated P&l'!D34 -> 0.56 | E16: ='Consolidated P&l'!E34 -> 0.57 | F16: ='Consolidated P&l'!F34 -> 0.63
A17: Net Profit- Pat | B17: =B14-B15-B16 -> 1492.25 | C17: =C14-C15-C16 -> 2378.17 | D17: =D14-D15-D16 -> 2535.05 | E17: =E14-E15-E16 -> 2706.88 | F17: =F14-F15-F16 -> 2969.23
A23: Historical Growth
A24: Average Growth | B24: =AVERAGE(C4:F4) -> 0.22416967
A25: CAGR | B25: =(F3/B3)^(1/4)-1 -> 0.2208788 | C25: =_xlfn.RRI(4,B3,F3) -> 0.2208788 | D25: RRI
A27: Margins
A28: EBITDA | B28: =B9/B3 -> 0.080658517 | C28: =C9/C3 -> 0.084898865 | D28: =D9/D3 -> 0.080800641 | E28: =E9/E3 -> 0.075597665 | F28: =F9/F3 -> 0.075363764
A29: EBIT | B29: =B11/B3 -> 0.064579112 | C29: =C11/C3 -> 0.069985779 | D29: =D11/D3 -> 0.066412438 | E29: =E11/E3 -> 0.060948936 | F29: =F11/F3 -> 0.060295341
A30: EBT | B30: =B14/B3 -> 0.066635525 | C30: =C14/C3 -> 0.071431406 | D30: =D14/D3 -> 0.068151403 | E30: =E14/E3 -> 0.061873158 | F30: =F14/F3 -> 0.059307993
A31: Net Proftt | B31: =B17/B3 -> 0.048173973 | C31: =C17/C3 -> 0.055513409 | D31: =D17/D3 -> 0.049913534 | E31: =E17/E3 -> 0.045602576 | F31: =F17/F3 -> 0.043144407
A33: Tax Rate
A34: Effective tax rate | B34: =B15/B14 -> 0.27698002 | C34: =C15/C14 -> 0.22278757 | D34: =D15/D14 -> 0.26744633 | E34: =E15/E14 -> 0.26281152 | F34: =F15/F14 -> 0.27238204 | G34: =AVERAGE(B34:F34) -> 0.2604815 | H34: Effective tax rate
A35: Marginal Tax rate | B35: 0.26 | C35: =B35 -> 0.26 | D35: =C35 -> 0.26 | E35: =D35 -> 0.26 | F35: =E35 -> 0.26
A37: Return On Capital
A38: EBIT*(1-T) | B38: =B11*(1-B35) -> 1480.3108 | C38: =C11*(1-C35) -> 2218.6384 | D38: =D11*(1-D35) -> 2496.0274 | E38: =E11*(1-E35) -> 2677.1794 | F38: =F11*(1-F35) -> 3070.6818
A39: Book Equity | B39: ='Consolidated Balance sheet'!B11 -> 13677.64 | C39: ='Consolidated Balance sheet'!C11 -> 16077.79 | D39: ='Consolidated Balance sheet'!D11 -> 18697.82 | E39: ='Consolidated Balance sheet'!E11 -> 21427.75 | F39: ='Consolidated Balance sheet'!F11 -> 24464.04
A40: Book Debt | B40: ='Consolidated Balance sheet'!B16+'Consolidated Balance sheet'!B23 -> 0 | C40: ='Consolidated Balance sheet'!C16+'Consolidated Balance sheet'!C23 -> 0 | D40: ='Consolidated Balance sheet'!D16+'Consolidated Balance sheet'!D23 -> 0 | E40: ='Consolidated Balance sheet'!E16+'Consolidated Balance sheet'!E23 -> 0 | F40: ='Consolidated Balance sheet'!F16+'Consolidated Balance sheet'!F23 -> 2424.99
A41: Cash and Cash equivalents | B41: ='Consolidated Balance sheet'!B45 -> 298.58 | C41: ='Consolidated Balance sheet'!C45 -> 1408.33 | D41: ='Consolidated Balance sheet'!D45 -> 638.18 | E41: ='Consolidated Balance sheet'!E45 -> 358.2 | F41: ='Consolidated Balance sheet'!F45 -> 303.78
A42: Capital Employed | B42: =B39+B40-B41 -> 13379.06 | C42: =C39+C40-C41 -> 14669.46 | D42: =D39+D40-D41 -> 18059.64 | E42: =E39+E40-E41 -> 21069.55 | F42: =F39+F40-F41 -> 26585.25
A44: Pre-Tax Return on capital | B44: =B11/B42 -> 0.14951873 | C44: =C11/C42 -> 0.20438107 | D44: =D11/D42 -> 0.18677061 | E44: =E11/E42 -> 0.17170799 | F44: =F11/F42 -> 0.15608542
A45: Post Tax return On capital | B45: =B38/B42 -> 0.11064386 | C45: =C38/C42 -> 0.151242 | D45: =D38/D42 -> 0.13821025 | E45: =E38/E42 -> 0.12706391 | F45: =F38/F42 -> 0.11550321
A47: Growth In EBIT Margin | B47: =((F29/B29)^1/5)-1 -> -0.81326674
A48: Growth In EBIT | B48: =FCFF!C13*Assumptions!F45 -> 0.14451849

Sheet wacc
A1: Capital Structure
A2: Total Debt | B2: ='Consolidated Balance sheet'!F16+'Consolidated Balance sheet'!F23 -> 2424.99
A3: Total Equity | B3: ='Consolidated Balance sheet'!F6/10*4200 -> 273823.2
A4: Total Mix (Debt + Equity) | B4: =B2+B3 -> 276248.19
A5: % of Debt | B5: =B2/B4 -> 0.0087783019
A6: % of Equity | B6: =B3/B4 -> 0.9912217
A7: Debt to Equity | B7: =B2/B3 -> 0.0088560429
A9: Cost of Equity (CAPM)
A10: Risk-free Rate (Rf) | B10: 0.07 | D10: Source: RBI 10-year Government Securities yield (FY2025)
A11: Beta (β) | B11: =Beta!H5 -> 0.76280297
A12: Market Risk Premium (Rm - Rf) | B12: 0.0685 | D12: Source: India Equity Risk Premium (Damodaran estimate)
A13: Cost of Equity [Ke = Rf + β×(Rm-Rf)] | B13: =B10+B11*(B12) -> 0.122252
A15: Cost of Debt
A16: Finance Cost (FY2025) | B16: ='Consolidated P&l'!F17 -> 142.05
A17: Total Debt (FY2025) | B17: =B2 -> 2424.99
A18: Pre-tax Cost of Debt [Kd = FC/Debt] | B18: =B16/B17 -> 0.058577561
A19: Tax Rate | B19: =Assumptions!G34 -> 0.2604815
A20: Post-tax Cost of Debt [Kd*(1-T)] | B20: =B18*(1-B19) -> 0.04331919
A22: WACC
A23: Source | B23: Weight | C23: Cost | D23: Weighted Cost
A24: Debt | B24: =B5 -> 0.0087783019 | C24: =B20 -> 0.04331919 | D24: =C24*B24 -> 0.00038026893
A25: Equity | B25: =B6 -> 0.9912217 | C25: =B13 -> 0.122252 | D25: =C25*B25 -> 0.12117884
A26: WACC | B26: =B24+B25 -> 1 | D26: =D24+D25 -> 0.12155911 | F26: wacc = we*ke+wd*kd

Sheet Forecasting
D3: Sales Forecasting | I3: EBITDA Forecasting | N3: Earning per share Forecasting
D4: Year Weight | E4: Year | F4: Sales | G4: Sales Growth | I4: Year Weight | J4: Year | K4: EBITDA | L4: EBITDA Growth | N4: Year Weight | O4: Year | P4: EPS | Q4: EPS Growth
D5: 1 | E5: 44621 | F5: ='Consolidated P&l'!B9 -> 30976.27 | I5: 1 | J5: 44621 | K5: ='Consolidated P&l'!B23+'Consolidated P&l'!B17+'Consolidated P&l'!B18 -> 2615.99 | N5: 1 | O5: 44621 | P5: ='Consolidated P&l'!B39 -> 23
D6: =D5+1 -> 2 | E6: 44986 | F6: ='Consolidated P&l'!C9 -> 42839.56 | G6: =(F6-F5)/F5 -> 0.38297994 | I6: =I5+1 -> 2 | J6: 44986 | K6: ='Consolidated P&l'!C23+'Consolidated P&l'!C17+'Consolidated P&l'!C18 -> 3766.37 | L6: =(K6-K5)/K5 -> 0.43974939 | N6: =N5+1 -> 2 | O6: 44986 | P6: ='Consolidated P&l'!C39 -> 37 | Q6: =(P6-P5)/P5 -> 0.60869565
D7: =D6+1 -> 3 | E7: 45352 | F7: ='Consolidated P&l'!D9 -> 50788.83 | G7: =(F7-F6)/F6 -> 0.1855591 | I7: =I6+1 -> 3 | J7: 45352 | K7: ='Consolidated P&l'!D23+'Consolidated P&l'!D17+'Consolidated P&l'!D18 -> 4250.22 | L7: =(K7-K6)/K6 -> 0.12846587 | N7: =N6+1 -> 3 | O7: 45352 | P7: ='Consolidated P&l'!D39 -> 39 | Q7: =(P7-P6)/P6 -> 0.054054054
D8: =D7+1 -> 4 | E8: 45717 | F8: ='Consolidated P&l'!E9 -> 59358.05 | G8: =(F8-F7)/F7 -> 0.16872253 | I8: =I7+1 -> 4 | J8: 45717 | K8: ='Consolidated P&l'!E23+'Consolidated P&l'!E17+'Consolidated P&l'!E18 -> 4611.64 | L8: =(K8-K7)/K7 -> 0.085035598 | N8: =N7+1 -> 4 | O8: 45717 | P8: ='Consolidated P&l'!E39 -> 42 | Q8: =(P8-P7)/P7 -> 0.076923077
D9: =D8+1 -> 5 | E9: 46082 | F9: ='Consolidated P&l'!F9 -> 68820.74 | G9: =(F9-F8)/F8 -> 0.15941713 | I9: =I8+1 -> 5 | J9: 46082 | K9: ='Consolidated P&l'!F23+'Consolidated P&l'!F17+'Consolidated P&l'!F18 -> 5260.69 | L9: =(K9-K8)/K8 -> 0.14074169 | N9: =N8+1 -> 5 | O9: 46082 | P9: ='Consolidated P&l'!F39 -> 46 | Q9: =(P9-P8)/P8 -> 0.095238095
D10: =D9+1 -> 6 | E10: 46447 | F10: =FORECAST(D10,$F$5:$F$9,$D$5:$D$9) -> 78218.919 | G10: =(F10-F9)/F9 -> 0.13656027 | I10: =I9+1 -> 6 | J10: 46447 | K10: =FORECAST(I10,$K$5:$K$9,$I$5:$I$9) -> 5941.383 | L10: =(K10-K9)/K9 -> 0.12939234 | N10: =N9+1 -> 6 | O10: 46447 | P10: =FORECAST(N10,$P$5:$P$9,$N$5:$N$9) -> 52.7 | Q10: =(P10-P9)/P9 -> 0.14565217
D11: =D10+1 -> 7 | E11: 46813 | F11: =FORECAST(D11,$F$5:$F$9,$D$5:$D$9) -> 87439.662 | G11: =(F11-F10)/F10 -> 0.11788379 | I11: =I10+1 -> 7 | J11: 46813 | K11: =FORECAST(I11,$K$5:$K$9,$I$5:$I$9) -> 6554.85 | L11: =(K11-K10)/K10 -> 0.10325323 | N11: =N10+1 -> 7 | O11: 46813 | P11: =FORECAST(N11,$P$5:$P$9,$N$5:$N$9) -> 57.8 | Q11: =(P11-P10)/P10 -> 0.096774194
D12: =D11+1 -> 8 | E12: 47178 | F12: =FORECAST(D12,$F$5:$F$9,$D$5:$D$9) -> 96660.405 | G12: =(F12-F11)/F11 -> 0.10545264 | I12: =I11+1 -> 8 | J12: 47178 | K12: =FORECAST(I12,$K$5:$K$9,$I$5:$I$9) -> 7168.317 | L12: =(K12-K11)/K11 -> 0.093589785 | N12: =N11+1 -> 8 | O12: 47178 | P12: =FORECAST(N12,$P$5:$P$9,$N$5:$N$9) -> 62.9 | Q12: =(P12-P11)/P11 -> 0.088235294
D13: =D12+1 -> 9 | E13: 47543 | F13: =FORECAST(D13,$F$5:$F$9,$D$5:$D$9) -> 105881.15 | G13: =(F13-F12)/F12 -> 0.095393176 | I13: =I12+1 -> 9 | J13: 47543 | K13: =FORECAST(I13,$K$5:$K$9,$I$5:$I$9) -> 7781.784 | L13: =(K13-K12)/K12 -> 0.085580339 | N13: =N12+1 -> 9 | O13: 47543 | P13: =FORECAST(N13,$P$5:$P$9,$N$5:$N$9) -> 68 | Q13: =(P13-P12)/P12 -> 0.081081081
D14: =D13+1 -> 10 | E14: 47908 | F14: =FORECAST(D14,$F$5:$F$9,$D$5:$D$9) -> 115101.89 | G14: =(F14-F13)/F13 -> 0.087085786 | I14: =I13+1 -> 10 | J14: 47908 | K14: =FORECAST(I14,$K$5:$K$9,$I$5:$I$9) -> 8395.251 | L14: =(K14-K13)/K13 -> 0.078833722 | N14: =N13+1 -> 10 | O14: 47908 | P14: =FORECAST(N14,$P$5:$P$9,$N$5:$N$9) -> 73.1 | Q14: =(P14-P13)/P13 -> 0.075
D16: Historical Avg Growth | F16: =AVERAGE(G6:G9) -> 0.22416967 | I16: Historical Avg Growth | K16: =AVERAGE(L6:L9) -> 0.19849814 | N16: Historical Avg Growth | P16: =AVERAGE(Q6:Q9) -> 0.20872772
D17: Forecast Avg Growth | F17: =AVERAGE(G10:G14) -> 0.10847513 | I17: Forecast Avg Growth | K17: =AVERAGE(L10:L14) -> 0.098129884 | N17: Forecast Avg Growth | P17: =AVERAGE(Q10:Q14) -> 0.097348549

Sheet Growth Scenario
A1: Scenario 1: Bull Case (High Growth)
A2: INR Cr. | B2: LTM | C2: Y1E | D2: Y2E | E2: Y3E | F2: Y4W | G2: Y5E | H2: Y6E | I2: Y7E | J2: Y8E | K2: Y9E | L2: Y10E
A3: Sales | B3: =Assumptions!F3 -> 68820.74 | C3: =B3*(1+C4) -> 84021.783 | D3: =C3*(1+D4) -> 101206.39 | E3: =D3*(1+E4) -> 120250.64 | F3: =E3*(1+F4) -> 140912.01 | G3: =F3*(1+G4) -> 162819.03 | H3: =G3*(1+H4) -> 185469.25 | I3: =H3*(1+I4) -> 208237.38 | J3: =I3*(1+J4) -> 230395.17 | ... L3: =K3*(1+L4) -> 269652.23 | M3: CAGR | N3: =Assumptions!B25 -> 0.2208788 | P3: Risk free rate
A4: Sales Growth % | C4: =N3 -> 0.2208788 | D4: =C4-$O$4 -> 0.2045256 | E4: =D4-$O$4 -> 0.1881724 | F4: =E4-$O$4 -> 0.1718192 | G4: =F4-$O$4 -> 0.155466 | H4: =G4-$O$4 -> 0.1391128 | I4: =H4-$O$4 -> 0.1227596 | J4: =I4-$O$4 -> 0.1064064 | K4: =J4-$O$4 -> 0.090053201 | L4: =K4-$O$4 -> 0.0737 | M4: 0.0737 | N4: =N3-M4 -> 0.1471788 | O4: =N4/9 -> 0.016353201 | P4: =M4 -> 0.0737
A6: Scenario 2: Base Case (Average Growth)
A7: INR Cr. | B7: LTM | C7: Y1E | D7: Y2E | E7: Y3E | F7: Y4W | G7: Y5E | H7: Y6E | I7: Y7E | J7: Y8E | K7: Y9E | L7: Y10E | M7: Average rate | N7: =Assumptions!B24 -> 0.22416967
A8: Sales | B8: =B3 -> 68820.74 | C8: =B8*(1+C9) -> 84248.263 | D8: =C8*(1+D9) -> 101725.63 | E8: =D8*(1+E9) -> 121127.96 | F8: =E8*(1+F9) -> 142205.82 | G8: =F8*(1+G9) -> 164573.98 | H8: =G8*(1+H9) -> 187709.03 | I8: =H8*(1+I9) -> 210958.03 | J8: =I8*(1+J9) -> 233559.59 | ... L8: =K8*(1+L9) -> 273447.53 | N8: =M4 -> 0.0737 | O8: =N7-N8 -> 0.15046967 | P8: =O8/9 -> 0.016718853
A9: Sales Growth % | C9: =N7 -> 0.22416967 | D9: =C9-$P$8 -> 0.20745082 | E9: =D9-$P$8 -> 0.19073197 | F9: =E9-$P$8 -> 0.17401312 | G9: =F9-$P$8 -> 0.15729426 | H9: =G9-$P$8 -> 0.14057541 | I9: =H9-$P$8 -> 0.12385656 | J9: =I9-$P$8 -> 0.10713771 | K9: =J9-$P$8 -> 0.090418853 | L9: =K9-$P$8 -> 0.0737
A11: Scenario 3: Bear Case (EBIT Growth)
A12: INR Cr. | B12: LTM | C12: Y1E | D12: Y2E | E12: Y3E | F12: Y4W | G12: Y5E | H12: Y6E | I12: Y7E | J12: Y8E | K12: Y9E | L12: Y10E | N12: =Assumptions!B47 -> -0.81326674
A13: Sales | B13: =B8 -> 68820.74 | C13: =B13*(1+C14) -> 12851.121 | D13: =C13*(1+D14) -> 3666.2337 | E13: =D13*(1+E14) -> 1407.2361 | F13: =E13*(1+F14) -> 678.83499 | G13: =F13*(1+G14) -> 394.36287 | H13: =G13*(1+H14) -> 267.96664 | I13: =H13*(1+I14) -> 208.48995 | J13: =I13*(1+J14) -> 182.76151 | ... L13: =K13*(1+L14) -> 191.35433 | N13: =N8 -> 0.0737 | O13: =N12-N13 -> -0.88696674 | P13: =O13/9 -> -0.09855186
A14: Sales Growth % | C14: =N12 -> -0.81326674 | D14: =C14-($P$13) -> -0.71471488 | E14: =D14-($P$13) -> -0.61616302 | F14: =E14-($P$13) -> -0.51761116 | G14: =F14-($P$13) -> -0.4190593 | H14: =G14-($P$13) -> -0.32050744 | I14: =H14-($P$13) -> -0.22195558 | J14: =I14-($P$13) -> -0.12340372 | K14: =J14-($P$13) -> -0.02485186 | L14: =K14-($P$13) -> 0.0737
A16: Live Scenario | B16: 3
A17: INR Cr. | C17: Y1E | D17: Y2E | E17: Y3E | F17: Y4W | G17: Y5E | H17: Y6E | I17: Y7E | J17: Y8E | K17: Y9E | L17: Y10E
A18: Sales | B18: =B13 -> 68820.74 | C18: =B18*(1+C19) -> 12851.121 | D18: =C18*(1+D19) -> 3666.2337 | E18: =D18*(1+E19) -> 1407.2361 | F18: =E18*(1+F19) -> 678.83499 | G18: =F18*(1+G19) -> 394.36287 | H18: =G18*(1+H19) -> 267.96664 | I18: =H18*(1+I19) -> 208.48995 | J18: =I18*(1+J19) -> 182.76151 | ... L18: =K18*(1+L19) -> 191.35433
A19: Sales Growth % | C19: =CHOOSE($B$16,C4,C9,C14) -> -0.81326674 | D19: =CHOOSE($B$16,D4,D9,D14) -> -0.71471488 | E19: =CHOOSE($B$16,E4,E9,E14) -> -0.61616302 | F19: =CHOOSE($B$16,F4,F9,F14) -> -0.51761116 | G19: =CHOOSE($B$16,G4,G9,G14) -> -0.4190593 | H19: =CHOOSE($B$16,H4,H9,H14) -> -0.32050744 | I19: =CHOOSE($B$16,I4,I9,I14) -> -0.22195558 | J19: =CHOOSE($B$16,J4,J9,J14) -> -0.12340372 | ... L19: =CHOOSE($B$16,L4,L9,L14) -> 0.0737
A25: Dividend Per share | B25: 0
A26: EPS | B26: 45.55
A27: ROE | B27: =Assumptions!F17/SUM('Consolidated Balance sheet'!F6,'Consolidated Balance sheet'!F9) -> 0.1213712
A28: DPR | B28: 0
A29: Retained Earnings | B29: 1
A31: Growth Rate | B31: =B29*B27 -> 0.1213712

Sheet DCF valuation
C1: 1 | D1: 2 | E1: 3 | F1: 4 | G1: 5 | H1: 6 | I1: 7 | J1: 8 | K1: 9 | L1: 10
A2: INR Cr. | B2: LTM | C2: Y1E | D2: Y2E | E2: Y3E | F2: Y4E | G2: Y5E | H2: Y6E | I2: Y7E | J2: Y8E | K2: Y9E | L2: Y10E | N2: Terminal Year | P2: Key Inputs | Q2: Value | R2: GROWTH RATE | S2: Roe *Retention Ratio
