Workbook

Sheet About the company
A1: About the Company Exide Industries Limited
A3: Exide Industries Limited is India's leading and largest manufacturer of storage batteries and power solutions, incorporated in 1947 and headquartered at Exide House, 59E Chowringhee Road, Kolkata – 700 020. Listed on BSE (500086) and NSE (EXIDEIND) with CIN: L31402WB1947PLC014919, Exide commands a near ~80-year brand legacy and serves a diverse range of industries through its comprehensive product portfolio spanning 2.5Ah to 20,200Ah. The Company operates 11 manufacturing plants (standalone), 3 lead recycling plants under Chloride Metals Limited (CML), and 2 Li-ion battery plants under Exide Energy Solutions Limited (EESL) in Bengaluru, with a pan-India distribution network of 1,20,000+ channel partners and 18,000+ rural touchpoints serving 70+ countries. Business Model — Exide's business is organised across eight product verticals: Automotive OEM Batteries (2-wheeler, 3-wheeler, passenger vehicle, commercial vehicle and tractor OEMs); Automotive Aftermarket Batteries; Home Batteries & Inverters; Industrial UPS (BFSI, healthcare, manufacturing, critical infrastructure); Solar Batteries and Inverters; Industrial Infrastructure (railways, traction, data centres, power & projects, defence); Telecom Backup Power; and Submarine Batteries. The Company's circularity model is powered by Chloride Metals Limited (CML), which supplied ~50% of Exide's lead requirement in FY26. Through EESL, Exide is advancing its lithium-ion cell manufacturing platform for EV and stationary storage markets. FY26 Key Highlights (Standalone) — Revenue: ₹17,269 Crore | EBITDA Margin: 11.3% | PAT: ₹1,111 Crore | Zero-Debt Balance Sheet | Long-Term Rating: AAA (Stable Outlook) by ICRA | Short-Term Rating: A1+ | Market Capitalisation: ₹33,341 Crore (as on 1st June 2026) | Automotive Battery Capacity: 66 Mn units | Non-Automotive & Stationary Battery Capacity: 7.6 Bn Ah | Countries of Export: 70+ | Recycled Lead & Lead Alloys Used in Products: 79% | Renewable Energy Mix: 24%+ | Scope 1 & 2 Emissions Intensity: 22.46 tCO₂e/MAh (↓15.6% YoY) | Lives impacted through CSR: 4.05 Lakh+. Strategic Direction — Exide's growth strategy rests on four pillars: (1) Strengthening the core lead-acid business across all segments; (2) Deepening channel reach and OEM partnerships; (3) Building a future-ready lithium-ion platform through EESL; and (4) Advancing sustainability through circularity (CML), renewable energy adoption and ESG commitments. The Company's S&P Global Corporate Sustainability Assessment score improved by approximately 50% YoY, placing Exide in the top 14% of the 'Manufacture of Batteries & Accumulators' industry globally. Exide's 79th Annual General Meeting is scheduled for FY 2025-26. Vision & Mission — Exide powers India's progress through trusted energy solutions, combining engineering strength, technological innovation and operational excellence to support evolving mobility and energy ecosystems.
A17: Key Subsidiaries / Group Entities
A18: S.No | B18: Company Name | C18: Type | D18: FY26 Revenue / Status
A19: 1 | B19: Exide Energy Solutions Limited (EESL) | C19: Wholly Owned Subsidiary | D19: Lithium-ion cell manufacturing platform for EV and stationary storage; Bengaluru facility (cylindrical + prismatic lines) in installation & validation stage; cumulative investment ₹4,802 Crore by FY26; initial commercial dispatches targeted in FY2026-27
A20: 2 | B20: Chloride Metals Limited (CML) | C20: Wholly Owned Subsidiary | D20: Lead recycling and backward integration; operates 3 recycling plants; supplied ~50% of Exide's lead requirement in FY26; strengthens supply chain resilience and circularity
A21: 3 | B21: Chloride International Limited | C21: Subsidiary | D21: International business and export operations; Exide exports batteries to 70+ countries through its international marketing network
A22: 4 | B22: Caldyne Automatics Limited | C22: Subsidiary | D22: Engaged in battery-related automation and ancillary manufacturing activities supporting Exide's core operations
A23: 5 | B23: Exide Life Insurance Company Limited | C23: Former Subsidiary (Divested) | D23: Insurance business divested in an earlier period; no longer part of the Group as of FY26
A24: 6 | B24: Associated Battery Manufacturers (Ceylon) Limited | C24: Overseas Associate | D24: Overseas technical collaboration entity; Exide has 5 overseas technical collaborations as of FY26
A25: Key Group Entities (as on 31st March 2026) | C25: 2 Material Subsidiaries (EESL, CML) | 5 Overseas Technical Collaborations
A27: Registered Office
A28: Exide House, 59E Chowringhee Road, Kolkata – 700 020, India
A29: CIN: L31402WB1947PLC014919 | Phone: (033) 2302 3400 / 2283 2118
A30: Website: www.exideindustries.com | Email: cosec@exide.co.in
A32: Operational Footprint
A33: Entity | B33: Metric | C33: Value | D33: Details
A34: Exide Group | B34: Revenue (Standalone, FY26) | C34: ₹17,269 Crore | D34: Standalone revenue for FY 2025-26
A35: Exide Group | B35: EBITDA Margin | C35: 11.3% | D35: Standalone EBITDA margin for FY26
A36: Exide Group | B36: PAT (Standalone) | C36: ₹1,111 Crore | D36: Profit After Tax for FY 2025-26
A37: Exide Group | B37: Balance Sheet | C37: Zero-Debt | D37: Debt-free balance sheet as at March 31, 2026
A38: Exide Group | B38: Market Capitalisation | C38: ~₹33,341 Crore | D38: As on 1st June 2026
A39: Exide Group | B39: Credit Rating (Long-Term) | C39: AAA (Stable) | D39: Rated by ICRA; Short-Term Rating: A1+
A40: Exide Group | B40: Manufacturing Plants | C40: 13^ | D40: 11 Exide plants + 2 EESL plants (excludes 3 CML plants)
A41: Exide Group | B41: Automotive Battery Capacity | C41: 66 Mn units | D41: Standalone manufacturing capacity
A42: Exide Group | B42: Non-Auto & Stationary Capacity | C42: 7.6 Bn Ah | D42: Industrial and infrastructure battery capacity
A43: Exide Group | B43: Channel Partners | C43: 1,20,000+ | D43: Pan-India distribution network
A44: Exide Group | B44: Countries of Export | C44: 70+ | D44: International markets served
... A49: Exide Group | B49: Registrar & Transfer Agent | C49: MUFG Intime India Pvt. Ltd. | D49: Rasoi Court, 5th Floor, 20 Sir R N Mukherjee Road, Kolkata – 700 001
A51: Board of Directors
A52: Name | C52: Designation
A53: Mr. Sridhar Gorthi | C53: Chairman & Independent Director
A54: Mr. Rajan B Raheja | C54: Vice-Chairman & Non-Executive Non-Independent Director
A55: Mr. Avik Roy | C55: Managing Director & Chief Executive Officer
A56: Mr. Surin Kapadia | C56: Independent Director
A57: Ms. Radhika Rajan | C57: Independent Director
A58: Mr. Jaidit Brar | C58: Independent Director
A59: Mr. Manoj Agarwal | C59: Director – Finance & Chief Financial Officer
A60: Mr. Rajeev Khandelwal | C60: Executive Director
A61: Mr. Pravin Saraf | C61: Executive Director & Managing Director & CEO, EESL
...

Sheet Promoter
A1: EXIDE INDUSTRIES LIMITED
A2: Shareholding Pattern – Promoter & Promoter Group | As at March 31, 2026
A4: (A) PROMOTER & PROMOTER GROUP SHAREHOLDING
A5: Category of Shareholder | B5: Entity Type | C5: No. of Shareholders | D5: No. of Fully Paid-up Equity Shares Held | E5: Total No. of Shares Held | F5: % of Total Shares (SCRR, 1957) | G5: Voting Rights Held in Each Class of Securities | I5: Total Shares – Fully Diluted Basis | J5: % – Fully Diluted Basis | K5: No. of Shares in Demat Form
G6: Class X | H6: Total
A7: A3) Indian
A8: A4) Foreign
A9: Individuals (NonResident Individuals/ Foreign Individuals) | C9: 1 | D9: 390954666 | E9: 390954666 | F9: 45.99 | G9: 390954666 | H9: 45.99 | I9: 390954666 | J9: 45.99 | K9: 390954666
A10: Chloride Eastern Limited | B10: Promoter | C10: 1 | D10: 390954666 | E10: 390954666 | F10: 45.99 | G10: 390954666 | H10: 45.99 | I10: 390954666 | J10: 45.99 | K10: 390954666
A11: Sub Total A2 | C11: 1 | D11: 390954666 | E11: 390954666 | F11: 45.99 | G11: 390954666 | H11: 45.99 | I11: 390954666 | J11: 45.99 | K11: 390954666
A12: A=A1+A2 | C12: 1 | D12: 390954666 | E12: 390954666 | F12: 45.99 | G12: 390954666 | H12: 45.99 | I12: 390954666 | J12: 45.99 | K12: 390954666

Sheet Public
A1: EXIDE INDUSTRIES LIMITED
A2: Shareholding Pattern – Public Shareholders | As at March 31, 2026
A4: Category & Name of Shareholder | B4: No. of Shareholders | C4: No. of Fully Paid-up Equity Shares Held | D4: Total No. of Shares Held | E4: % of Total Shares (SCRR, 1957) | F4: No. of Voting Rights | G4: Voting Rights (%) | H4: Total Shares – Fully Diluted Basis | I4: % – Fully Diluted Basis | J4: No. of Shares in Demat Form | K4: Sub-categorization of Shares
K5: Sub-Category I | L5: Sub-Category II | M5: Sub-Category III
A6: Institutions
A7: B2) Institutions (Domestic)
A8: Mutual Funds/ | B8: 37 | C8: 75766162 | D8: 75766162 | E8: 8.91 | F8: 75766162 | G8: 8.91 | H8: 75766162 | I8: 8.91 | J8: 75766162 | K8: - | L8: - | M8: -
A9: Bandhan Large & Mid Cap Fund | B9: 1 | C9: 10488530 | D9: 10488530 | E9: 1.23 | F9: 10488530 | G9: 1.23 | H9: 10488530 | I9: 1.23 | J9: 10488530 | K9: - | L9: - | M9: -
A10: Aditya Birla Sun Life Trustee Private Limited A/C Aditya Birla Sun Life Flexi Cap Fund | B10: 1 | C10: 12202799 | D10: 12202799 | E10: 1.44 | F10: 12202799 | G10: 1.44 | H10: 12202799 | I10: 1.44 | J10: 12202799 | K10: - | L10: - | M10: -
A11: Venture Capital Funds | B11: 0 | C11: 0 | D11: - | E11: 0 | F11: - | G11: 0 | H11: - | I11: 0 | J11: - | K11: - | L11: - | M11: -
A12: Alternate Investment Funds | B12: 8 | C12: 1086983 | D12: 1086983 | E12: 0.13 | F12: 1086983 | G12: 0.13 | H12: 1086983 | I12: 0.13 | J12: 1086983 | K12: - | L12: - | M12: -
A13: Banks | B13: 18 | C13: 194015 | D13: 194015 | E13: 0.02 | F13: 194015 | G13: 0.02 | H13: 194015 | I13: 0.02 | J13: 147045 | K13: - | L13: - | M13: -
A14: Insurance Companies | B14: 17 | C14: 85453221 | D14: 85453221 | E14: 10.05 | F14: 85453221 | G14: 10.05 | H14: 85453221 | I14: 10.05 | J14: 85453221 | K14: - | L14: - | M14: -
A15: Life Insurance Corporation Of India | B15: 1 | C15: 50611447 | D15: 50611447 | E15: 5.95 | F15: 50611447 | G15: 5.95 | H15: 50611447 | I15: 5.95 | J15: 50611447 | K15: - | L15: - | M15: -
A16: Provident Funds/ Pension Funds | B16: 0 | C16: 0 | D16: - | E16: 0 | F16: - | G16: 0 | H16: - | I16: 0 | J16: - | K16: - | L16: - | M16: -
A17: Asset reconstruction companies | B17: 0 | C17: 0 | D17: - | E17: 0 | F17: - | G17: 0 | H17: - | I17: 0 | J17: - | K17: - | L17: - | M17: -
A18: Sovereign Wealth Funds | B18: 0 | C18: 0 | D18: - | E18: 0 | F18: - | G18: 0 | H18: - | I18: 0 | J18: - | K18: - | L18: - | M18: -
A19: NBFCs registered with RBI | B19: 8 | C19: 108435 | D19: 108435 | E19: 0.01 | F19: 108435 | G19: 0.01 | H19: 108435 | I19: 0.01 | J19: 108435 | K19: - | L19: - | M19: -
A20: Other Financial Institutions | B20: 0 | C20: 0 | D20: - | E20: 0 | F20: - | G20: 0 | H20: - | I20: 0 | J20: - | K20: - | L20: - | M20: -
A21: Any Other(Institutions (Domestic)) | B21: 0 | C21: 0 | D21: - | E21: 0 | F21: - | G21: 0 | H21: - | I21: 0 | J21: - | K21: - | L21: - | M21: -
A22: Sub Total B1 | B22: 88 | C22: 162608816 | D22: 162608816 | E22: 19.13 | F22: 162608816 | G22: 19.13 | H22: 162608816 | I22: 19.13 | J22: 162561846 | K22: - | L22: - | M22: -
A23: B18) Institutions (Foreign)
A24: Foreign Direct Investment | B24: 0 | C24: 0 | D24: - | E24: 0 | F24: - | G24: 0 | H24: - | I24: 0 | J24: - | K24: - | L24: - | M24: -
A25: Foreign Venture Capital Investors | B25: 0 | C25: 0 | D25: - | E25: 0 | F25: - | G25: 0 | H25: - | I25: 0 | J25: - | K25: - | L25: - | M25: -
A26: Sovereign Wealth Funds | B26: 0 | C26: 0 | D26: - | E26: 0 | F26: - | G26: 0 | H26: - | I26: 0 | J26: - | K26: - | L26: - | M26: -
A27: Foreign Portfolio Investors Category I | B27: 190 | C27: 85360645 | D27: 85360645 | E27: 10.04 | F27: 85360645 | G27: 10.04 | H27: 85360645 | I27: 10.04 | J27: 85360645 | K27: - | L27: - | M27: -
A28: Government Pension Fund Global | B28: 1 | C28: 20520739 | D28: 20520739 | E28: 2.41 | F28: 20520739 | G28: 2.41 | H28: 20520739 | I28: 2.41 | J28: 20520739 | K28: - | L28: - | M28: -
A29: Foreign Portfolio Investors Category II | B29: 13 | C29: 2168921 | D29: 2168921 | E29: 0.26 | F29: 2168921 | G29: 0.26 | H29: 2168921 | I29: 0.26 | J29: 2168921 | K29: - | L29: - | M29: -
A30: Overseas Depositories (holding DRs) (balancing figure) | B30: 0 | C30: 0 | D30: - | E30: 0 | F30: - | G30: 0 | H30: - | I30: 0 | J30: - | K30: - | L30: - | M30: -
A31: Any Other(Institutions (Foreign)) | B31: 1 | C31: 560 | D31: 560 | E31: 0 | F31: 560 | G31: 0 | H31: 560 | I31: 0 | J31: 560 | K31: - | L31: - | M31: -
A32: Citibank N.A. | B32: 1 | C32: 560 | D32: 560 | E32: 0 | F32: 560 | G32: 0 | H32: 560 | I32: 0 | J32: 560 | K32: - | L32: - | M32: -
A33: Sub Total B2 | B33: 204 | C33: 87530126 | D33: 87530126 | E33: 10.3 | F33: 87530126 | G33: 10.3 | H33: 87530126 | I33: 10.3 | J33: 87530126 | K33: - | L33: - | M33: -
A34: B29) Central Government/ State Government(s)/ President of India
A35: Central Government / President of India | B35: 1 | C35: 90 | D35: 90 | E35: 0 | F35: 90 | G35: 0 | H35: 90 | I35: 0 | J35: 90 | K35: - | L35: - | M35: -
A36: State Government / Governor | B36: 0 | C36: 0 | D36: - | E36: 0 | F36: - | G36: 0 | H36: - | I36: 0 | J36: - | K36: - | L36: - | M36: -
A37: Shareholding by Companies or Bodies Corporate where Central / State Government is a promoter | B37: 0 | C37: 0 | D37: - | E37: 0 | F37: - | G37: 0 | H37: - | I37: 0 | J37: - | K37: - | L37: - | M37: -
A38: Sub Total B3 | B38: 1 | C38: 90 | D38: 90 | E38: 0 | F38: 90 | G38: 0 | H38: 90 | I38: 0 | J38: 90 | K38: - | L38: - | M38: -
A39: B34) Non-Institutions
A40: Associate companies / Subsidiaries | B40: 0 | C40: 0 | D40: - | E40: 0 | F40: - | G40: 0 | H40: - | I40: 0 | J40: - | K40: - | L40: - | M40: -
A41: Directors and their relatives (excluding independent directors and nominee directors) | B41: 1 | C41: 350 | D41: 350 | E41: 0 | F41: 350 | G41: 0 | H41: 350 | I41: 0 | J41: 350 | K41: - | L41: - | M41: -
...

Sheet Consolidated P&L
A1: EXIDE INDUSTRIES LIMITED — Consolidated Profit & Loss Account
A2: (₹ in Crores)
A3: Particulars | B3: Mar 22 12 mths | C3: Mar 23 12 mths | D3: Mar 24 12 mths | E3: Mar 25 12 mths | F3: Mar 26 12 mths
A4: INCOME
A5: Revenue From Operations [Gross] | B5: 12712.75 | C5: 14980.73 | D5: 16672.96 | E5: 17144.52 | F5: 17907.99
A6: Revenue From Operations [Net] | B6: 12712.75 | C6: 14980.73 | D6: 16672.96 | E6: 17144.52 | F6: 17907.99
A7: Other Operating Revenues | B7: 76.47 | C7: 97.43 | D7: 96.77 | E7: 93.33 | F7: 87.36
A8: Total Operating Revenues | B8: 12789.22 | C8: 15078.16 | D8: 16769.73 | E8: 17237.85 | F8: 17995.35
A9: Other Income | B9: 62.07 | C9: 124.74 | D9: 89.95 | E9: 112.8 | F9: 100.86
A10: Total Revenue | B10: 12851.29 | C10: 15202.9 | D10: 16859.68 | E10: 17350.65 | F10: 18096.21
A11: EXPENSES
A12: Cost Of Materials Consumed | B12: 8882.49 | C12: 10585.52 | D12: 11481.61 | E12: 11697.3 | F12: 12173.73
A13: Purchase Of Stock-In Trade | B13: 63.92 | C13: 77.77 | D13: 216.31 | E13: 119.62 | F13: 106.02
A14: Changes In Inventories Of FG, WIP And Stock-In Trade | B14: -269.63 | C14: -310 | D14: -300.33 | E14: -219.5 | F14: -87.55
A15: Employee Benefit Expenses | B15: 906.36 | C15: 1002.62 | D15: 1166.63 | E15: 1296.31 | F15: 1372.17
A16: Finance Costs | B16: 60.93 | C16: 73.84 | D16: 116 | E16: 153.03 | F16: 123.83
A17: Depreciation And Amortisation Expenses | B17: 439.52 | C17: 502.12 | D17: 560.42 | E17: 582.34 | F17: 588.75
A18: Other Expenses | B18: 1806.15 | C18: 2133.72 | D18: 2388.42 | E18: 2546.09 | F18: 2560.54
A19: Total Expenses | B19: 11889.74 | C19: 14065.59 | D19: 15629.06 | E19: 16175.19 | F19: 16837.49
A20: PROFIT / LOSS
A21: Profit/Loss Before Exceptional, ExtraOrdinary Items And Tax | B21: 961.55 | C21: 1137.31 | D21: 1230.62 | E21: 1175.46 | F21: 1258.72
A22: Exceptional Items | B22: 0 | C22: 0 | D22: 0 | E22: 0 | F22: -10.38
A23: Profit/Loss Before Tax | B23: 961.55 | C23: 1137.31 | D23: 1230.62 | E23: 1175.46 | F23: 1248.34
A24: TAX EXPENSES — CONTINUED OPERATIONS
A25: Current Tax | B25: 265.86 | C25: 327.99 | D25: 393.98 | E25: 394.41 | F25: 412.43
A26: Deferred Tax | B26: 0.44 | C26: -13.17 | D26: -45.63 | E26: -18.95 | F26: -23.54
A27: Total Tax Expenses | B27: 266.3 | C27: 314.82 | D27: 348.35 | E27: 375.46 | F27: 388.89
A28: Profit/Loss After Tax And Before ExtraOrdinary Items | B28: 695.25 | C28: 822.49 | D28: 882.27 | E28: 800 | F28: 859.45
A29: Profit/Loss From Continuing Operations | B29: 695.25 | C29: 822.49 | D29: 882.27 | E29: 800 | F29: 859.45
A30: Profit Loss From Discontinuing Operations | B30: 4437.09 | C30: 0 | D30: 0 | E30: 0 | F30: 0
A31: Total Tax Expenses Discontinuing Operations | B31: 774.56 | C31: 0 | D31: 0 | E31: 0 | F31: 0
A32: Net Profit Loss From Discontinuing Operations | B32: 3662.53 | C32: 0 | D32: 0 | E32: 0 | F32: 0
A33: Profit/Loss For The Period | B33: 4357.78 | C33: 822.49 | D33: 882.27 | E33: 800 | F33: 859.45
A34: Minority Interest | B34: 10.09 | C34: -0.07 | D34: -6.14 | E34: -5.48 | F34: -5.73
A35: Share Of Profit/Loss Of Associates | B35: -0.94 | C35: 0.28 | D35: 0.55 | E35: 0.5 | F35: 0.47
A36: Consolidated Profit/Loss After MI And Associates | B36: 4366.93 | C36: 822.7 | D36: 876.68 | E36: 795.02 | F36: 854.19
A37: EARNINGS PER SHARE
A38: Basic EPS (₹) | B38: 51 | C38: 10 | D38: 10 | E38: 9 | F38: 10
A39: Diluted EPS (₹) | B39: 51 | C39: 10 | D39: 10 | E39: 9 | F39: 10
A40: DIVIDEND
...

Sheet Consolidated Balance sheet
A1: EXIDE INDUSTRIES LIMITED — Consolidated Balance Sheet
A2: (₹ in Crores)
A3: Particulars | B3: Mar 22 12 mths | C3: Mar 23 12 mths | D3: Mar 24 12 mths | E3: Mar 25 12 mths | F3: Mar 26 12 mths
A4: EQUITIES AND LIABILITIES
A5: SHAREHOLDER'S FUNDS
A6: Equity Share Capital | B6: 85 | C6: 85 | D6: 85 | E6: 85 | F6: 85
A7: Total Share Capital | B7: 85 | C7: 85 | D7: 85 | E7: 85 | F7: 85
A8: Reserves and Surplus | B8: 10498.74 | C8: 11047.28 | D8: 12801.34 | E8: 13828.48 | F8: 13819.85
A9: Total Reserves and Surplus | B9: 10498.74 | C9: 11047.28 | D9: 12801.34 | E9: 13828.48 | F9: 13819.85
A10: Total Shareholders Funds | B10: 10583.74 | C10: 11132.28 | D10: 12886.34 | E10: 13913.48 | F10: 13904.85
A11: Minority Interest | B11: 40.21 | C11: 9.02 | D11: 15.16 | E11: 20.64 | F11: 26.37
A12: NON-CURRENT LIABILITIES
A13: Long Term Borrowings | B13: 82.36 | C13: 141.29 | D13: 221.54 | E13: 943.07 | F13: 906.45
A14: Deferred Tax Liabilities [Net] | B14: 8.2 | C14: 7.73 | D14: 0.89 | E14: 12.83 | F14: 2.3
A15: Other Long Term Liabilities | B15: 316.66 | C15: 387.77 | D15: 509.33 | E15: 525.05 | F15: 503.4
A16: Long Term Provisions | B16: 61.6 | C16: 65.2 | D16: 69.2 | E16: 100.89 | F16: 95.09
A17: Total Non-Current Liabilities | B17: 468.82 | C17: 601.99 | D17: 800.96 | E17: 1581.84 | F17: 1507.24
A18: CURRENT LIABILITIES
A19: Short Term Borrowings | B19: 126.87 | C19: 138.09 | D19: 475.42 | E19: 618.1 | F19: 186.7
A20: Trade Payables | B20: 1846.33 | C20: 1855.61 | D20: 2707.74 | E20: 3344.96 | F20: 3676.19
A21: Other Current Liabilities | B21: 576 | C21: 742.48 | D21: 941.13 | E21: 1518.31 | F21: 1507
A22: Short Term Provisions | B22: 268.64 | C22: 288.21 | D22: 323.27 | E22: 399 | F22: 411.53
A23: Total Current Liabilities | B23: 2817.84 | C23: 3024.39 | D23: 4447.56 | E23: 5880.37 | F23: 5781.42
A24: Total Capital And Liabilities | B24: 13910.61 | C24: 14767.68 | D24: 18150.02 | E24: 21396.33 | F24: 21219.88
A25: ASSETS
A26: NON-CURRENT ASSETS
A27: Tangible Assets | B27: 3240.18 | C27: 3582.06 | D27: 3760.47 | E27: 3853.63 | F27: 3936.74
A28: Intangible Assets | B28: 74.28 | C28: 56.94 | D28: 46.55 | E28: 35.89 | F28: 23.54
A29: Capital Work-In-Progress | B29: 322.42 | C29: 335.38 | D29: 1164.54 | E29: 3426.05 | F29: 3937.84
A30: Intangible Assets Under Development | B30: 18.52 | C30: 189.67 | D30: 187.44 | E30: 217.36 | F30: 260.53
A31: Fixed Assets | B31: 3655.4 | C31: 4164.05 | D31: 5159 | E31: 7532.93 | F31: 8158.65
A32: Non-Current Investments | B32: 4846.9 | C32: 4502.66 | D32: 5681.11 | E32: 6149.69 | F32: 5299.56
A33: Deferred Tax Assets [Net] | B33: 65.38 | C33: 115.98 | D33: 23.04 | E33: 6.65 | F33: 141.01
A34: Long Term Loans And Advances | B34: 0.09 | C34: 0.07 | D34: 0.25 | E34: 0.19 | F34: 0.11
A35: Other Non-Current Assets | B35: 174.82 | C35: 248.11 | D35: 989.28 | E35: 457 | F35: 496.26
A36: Total Non-Current Assets | B36: 8789.36 | C36: 9076.69 | D36: 11898.5 | E36: 14192.28 | F36: 14141.41
A37: CURRENT ASSETS
A38: Current Investments | B38: 711.54 | C38: 603.25 | D38: 258.9 | E38: 318.27 | F38: 831.21
A39: Inventories | B39: 2855.29 | C39: 3436.4 | D39: 3868.53 | E39: 4564.9 | F39: 4004.05
A40: Trade Receivables | B40: 1097.85 | C40: 1229.55 | D40: 1382.27 | E40: 1686.39 | F40: 1574.81
...

Sheet Cash flow
A1: EXIDE INDUSTRIES LIMITED — Consolidated Cash Flow Statement
A2: (₹ in Crores)
A3: Particulars | B3: Mar 22 12 mths | C3: Mar 23 12 mths | D3: Mar 24 12 mths | E3: Mar 25 12 mths | F3: Mar 26 12 mths
A4: CASH FLOW STATEMENT
A5: Net Profit Before Tax | B5: 960.61 | C5: 1137.59 | D5: 1231.17 | E5: 1175.96 | F5: 1248.81
A6: Net Cash From Operating Activities | B6: 61.25 | C6: 768.24 | D6: 1531.41 | E6: 1272.9 | F6: 2413.16
A7: Net Cash (used in)/from Investing Activities | B7: 66.33 | C7: -798.82 | D7: -1458.27 | E7: -1933.92 | F7: -1551.2
A8: Net Cash (used in)/from Financing Activities | B8: -172.32 | C8: -30.1 | D8: 109.83 | E8: 514.62 | F8: -804.51
A9: Net (decrease)/increase In Cash and Cash Equivalents | B9: -56.85 | C9: -60.68 | D9: 182.97 | E9: -146.4 | F9: 69.99
A10: Opening Cash & Cash Equivalents | B10: 245.96 | C10: 189.11 | D10: 131.78 | E10: 322.99 | F10: 180.82
A11: Closing Cash & Cash Equivalents | B11: 189.11 | C11: 128.43 | D11: 314.75 | E11: 176.59 | F11: 250.81

Sheet Consolidated Quarterly Result
A1: Consolidated Quarterly Results (Rs. Crores)
B2: Quarter ended | E2: Years | G2: % CHANGE
A3: Particulars | B3: 46082 | C3: 45992 | D3: 45901 | E3: 46082 | F3: 45717 | G3: QTQ | H3: YOY
A5: Net Sales | B5: 4735.13 | C5: 4200.59 | D5: 4364.51 | E5: 17995.35 | F5: 17237.85 | G5: 12.7% | H5: 4.4%
A6: Other Income | B6: 4.24 | C6: 15.39 | D6: 53.66 | E6: 100.86 | F6: 112.8
A7: Total Income | B7: 4739.37 | C7: 4215.98 | D7: 4418.17 | E7: 18096.21 | F7: 17350.65 | G7: 12.4% | H7: 4.3%
A8: Expenditure | B8: -4411.63 | C8: -3922.81 | D8: -4164.93 | E8: -16837.49 | F8: -16175.19 | G8: -12.5% | H8: -4.1%
A9: Cost of Materials Consumed | C9: -2951.71 | D9: -2960.63 | E9: -12173.73 | F9: -11697.3
A10: Finance Costs | C10: -25.07 | D10: -39.74 | E10: -123.83 | F10: -153.03
A11: Other Expenses | C11: -605.64 | D11: -656.2 | E11: -2560.54 | F11: -2546.09
A12: Employee Benefit Expenses | C12: -334.09 | D12: -342.25 | E12: -1372.17 | F12: -1296.31
A13: Changes in Inventories of FG, WIP & Stock-in-Trade | C13: 162.46 | D13: -5.27 | E13: 87.55 | F13: 219.5
A14: Purchases of Stock-in-Trade | C14: -19.43 | D14: -8.74 | E14: -106.02 | F14: -119.62
A15: Depreciation and Amortisation Expenses | C15: -149.33 | D15: -152.1 | E15: -588.75 | F15: -582.34
A16: Profit Before Tax (Before Exceptional Items) | B16: 327.74 | C16: 282.79 | D16: 253.24 | E16: 1248.34 | F16: 1175.46 | G16: 15.9% | H16: 6.2%
A17: Tax | B17: -110.72 | C17: -88.15 | D17: -79.69 | E17: -388.89 | F17: -375.46
A18: Net Profit from Ordinary Activities after Tax | B18: 217.02 | C18: 194.64 | D18: 173.55 | E18: 859.45 | F18: 800
A19: Net Profit | B19: 216.73 | C19: 194.97 | D19: 173.64 | E19: 859.92 | F19: 800.5 | G19: 11.2% | H19: 7.4%
A20: Current Tax | C20: -98.42 | D20: -86.36 | E20: -412.43 | F20: -394.41
A21: Deferred Tax | C21: 10.27 | D21: 6.67 | E21: 23.54 | F21: 18.95
A22: Minority Interest | B22: 0 | C22: 0 | D22: 0 | E22: 0 | F22: 0
A23: Share of Profit & Loss of Associates | B23: 0 | C23: 0 | D23: 0 | E23: 0 | F23: 0
A24: Net Profit after Minority Interest & Share of P&L | B24: 216.73 | C24: 194.97 | D24: 173.64 | E24: 859.92 | F24: 800.5 | G24: 11.2% | H24: 7.4%
A25: Any Other | B25: 0 | C25: 0 | D25: 0 | E25: 0 | F25: 0
A26: Income Attributable to Consolidated Group | B26: 216.73 | C26: 194.97 | D26: 173.64 | E26: 859.92 | F26: 800.5
A27: EPS after Extraordinary Items (in Rs.) | B27: - | C27: - | D27: - | E27: - | F27: -
A28: Exceptional Item | B28: 0 | C28: -10.38 | D28: 0 | E28: -10.38 | F28: 0
A29: Profit after Interest but before Exceptional Items | B29: 327.74 | C29: 293.17 | D29: 253.24 | E29: 1258.72 | F29: 1175.46
A30: Net Profit from Continuing Operations | B30: 217.02 | C30: 194.64 | D30: 173.55 | E30: 859.45 | F30: 800
A31: Profit/(Loss) from Discontinuing Operations (before Tax) | B31: 0 | C31: 0 | D31: 0 | E31: 0 | F31: 0
A32: Tax Expense of Discontinuing Operations | B32: 0 | C32: 0 | D32: 0 | E32: 0 | F32: 0
A33: Net Profit/(Loss) from Discontinuing Operations after Tax | B33: 0 | C33: 0 | D33: 0 | E33: 0 | F33: 0
A34: Other Comprehensive Income Net of Taxes | B34: -1182.57 | C34: -46.53 | D34: -430.51 | E34: -692.82 | F34: 402.12
A35: Any Other Comprehensive Item | B35: 0 | C35: 0 | D35: 0 | E35: 0 | F35: 0
A36: Total Comprehensive Income for the Period | B36: -965.84 | C36: 148.44 | D36: -256.87 | E36: 167.1 | F36: 1202.62 | G36: -750.7% | H36: -86.1%
A37: Items that will not be reclassified to P&L | B37: 0 | C37: 0 | D37: 0 | E37: 0 | F37: 0
A38: Tax on items not reclassified to P&L | B38: 0 | C38: 0 | D38: 0 | E38: 0 | F38: 0
A39: Items that will be reclassified to P&L | B39: 0 | C39: 0 | D39: 0 | E39: 0 | F39: 0
A40: Tax on items reclassified to P&L | B40: 0 | C40: 0 | D40: 0 | E40: 0 | F40: 0
A41: Net movement in regulatory deferral account balances | B41: 0 | C41: 0 | D41: 0 | E41: 0 | F41: 0
...

Sheet BEta
A1: Date | B1: Nifty50_Close | C1: Exide_Close | D1: Rm exide | E1: Rm nifty50
A2: 43922 | B2: 8253.7998 | C2: 126.76605 | F2: SLOPE | G2: COVARIANCE
A3: 43924 | B3: 8083.7998 | C3: 123.68711 | D3: =(C3-C2)/C2 -> -0.024288374 | E3: =(B3-B2)/B2 -> -0.020596574 | F3: =SLOPE(D3:D1536,E3:E1536) -> 1.0178953 | G3: =_xlfn.COVARIANCE.S(D3:D1536,E3:E1536)/_xlfn.VAR.S(E3:E1536) -> 1.0178953 | H3: SUMMARY OUTPUT
A4: 43928 | B4: 8792.2002 | C4: 134.22289 | D4: =(C4-C3)/C3 -> 0.085180858 | E4: =(B4-B3)/B3 -> 0.087632105
A5: 43929 | B5: 8748.75 | C5: 134.55965 | D5: =(C5-C4)/C4 -> 0.0025089721 | E5: =(B5-B4)/B4 -> -0.0049419024 | H5: Regression Statistics
A6: 43930 | B6: 9111.9004 | C6: 142.40134 | D6: =(C6-C5)/C5 -> 0.058276684 | E6: =(B6-B5)/B5 -> 0.041508832 | H6: Multiple R | I6: 0.52664951
A7: 43934 | B7: 8993.8496 | C7: 137.44617 | D7: =(C7-C6)/C6 -> -0.034797213 | E7: =(B7-B6)/B6 -> -0.012955671 | H7: R Square | I7: 0.2773597
A8: 43936 | B8: 8925.2998 | C8: 135.13693 | D8: =(C8-C7)/C7 -> -0.016801011 | E8: =(B8-B7)/B7 -> -0.0076218536 | H8: Adjusted R Square | I8: 0.27688801
A9: 43937 | B9: 8992.7998 | C9: 137.20563 | D9: =(C9-C8)/C8 -> 0.01530814 | E9: =(B9-B8)/B8 -> 0.0075627712 | H9: Standard Error | I9: 0.016100449
A10: 43938 | B10: 9266.75 | C10: 140.66943 | D10: =(C10-C9)/C9 -> 0.025245365 | E10: =(B10-B9)/B9 -> 0.030463282 | H10: Observations | I10: 1534
A11: 43941 | B11: 9261.8496 | C11: 144.08514 | D11: =(C11-C10)/C10 -> 0.024281824 | E11: =(B11-B10)/B10 -> -0.00052881438
A12: 43942 | B12: 8981.4502 | C12: 135.81047 | D12: =(C12-C11)/C11 -> -0.057429054 | E12: =(B12-B11)/B11 -> -0.030274667 | H12: ANOVA
A13: 43943 | B13: 9187.2998 | C13: 141.63159 | D13: =(C13-C12)/C12 -> 0.042862094 | E13: =(B13-B12)/B12 -> 0.022919418 | I13: df | J13: SS | K13: MS | L13: F | M13: Significance F
A14: 43944 | B14: 9313.9004 | C14: 143.8446 | D14: =(C14-C13)/C13 -> 0.015625135 | E14: =(B14-B13)/B13 -> 0.013779956 | H14: Regression | I14: 1 | J14: 0.1524249 | K14: 0.1524249 | L14: 588.00356 | M14: 3.3217746e-110
A15: 43945 | B15: 9154.4004 | C15: 142.83432 | D15: =(C15-C14)/C14 -> -0.0070234433 | E15: =(B15-B14)/B14 -> -0.017124942 | H15: Residual | I15: 1532 | J15: 0.39713186 | K15: 0.00025922445
A16: 43948 | B16: 9282.2998 | C16: 142.40134 | D16: =(C16-C15)/C15 -> -0.0030313681 | E16: =(B16-B15)/B15 -> 0.013971359 | H16: Total | I16: 1533 | J16: 0.54955675
A17: 43949 | B17: 9380.9004 | C17: 140.57321 | D17: =(C17-C16)/C16 -> -0.012837836 | E17: =(B17-B16)/B16 -> 0.010622431
A18: 43950 | B18: 9553.3496 | C18: 149.37708 | D18: =(C18-C17)/C17 -> 0.062628316 | E18: =(B18-B17)/B17 -> 0.018383014 | I18: Coefficients | J18: Standard Error | K18: t Stat | L18: P-value | M18: Lower 95% | N18: Upper 95% | O18: Lower 95.0% | P18: Upper 95.0%
A19: 43951 | B19: 9859.9004 | C19: 151.30142 | D19: =(C19-C18)/C18 -> 0.012882478 | E19: =(B19-B18)/B18 -> 0.032088303 | H19: Intercept | I19: 0.0001395607 | J19: 0.00041227809 | K19: 0.33851109 | L19: 0.73502446 | M19: -0.0006691284 | N19: 0.00094824981 | O19: -0.0006691284 | P19: 0.00094824981
A20: 43955 | B20: 9293.5 | C20: 141.6797 | D20: =(C20-C19)/C19 -> -0.063593053 | E20: =(B20-B19)/B19 -> -0.057444839 | H20: X Variable 1 | I20: 1.0178953 | J20: 0.041977168 | K20: 24.248785 | L20: 3.3217746e-110 | M20: 0.93555651 | N20: 1.1002341 | O20: 0.93555651 | P20: 1.1002341
A21: 43956 | B21: 9205.5996 | C21: 141.48727 | D21: =(C21-C20)/C20 -> -0.0013581945 | E21: =(B21-B20)/B20 -> -0.0094582655
A22: 43957 | B22: 9270.9004 | C22: 141.82404 | D22: =(C22-C21)/C21 -> 0.0023801538 | E22: =(B22-B21)/B21 -> 0.0070935935
A23: 43958 | B23: 9199.0498 | C23: 141.48727 | D23: =(C23-C22)/C22 -> -0.0023745021 | E23: =(B23-B22)/B22 -> -0.0077501195
A24: 43959 | B24: 9251.5 | C24: 141.15051 | D24: =(C24-C23)/C23 -> -0.0023801538 | E24: =(B24-B23)/B23 -> 0.0057016971
A25: 43962 | B25: 9239.2002 | C25: 142.68999 | D25: =(C25-C24)/C24 -> 0.010906616 | E25: =(B25-B24)/B24 -> -0.001329493
A26: 43963 | B26: 9196.5498 | C26: 146.58678 | D26: =(C26-C25)/C25 -> 0.027309481 | E26: =(B26-B25)/B25 -> -0.0046162427
A27: 43964 | B27: 9383.5498 | C27: 147.11598 | D27: =(C27-C26)/C26 -> 0.0036101846 | E27: =(B27-B26)/B26 -> 0.020333713
A28: 43965 | B28: 9142.75 | C28: 145.19165 | D28: =(C28-C27)/C27 -> -0.013080371 | E28: =(B28-B27)/B27 -> -0.025661909
A29: 43966 | B29: 9136.8496 | C29: 148.94411 | D29: =(C29-C28)/C28 -> 0.025844852 | E29: =(B29-B28)/B28 -> -0.00064536279
A30: 43969 | B30: 8823.25 | C30: 145.5284 | D30: =(C30-C29)/C29 -> -0.022932834 | E30: =(B30-B29)/B29 -> -0.03432251
A31: 43970 | B31: 8879.0996 | C31: 144.22945 | D31: =(C31-C30)/C30 -> -0.0089257508 | E31: =(B31-B30)/B30 -> 0.0063298228
A32: 43971 | B32: 9066.5498 | C32: 143.74838 | D32: =(C32-C31)/C31 -> -0.0033354066 | E32: =(B32-B31)/B31 -> 0.021111397
... A1536: 46191 | B1536: 24168 | C1536: 384.85001 | D1536: =(C1536-C1535)/C1535 -> -0.0091400305 | E1536: =(B1536-B1535)/B1535 -> 0.0034169978

Sheet WACC
A1: Capital Structure
A2: Total Debt | B2: ='Consolidated Balance sheet'!E13+'Consolidated Balance sheet'!E19 -> 1561.17
A3: Total Equity | B3: ='Consolidated Balance sheet'!E6/2*E3 -> 16235 | D3: CMP (₹) — Current Market Price (Input) | E3: 382
A4: Total Mix (Debt + Equity) | B4: =B2+B3 -> 17796.17
A5: % of Debt | B5: =B2/B4 -> 0.087725055
A6: % of Equity | B6: =B3/B4 -> 0.91227494
A7: Debt to Equity | B7: =B2/B3 -> 0.096160764
A9: Cost of Equity (CAPM)
A10: Risk-free Rate (Rf) | B10: 0.0625 | D10: Source: RBI 10-year Government Securities yield (FY2025)
A11: Beta (β) | B11: =BEta!I20 -> 1.0178953
A12: Market Risk Premium (Rm - Rf) | B12: 0.0605 | D12: Source: India Equity Risk Premium (Damodaran estimate)
A13: Cost of Equity [Ke = Rf + β×(Rm-Rf)] | B13: =B10+B11*B12 -> 0.12408267
A15: Cost of Debt
A16: Finance Cost (FY2025) | B16: ='Consolidated P&L'!E16 -> 153.03
A17: Total Debt (FY2025) | B17: =B2 -> 1561.17
A18: Pre-tax Cost of Debt [Kd = FC/Debt] | B18: =IF(B17=0,0,B16/B17) -> 0.098022637
A19: Tax Rate | B19: =Assumptions!G34 -> 0.29304011
A20: Post-tax Cost of Debt [Kd*(1-T)] | B20: =B18*(1-B19) -> 0.069298073
A22: WACC
A23: Source | B23: Weight | C23: Cost | D23: Weighted Cost
A24: Debt | B24: =B5 -> 0.087725055 | C24: =B20 -> 0.069298073 | D24: =C24*B24 -> 0.0060791773
A25: Equity | B25: =B6 -> 0.91227494 | C25: =B13 -> 0.12408267 | D25: =C25*B25 -> 0.11319751
A26: WACC | B26: =B24+B25 -> 1 | D26: =D24+D25 -> 0.11927668 | F26: wacc = we*ke+wd*kd

Sheet Ratio Analysis
A1: Ratio Analysis- Exide Industries Ltd
A2: Years | B2: 44621 | C2: 44986 | D2: 45352 | E2: 45717 | F2: 46082 | G2: Trends | H2: Mean | I2: Median
A4: Sales Growth | C4: =(Assumptions!C3-Assumptions!B3)/Assumptions!B3 -> 0.17897417 | D4: =(Assumptions!D3-Assumptions!C3)/Assumptions!C3 -> 0.11218677 | E4: =(Assumptions!E3-Assumptions!D3)/Assumptions!D3 -> 0.027914582 | F4: =(Assumptions!F3-Assumptions!E3)/Assumptions!E3 -> 0.043943995 | H4: =AVERAGE(C4:F4) -> 0.090754877 | I4: =MEDIAN(B4:F4) -> 0.07806538
A5: EBITDA Growth | C5: =(Assumptions!C9-Assumptions!B9)/Assumptions!B9 -> 0.13472102 | D5: =(Assumptions!D9-Assumptions!C9)/Assumptions!C9 -> 0.14388145 | E5: =(Assumptions!E9-Assumptions!D9)/Assumptions!D9 -> -0.010489299 | F5: =(Assumptions!F9-Assumptions!E9)/Assumptions!E9 -> 0.040271853 | H5: =AVERAGE(B5:F5) -> 0.077096257 | I5: =MEDIAN(B5:F5) -> 0.087496437
A6: EBIT Growth | C6: =(Assumptions!C11-Assumptions!B11)/Assumptions!B11 -> 0.13119397 | D6: =(Assumptions!D11-Assumptions!C11)/Assumptions!C11 -> 0.156718 | E6: =(Assumptions!E11-Assumptions!D11)/Assumptions!D11 -> -0.032609993 | F6: =(Assumptions!F11-Assumptions!E11)/Assumptions!E11 -> 0.054290156 | H6: =AVERAGE(B6:F6) -> 0.077398033 | I6: =MEDIAN(B6:F6) -> 0.092742063
A7: Net Profit Growth | C7: =(Assumptions!C17-Assumptions!B17)/Assumptions!B17 -> 0.20033277 | D7: =(Assumptions!D17-Assumptions!C17)/Assumptions!C17 -> 0.065307264 | E7: =(Assumptions!E17-Assumptions!D17)/Assumptions!D17 -> -0.093148277 | F7: =(Assumptions!F17-Assumptions!E17)/Assumptions!E17 -> 0.087574888 | H7: =AVERAGE(B7:F7) -> 0.065016661 | I7: =MEDIAN(B7:F7) -> 0.076441076
A8: Dividend Growth
A10: Gross Margin | B10: =(Assumptions!B3-Assumptions!B8)/Assumptions!B3 -> 0.10946172 | C10: =(Assumptions!C3-Assumptions!C8)/Assumptions!C3 -> 0.10535304 | D10: =(Assumptions!D3-Assumptions!D8)/Assumptions!D3 -> 0.10835535 | E10: =(Assumptions!E3-Assumptions!E8)/Assumptions!E3 -> 0.10430709 | F10: =(Assumptions!F3-Assumptions!F8)/Assumptions!F3 -> 0.10394018 | H10: =AVERAGE(B10:F10) -> 0.10628348 | I10: =MEDIAN(B10:F10) -> 0.10535304
A11: EBITDA Margin | B11: =Assumptions!B28 -> 0.10946172 | C11: =Assumptions!C28 -> 0.10535304 | D11: =Assumptions!D28 -> 0.10835535 | E11: =Assumptions!E28 -> 0.10430709 | F11: =Assumptions!F28 -> 0.10394018 | H11: =AVERAGE(B11:F11) -> 0.10628348 | I11: =MEDIAN(B11:F11) -> 0.10535304
A12: EBIT Margin | B12: =Assumptions!B29 -> 0.075095276 | C12: =Assumptions!C29 -> 0.072051895 | D12: =Assumptions!D29 -> 0.074936806 | E12: =Assumptions!E29 -> 0.070524456 | F12: =Assumptions!F29 -> 0.071223399 | H12: =AVERAGE(B12:F12) -> 0.072766366 | I12: =MEDIAN(B12:F12) -> 0.072051895
A13: EBT Margin | B13: =Assumptions!B30 -> 0.075184413 | C13: =Assumptions!C30 -> 0.075427638 | D13: =Assumptions!D30 -> 0.073383412 | E13: =Assumptions!E30 -> 0.068190639 | F13: =Assumptions!F30 -> 0.069946959 | H13: =AVERAGE(B13:F13) -> 0.072426612 | I13: =MEDIAN(B13:F13) -> 0.073383412
A14: Net Profit Margin | B14: =Assumptions!B31 -> 0.053573244 | C14: =Assumptions!C31 -> 0.05454379 | D14: =Assumptions!D31 -> 0.052244729 | E14: =Assumptions!E31 -> 0.046091595 | F14: =Assumptions!F31 -> 0.04801796 | H14: =AVERAGE(B14:F14) -> 0.050894264 | I14: =MEDIAN(B14:F14) -> 0.052244729
A16: Sales Expenses%Sales | B16: =Assumptions!B8/Assumptions!B3 -> 0.89053828 | C16: =Assumptions!C8/Assumptions!C3 -> 0.89464696 | D16: =Assumptions!D8/Assumptions!D3 -> 0.89164465 | E16: =Assumptions!E8/Assumptions!E3 -> 0.89569291 | F16: =Assumptions!F8/Assumptions!F3 -> 0.89605982 | H16: =AVERAGE(B16:F16) -> 0.89371652 | I16: =MEDIAN(B16:F16) -> 0.89464696
A17: Depriciation%Sales | B17: =Assumptions!B10/Assumptions!B3 -> 0.034366443 | C17: =Assumptions!C10/Assumptions!C3 -> 0.033301145 | D17: =Assumptions!D10/Assumptions!D3 -> 0.033418546 | E17: =Assumptions!E10/Assumptions!E3 -> 0.033782635 | F17: =Assumptions!F10/Assumptions!F3 -> 0.032716785 | H17: =AVERAGE(B17:F17) -> 0.033517111 | I17: =MEDIAN(B17:F17) -> 0.033418546
A18: Operating Income%Sales | B18: =Assumptions!B9/Assumptions!B3 -> 0.10946172 | C18: =Assumptions!C9/Assumptions!C3 -> 0.10535304 | D18: =Assumptions!D9/Assumptions!D3 -> 0.10835535 | E18: =Assumptions!E9/Assumptions!E3 -> 0.10430709 | F18: =Assumptions!F9/Assumptions!F3 -> 0.10394018 | H18: =AVERAGE(B18:F18) -> 0.10628348 | I18: =MEDIAN(B18:F18) -> 0.10535304
A20: Return on Capital Employed | B20: =Assumptions!B44 -> 0.090656203 | C20: =Assumptions!C44 -> 0.096386857 | D20: =Assumptions!D44 -> 0.094823052 | E20: =Assumptions!E44 -> 0.079526357 | F20: =Assumptions!F44 -> 0.086952068 | H20: =AVERAGE(B20:F20) -> 0.089668907 | I20: =MEDIAN(B20:F20) -> 0.090656203
A21: Retained Earning % | B21: =Assumptions!B17/Assumptions!B3 -> 0.053573244 | C21: =Assumptions!C17/Assumptions!C3 -> 0.05454379 | D21: =Assumptions!D17/Assumptions!D3 -> 0.052244729 | E21: =Assumptions!E17/Assumptions!E3 -> 0.046091595 | F21: =Assumptions!F17/Assumptions!F3 -> 0.04801796 | H21: =AVERAGE(B21:F21) -> 0.050894264 | I21: =MEDIAN(B21:F21) -> 0.052244729
A22: Return on Equity % | B22: =Assumptions!B17/Assumptions!B39 -> 0.06473704 | C22: =Assumptions!C17/Assumptions!C39 -> 0.073877049 | D22: =Assumptions!D17/Assumptions!D39 -> 0.067989049 | E22: =Assumptions!E17/Assumptions!E39 -> 0.057104333 | F22: =Assumptions!F17/Assumptions!F39 -> 0.062143784 | H22: =AVERAGE(B22:F22) -> 0.065170251 | I22: =MEDIAN(B22:F22) -> 0.06473704
A23: Self Sustained Growth Rate | B23: =B22*B21 -> 0.0034681732 | C23: =C22*C21 -> 0.0040295343 | D23: =D22*D21 -> 0.0035520694 | E23: =E22*E21 -> 0.0026320298 | F23: =F22*F21 -> 0.0029840178 | H23: =AVERAGE(B23:F23) -> 0.0033331649 | I23: =MEDIAN(B23:F23) -> 0.0034681732
A24: Interest Coverage Ratio | B24: =IF(Assumptions!B13=0,"",Assumptions!B11/Assumptions!B13) -> 15.762514 | C24: =IF(Assumptions!C13=0,"",Assumptions!C11/Assumptions!C13) -> 14.713028 | D24: =IF(Assumptions!D13=0,"",Assumptions!D11/Assumptions!D13) -> 10.833362 | E24: =IF(Assumptions!E13=0,"",Assumptions!E11/Assumptions!E13) -> 7.9441286 | F24: =IF(Assumptions!F13=0,"",Assumptions!F11/Assumptions!F13) -> 10.3504 | H24: =AVERAGE(B24:F24) -> 11.920687 | I24: =MEDIAN(B24:F24) -> 10.833362
A26: Debtor Turnover Ratio | B26: =Assumptions!B3/'Consolidated Balance sheet'!B40 -> 11.649333 | C26: =Assumptions!C3/'Consolidated Balance sheet'!C40 -> 12.263153 | D26: =Assumptions!D3/'Consolidated Balance sheet'!D40 -> 12.132022 | E26: =Assumptions!E3/'Consolidated Balance sheet'!E40 -> 10.221746 | F26: =Assumptions!F3/'Consolidated Balance sheet'!F40 -> 11.426998 | H26: =AVERAGE(B26:F26) -> 11.53865 | I26: =MEDIAN(B26:F26) -> 11.649333
A27: Creditor Turnover Ratio | B27: =Assumptions!B8/'Consolidated Balance sheet'!B20 -> 6.1686102 | C27: =Assumptions!C8/'Consolidated Balance sheet'!C20 -> 7.2696472 | D27: =Assumptions!D8/'Consolidated Balance sheet'!D20 -> 5.5221846 | E27: =Assumptions!E8/'Consolidated Balance sheet'!E20 -> 4.6158459 | F27: =Assumptions!F8/'Consolidated Balance sheet'!F20 -> 4.3863103 | H27: =AVERAGE(B27:F27) -> 5.5925196 | I27: =MEDIAN(B27:F27) -> 5.5221846
A28: Inventory Turnover | B28: =Assumptions!B8/'Consolidated Balance sheet'!B39 -> 3.9888383 | C28: =Assumptions!C8/'Consolidated Balance sheet'!C39 -> 3.9255122 | D28: =Assumptions!D8/'Consolidated Balance sheet'!D39 -> 3.8651994 | E28: =Assumptions!E8/'Consolidated Balance sheet'!E39 -> 3.382291 | F28: =Assumptions!F8/'Consolidated Balance sheet'!F39 -> 4.02715 | H28: =AVERAGE(B28:F28) -> 3.8377982 | I28: =MEDIAN(B28:F28) -> 3.9255122
A29: Fixed Asset Turnover | B29: =Assumptions!B3/'Consolidated Balance sheet'!B31 -> 3.4987197 | C29: =Assumptions!C3/'Consolidated Balance sheet'!C31 -> 3.6210324 | D29: =Assumptions!D3/'Consolidated Balance sheet'!D31 -> 3.2505776 | E29: =Assumptions!E3/'Consolidated Balance sheet'!E31 -> 2.2883327 | F29: =Assumptions!F3/'Consolidated Balance sheet'!F31 -> 2.2056774 | H29: =AVERAGE(B29:F29) -> 2.972868 | I29: =MEDIAN(B29:F29) -> 3.2505776
A30: Capital Turnover Ratio | B30: =Assumptions!B3/Assumptions!B42 -> 1.2072158 | C30: =Assumptions!C3/Assumptions!C42 -> 1.3377422 | D30: =Assumptions!D3/Assumptions!D42 -> 1.2653736 | E30: =Assumptions!E3/Assumptions!E42 -> 1.1276423 | F30: =Assumptions!F3/Assumptions!F42 -> 1.2208357 | H30: =AVERAGE(B30:F30) -> 1.2317619 | I30: =MEDIAN(B30:F30) -> 1.2208357
A32: (In days)
A33: Debtors Day | B33: =365/B26 -> 31.332267 | C33: =365/C26 -> 29.76396 | D33: =365/D26 -> 30.085669 | E33: =365/E26 -> 35.708186 | F33: =365/F26 -> 31.941899 | H33: =AVERAGE(B33:F33) -> 31.766396 | I33: =MEDIAN(B33:F33) -> 31.332267
A34: Payable Days | B34: =365/B27 -> 59.170541 | C34: =365/C27 -> 50.208764 | D34: =365/D27 -> 66.09703 | E34: =365/E27 -> 79.07543 | F34: =365/F27 -> 83.213447 | H34: =AVERAGE(B34:F34) -> 67.553042 | I34: =MEDIAN(B34:F34) -> 66.09703
A35: Inventory Days | B35: =365/B28 -> 91.50534 | C35: =365/C28 -> 92.981498 | D35: =365/D28 -> 94.432385 | E35: =365/E28 -> 107.91502 | F35: =365/F28 -> 90.634816 | H35: =AVERAGE(B35:F35) -> 95.493812 | I35: =MEDIAN(B35:F35) -> 92.981498
A36: Cash Conversion Cycle | B36: =B33+B35-B34 -> 63.667065 | C36: =C33+C35-C34 -> 72.536694 | D36: =D33+D35-D34 -> 58.421023 | E36: =E33+E35-E34 -> 64.547777 | F36: =F33+F35-F34 -> 39.363267 | H36: =AVERAGE(B36:F36) -> 59.707165 | I36: =MEDIAN(B36:F36) -> 63.667065
A38: CFO/Sales | B38: =(Assumptions!B17+Assumptions!B10)/Assumptions!B3 -> 0.087939687 | C38: =(Assumptions!C17+Assumptions!C10)/Assumptions!C3 -> 0.087844936 | D38: =(Assumptions!D17+Assumptions!D10)/Assumptions!D3 -> 0.085663275 | E38: =(Assumptions!E17+Assumptions!E10)/Assumptions!E3 -> 0.07987423 | F38: =(Assumptions!F17+Assumptions!F10)/Assumptions!F3 -> 0.080734745 | H38: =AVERAGE(B38:F38) -> 0.084411375 | I38: =MEDIAN(B38:F38) -> 0.085663275
A39: CFO/Total Assets | B39: =(Assumptions!B17+Assumptions!B10)/'Consolidated Balance sheet'!B45 -> 0.080850516 | C39: =(Assumptions!C17+Assumptions!C10)/'Consolidated Balance sheet'!C45 -> 0.089691813 | D39: =(Assumptions!D17+Assumptions!D10)/'Consolidated Balance sheet'!D45 -> 0.079148673 | E39: =(Assumptions!E17+Assumptions!E10)/'Consolidated Balance sheet'!E45 -> 0.064350288 | F39: =(Assumptions!F17+Assumptions!F10)/'Consolidated Balance sheet'!F45 -> 0.068466457 | H39: =AVERAGE(B39:F39) -> 0.07650155 | I39: =MEDIAN(B39:F39) -> 0.079148673
A40: CFO/Total Debt | B40: =IF(Assumptions!B40=0,"",(Assumptions!B17+Assumptions!B10)/Assumptions!B40) -> 5.3753286 | C40: =IF(Assumptions!C40=0,"",(Assumptions!C17+Assumptions!C10)/Assumptions!C40) -> 4.7409979 | D40: =IF(Assumptions!D40=0,"",(Assumptions!D17+Assumptions!D10)/Assumptions!D40) -> 2.0611656 | E40: =IF(Assumptions!E40=0,"",(Assumptions!E17+Assumptions!E10)/Assumptions!E40) -> 0.88194111 | F40: =IF(Assumptions!F40=0,"",(Assumptions!F17+Assumptions!F10)/Assumptions!F40) -> 1.3290491 | H40: =AVERAGE(B40:F40) -> 2.8776965 | I40: =MEDIAN(B40:F40) -> 2.0611656

Sheet FCFF
A1: Particular | B1: 44621 | C1: 44986 | D1: 45352 | E1: 45717 | F1: 46082
A2: EBIT | B2: =Assumptions!B11 -> 960.41 | C2: =Assumptions!C11 -> 1086.41 | D2: =Assumptions!D11 -> 1256.67 | E2: =Assumptions!E11 -> 1215.69 | F2: =Assumptions!F11 -> 1281.69
A3: Less: Tax on EBIT | B3: =B2*$J$5 -> 281.43865 | C3: =C2*$J$5 -> 318.3617 | D3: =D2*$J$5 -> 368.25471 | E3: =E2*$J$5 -> 356.24593 | F3: =F2*$J$5 -> 375.58658
A4: EBIT * (1- Tax) NOPAT | B4: =B2-B3 -> 678.97135 | C4: =C2-C3 -> 768.0483 | D4: =D2-D3 -> 888.41529 | E4: =E2-E3 -> 859.44407 | F4: =F2-F3 -> 906.10342
A5: Less: Net Capital expenditure | C5: ='Fixed Asset Scheduled'!C8 -> 508.65 | D5: ='Fixed Asset Scheduled'!D8 -> 994.95 | E5: ='Fixed Asset Scheduled'!E8 -> 2373.93 | F5: ='Fixed Asset Scheduled'!F8 -> 625.72 | I5: Avg of effective tax rate | J5: =AVERAGE(Assumptions!B34:F34) -> 0.29304011
A6: Less: Net Change in working Capital | C6: ='Change in working Capital'!C6 -> 703.53 | D6: ='Change in working Capital'!D6 -> -267.28 | E6: ='Change in working Capital'!E6 -> 363.27 | F6: ='Change in working Capital'!F6 -> -1003.66
A7: Reinvestment | C7: =C5+C6 -> 1212.18 | D7: =D5+D6 -> 727.67 | E7: =E5+E6 -> 2737.2 | F7: =F5+F6 -> -377.94
A8: Free Cash Flow | C8: =C4-C7 -> -444.1317 | D8: =D4-D7 -> 160.74529 | E8: =E4-E7 -> -1877.7559 | F8: =F4-F7 -> 1284.0434
I9: Marginal tax rate | J9: =Assumptions!B35 -> 0.28
A10: Reinvestment Rate | C10: =C7/C4 -> 1.5782601 | D10: =D7/D4 -> 0.81906515 | E10: =E7/E4 -> 3.1848495 | F10: =F7/F4 -> -0.4171047
A12: Median Reinvestment rate /Sales percentage | B12: =MEDIAN(C10:F10) -> 1.1986626
A13: Average Reinvestment rate /Sales percentage | B13: =AVERAGE(C10:F10) -> 1.2912675

Sheet Change in working Capital
A1: Particular | B1: 44621 | C1: 44986 | D1: 45352 | E1: 45717 | F1: 46082
A2: Inventory | B2: ='Consolidated Balance sheet'!B39 -> 2855.29 | C2: ='Consolidated Balance sheet'!C39 -> 3436.4 | D2: ='Consolidated Balance sheet'!D39 -> 3868.53 | E2: ='Consolidated Balance sheet'!E39 -> 4564.9 | F2: ='Consolidated Balance sheet'!F39 -> 4004.05
A3: Trade Receivables | B3: ='Consolidated Balance sheet'!B40 -> 1097.85 | C3: ='Consolidated Balance sheet'!C40 -> 1229.55 | D3: ='Consolidated Balance sheet'!D40 -> 1382.27 | E3: ='Consolidated Balance sheet'!E40 -> 1686.39 | F3: ='Consolidated Balance sheet'!F40 -> 1574.81
A4: Trade Payable | B4: ='Consolidated Balance sheet'!B20 -> 1846.33 | C4: ='Consolidated Balance sheet'!C20 -> 1855.61 | D4: ='Consolidated Balance sheet'!D20 -> 2707.74 | E4: ='Consolidated Balance sheet'!E20 -> 3344.96 | F4: ='Consolidated Balance sheet'!F20 -> 3676.19
A5: Non Cash working Capital | B5: =B2+B3-B4 -> 2106.81 | C5: =C2+C3-C4 -> 2810.34 | D5: =D2+D3-D4 -> 2543.06 | E5: =E2+E3-E4 -> 2906.33 | F5: =F2+F3-F4 -> 1902.67
A6: Change in Working Capital | C6: =C5-B5 -> 703.53 | D6: =D5-C5 -> -267.28 | E6: =E5-D5 -> 363.27 | F6: =F5-E5 -> -1003.66
A7: change in working Capital /percentage of sales | C7: =C6/'Consolidated P&L'!B8 -> 0.05500961 | D7: =D6/'Consolidated P&L'!C8 -> -0.017726301 | E7: =E6/'Consolidated P&L'!D8 -> 0.021662245 | F7: =F6/'Consolidated P&L'!E8 -> -0.058224198
A9: Median Non Cash working Capital /Sales percentage | C9: =MEDIAN(C7:F7) -> 0.0019679721
A10: Average Non Cash working Capital /Sales percentage | C10: =AVERAGE(C7:F7) -> 0.00018033884

Sheet Fixed Asset Scheduled
A1: Particular | B1: 44621 | C1: 44986 | D1: 45352 | E1: 45717 | F1: 46082
A2: Beginning balance | C2: =B6 -> 3655.4 | D2: =C6 -> 4164.05 | E2: =D6 -> 5159 | F2: =E6 -> 7532.93
A3: Add: Net Purchases | C3: =C6-C2+C5 -> 1010.77 | D3: =D6-D2+D5 -> 1555.37 | E3: =E6-E2+E5 -> 2956.27 | F3: =F6-F2+F5 -> 1214.47
A4: Total Fixed Assets | B4: =B5+B6 -> 4094.92 | C4: =C5+C6 -> 4666.17 | D4: =D5+D6 -> 5719.42 | E4: =E5+E6 -> 8115.27 | F4: =F5+F6 -> 8747.4
A5: Less: Depreciation | B5: ='Consolidated P&L'!B17 -> 439.52 | C5: ='Consolidated P&L'!C17 -> 502.12 | D5: ='Consolidated P&L'!D17 -> 560.42 | E5: ='Consolidated P&L'!E17 -> 582.34 | F5: ='Consolidated P&L'!F17 -> 588.75
A6: Closing Balance(Fixed Asests ) | B6: ='Consolidated Balance sheet'!B31 -> 3655.4 | C6: ='Consolidated Balance sheet'!C31 -> 4164.05 | D6: ='Consolidated Balance sheet'!D31 -> 5159 | E6: ='Consolidated Balance sheet'!E31 -> 7532.93 | F6: ='Consolidated Balance sheet'!F31 -> 8158.65
A8: Net Capital expenditure | C8: =C3-C5 -> 508.65 | D8: =D3-D5 -> 994.95 | E8: =E3-E5 -> 2373.93 | F8: =F3-F5 -> 625.72
A9: Net Capital expenditure / Sales percentage | C9: =C8/'Consolidated P&L'!B8 -> 0.039771777 | D9: =D8/'Consolidated P&L'!C8 -> 0.065986168 | E9: =E8/'Consolidated P&L'!D8 -> 0.14156042 | F9: =F8/'Consolidated P&L'!E8 -> 0.03629919
A11: Median Capital expenditure /Sales percentage | C11: =MEDIAN(C9:F9) -> 0.052878972
A12: Average Capital expenditure /Sales percentage | C12: =AVERAGE(C9:F9) -> 0.070904388

Sheet Assumptions
A1: Exide Industries Ltd
A2: Particulars (in RS Cr.) | B2: Mar 22 | C2: Mar 23 | D2: Mar 24 | E2: 45717 | F2: 46082
A3: Revenue from operations | B3: ='Consolidated P&L'!B8 -> 12789.22 | C3: ='Consolidated P&L'!C8 -> 15078.16 | D3: ='Consolidated P&L'!D8 -> 16769.73 | E3: ='Consolidated P&L'!E8 -> 17237.85 | F3: ='Consolidated P&L'!F8 -> 17995.35
A4: Revenue growth in % | C4: =(C3-B3)/B3 -> 0.17897417 | D4: =(D3-C3)/C3 -> 0.11218677 | E4: =(E3-D3)/D3 -> 0.027914582 | F4: =(F3-E3)/E3 -> 0.043943995
A5: Less: Material cost | B5: ='Consolidated P&L'!B12+'Consolidated P&L'!B13+'Consolidated P&L'!B14 -> 8676.78 | C5: ='Consolidated P&L'!C12+'Consolidated P&L'!C13+'Consolidated P&L'!C14 -> 10353.29 | D5: ='Consolidated P&L'!D12+'Consolidated P&L'!D13+'Consolidated P&L'!D14 -> 11397.59 | E5: ='Consolidated P&L'!E12+'Consolidated P&L'!E13+'Consolidated P&L'!E14 -> 11597.42 | F5: ='Consolidated P&L'!F12+'Consolidated P&L'!F13+'Consolidated P&L'!F14 -> 12192.2
A6: Less: Employee costs | B6: ='Consolidated P&L'!B15 -> 906.36 | C6: ='Consolidated P&L'!C15 -> 1002.62 | D6: ='Consolidated P&L'!D15 -> 1166.63 | E6: ='Consolidated P&L'!E15 -> 1296.31 | F6: ='Consolidated P&L'!F15 -> 1372.17
A7: Less: Other Expenses | B7: ='Consolidated P&L'!B18 -> 1806.15 | C7: ='Consolidated P&L'!C18 -> 2133.72 | D7: ='Consolidated P&L'!D18 -> 2388.42 | E7: ='Consolidated P&L'!E18 -> 2546.09 | F7: ='Consolidated P&L'!F18 -> 2560.54
A8: Total Expenses | B8: =B5+B6+B7 -> 11389.29 | C8: =C5+C6+C7 -> 13489.63 | D8: =D5+D6+D7 -> 14952.64 | E8: =E5+E6+E7 -> 15439.82 | F8: =F5+F6+F7 -> 16124.91
A9: EBITDA | B9: =B3-B8 -> 1399.93 | C9: =C3-C8 -> 1588.53 | D9: =D3-D8 -> 1817.09 | E9: =E3-E8 -> 1798.03 | F9: =F3-F8 -> 1870.44
A10: Less: Depreciation And Amortization | B10: ='Consolidated P&L'!B17 -> 439.52 | C10: ='Consolidated P&L'!C17 -> 502.12 | D10: ='Consolidated P&L'!D17 -> 560.42 | E10: ='Consolidated P&L'!E17 -> 582.34 | F10: ='Consolidated P&L'!F17 -> 588.75
A11: EBIT | B11: =B9-B10 -> 960.41 | C11: =C9-C10 -> 1086.41 | D11: =D9-D10 -> 1256.67 | E11: =E9-E10 -> 1215.69 | F11: =F9-F10 -> 1281.69
A12: ADD: Non operating income/ Other Income | B12: ='Consolidated P&L'!B9 -> 62.07 | C12: ='Consolidated P&L'!C9 -> 124.74 | D12: ='Consolidated P&L'!D9 -> 89.95 | E12: ='Consolidated P&L'!E9 -> 112.8 | F12: ='Consolidated P&L'!F9 -> 100.86
A13: Less: Interest Expenses | B13: ='Consolidated P&L'!B16 -> 60.93 | C13: ='Consolidated P&L'!C16 -> 73.84 | D13: ='Consolidated P&L'!D16 -> 116 | E13: ='Consolidated P&L'!E16 -> 153.03 | F13: ='Consolidated P&L'!F16 -> 123.83
A14: EBT | B14: =B11+B12-B13 -> 961.55 | C14: =C11+C12-C13 -> 1137.31 | D14: =D11+D12-D13 -> 1230.62 | E14: =E11+E12-E13 -> 1175.46 | F14: =F11+F12-F13 -> 1258.72
A15: Less: TAX | B15: ='Consolidated P&L'!B27 -> 266.3 | C15: ='Consolidated P&L'!C27 -> 314.82 | D15: ='Consolidated P&L'!D27 -> 348.35 | E15: ='Consolidated P&L'!E27 -> 375.46 | F15: ='Consolidated P&L'!F27 -> 388.89
A16: Less:Non Controlling Interest/Minority Interest | B16: =ABS('Consolidated P&L'!B34) -> 10.09 | C16: =ABS('Consolidated P&L'!C34) -> 0.07 | D16: =ABS('Consolidated P&L'!D34) -> 6.14 | E16: =ABS('Consolidated P&L'!E34) -> 5.48 | F16: =ABS('Consolidated P&L'!F34) -> 5.73
A17: Net Profit- Pat | B17: =B14-B15-B16 -> 685.16 | C17: =C14-C15-C16 -> 822.42 | D17: =D14-D15-D16 -> 876.13 | E17: =E14-E15-E16 -> 794.52 | F17: =F14-F15-F16 -> 864.1
A23: Historical Growth
A24: Average Growth | B24: =AVERAGE(C4:F4) -> 0.090754877
A25: CAGR | B25: =(F3/B3)^(1/5)-1 -> 0.070688771 | C25: =_xlfn.RRI(5,B3,F3) -> 0.070688771 | D25: RRI
A27: Margins
A28: EBITDA | B28: =B9/B3 -> 0.10946172 | C28: =C9/C3 -> 0.10535304 | D28: =D9/D3 -> 0.10835535 | E28: =E9/E3 -> 0.10430709 | F28: =F9/F3 -> 0.10394018
A29: EBIT | B29: =B11/B3 -> 0.075095276 | C29: =C11/C3 -> 0.072051895 | D29: =D11/D3 -> 0.074936806 | E29: =E11/E3 -> 0.070524456 | F29: =F11/F3 -> 0.071223399
A30: EBT | B30: =B14/B3 -> 0.075184413 | C30: =C14/C3 -> 0.075427638 | D30: =D14/D3 -> 0.073383412 | E30: =E14/E3 -> 0.068190639 | F30: =F14/F3 -> 0.069946959
A31: Net Proftt | B31: =B17/B3 -> 0.053573244 | C31: =C17/C3 -> 0.05454379 | D31: =D17/D3 -> 0.052244729 | E31: =E17/E3 -> 0.046091595 | F31: =F17/F3 -> 0.04801796
A33: Tax Rate
A34: Effective tax rate | B34: =B15/B14 -> 0.27694868 | C34: =C15/C14 -> 0.27681107 | D34: =D15/D14 -> 0.2830687 | E34: =E15/E14 -> 0.31941538 | F34: =F15/F14 -> 0.30895672 | G34: =AVERAGE(B34:F34) -> 0.29304011 | H34: Effective tax rate
A35: Marginal Tax rate | B35: 0.28 | C35: =B35 -> 0.28 | D35: =C35 -> 0.28 | E35: =D35 -> 0.28 | F35: =E35 -> 0.28
A37: Return On Capital
A38: EBIT*(1-T) | B38: =B11*(1-B35) -> 691.4952 | C38: =C11*(1-C35) -> 782.2152 | D38: =D11*(1-D35) -> 904.8024 | E38: =E11*(1-E35) -> 875.2968 | F38: =F11*(1-F35) -> 922.8168
A39: Book Equity | B39: ='Consolidated Balance sheet'!B10 -> 10583.74 | C39: ='Consolidated Balance sheet'!C10 -> 11132.28 | D39: ='Consolidated Balance sheet'!D10 -> 12886.34 | E39: ='Consolidated Balance sheet'!E10 -> 13913.48 | F39: ='Consolidated Balance sheet'!F10 -> 13904.85
A40: Book Debt | B40: ='Consolidated Balance sheet'!B13+'Consolidated Balance sheet'!B19 -> 209.23 | C40: ='Consolidated Balance sheet'!C13+'Consolidated Balance sheet'!C19 -> 279.38 | D40: ='Consolidated Balance sheet'!D13+'Consolidated Balance sheet'!D19 -> 696.96 | E40: ='Consolidated Balance sheet'!E13+'Consolidated Balance sheet'!E19 -> 1561.17 | F40: ='Consolidated Balance sheet'!F13+'Consolidated Balance sheet'!F19 -> 1093.15
A41: Cash and Cash equivalents | B41: ='Consolidated Balance sheet'!B41 -> 198.99 | C41: ='Consolidated Balance sheet'!C41 -> 140.31 | D41: ='Consolidated Balance sheet'!D41 -> 330.51 | E41: ='Consolidated Balance sheet'!E41 -> 188.02 | F41: ='Consolidated Balance sheet'!F41 -> 257.81
A42: Capital Employed | B42: =B39+B40-B41 -> 10593.98 | C42: =C39+C40-C41 -> 11271.35 | D42: =D39+D40-D41 -> 13252.79 | E42: =E39+E40-E41 -> 15286.63 | F42: =F39+F40-F41 -> 14740.19
A44: Pre-Tax Return on capital | B44: =B11/B42 -> 0.090656203 | C44: =C11/C42 -> 0.096386857 | D44: =D11/D42 -> 0.094823052 | E44: =E11/E42 -> 0.079526357 | F44: =F11/F42 -> 0.086952068
A45: Post Tax return On capital | B45: =B38/B42 -> 0.065272466 | C45: =C38/C42 -> 0.069398537 | D45: =D38/D42 -> 0.068272598 | E45: =E38/E42 -> 0.057258977 | F45: =F38/F42 -> 0.062605489
A47: Growth In EBIT | B47: =FCFF!B12*F45 -> 0.07504286

Sheet Forecasting
E3: Sales Forecasting | J3: EBITDA Forecasting | O3: Earning per share Forecasting
E4: Year Weight | F4: Year | G4: Sales | H4: Sales Growth | J4: Year Weight | K4: Year | L4: EBITDA | M4: EBITDA Growth | O4: Year Weight | P4: Year | Q4: EPS | R4: EPS Growth
E5: 1 | F5: 44621 | G5: ='Consolidated P&L'!B8 -> 12789.22 | J5: 1 | K5: 44621 | L5: ='Consolidated P&L'!B21+'Consolidated P&L'!B16+'Consolidated P&L'!B17 -> 1462 | O5: 1 | P5: 44621 | Q5: ='Consolidated P&L'!B38 -> 51
E6: 2 | F6: 44986 | G6: ='Consolidated P&L'!C8 -> 15078.16 | H6: =(G6-G5)/G5 -> 0.17897417 | J6: 2 | K6: 44986 | L6: ='Consolidated P&L'!C21+'Consolidated P&L'!C16+'Consolidated P&L'!C17 -> 1713.27 | M6: =(L6-L5)/L5 -> 0.17186731 | O6: 2 | P6: 44986 | Q6: ='Consolidated P&L'!C38 -> 10 | R6: =(Q6-Q5)/Q5 -> -0.80392157
E7: 3 | F7: 45352 | G7: ='Consolidated P&L'!D8 -> 16769.73 | H7: =(G7-G6)/G6 -> 0.11218677 | J7: 3 | K7: 45352 | L7: ='Consolidated P&L'!D21+'Consolidated P&L'!D16+'Consolidated P&L'!D17 -> 1907.04 | M7: =(L7-L6)/L6 -> 0.11309951 | O7: 3 | P7: 45352 | Q7: ='Consolidated P&L'!D38 -> 10 | R7: =(Q7-Q6)/Q6 -> 0
E8: 4 | F8: 45717 | G8: ='Consolidated P&L'!E8 -> 17237.85 | H8: =(G8-G7)/G7 -> 0.027914582 | J8: 4 | K8: 45717 | L8: ='Consolidated P&L'!E21+'Consolidated P&L'!E16+'Consolidated P&L'!E17 -> 1910.83 | M8: =(L8-L7)/L7 -> 0.0019873731 | O8: 4 | P8: 45717 | Q8: ='Consolidated P&L'!E38 -> 9 | R8: =(Q8-Q7)/Q7 -> -0.1
E9: 5 | F9: 46082 | G9: ='Consolidated P&L'!F8 -> 17995.35 | H9: =(G9-G8)/G8 -> 0.043943995 | J9: 5 | K9: 46082 | L9: ='Consolidated P&L'!F21+'Consolidated P&L'!F16+'Consolidated P&L'!F17 -> 1971.3 | M9: =(L9-L8)/L8 -> 0.031645934 | O9: 5 | P9: 46082 | Q9: ='Consolidated P&L'!F38 -> 10 | R9: =(Q9-Q8)/Q8 -> 0.11111111
E10: 6 | F10: 46447 | G10: =FORECAST(E10,$G$5:$G$9,$E$5:$E$9) -> 19745.647 | H10: =(G10-G9)/G9 -> 0.097263849 | J10: 6 | K10: 46447 | L10: =FORECAST(J10,$L$5:$L$9,$J$5:$J$9) -> 2157.736 | M10: =(L10-L9)/L9 -> 0.094575153 | O10: 6 | P10: 46447 | Q10: =FORECAST(O10,$Q$5:$Q$9,$O$5:$O$9) -> -6.9 | R10: =(Q10-Q9)/Q9 -> -1.69
E11: 7 | F11: 46813 | G11: =FORECAST(E11,$G$5:$G$9,$E$5:$E$9) -> 21002.842 | H11: =(G11-G10)/G10 -> 0.063669476 | J11: 7 | K11: 46813 | L11: =FORECAST(J11,$L$5:$L$9,$J$5:$J$9) -> 2279.352 | M11: =(L11-L10)/L10 -> 0.05636278 | O11: 7 | P11: 46813 | Q11: =FORECAST(O11,$Q$5:$Q$9,$O$5:$O$9) -> -15.2 | R11: =(Q11-Q10)/Q10 -> 1.2028986
E12: 8 | F12: 47178 | G12: =FORECAST(E12,$G$5:$G$9,$E$5:$E$9) -> 22260.037 | H12: =(G12-G11)/G11 -> 0.059858328 | J12: 8 | K12: 47178 | L12: =FORECAST(J12,$L$5:$L$9,$J$5:$J$9) -> 2400.968 | M12: =(L12-L11)/L11 -> 0.053355515 | O12: 8 | P12: 47178 | Q12: =FORECAST(O12,$Q$5:$Q$9,$O$5:$O$9) -> -23.5 | R12: =(Q12-Q11)/Q11 -> 0.54605263
E13: 9 | F13: 47543 | G13: =FORECAST(E13,$G$5:$G$9,$E$5:$E$9) -> 23517.232 | H13: =(G13-G12)/G12 -> 0.056477669 | J13: 9 | K13: 47543 | L13: =FORECAST(J13,$L$5:$L$9,$J$5:$J$9) -> 2522.584 | M13: =(L13-L12)/L12 -> 0.050652903 | O13: 9 | P13: 47543 | Q13: =FORECAST(O13,$Q$5:$Q$9,$O$5:$O$9) -> -31.8 | R13: =(Q13-Q12)/Q12 -> 0.35319149
E14: 10 | F14: 47908 | G14: =FORECAST(E14,$G$5:$G$9,$E$5:$E$9) -> 24774.427 | H14: =(G14-G13)/G13 -> 0.05345846 | J14: 10 | K14: 47908 | L14: =FORECAST(J14,$L$5:$L$9,$J$5:$J$9) -> 2644.2 | M14: =(L14-L13)/L13 -> 0.048210882 | O14: 10 | P14: 47908 | Q14: =FORECAST(O14,$Q$5:$Q$9,$O$5:$O$9) -> -40.1 | R14: =(Q14-Q13)/Q13 -> 0.26100629
E16: Historical Avg Growth | G16: =AVERAGE(H6:H9) -> 0.090754877 | J16: Historical Avg Growth | L16: =AVERAGE(M6:M9) -> 0.079650031 | O16: Historical Avg Growth | Q16: =AVERAGE(R6:R9) -> -0.19820261
E17: Forecast Avg Growth | G17: =AVERAGE(H10:H14) -> 0.066145556 | J17: Forecast Avg Growth | L17: =AVERAGE(M10:M14) -> 0.060631447 | O17: Forecast Avg Growth | Q17: =AVERAGE(R10:R14) -> 0.13462979

Sheet Growth Scenario
A1: Scenario 1: High Growth
A2: INR Cr. | B2: LTM | C2: Y1E | D2: Y2E | E2: Y3E | F2: Y4W | G2: Y5E | H2: Y6E | I2: Y7E | J2: Y8E | K2: Y9E | L2: Y10E
A3: Sales | B3: =Assumptions!F3 -> 17995.35 | C3: =B3*(1+C4) -> 19267.419 | D3: =C3*(1+D4) -> 20611.879 | E3: =D3*(1+E4) -> 22031.399 | F3: =E3*(1+F4) -> 23528.635 | G3: =F3*(1+G4) -> 25106.214 | H3: =G3*(1+H4) -> 26766.725 | I3: =H3*(1+I4) -> 28512.708 | J3: =I3*(1+J4) -> 30346.637 | ... L3: =K3*(1+L4) -> 34287.845 | M3: CAGR | N3: =Assumptions!B25 -> 0.070688771 | P3: Risk free rate
A4: Sales Growth % | C4: =N3 -> 0.070688771 | D4: =C4-$O$4 -> 0.069778907 | E4: =D4-$O$4 -> 0.068869044 | F4: =E4-$O$4 -> 0.067959181 | G4: =F4-$O$4 -> 0.067049317 | H4: =G4-$O$4 -> 0.066139454 | I4: =H4-$O$4 -> 0.06522959 | J4: =I4-$O$4 -> 0.064319727 | K4: =J4-$O$4 -> 0.063409863 | L4: =K4-$O$4 -> 0.0625 | M4: =P4 -> 0.0625 | N4: =N3-M4 -> 0.0081887709 | O4: =N4/9 -> 0.00090986344 | P4: =WACC!B10 -> 0.0625
A6: Scenario 2: Average Growth
A7: INR Cr. | B7: LTM | C7: Y1E | D7: Y2E | E7: Y3E | F7: Y4W | G7: Y5E | H7: Y6E | I7: Y7E | J7: Y8E | K7: Y9E | L7: Y10E | M7: Average rate | N7: =Assumptions!B24 -> 0.090754877
A8: Sales | B8: =B3 -> 17995.35 | C8: =B8*(1+C9) -> 19628.516 | D8: =C8*(1+D9) -> 21348.277 | E8: =D8*(1+E9) -> 23151.694 | F8: =E8*(1+F9) -> 25034.774 | G8: =F8*(1+G9) -> 26992.422 | H8: =G8*(1+H9) -> 29018.412 | I8: =H8*(1+I9) -> 31105.367 | J8: =I8*(1+J9) -> 33244.758 | ... L8: =K8*(1+L9) -> 37641.108 | N8: =M4 -> 0.0625 | O8: =N7-N8 -> 0.028254877 | P8: =O8/9 -> 0.0031394308
A9: Sales Growth % | C9: =N7 -> 0.090754877 | D9: =C9-$P$8 -> 0.087615447 | E9: =D9-$P$8 -> 0.084476016 | F9: =E9-$P$8 -> 0.081336585 | G9: =F9-$P$8 -> 0.078197154 | H9: =G9-$P$8 -> 0.075057723 | I9: =H9-$P$8 -> 0.071918292 | J9: =I9-$P$8 -> 0.068778862 | K9: =J9-$P$8 -> 0.065639431 | L9: =K9-$P$8 -> 0.0625
A11: Scenario 3: EBIT Growth
