Workbook

Sheet About the Company
E13: About the Company
E15: Message from the chairman -“Our strategic pivot to an AI-first approach has been instrumental in reimagining our operations and client relationships. By embedding AI in every aspect of our services, we have harnessed its power to enhance decisionmaking, optimize processes, and elevate customer experiences.” Who we are - As one of the world’s leading technology consulting and digital solutions enterprise, LTIMindtree enables businesses across diverse sectors to harness the power of digital technology to deal with complex business challenges, innovate at scale, and drive tangible business outcomes Services offering - Consulting, Enterprise Automation, Digital Engineering, Platform Operations, Low Code Integration, Enterprise Cloud Applications, Oracle, Data and Analytics, Cloud and Digital Infrastructure, Cybersecurity, Salesforce, Interactive, SAP, Quality Engineering Services, Enterprise AI, iNXT Industires Served - 1. Core / Strong Presence BFSI (Banking, Financial Services, Insurance) Technology sector 2. Expansion / Growth Industries Manufacturing, Resources (Energy & Utilities),Healthcare,Life Sciences,Media & Communications Consumer Business which include: Retail, Consumer Goods,Travel, Transport, Hospitality
E31: Subsidiaries
E32: S.No | F32: Company Name,Type,Country/Region
E33: 1 | F33: Larsen & Toubro Limited,Parent Company,India
E34: 2 | F34: L&T Infotech LLC,Subsidiary,USA
E35: 3 | F35: L&T Infotech GmbH,Subsidiary,Germany
E36: 4 | F36: L&T Infotech S.A.,Subsidiary,France
E37: 5 | F37: L&T Infotech (Canada) Limited,Subsidiary,Canada
E38: 6 | F38: L&T Infotech (UK) Limited,Subsidiary,UK
E39: 7 | F39: L&T Infotech (Singapore) Pte. Ltd.,Subsidiary,Singapore
E40: 8 | F40: L&T Infotech (Australia) Pty Ltd,Subsidiary,Australia
E41: 9 | F41: L&T Infotech (South Africa) (Pty) Ltd,Subsidiary,South Africa
E42: 10 | F42: Mindtree LLC,Subsidiary,USA
E43: 11 | F43: Mindtree Software Solutions (UK) Ltd,Subsidiary,UK
E44: 12 | F44: Mindtree Consulting Pte Ltd,Subsidiary,Singapore
... E46: 14 | F46: Mindtree GmbH,Subsidiary,Germany
E48: Registered Office
E49: L&T House, Ballard Estate, Mumbai – 400001, Maharashtra
E50: Technology Tower I, Powai, Mumbai – 400072
E51: Global Village, Mysore Road, Bengaluru – 560059
E54: Units
E55: Company | F55: Units Type | G55: Number | H55: Details
E56: LTIMindtree | F56: Offices | G56: 117 | H56: Across 41 countries
E57: LTIMindtree | F57: Countries | G57: 41 | H57: Global presence

Sheet Promoter
A1: Category & Name of Shareholder | B1: Entity Type | C1: No. of Shareholders | D1: No. of Fully Paid-Up Equity Shares held | E1: Partly paid up equity shares held | F1: No. of shares underlying Depository Receipts | G1: Total No. Shares held | H1: Shareholding Calculated as per SCRR , 1957 As a % of (A+B+C2) | I1: Number of Voting Rights held in each class of securities | M1: No. of Shares Underlying Outstanding convertible securities | N1: No. Of Shares Underlying Outstanding Warrants | O1: No. Of Outstanding ESOP Granted | P1: Total No. Of shares on fully diluted basis (including warrants, ESOP, Convertible Securities etc.) | Q1: Total Shareholding, as a% assuming full conversion of convertible securities ( as a percentage of diluted share capital) As a % of (A+B+C) | R1: No. of equity shares held in dematerialized form
I2: No. of Voting Rights | L2: Total as a % of Total Voting Rights
I3: Class X | J3: Class Y | K3: Total
A4: Promoter and Promoter Group | C4: 0 | H4: 0 | L4: 0 | Q4: 0
A5: A1) Indian | C5: 0 | H5: 0 | L5: 0 | Q5: 0
A6: Bodies Corporate | C6: 1 | D6: 203169279 | G6: 203169279 | H6: 68.53 | I6: 203169279 | K6: 203169279 | L6: 68.53 | P6: 203169279 | Q6: 68.46 | R6: 203169279
A7: Larsen And Toubro Limited | B7: 0 | C7: 0 | D7: 203169279 | G7: 203169279 | H7: 68.53 | I7: 203169279 | K7: 203169279 | L7: 0 | P7: 203169279 | Q7: 68.46 | R7: 203169279
A8: Sub-Total(A)(1) | C8: 1 | D8: 203169279 | G8: 203169279 | H8: 68.53 | I8: 203169279 | K8: 203169279 | L8: 68.53 | P8: 203169279 | Q8: 68.46 | R8: 203169279
A9: A2) Foreign | C9: 0 | H9: 0 | L9: 0 | Q9: 0
A10: Sub-Total(A)(2) | C10: 0 | H10: 0 | L10: 0 | Q10: 0
A11: Promoter and Promoter Group (A=A1+A2) | C11: 1 | D11: 203169279 | G11: 203169279 | H11: 68.53 | I11: 203169279 | K11: 203169279 | L11: 68.53 | P11: 203169279 | Q11: 68.46 | R11: 203169279
A12: Public | C12: 0 | H12: 0 | L12: 0 | Q12: 0
A13: B1) Institutions (Domestic) | C13: 0 | H13: 0 | L13: 0 | Q13: 0
A14: Mutual Funds | C14: 36 | D14: 13675751 | G14: 13675751 | H14: 4.61 | I14: 13675751 | K14: 13675751 | L14: 4.61 | P14: 13675751 | Q14: 4.61 | R14: 13675751
A15: Alternate Investment Funds | C15: 23 | D15: 447487 | G15: 447487 | H15: 0.15 | I15: 447487 | K15: 447487 | L15: 0.15 | P15: 447487 | Q15: 0.15 | R15: 447487
A16: Banks | C16: 5 | D16: 904 | G16: 904 | H16: 0 | I16: 904 | K16: 904 | L16: 0 | P16: 904 | Q16: 0 | R16: 904
A17: Insurance Companies | C17: 31 | D17: 32877824 | G17: 32877824 | H17: 11.09 | I17: 32877824 | K17: 32877824 | L17: 11.09 | P17: 32877824 | Q17: 11.08 | R17: 32877824
A18: LICI INDEX PLUS FLEXI GROWTH FUND | B18: 0 | C18: 0 | D18: 28388052 | G18: 28388052 | H18: 9.58 | I18: 28388052 | K18: 28388052 | L18: 0 | P18: 28388052 | Q18: 9.57 | R18: 28388052
A19: Provident Funds/ Pension Funds | C19: 1 | D19: 2819735 | G19: 2819735 | H19: 0.95 | I19: 2819735 | K19: 2819735 | L19: 0.95 | P19: 2819735 | Q19: 0.95 | R19: 2819735
A20: NBFCs registered with RBI | C20: 6 | D20: 8763 | G20: 8763 | H20: 0 | I20: 8763 | K20: 8763 | L20: 0 | P20: 8763 | Q20: 0 | R20: 8763
A21: Bodies Corporate | C21: 2 | D21: 294725 | G21: 294725 | H21: 0.1 | I21: 294725 | K21: 294725 | L21: 0.1 | P21: 294725 | Q21: 0.1 | R21: 294725
A22: Trust | C22: 9 | D22: 89214 | G22: 89214 | H22: 0.03 | I22: 89214 | K22: 89214 | L22: 0.03 | P22: 89214 | Q22: 0.03 | R22: 89214
A23: Sub-Total(B)(1) | C23: 113 | D23: 50214403 | G23: 50214403 | H23: 16.93 | I23: 50214403 | K23: 50214403 | L23: 16.93 | P23: 50214403 | Q23: 16.92 | R23: 50214403
A24: B2) Institutions (Foreign) | C24: 0 | H24: 0 | L24: 0 | Q24: 0
A25: Foreign Portfolio Investors Category I | C25: 455 | D25: 18667693 | G25: 18667693 | H25: 6.3 | I25: 18667693 | K25: 18667693 | L25: 6.3 | P25: 18667693 | Q25: 6.29 | R25: 18667693
A26: Foreign Portfolio Investors Category II | C26: 27 | D26: 620614 | G26: 620614 | H26: 0.21 | I26: 620614 | K26: 620614 | L26: 0.21 | P26: 620614 | Q26: 0.21 | R26: 620614
A27: Sub-Total(B)(2) | C27: 482 | D27: 19288307 | G27: 19288307 | H27: 6.51 | I27: 19288307 | K27: 19288307 | L27: 6.51 | P27: 19288307 | Q27: 6.5 | R27: 19288307
A28: B3) Central Government/ State Government(s)/ President of India | C28: 0 | H28: 0 | L28: 0 | Q28: 0
A29: Sub-Total(B)(3) | C29: 0 | H29: 0 | K29: - | L29: 0 | O29: - | P29: - | Q29: 0
A30: B4) Non-Institutions | C30: 0 | H30: 0 | L30: 0 | Q30: 0
A31: Investor Education and Protection Fund (IEPF) | C31: 1 | D31: 93849 | G31: 93849 | H31: 0.03 | I31: 93849 | K31: 93849 | L31: 0.03 | P31: 93849 | Q31: 0.03 | R31: 93849
A32: Resident Individuals holding nominal share capital up to Rs. 2 lakhs | C32: 360593 | D32: 15515724 | G32: 15515724 | H32: 5.23 | I32: 15515724 | K32: 15515724 | L32: 5.23 | P32: 15515724 | Q32: 5.23 | R32: 15510847
A33: Resident Individuals holding nominal share capital in excess of Rs. 2 lakhs | C33: 3 | D33: 1668088 | G33: 1668088 | H33: 0.56 | I33: 1668088 | K33: 1668088 | L33: 0.56 | P33: 1668088 | Q33: 0.56 | R33: 1668088
A34: Non Resident Indians (NRIs) | C34: 10595 | D34: 5434602 | G34: 5434602 | H34: 1.83 | I34: 5434602 | K34: 5434602 | L34: 1.83 | P34: 5434602 | Q34: 1.83 | R34: 5434152
A35: Foreign Nationals | C35: 17 | D35: 167612 | G35: 167612 | H35: 0.06 | I35: 167612 | K35: 167612 | L35: 0.06 | P35: 167612 | Q35: 0.06 | R35: 167612
A36: Bodies Corporate | C36: 1087 | D36: 410209 | G36: 410209 | H36: 0.14 | I36: 410209 | K36: 410209 | L36: 0.14 | N36: 291467 | O36: 291467 | P36: 701676 | Q36: 0.24 | R36: 410209
A37: Clearing Members | C37: 53 | D37: 27408 | G37: 27408 | H37: 0.01 | I37: 27408 | K37: 27408 | L37: 0.01 | P37: 27408 | Q37: 0.01 | R37: 27408
A38: Foreign Nationals | C38: 5 | D38: 20525 | G38: 20525 | H38: 0.01 | I38: 20525 | K38: 20525 | L38: 0.01 | P38: 20525 | Q38: 0.01
A39: HUF | C39: 7028 | D39: 323451 | G39: 323451 | H39: 0.11 | I39: 323451 | K39: 323451 | L39: 0.11 | P39: 323451 | Q39: 0.11 | R39: 323451
A40: LLP | C40: 131 | D40: 23674 | G40: 23674 | H40: 0.01 | I40: 23674 | K40: 23674 | L40: 0.01 | P40: 23674 | Q40: 0.01 | R40: 23674
...

Sheet Public
A1: Category & Name of the Shareholders | B1: No. of shareholder | C1: No. of fully paid up equity shares held | D1: Total no. shares held | E1: Shareholding % calculated as per SCRR, 1957 As a % of (A+B+C2) | F1: No. of Voting Rights | G1: Total as a % of Total Voting right | H1: No. Of Outstanding ESOP Granted | I1: Total No. Of shares on fully diluted basis (including warrants, ESOP, Convertible Securities etc.) | J1: Shareholding , as a % assuming full conversion of convertible securities ( as a percentage of diluted share capital)As a % of (A+B+C2) | K1: No. of equity shares held in dematerialized form(Not Applicable)
A5: Institutions | B5: 0 | C5: 0 | E5: 0 | G5: 0 | J5: 0
A6: B1) Institutions (Domestic) | B6: 0 | C6: 0 | E6: 0 | G6: 0 | J6: 0
A7: Mutual Funds/ | B7: 35 | C7: 12833231 | D7: 12833231 | E7: 4.33 | F7: 12833231 | G7: 4.33 | I7: 12833231 | J7: 4.32 | K7: 12833231
A8: Venture Capital Funds | B8: 0 | C8: 0 | E8: 0 | G8: 0 | J8: 0
A9: Alternate Investment Funds | B9: 13 | C9: 338888 | D9: 338888 | E9: 0.11 | F9: 338888 | G9: 0.11 | I9: 338888 | J9: 0.11 | K9: 338888
A10: Banks | B10: 4 | C10: 104 | D10: 104 | E10: 0 | F10: 104 | G10: 0 | I10: 104 | J10: 0 | K10: 104
A11: Insurance Companies | B11: 28 | C11: 33752317 | D11: 33752317 | E11: 11.38 | F11: 33752317 | G11: 11.38 | I11: 33752317 | J11: 11.37 | K11: 33752317
A12: Life Insurance Corporation Of India | B12: 1 | C12: 29061981 | D12: 29061981 | E12: 9.8 | F12: 29061981 | G12: 9.8 | I12: 29061981 | J12: 9.79 | K12: 29061981
A13: Provident Funds/ Pension Funds | B13: 1 | C13: 3197187 | D13: 3197187 | E13: 1.08 | F13: 3197187 | G13: 1.08 | I13: 3197187 | J13: 1.08 | K13: 3197187
A14: Nps Trust A/C Uti Pension Fund Limited-Scheme State Govt | B14: 1 | C14: 3197187 | D14: 3197187 | E14: 1.08 | F14: 3197187 | G14: 1.08 | I14: 3197187 | J14: 1.08 | K14: 3197187
A15: Asset reconstruction companies | B15: 0 | C15: 0 | E15: 0 | G15: 0 | J15: 0
A16: Sovereign Wealth Funds | B16: 2 | C16: 294725 | D16: 294725 | E16: 0.1 | F16: 294725 | G16: 0.1 | I16: 294725 | J16: 0.1 | K16: 294725
A17: NBFCs registered with RBI | B17: 4 | C17: 8338 | D17: 8338 | E17: 0 | F17: 8338 | G17: 0 | I17: 8338 | J17: 0 | K17: 8338
A18: Other Financial Institutions | B18: 0 | C18: 0 | E18: 0 | G18: 0 | J18: 0
A19: Any Other(Institutions (Domestic)) | B19: 0 | C19: 0 | E19: 0 | G19: 0 | J19: 0
A20: Sub Total B1 | B20: 87 | C20: 50424790 | D20: 50424790 | E20: 17.01 | F20: 50424790 | G20: 17.01 | I20: 50424790 | J20: 16.99 | K20: 50424790
A21: B2) Institutions (Foreign) | B21: 0 | C21: 0 | E21: 0 | G21: 0 | J21: 0
A22: Foreign Direct Investment | B22: 0 | C22: 0 | E22: 0 | G22: 0 | J22: 0
A23: Foreign Venture Capital Investors | B23: 0 | C23: 0 | E23: 0 | G23: 0 | J23: 0
A24: Sovereign Wealth Funds | B24: 0 | C24: 0 | E24: 0 | G24: 0 | J24: 0
A25: Foreign Portfolio Investors Category I | B25: 450 | C25: 18904782 | D25: 18904782 | E25: 6.38 | F25: 18904782 | G25: 6.38 | I25: 18904782 | J25: 6.37 | K25: 18904782
A26: Foreign Portfolio Investors Category II | B26: 24 | C26: 755300 | D26: 755300 | E26: 0.25 | F26: 755300 | G26: 0.25 | I26: 755300 | J26: 0.25 | K26: 755300
A27: Overseas Depositories (holding DRs) (balancing figure) | B27: 0 | C27: 0 | E27: 0 | G27: 0 | J27: 0
A28: Any Other(Institutions (Foreign)) | B28: 0 | C28: 0 | E28: 0 | G28: 0 | J28: 0
A29: Sub Total B2 | B29: 474 | C29: 19660082 | D29: 19660082 | E29: 6.63 | F29: 19660082 | G29: 6.63 | I29: 19660082 | J29: 6.62 | K29: 19660082
A30: B3) Central Government/ State Government(s)/ President of India | B30: 0 | C30: 0 | E30: 0 | G30: 0 | J30: 0
A31: Central Government / President of India | B31: 1 | C31: 2256 | D31: 2256 | E31: 0 | F31: 2256 | G31: 0 | I31: 2256 | J31: 0 | K31: 2256
A32: State Government / Governor | B32: 0 | C32: 0 | E32: 0 | G32: 0 | J32: 0
A33: Shareholding by Companies or Bodies Corporate where Central / State Government is a promoter | B33: 0 | C33: 0 | E33: 0 | G33: 0 | J33: 0
A34: Sub Total B3 | B34: 1 | C34: 2256 | D34: 2256 | E34: 0 | F34: 2256 | G34: 0 | I34: 2256 | J34: 0 | K34: 2256
A35: B4) Non-Institutions | B35: 0 | C35: 0 | E35: 0 | G35: 0 | J35: 0
A36: Associate companies / Subsidiaries | B36: 0 | C36: 0 | E36: 0 | G36: 0 | J36: 0
A37: Directors and their relatives (excluding independent directors and nominee directors) | B37: 4 | C37: 318644 | D37: 318644 | E37: 0.11 | F37: 318644 | G37: 0.11 | H37: 30000 | I37: 348644 | J37: 0.12 | K37: 318644
A38: Key Managerial Personnel | B38: 1 | C38: 4885 | D38: 4885 | E38: 0 | F38: 4885 | G38: 0 | I38: 4885 | J38: 0 | K38: 4885
A39: Relatives of promoters (other than 'immediate relatives' of promoters disclosed under 'Promoter and Promoter Group' category) | B39: 0 | C39: 0 | E39: 0 | G39: 0 | J39: 0
A40: Trusts where any person belonging to 'Promoter and Promoter Group' category is 'trustee', 'beneficiary', or 'author of the trust' | B40: 0 | C40: 0 | E40: 0 | G40: 0 | J40: 0
A41: Investor Education and Protection Fund (IEPF) | B41: 1 | C41: 97191 | D41: 97191 | E41: 0.03 | F41: 97191 | G41: 0.03 | I41: 97191 | J41: 0.03 | K41: 97191
A42: Resident Individuals holding nominal share capital up to Rs. 2 lakhs | B42: 356089 | C42: 14777058 | D42: 14777058 | E42: 4.98 | F42: 14777058 | G42: 4.98 | I42: 14777058 | J42: 4.98 | K42: 14772253
A43: Resident Individuals holding nominal share capital in excess of Rs. 2 lakhs | B43: 3 | C43: 1667588 | D43: 1667588 | E43: 0.56 | F43: 1667588 | G43: 0.56 | I43: 1667588 | J43: 0.56 | K43: 1667588
...

Sheet Standalone Quarterly Results
C1: Standalone Quarterly Results (Rs. Crores) | J1: % CHANGE
D2: Quarter ended | F2: Half Year ended | H2: Years | J2: QTQ | K2: HY YOY | L2: YOY
C3: Particulars | D3: 45992 | E3: 45901 | F3: 45992 | G3: 45627 | H3: 45717 | I3: 45352
C4: I. REVENUE
C5: Revenue from Operations | D5: 10312 | E5: 9966 | F5: =D5+E5 -> 20278 | G5: 9286 | H5: 34921 | I5: 33992 | J5: =D5/E5-1 -> 0.034718041 | K5: =F5/G5-1 -> 1.1837174 | L5: =H5/I5-1 -> 0.02732996
C6: Other Income | D6: 234 | E6: 288 | F6: =D6+E6 -> 522 | G6: 518 | H6: 810 | I6: 653 | J6: =D6/E6-1 -> -0.1875 | K6: =F6/G6-1 -> 0.0077220077 | L6: =H6/I6-1 -> 0.24042879
C7: Total Income | D7: =D5+D6 -> 10546 | E7: =E5+E6 -> 10254 | F7: =D7+E7 -> 20800 | G7: =G5+G6 -> 9804 | H7: =H5+H6 -> 35731 | I7: =I5+I6 -> 34645 | J7: =D7/E7-1 -> 0.028476692 | K7: =F7/G7-1 -> 1.121583 | L7: =H7/I7-1 -> 0.031346515
C8: II. EXPENSES
C9: Employee Benefits Expense | D9: 5942 | E9: 5863 | F9: =D9+E9 -> 11805 | G9: 11204 | H9: 21370 | I9: 20892 | J9: =D9/E9-1 -> 0.013474331 | K9: =F9/G9-1 -> 0.053641557 | L9: =H9/I9-1 -> 0.022879571
C10: Other Expenses | D10: 2449 | E10: 2222 | F10: =D10+E10 -> 4671 | G10: 4073 | H10: 7251 | I10: 7259 | J10: =D10/E10-1 -> 0.10216022 | K10: =F10/G10-1 -> 0.14682053 | L10: =H10/I10-1 -> -0.0011020802
C11: Depreciation & Amortisation | D11: 249 | E11: 249 | F11: =D11+E11 -> 498 | G11: 461 | H11: 797 | I11: 721 | J11: =D11/E11-1 -> 0 | K11: =F11/G11-1 -> 0.080260304 | L11: =H11/I11-1 -> 0.10540915
C12: Finance Costs | D12: 66 | E12: 65 | F12: =D12+E12 -> 131 | G12: 134 | H12: 224 | I12: 197 | J12: =D12/E12-1 -> 0.015384615 | K12: =F12/G12-1 -> -0.02238806 | L12: =H12/I12-1 -> 0.13705584
C13: Total Expenses | D13: =D9+D10+D11+D12 -> 8706 | E13: =E9+E10+E11+E12 -> 8399 | F13: =D13+E13 -> 17105 | G13: =G9+G10+G11+G12 -> 15872 | H13: =H9+H10+H11+H12 -> 29642 | I13: =I9+I10+I11+I12 -> 29069 | J13: =D13/E13-1 -> 0.03655197 | K13: =F13/G13-1 -> 0.077683972 | L13: =H13/I13-1 -> 0.01971172
C14: III. PROFIT & LOSS
C15: EBITDA | D15: =D7-D9-D10 -> 2155 | E15: =E7-E9-E10 -> 2169 | F15: =D15+E15 -> 4324 | G15: =G7-G9-G10 -> -5473 | H15: =H7-H9-H10 -> 7110 | I15: =I7-I9-I10 -> 6494 | J15: =D15/E15-1 -> -0.0064545874 | K15: =F15/G15-1 -> -1.7900603 | L15: =H15/I15-1 -> 0.094856791
C16: EBIT | D16: =D15-D11 -> 1906 | E16: =E15-E11 -> 1920 | F16: =D16+E16 -> 3826 | G16: =G15-G11 -> -5934 | H16: =H15-H11 -> 6313 | I16: =I15-I11 -> 5773 | J16: =D16/E16-1 -> -0.0072916667 | K16: =F16/G16-1 -> -1.644759 | L16: =H16/I16-1 -> 0.093538888
C17: Profit before Exceptional Items & Tax | D17: =D16-D12 -> 1840 | E17: =E16-E12 -> 1855 | F17: =D17+E17 -> 3695 | G17: =G16-G12 -> -6068 | H17: =H16-H12 -> 6089 | I17: =I16-I12 -> 5576 | J17: =D17/E17-1 -> -0.0080862534 | K17: =F17/G17-1 -> -1.6089321 | L17: =H17/I17-1 -> 0.092001435
C18: Exceptional Items | D18: -590 | E18: 0 | F18: =D18+E18 -> -590 | G18: 0 | H18: 0 | I18: 0
C19: Profit Before Tax | D19: =D17+D18 -> 1250 | E19: =E17+E18 -> 1855 | F19: =D19+E19 -> 3105 | G19: =G17+G18 -> -6068 | H19: =H17+H18 -> 6089 | I19: =I17+I18 -> 5576 | J19: =D19/E19-1 -> -0.32614555 | K19: =F19/G19-1 -> -1.5117007 | L19: =H19/I19-1 -> 0.092001435
C20: Tax Expense | D20: 320 | E20: 468 | F20: =D20+E20 -> 788 | G20: 772 | H20: 1503 | I20: 1288 | J20: =D20/E20-1 -> -0.31623932 | K20: =F20/G20-1 -> 0.020725389 | L20: =H20/I20-1 -> 0.16692547
C21: Profit After Tax (PAT) | D21: =D19-D20 -> 930 | E21: =E19-E20 -> 1387 | F21: =D21+E21 -> 2317 | G21: =G19-G20 -> -6840 | H21: =H19-H20 -> 4586 | I21: =I19-I20 -> 4288 | J21: =D21/E21-1 -> -0.3294881 | K21: =F21/G21-1 -> -1.3387427 | L21: =H21/I21-1 -> 0.069496269
C22: IV. EARNINGS PER SHARE (Rs.)
C23: Basic EPS | D23: 31.33 | E23: 46.77 | F23: =D23+E23 -> 78.1 | G23: 76.38 | H23: 90.56 | I23: 78.58 | J23: =D23/E23-1 -> -0.33012615 | K23: =F23/G23-1 -> 0.022518984 | L23: =H23/I23-1 -> 0.1524561
C24: Diluted EPS | D24: 31.3 | E24: 46.72 | F24: =D24+E24 -> 78.02 | G24: 76.28 | H24: 90.45 | I24: 78.43 | J24: =D24/E24-1 -> -0.33005137 | K24: =F24/G24-1 -> 0.022810697 | L24: =H24/I24-1 -> 0.15325768
C25: V. SUPPLEMENTARY
C26: Paid-up Equity Share Capital (Rs. Cr) | D26: 29 | E26: 29 | F26: =D26 -> 29 | G26: 29 | H26: 29 | I26: 29 | J26: =D26/E26-1 -> 0 | K26: =F26/G26-1 -> 0 | L26: =H26/I26-1 -> 0
C27: Reserves excl. Revaluation (Rs. Cr) | F27: =D27+E27 -> 0 | H27: 19268

Sheet Consolidated Quarterly Results
E1: Consolidated Quarterly Results (Rs. Crores) | L1: % CHANGE
F2: Quarter ended | I2: Years | L2: QTQ | M2: QOQ YOY | N2: YOY
E3: Particulars | F3: 45992 | G3: 45901 | H3: 45627 | I3: 45717 | J3: 45352
E4: I. REVENUE
E5: Revenue from Operations | F5: 10781 | G5: 10394 | H5: 9660 | I5: 38008 | J5: 35517 | L5: =F5/G5-1 -> 0.037233019 | M5: =F5/H5-1 -> 0.11604555 | N5: =I5/J5-1 -> 0.070135428
E6: Other Income | F6: 227 | G6: 300 | H6: 212 | I6: 990 | J6: 702 | L6: =F6/G6-1 -> -0.24333333 | M6: =F6/H6-1 -> 0.070754717 | N6: =I6/J6-1 -> 0.41025641
E7: Total Income | F7: =F5+F6 -> 11008 | G7: =G5+G6 -> 10694 | H7: =H5+H6 -> 9872 | I7: =I5+I6 -> 38998 | J7: =J5+J6 -> 36219 | L7: =F7/G7-1 -> 0.029362259 | M7: =F7/H7-1 -> 0.11507293 | N7: =I7/J7-1 -> 0.076727684
E8: II. EXPENSES
E9: Employee Benefits Expense | F9: 6549 | G9: 6467 | H9: 6254 | I9: 23180 | J9: 22504 | L9: =F9/G9-1 -> 0.012679759 | M9: =F9/H9-1 -> 0.047169811 | N9: =I9/J9-1 -> 0.030039104
E10: Other Expenses | F10: 2229 | G10: 1996 | H10: 1812 | I10: 6430 | J10: 6615 | L10: =F10/G10-1 -> 0.11673347 | M10: =F10/H10-1 -> 0.23013245 | N10: =I10/J10-1 -> -0.027966742
E11: Depreciation & Amortisation | F11: 265 | G11: 282 | H11: 264 | I11: 868 | J11: 786 | L11: =F11/G11-1 -> -0.060283688 | M11: =F11/H11-1 -> 0.0037878788 | N11: =I11/J11-1 -> 0.1043257
E12: Finance Costs | F12: 69 | G12: 69 | H12: 68 | I12: 235 | J12: 209 | L12: =F12/G12-1 -> 0 | M12: =F12/H12-1 -> 0.014705882 | N12: =I12/J12-1 -> 0.12440191
E13: Total Expenses | F13: =F9+F10+F11+F12 -> 9112 | G13: =G9+G10+G11+G12 -> 8814 | H13: =H9+H10+H11+H12 -> 8398 | I13: =I9+I10+I11+I12 -> 30713 | J13: =J9+J10+J11+J12 -> 30114 | L13: =F13/G13-1 -> 0.033809848 | M13: =F13/H13-1 -> 0.085020243 | N13: =I13/J13-1 -> 0.019891081
E14: III. PROFIT & LOSS
E15: EBITDA | F15: =F7-F9-F10 -> 2230 | G15: =G7-G9-G10 -> 2231 | H15: =H7-H9-H10 -> 1806 | I15: =I7-I9-I10 -> 9388 | J15: =J7-J9-J10 -> 7100 | L15: =F15/G15-1 -> -0.00044822949 | M15: =F15/H15-1 -> 0.23477298 | N15: =I15/J15-1 -> 0.32225352
E16: EBIT | F16: =F15-F11 -> 1965 | G16: =G15-G11 -> 1949 | H16: =H15-H11 -> 1542 | I16: =I15-I11 -> 8520 | J16: =J15-J11 -> 6314 | L16: =F16/G16-1 -> 0.0082093381 | M16: =F16/H16-1 -> 0.27431907 | N16: =I16/J16-1 -> 0.34938232
E17: Profit before Exceptional Items & Tax | F17: =F16-F12 -> 1896 | G17: =G16-G12 -> 1880 | H17: =H16-H12 -> 1474 | I17: =I16-I12 -> 8285 | J17: =J16-J12 -> 6105 | L17: =F17/G17-1 -> 0.0085106383 | M17: =F17/H17-1 -> 0.28629579 | N17: =I17/J17-1 -> 0.35708436
E18: Exceptional Items | F18: -590 | G18: 0 | H18: 0 | I18: 0 | J18: 0
E19: Profit Before Tax | F19: =F17+F18 -> 1306 | G19: =G17+G18 -> 1880 | H19: =H17+H18 -> 1474 | I19: =I17+I18 -> 8285 | J19: =J17+J18 -> 6105 | L19: =F19/G19-1 -> -0.30531915 | M19: =F19/H19-1 -> -0.11397558 | N19: =I19/J19-1 -> 0.35708436
E20: Tax Expense | F20: 345 | G20: 498 | H20: 385 | I20: 1612 | J20: 1464 | L20: =F20/G20-1 -> -0.30722892 | M20: =F20/H20-1 -> -0.1038961 | N20: =I20/J20-1 -> 0.1010929
E21: Profit After Tax (PAT) | F21: =F19-F20 -> 961 | G21: =G19-G20 -> 1382 | H21: =H19-H20 -> 1089 | I21: =I19-I20 -> 6673 | J21: =J19-J20 -> 4641 | L21: =F21/G21-1 -> -0.30463097 | M21: =F21/H21-1 -> -0.11753903 | N21: =I21/J21-1 -> 0.43783667
E22: Minority Interest | F22: 11 | G22: 19 | H22: -1 | I22: 19 | J22: -1 | L22: =F22/G22-1 -> -0.42105263 | M22: =F22/H22-1 -> -12 | N22: =I22/J22-1 -> -20
E23: Net Profit after Minority Interest | F23: =F21+F22 -> 972 | G23: =G21+G22 -> 1401 | H23: =H21+H22 -> 1088 | I23: =I21+I22 -> 6692 | J23: =J21+J22 -> 4640 | L23: =F23/G23-1 -> -0.30620985 | M23: =F23/H23-1 -> -0.10661765 | N23: =I23/J23-1 -> 0.44224138
E24: Total Comprehensive Income | F24: 918 | G24: 692 | H24: 782 | I24: 4547 | L24: =F24/G24-1 -> 0.3265896 | M24: =F24/H24-1 -> 0.17391304
E25: IV. EARNINGS PER SHARE (Rs.)
E26: Basic EPS | F26: 32.75 | G26: 47.28 | H26: 36.65 | I26: 155.22 | J26: 154.55 | L26: =F26/G26-1 -> -0.3073181 | M26: =F26/H26-1 -> -0.10641201 | N26: =I26/J26-1 -> 0.0043351666
E27: Diluted EPS | F27: 32.71 | G27: 47.23 | H27: 36.59 | I27: 155.22 | J27: 154.55 | L27: =F27/G27-1 -> -0.30743172 | M27: =F27/H27-1 -> -0.1060399 | N27: =I27/J27-1 -> 0.0043351666
E28: V. SUPPLEMENTARY
E29: Paid-up Equity Share Capital (Rs. Cr) | F29: 29 | G29: 29 | H29: 29 | I29: 29 | J29: 29 | L29: =F29/G29-1 -> 0 | M29: =F29/H29-1 -> 0 | N29: =I29/J29-1 -> 0
E30: Reserves excl. Revaluation (Rs. Cr) | I30: 19996

Sheet Standalone Balance sheet
E1: Standalone Balance Sheet
E2: Particulars (Rs. Cr.) | F2: Mar 25 | G2: Mar 24 | H2: % Change
E3: 12 Months Ended | F3: 12 mths | G3: 12 mths
E4: EQUITIES AND LIABILITIES
E5: SHAREHOLDER'S FUNDS
E6: Equity Share Capital | F6: 29.6 | G6: 29.6 | H6: =F6/G6-1 -> 0
E7: Total Share Capital | F7: =F6 -> 29.6 | G7: =G6 -> 29.6 | H7: =F7/G7-1 -> 0
E8: Reserves and Surplus | F8: 21570.7 | G8: 18925.5 | H8: =F8/G8-1 -> 0.13976909
E9: Total Reserves and Surplus | F9: =F8 -> 21570.7 | G9: =G8 -> 18925.5 | H9: =F9/G9-1 -> 0.13976909
E10: Employees Stock Options | F10: 233.7 | G10: 343.3 | H10: =F10/G10-1 -> -0.3192543
E11: Total Shareholders Funds | F11: =F7+F9+F10 -> 21834 | G11: =G7+G9+G10 -> 19298.4 | H11: =F11/G11-1 -> 0.13138913
E12: Equity Share Application Money | F12: 0.1 | G12: 0.1 | H12: =F12/G12-1 -> 0
E13: NON-CURRENT LIABILITIES
E14: Other Long Term Liabilities | F14: 1825.4 | G14: 1674.3 | H14: =F14/G14-1 -> 0.09024667
E15: Long Term Provisions | F15: 19.7 | G15: 15.7 | H15: =F15/G15-1 -> 0.25477707
E16: Total Non-Current Liabilities | F16: =F14+F15 -> 1845.1 | G16: =G14+G15 -> 1690 | H16: =F16/G16-1 -> 0.091775148
E17: CURRENT LIABILITIES
E18: Trade Payables | F18: 1515.3 | G18: 1504.5 | H18: =F18/G18-1 -> 0.0071784646
E19: Other Current Liabilities | F19: 3115.6 | G19: 3169.3 | H19: =F19/G19-1 -> -0.016943805
E20: Short Term Provisions | F20: 906.6 | G20: 795.4 | H20: =F20/G20-1 -> 0.13980387
E21: Total Current Liabilities | F21: =F18+F19+F20 -> 5537.5 | G21: =G18+G19+G20 -> 5469.2 | H21: =F21/G21-1 -> 0.012488115
E22: Total Capital And Liabilities | F22: =F11+F12+F16+F21 -> 29216.7 | G22: =G11+G12+G16+G21 -> 26457.7 | H22: =F22/G22-1 -> 0.10427966
E23: ASSETS
E24: NON-CURRENT ASSETS
E25: Tangible Assets | F25: 3845.6 | G25: 3444.7 | H25: =F25/G25-1 -> 0.11638169
E26: Intangible Assets | F26: 715.2 | G26: 774.9 | H26: =F26/G26-1 -> -0.077042199
E27: Capital Work-In-Progress | F27: 563.2 | G27: 464.2 | H27: =F27/G27-1 -> 0.21327014
E28: Intangible Assets Under Development | F28: 0 | G28: 12.7 | H28: =F28/G28-1 -> -1
E29: Fixed Assets | F29: =F25+F26+F27+F28 -> 5124 | G29: =G25+G26+G27+G28 -> 4696.5 | H29: =F29/G29-1 -> 0.091025232
E30: Non-Current Investments | F30: 2982.7 | G30: 2449.9 | H30: =F30/G30-1 -> 0.21747826
E31: Deferred Tax Assets [Net] | F31: 201.8 | G31: 201.4 | H31: =F31/G31-1 -> 0.0019860973
E32: Long Term Loans And Advances | F32: 0 | G32: 0
E33: Other Non-Current Assets | F33: 986.9 | G33: 928.3 | H33: =F33/G33-1 -> 0.063126145
E34: Total Non-Current Assets | F34: =F29+F30+F31+F32+F33 -> 9295.4 | G34: =G29+G30+G31+G32+G33 -> 8276.1 | H34: =F34/G34-1 -> 0.12316188
E35: CURRENT ASSETS
E36: Current Investments | F36: 7374 | G36: 6753.4 | H36: =F36/G36-1 -> 0.091894453
E37: Inventories | F37: 2.8 | G37: 3 | H37: =F37/G37-1 -> -0.066666667
E38: Trade Receivables | F38: 5671.8 | G38: 5372.1 | H38: =F38/G38-1 -> 0.055788239
E39: Cash And Cash Equivalents | F39: 2964.7 | G39: 2590.7 | H39: =F39/G39-1 -> 0.14436253
E40: Short Term Loans And Advances | F40: 35.1 | G40: 45.6 | H40: =F40/G40-1 -> -0.23026316
...

Sheet Standalone P&L
E1: Standalone Profit & Loss account
E2: Particulars (Rs. Cr.) | F2: Mar 25 | G2: Mar 24 | H2: % Change
E3: 12 Months Ended | F3: 12 mths | G3: 12 mths
E4: INCOME
E5: Revenue From Operations [Gross] | F5: 36682.5 | G5: 34253.4 | H5: =F5/G5-1 -> 0.070915588
E6: Revenue From Operations [Net] | F6: =F5 -> 36682.5 | G6: =G5 -> 34253.4 | H6: =F6/G6-1 -> 0.070915588
E7: Total Operating Revenues | F7: =F6 -> 36682.5 | G7: =G6 -> 34253.4 | H7: =F7/G7-1 -> 0.070915588
E8: Other Income | F8: 973.8 | G8: 709.9 | H8: =F8/G8-1 -> 0.3717425
E9: Total Revenue | F9: =F7+F8 -> 37656.3 | G9: =G7+G8 -> 34963.3 | H9: =F9/G9-1 -> 0.077023622
E10: EXPENSES
E11: Operating And Direct Expenses | F11: 3627.1 | G11: 4813.5 | H11: =F11/G11-1 -> -0.24647346
E12: Employee Benefit Expenses | F12: 22596.1 | G12: 21049 | H12: =F12/G12-1 -> 0.073499929
E13: Finance Costs | F13: 270.7 | G13: 207.1 | H13: =F13/G13-1 -> 0.30709802
E14: Depreciation And Amortisation Expenses | F14: 904.3 | G14: 760.4 | H14: =F14/G14-1 -> 0.1892425
E15: Other Expenses | F15: 4289.4 | G15: 2253.9 | H15: =F15/G15-1 -> 0.90310129
E16: Total Expenses | F16: =F11+F12+F13+F14+F15 -> 31687.6 | G16: =G11+G12+G13+G14+G15 -> 29083.9 | H16: =F16/G16-1 -> 0.089523757
F17: 45717 | G17: 45352
F19: 12 mths | G19: 12 mths
E21: Profit/Loss Before Exceptional, ExtraOrdinary Items And Tax | F21: =F9-F16 -> 5968.7 | G21: =G9-G16 -> 5879.4 | H21: =F21/G21-1 -> 0.015188625
E22: Profit/Loss Before Tax | F22: =F21 -> 5968.7 | G22: =G21 -> 5879.4 | H22: =F22/G22-1 -> 0.015188625
E23: Tax Expenses-Continued Operations
E24: Current Tax | F24: 1505.7 | G24: 1391.7 | H24: =F24/G24-1 -> 0.081914206
E25: Deferred Tax | F25: 16.5 | G25: 1.8 | H25: =F25/G25-1 -> 8.1666667
E26: Total Tax Expenses | F26: =F24+F25 -> 1522.2 | G26: =G24+G25 -> 1393.5 | H26: =F26/G26-1 -> 0.092357374
E27: Profit/Loss After Tax And Before ExtraOrdinary Items | F27: =F22-F26 -> 4446.5 | G27: =G22-G26 -> 4485.9 | H27: =F27/G27-1 -> -0.0087830759
E28: Profit/Loss From Continuing Operations | F28: =F27 -> 4446.5 | G28: =G27 -> 4485.9 | H28: =F28/G28-1 -> -0.0087830759
E29: Profit/Loss For The Period | F29: =F28 -> 4446.5 | G29: =G28 -> 4485.9 | H29: =F29/G29-1 -> -0.0087830759
F30: 45717 | G30: 45352
F32: 12 mths | G32: 12 mths
E34: OTHER ADDITIONAL INFORMATION
E35: EARNINGS PER SHARE
E36: Basic EPS (Rs.) | F36: 150.15 | G36: 151.6 | H36: =F36/G36-1 -> -0.0095646438
E37: Diluted EPS (Rs.) | F37: 149.87 | G37: 151.24 | H37: =F37/G37-1 -> -0.0090584501
E38: VALUE OF IMPORTED AND INDIGENIOUS RAW MATERIALS
E39: STORES, SPARES AND LOOSE TOOLS
E40: DIVIDEND AND DIVIDEND PERCENTAGE
E41: Equity Share Dividend | F41: 1924.6 | G41: 1775.3 | H41: =F41/G41-1 -> 0.084098462
E42: Equity Dividend Rate (%) | F42: 6500 | G42: 6500 | H42: =F42/G42-1 -> 0

Sheet Consolidated P&L
E1: Consolidated Profit & Loss account | L1: % Change
E2: Particulars (Rs. Cr.) | F2: Mar 22 | G2: Mar 23 | H2: Mar 24 | I2: Mar 25 | J2: Mar 26 | L2: Mar 22 | M2: Mar 23 | N2: Mar 24 | O2: Mar 25 | P2: Mar 26
E3: 12 Months Ended | F3: 12 mths | G3: 12 mths | H3: 12 mths | I3: 12 mths | J3: 12 mths
E4: INCOME
E5: Revenue From Operations [Gross] | F5: 15668.7 | G5: 33183 | H5: 35517 | I5: 38008.1 | J5: 42307.6 | M5: =(G5-F5)/F5 -> 1.117789 | N5: =(H5-G5)/G5 -> 0.070337221 | O5: =(I5-H5)/H5 -> 0.070138244 | P5: =(J5-I5)/I5 -> 0.11312062
E6: Revenue From Operations [Net] | F6: =F5 -> 15668.7 | G6: =G5 -> 33183 | H6: =H5 -> 35517 | I6: =I5 -> 38008.1 | J6: =J5 -> 42307.6 | M6: =(G6-F6)/F6 -> 1.117789 | N6: =(H6-G6)/G6 -> 0.070337221 | O6: =(I6-H6)/H6 -> 0.070138244 | P6: =(J6-I6)/I6 -> 0.11312062
E7: Total Operating Revenues | F7: =F6 -> 15668.7 | G7: =G6 -> 33183 | H7: =H6 -> 35517 | I7: =I6 -> 38008.1 | J7: =J6 -> 42307.6 | M7: =(G7-F7)/F7 -> 1.117789 | N7: =(H7-G7)/G7 -> 0.070337221 | O7: =(I7-H7)/H7 -> 0.070138244 | P7: =(J7-I7)/I7 -> 0.11312062
E8: Other Income | F8: 466.7 | G8: 556.9 | H8: 701.9 | I8: 989.7 | J8: 1094.4 | M8: =(G8-F8)/F8 -> 0.19327191 | N8: =(H8-G8)/G8 -> 0.2603699 | O8: =(I8-H8)/H8 -> 0.41002992 | P8: =(J8-I8)/I8 -> 0.10578963
E9: Total Revenue | F9: =F7+F8 -> 16135.4 | G9: =G7+G8 -> 33739.9 | H9: =H7+H8 -> 36218.9 | I9: =I7+I8 -> 38997.8 | J9: =J7+J8 -> 43402 | M9: =(G9-F9)/F9 -> 1.0910483 | N9: =(H9-G9)/G9 -> 0.07347384 | O9: =(I9-H9)/H9 -> 0.076725135 | P9: =(J9-I9)/I9 -> 0.11293458
E10: EXPENSES
E11: Operating And Direct Expenses | F11: 2656.5 | G11: 3967.9 | H11: 4179.5 | I11: 2631.2 | J11: 0 | M11: =(G11-F11)/F11 -> 0.49365707 | N11: =(H11-G11)/G11 -> 0.053327957 | O11: =(I11-H11)/H11 -> -0.37045101 | P11: =(J11-I11)/I11 -> -1
E12: Employee Benefit Expenses | F12: 9700.7 | G12: 20879.9 | H12: 22732.3 | I12: 24622.6 | J12: 26286.9 | M12: =(G12-F12)/F12 -> 1.1524117 | N12: =(H12-G12)/G12 -> 0.0887169 | O12: =(I12-H12)/H12 -> 0.083154806 | P12: =(J12-I12)/I12 -> 0.067592374
E13: Finance Costs | F13: 72.8 | G13: 150.4 | H13: 221.7 | I13: 278.9 | J13: 276.3 | M13: =(G13-F13)/F13 -> 1.0659341 | N13: =(H13-G13)/G13 -> 0.47406915 | O13: =(I13-H13)/H13 -> 0.25800631 | P13: =(J13-I13)/I13 -> -0.0093223378
E14: Depreciation And Amortisation Expenses | F14: 354.9 | G14: 722.7 | H14: 818.9 | I14: 991.5 | J14: 1054.1 | M14: =(G14-F14)/F14 -> 1.0363483 | N14: =(H14-G14)/G14 -> 0.13311194 | O14: =(I14-H14)/H14 -> 0.21077055 | P14: =(J14-I14)/I14 -> 0.063136662
E15: Other Expenses | F15: 253.1 | G15: 2227.5 | H15: 2217.8 | I15: 4259.4 | J15: 8465.5 | M15: =(G15-F15)/F15 -> 7.8008692 | N15: =(H15-G15)/G15 -> -0.0043546577 | O15: =(I15-H15)/H15 -> 0.9205519 | P15: =(J15-I15)/I15 -> 0.9874865
E16: Total Expenses | F16: =F11+F12+F13+F14+F15 -> 13038 | G16: =G11+G12+G13+G14+G15 -> 27948.4 | H16: =H11+H12+H13+H14+H15 -> 30170.2 | I16: =I11+I12+I13+I14+I15 -> 32783.6 | J16: =J11+J12+J13+J14+J15 -> 36082.8 | M16: =(G16-F16)/F16 -> 1.143611 | N16: =(H16-G16)/G16 -> 0.079496501 | O16: =(I16-H16)/H16 -> 0.086621898 | P16: =(J16-I16)/I16 -> 0.10063568
E17: Profit/Loss Before Exceptional, ExtraOrdinary Items And Tax | F17: =F9-F16 -> 3097.4 | G17: =G9-G16 -> 5791.5 | H17: =H9-H16 -> 6048.7 | I17: =I9-I16 -> 6214.2 | J17: =J9-J16 -> 7319.2 | M17: =(G17-F17)/F17 -> 0.86979402 | N17: =(H17-G17)/G17 -> 0.044409911 | O17: =(I17-H17)/H17 -> 0.027361251 | P17: =(J17-I17)/I17 -> 0.17781854
E18: Exceptional Items | F18: 0 | G18: 0 | H18: 0 | I18: 0 | J18: -528.1
E19: Profit/Loss Before Tax | F19: =F17+F18 -> 3097.4 | G19: =G17+G18 -> 5791.5 | H19: =H17+H18 -> 6048.7 | I19: =I17+I18 -> 6214.2 | J19: =J17+J18 -> 6791.1 | M19: =(G19-F19)/F19 -> 0.86979402 | N19: =(H19-G19)/G19 -> 0.044409911 | O19: =(I19-H19)/H19 -> 0.027361251 | P19: =(J19-I19)/I19 -> 0.092835763
E20: Tax Expenses-Continued Operations
E21: Current Tax | F21: 818.1 | G21: 1439.1 | H21: 1460 | I21: 1578.4 | J21: 1808.4 | M21: =(G21-F21)/F21 -> 0.75907591 | N21: =(H21-G21)/G21 -> 0.014522966 | O21: =(I21-H21)/H21 -> 0.08109589 | P21: =(J21-I21)/I21 -> 0.14571718
E22: Deferred Tax | F22: -19.2 | G22: -57.9 | H22: 4.1 | I22: 33.8 | J22: 0 | M22: =(G22-F22)/F22 -> 2.015625 | N22: =(H22-G22)/G22 -> -1.0708117 | O22: =(I22-H22)/H22 -> 7.2439024 | P22: =(J22-I22)/I22 -> -1
E23: Total Tax Expenses | F23: =F21+F22 -> 798.9 | G23: =G21+G22 -> 1381.2 | H23: =H21+H22 -> 1464.1 | I23: =I21+I22 -> 1612.2 | J23: =J21+J22 -> 1808.4 | M23: =(G23-F23)/F23 -> 0.72887721 | N23: =(H23-G23)/G23 -> 0.060020272 | O23: =(I23-H23)/H23 -> 0.10115429 | P23: =(J23-I23)/I23 -> 0.12169706
E24: Profit/Loss After Tax And Before ExtraOrdinary Items | F24: =F19-F23 -> 2298.5 | G24: =G19-G23 -> 4410.3 | H24: =H19-H23 -> 4584.6 | I24: =I19-I23 -> 4602 | J24: =J19-J23 -> 4982.7 | M24: =(G24-F24)/F24 -> 0.91877311 | N24: =(H24-G24)/G24 -> 0.039521121 | O24: =(I24-H24)/H24 -> 0.0037953147 | P24: =(J24-I24)/I24 -> 0.082724902
E25: Profit/Loss From Continuing Operations | F25: =F24 -> 2298.5 | G25: =G24 -> 4410.3 | H25: =H24 -> 4584.6 | I25: =I24 -> 4602 | J25: =J24 -> 4982.7 | M25: =(G25-F25)/F25 -> 0.91877311 | N25: =(H25-G25)/G25 -> 0.039521121 | O25: =(I25-H25)/H25 -> 0.0037953147 | P25: =(J25-I25)/I25 -> 0.082724902
E26: Profit/Loss For The Period | F26: =F25 -> 2298.5 | G26: =G25 -> 4410.3 | H26: =H25 -> 4584.6 | I26: =I25 -> 4602 | J26: =J25 -> 4982.7 | M26: =(G26-F26)/F26 -> 0.91877311 | N26: =(H26-G26)/G26 -> 0.039521121 | O26: =(I26-H26)/H26 -> 0.0037953147 | P26: =(J26-I26)/I26 -> 0.082724902
E27: Minority Interest | F27: -1.7 | G27: -2 | H27: -2.5 | I27: -3.3 | J27: 35.4 | M27: =(G27-F27)/F27 -> 0.17647059 | N27: =(H27-G27)/G27 -> 0.25 | O27: =(I27-H27)/H27 -> 0.32 | P27: =(J27-I27)/I27 -> -11.727273
E28: Consolidated Profit/Loss After MI And Associates | F28: =F26+F27 -> 2296.8 | G28: =G26+G27 -> 4408.3 | H28: =H26+H27 -> 4582.1 | I28: =I26+I27 -> 4598.7 | J28: =J26+J27 -> 5018.1 | M28: =(G28-F28)/F28 -> 0.91932254 | N28: =(H28-G28)/G28 -> 0.039425629 | O28: =(I28-H28)/H28 -> 0.003622793 | P28: =(J28-I28)/I28 -> 0.091199687
E29: OTHER ADDITIONAL INFORMATION
E30: EARNINGS PER SHARE
E31: Basic EPS (Rs.) | F31: 131 | G31: 149 | H31: 155 | I31: 155 | J31: 169 | M31: =(G31-F31)/F31 -> 0.13740458 | N31: =(H31-G31)/G31 -> 0.040268456 | O31: =(I31-H31)/H31 -> 0 | P31: =(J31-I31)/I31 -> 0.090322581
E32: Diluted EPS (Rs.) | F32: 131 | G32: 149 | H32: 155 | I32: 155 | M32: =(G32-F32)/F32 -> 0.13740458 | N32: =(H32-G32)/G32 -> 0.040268456 | O32: =(I32-H32)/H32 -> 0 | P32: =(J32-I32)/I32 -> -1
E33: DIVIDEND AND DIVIDEND PERCENTAGE
E34: Equity Share Dividend | F34: 874.9 | G34: 1562.7 | H34: 1775.3 | I34: 1924.6 | J34: 0 | M34: =(G34-F34)/F34 -> 0.78614699 | N34: =(H34-G34)/G34 -> 0.13604659 | O34: =(I34-H34)/H34 -> 0.084098462 | P34: =(J34-I34)/I34 -> -1

Sheet Consolidated Balance sheet
D1: Consolidated Balance Sheet | L1: % Change
D2: Particulars (Rs. Cr.) | E2: Mar 22 | F2: Mar 23 | G2: Mar 24 | H2: Mar 25 | I2: Mar 26 | L2: Mar 22 | M2: Mar 23 | N2: Mar 24 | O2: Mar 25 | P2: Mar 26
D3: 12 Months Ended | E3: 12 mths | F3: 12 mths | G3: 12 mths | H3: 12 mths | I3: 12 mths
D4: EQUITIES AND LIABILITIES
D5: SHAREHOLDER'S FUNDS
D6: Equity Share Capital | E6: 17.5 | F6: 29.6 | G6: 29.6 | H6: 29.6 | I6: 29.6 | M6: =(F6-E6)/E6 -> 0.69142857 | N6: =(G6-F6)/F6 -> 0 | O6: =(H6-G6)/G6 -> 0 | P6: =(I6-H6)/H6 -> 0
D7: Total Share Capital | E7: =E6 -> 17.5 | F7: =F6 -> 29.6 | G7: =G6 -> 29.6 | H7: =H6 -> 29.6 | I7: =I6 -> 29.6
D8: Reserves and Surplus | E8: 8797.1 | F8: 16078.6 | G8: 19503.6 | H8: 22434.9 | I8: 23995.4 | M8: =(F8-E8)/E8 -> 0.82771595 | N8: =(G8-F8)/F8 -> 0.21301606 | O8: =(H8-G8)/G8 -> 0.15029533 | P8: =(I8-H8)/H8 -> 0.069556807
D9: Total Reserves and Surplus | E9: =E8 -> 8797.1 | F9: =F8 -> 16078.6 | G9: =G8 -> 19503.6 | H9: =H8 -> 22434.9 | I9: =I8 -> 23995.4 | M9: =(F9-E9)/E9 -> 0.82771595 | N9: =(G9-F9)/F9 -> 0.21301606 | O9: =(H9-G9)/G9 -> 0.15029533 | P9: =(I9-H9)/H9 -> 0.069556807
D10: Employees Stock Options | E10: 0 | F10: 483.9 | G10: 483.9 | H10: 233.7 | I10: 0 | N10: =(G10-F10)/F10 -> 0 | O10: =(H10-G10)/G10 -> -0.51704898 | P10: =(I10-H10)/H10 -> -1
D11: Total Shareholders Funds | E11: =E7+E9+E10 -> 8814.6 | F11: =F7+F9+F10 -> 16592.1 | G11: =G7+G9+G10 -> 20017.1 | H11: =H7+H9+H10 -> 22698.2 | I11: =I7+I9+I10 -> 24025 | M11: =(F11-E11)/E11 -> 0.88234293 | N11: =(G11-F11)/F11 -> 0.20642354 | O11: =(H11-G11)/G11 -> 0.13394048 | P11: =(I11-H11)/H11 -> 0.058453974
D12: Equity Share Application Money | E12: 0 | F12: 0 | G12: 0.1 | H12: 0.1 | I12: 0 | P12: =(I12-H12)/H12 -> -1
D13: Minority Interest | E13: 5.7 | F13: 7.1 | G13: 9.2 | H13: 13.2 | I13: 82.7 | M13: =(F13-E13)/E13 -> 0.24561404 | N13: =(G13-F13)/F13 -> 0.29577465 | O13: =(H13-G13)/G13 -> 0.43478261 | P13: =(I13-H13)/H13 -> 5.2651515
D14: NON-CURRENT LIABILITIES
D15: Long Term Borrowings | E15: 667.5 | F15: 0 | G15: 0 | H15: 0 | I15: 0
D16: Deferred Tax Liabilities [Net] | E16: 10.5 | F16: 14.7 | G16: 18.7 | H16: 31.9 | I16: 47.5 | M16: =(F16-E16)/E16 -> 0.4 | N16: =(G16-F16)/F16 -> 0.27210884 | O16: =(H16-G16)/G16 -> 0.70588235 | P16: =(I16-H16)/H16 -> 0.48902821
D17: Other Long Term Liabilities | E17: 52.7 | F17: 1364.6 | G17: 1759 | H17: 1901 | I17: 3235.6 | M17: =(F17-E17)/E17 -> 24.893738 | N17: =(G17-F17)/F17 -> 0.28902242 | O17: =(H17-G17)/G17 -> 0.080727686 | P17: =(I17-H17)/H17 -> 0.70205155
D18: Long Term Provisions | E18: 0 | F18: 35 | G18: 15.7 | H18: 19.7 | I18: 21.5 | N18: =(G18-F18)/F18 -> -0.55142857 | O18: =(H18-G18)/G18 -> 0.25477707 | P18: =(I18-H18)/H18 -> 0.091370558
D19: Total Non-Current Liabilities | E19: =E15+E16+E17+E18 -> 730.7 | F19: =F15+F16+F17+F18 -> 1414.3 | G19: =G15+G16+G17+G18 -> 1793.4 | H19: =H15+H16+H17+H18 -> 1952.6 | I19: =I15+I16+I17+I18 -> 3304.6 | M19: =(F19-E19)/E19 -> 0.93554126 | N19: =(G19-F19)/F19 -> 0.2680478 | O19: =(H19-G19)/G19 -> 0.088769934 | P19: =(I19-H19)/H19 -> 0.69241012
D20: CURRENT LIABILITIES
D21: Short Term Borrowings | E21: 168 | F21: 125.3 | G21: 40.7 | H21: 2.3 | I21: 0 | M21: =(F21-E21)/E21 -> -0.25416667 | N21: =(G21-F21)/F21 -> -0.67517957 | O21: =(H21-G21)/G21 -> -0.94348894 | P21: =(I21-H21)/H21 -> -1
D22: Trade Payables | E22: 802.8 | F22: 1293.8 | G22: 1493.9 | H22: 1549.9 | I22: 2061 | M22: =(F22-E22)/E22 -> 0.61160937 | N22: =(G22-F22)/F22 -> 0.15466069 | O22: =(H22-G22)/G22 -> 0.037485775 | P22: =(I22-H22)/H22 -> 0.32976321
D23: Other Current Liabilities | E23: 1560.1 | F23: 3250.1 | G23: 3360 | H23: 3444.6 | I23: 6548.6 | M23: =(F23-E23)/E23 -> 1.0832639 | N23: =(G23-F23)/F23 -> 0.033814344 | O23: =(H23-G23)/G23 -> 0.025178571 | P23: =(I23-H23)/H23 -> 0.90112059
D24: Short Term Provisions | E24: 387.4 | F24: 813.4 | G24: 848.6 | H24: 969.1 | I24: 1174.1 | M24: =(F24-E24)/E24 -> 1.0996386 | N24: =(G24-F24)/F24 -> 0.043275141 | O24: =(H24-G24)/G24 -> 0.14199859 | P24: =(I24-H24)/H24 -> 0.21153648
D25: Total Current Liabilities | E25: =E21+E22+E23+E24 -> 2918.3 | F25: =F21+F22+F23+F24 -> 5482.6 | G25: =G21+G22+G23+G24 -> 5743.2 | H25: =H21+H22+H23+H24 -> 5965.9 | I25: =I21+I22+I23+I24 -> 9783.7 | M25: =(F25-E25)/E25 -> 0.8786965 | N25: =(G25-F25)/F25 -> 0.047532193 | O25: =(H25-G25)/G25 -> 0.038776292 | P25: =(I25-H25)/H25 -> 0.63993698
D26: Total Capital And Liabilities | E26: =E11+E12+E13+E19+E25 -> 12469.3 | F26: =F11+F12+F13+F19+F25 -> 23496.1 | G26: =G11+G12+G13+G19+G25 -> 27563 | H26: =H11+H12+H13+H19+H25 -> 30630 | I26: =I11+I12+I13+I19+I25 -> 37196 | M26: =(F26-E26)/E26 -> 0.88431588 | N26: =(G26-F26)/F26 -> 0.1730883 | O26: =(H26-G26)/G26 -> 0.11127236 | P26: =(I26-H26)/H26 -> 0.214365
D27: ASSETS
D28: NON-CURRENT ASSETS
D29: Tangible Assets | E29: 1135.9 | F29: 2223.6 | G29: 3556.8 | H29: 3963.1 | I29: 4175.6 | M29: =(F29-E29)/E29 -> 0.95756669 | N29: =(G29-F29)/F29 -> 0.59956827 | O29: =(H29-G29)/G29 -> 0.11423189 | P29: =(I29-H29)/H29 -> 0.053619641
D30: Intangible Assets | E30: 271.8 | F30: 266.3 | G30: 231.3 | H30: 118 | I30: 162.9 | M30: =(F30-E30)/E30 -> -0.020235467 | N30: =(G30-F30)/F30 -> -0.13143072 | O30: =(H30-G30)/G30 -> -0.48984003 | P30: =(I30-H30)/H30 -> 0.38050847
D31: Capital Work-In-Progress | E31: 437.4 | F31: 812.6 | G31: 466.9 | H31: 581.8 | I31: 917.1 | M31: =(F31-E31)/E31 -> 0.85779607 | N31: =(G31-F31)/F31 -> -0.42542456 | O31: =(H31-G31)/G31 -> 0.24609124 | P31: =(I31-H31)/H31 -> 0.57631488
D32: Intangible Assets Under Development | E32: 43.9 | F32: 89.7 | G32: 83.8 | H32: 99.6 | I32: 0 | M32: =(F32-E32)/E32 -> 1.0432802 | N32: =(G32-F32)/F32 -> -0.065774805 | O32: =(H32-G32)/G32 -> 0.18854415 | P32: =(I32-H32)/H32 -> -1
D33: Fixed Assets | E33: =E29+E30+E31+E32 -> 1889 | F33: =F29+F30+F31+F32 -> 3392.2 | G33: =G29+G30+G31+G32 -> 4338.8 | H33: =H29+H30+H31+H32 -> 4762.5 | I33: =I29+I30+I31+I32 -> 5255.6 | M33: =(F33-E33)/E33 -> 0.79576496 | N33: =(G33-F33)/F33 -> 0.27905194 | O33: =(H33-G33)/G33 -> 0.097653729 | P33: =(I33-H33)/H33 -> 0.10353806
D34: Non-Current Investments | E34: 345.4 | F34: 716.5 | G34: 1990.2 | H34: 2470.6 | I34: 532.2 | M34: =(F34-E34)/E34 -> 1.0744065 | N34: =(G34-F34)/F34 -> 1.7776692 | O34: =(H34-G34)/G34 -> 0.24138278 | P34: =(I34-H34)/H34 -> -0.78458674
D35: Deferred Tax Assets [Net] | E35: 54.9 | F35: 380.9 | G35: 225 | H35: 222 | I35: 951.8 | M35: =(F35-E35)/E35 -> 5.9380692 | N35: =(G35-F35)/F35 -> -0.40929378 | O35: =(H35-G35)/G35 -> -0.013333333 | P35: =(I35-H35)/H35 -> 3.2873874
D36: Long Term Loans And Advances | E36: 0 | F36: 0 | G36: 0 | H36: 0 | I36: 0
D37: Other Non-Current Assets | E37: 624.4 | F37: 631.5 | G37: 969.9 | H37: 1033.4 | I37: 1466.9 | M37: =(F37-E37)/E37 -> 0.011370916 | N37: =(G37-F37)/F37 -> 0.53586698 | O37: =(H37-G37)/G37 -> 0.065470667 | P37: =(I37-H37)/H37 -> 0.41948907
D38: Total Non-Current Assets | E38: 3603.7 | F38: 6310.3 | G38: 8716.6 | H38: 9692.1 | I38: 9498.8 | M38: =(F38-E38)/E38 -> 0.75106141 | N38: =(G38-F38)/F38 -> 0.38132894 | O38: =(H38-G38)/G38 -> 0.1119129 | P38: =(I38-H38)/H38 -> -0.019944078
D39: CURRENT ASSETS
D40: Current Investments | E40: 3136.6 | F40: 4741.8 | G40: 6753.4 | H40: 7374 | I40: 12035.5 | M40: =(F40-E40)/E40 -> 0.51176433 | N40: =(G40-F40)/F40 -> 0.42422709 | O40: =(H40-G40)/G40 -> 0.091894453 | P40: =(I40-H40)/H40 -> 0.63215351
...

Sheet Fixed assets scheduled
A1: Particular | B1: 44621 | C1: 44986 | D1: 45352 | E1: 45717 | F1: 46082
A2: Beginning balance | C2: =B6 -> 1889 | D2: =C6 -> 3392.2 | E2: =D6 -> 4338.8 | F2: =E6 -> 4762.5
A3: Add: Net Purchases | C3: =C6-C2+C5 -> 2225.9 | D3: =D6-D2+D5 -> 1765.5 | E3: =E6-E2+E5 -> 1415.2 | F3: =F6-F2+F5 -> 1547.2
A4: Total Fixed Assets | B4: =B5+B6 -> 2243.9 | C4: =C5+C6 -> 4114.9 | D4: =D5+D6 -> 5157.7 | E4: =E5+E6 -> 5754 | F4: =F5+F6 -> 6309.7
A5: Less: Depreciation | B5: ='Consolidated P&L'!F14 -> 354.9 | C5: ='Consolidated P&L'!G14 -> 722.7 | D5: ='Consolidated P&L'!H14 -> 818.9 | E5: ='Consolidated P&L'!I14 -> 991.5 | F5: ='Consolidated P&L'!J14 -> 1054.1
A6: Closing Balance(Fixed Asests ) | B6: ='Consolidated Balance sheet'!E33 -> 1889 | C6: ='Consolidated Balance sheet'!F33 -> 3392.2 | D6: ='Consolidated Balance sheet'!G33 -> 4338.8 | E6: ='Consolidated Balance sheet'!H33 -> 4762.5 | F6: ='Consolidated Balance sheet'!I33 -> 5255.6
A8: Net Capital expenditure | C8: =C3-C5 -> 1503.2 | D8: =D3-D5 -> 946.6 | E8: =E3-E5 -> 423.7 | F8: =F3-F5 -> 493.1
A9: Net Capital expenditure / Sales percentage | C9: =C8/'Consolidated P&L'!G7 -> 0.045300304 | D9: =D8/'Consolidated P&L'!H7 -> 0.026652026 | E9: =E8/'Consolidated P&L'!I7 -> 0.011147624 | F9: =F8/'Consolidated P&L'!J7 -> 0.011655116
A11: Median Capital expenditure /Sales percentage | C11: =MEDIAN(C9:F9) -> 0.019153571
A12: Average Capital expenditure /Sales percentage | C12: =AVERAGE(C9:F9) -> 0.023688768

Sheet Change in working capital
A1: Particular | B1: 44621 | C1: 44986 | D1: 45352 | E1: 45717 | F1: 46082
A2: Inventory | B2: ='Merge data sheet'!B41 -> 0 | C2: ='Merge data sheet'!C41 -> 3.3 | D2: ='Merge data sheet'!D41 -> 3 | E2: ='Merge data sheet'!E41 -> 2.8 | F2: ='Merge data sheet'!F41 -> 3.3
A3: Trade Receivables | B3: ='Merge data sheet'!B42 -> 2833.5 | C3: ='Merge data sheet'!C42 -> 5623.4 | D3: ='Merge data sheet'!D42 -> 5706 | E3: ='Merge data sheet'!E42 -> 5867.6 | F3: ='Merge data sheet'!F42 -> 7424.8
A4: Trade Payable | B4: ='Merge data sheet'!B22 -> 802.8 | C4: ='Merge data sheet'!C22 -> 1293.8 | D4: ='Merge data sheet'!D22 -> 1493.9 | E4: ='Merge data sheet'!E22 -> 1549.9 | F4: ='Merge data sheet'!F22 -> 2061
A5: Non Cash working Capital | B5: =B2+B3-B4 -> 2030.7 | C5: =C2+C3-C4 -> 4332.9 | D5: =D2+D3-D4 -> 4215.1 | E5: =E2+E3-E4 -> 4320.5 | F5: =F2+F3-F4 -> 5367.1
A6: Change in Working Capital | C6: =C5-B5 -> 2302.2 | D6: =D5-C5 -> -117.8 | E6: =E5-D5 -> 105.4 | F6: =F5-E5 -> 1046.6
A7: change in working Capital /percentage of sales | C7: =C6/'Merge data sheet'!B64 -> 0.14692987 | D7: =D6/'Merge data sheet'!C64 -> -0.0035500105 | E7: =E6/'Merge data sheet'!D64 -> 0.002967593 | F7: =F6/'Merge data sheet'!E64 -> 0.027536236
A9: Median Non Cash working Capital /Sales percentage | C9: =MEDIAN(C7:F7) -> 0.015251914
A10: Average Non Cash working Capital /Sales percentage | C10: =AVERAGE(C7:F7) -> 0.043470921

Sheet Peers
D3: LTIM | E3: LTIMindtree is a global technology consulting and digital solutions company that enables enterprises across industries to reimagine business models, accelerate innovation, and maximize growth by harnessing digital technologies. As a digital transformation partner to more than 700 clients, LTIMindtree brings extensive domain and technology expertise to help drive superior competitive differentiation, customer experiences, and business outcomes in a converging world. Powered by 83,000+ talented and entrepreneurial professionals across more than 40 countries, LTIMindtree - a Larsen & Toubro Group company - solves the most complex business challenges and delivers transformation at scale. LTP: ₹5,124.50 | Revenue (FY25): ₹38,008 Cr | PAT: ₹4,602 Cr | OPM: 17.08% | NPM: 12.09% | EPS: ₹155.22 | CEPS: ₹184.49 | ROCE: 28.60%
D7: TCS | E7: Tata Consultancy Services is an IT solution provider.TCS offers a consulting-led, integrated portfolio of IT and IT-enabled services delivered through its unique Global Network Delivery Model, recognized as the benchmark of excellence in software development..The company also engagged in the business of Telecom, Retail and Distribution, Banking, Financial Services and Insurance. LTP: ₹2,583.60 | Revenue (FY25): ₹2,55,324 Cr | PAT: ₹48,553 Cr | OPM: 26.40% | NPM: 19.01% | EPS: ₹134.13 | CEPS: ₹159.25 | ROCE: 69.78%
D11: Infosys | E11: Infosys Limited (Infosys), formerly Infosys Technologies Limited, provides business consulting, technology, engineering and outsourcing services. Its end-to-end business solutions include consulting and systems integration comprising consulting, enterprise solutions, systems integration and advanced technologies; business information technology (IT) services consisting application development and maintenance, independent validation services, infrastructure management, engineering services comprising product engineering and life cycle solutions and business process management; products, business platforms and solutions, including Finacle, its banking product, which offers solutions to address core banking, mobile banking and e-banking needs of retail, corporate and universal banks globally, and areas, such as cloud computing, enterprise mobility and sustainability. On January 4, 2012, Infosys BPO Limited acquired Portland Group Pty Ltd. In October 2012, it acquired Lodestone Holding AG..The company also in the business segment of Financial Services, Energy & utilities, Life Sciences and Healthcare, Consumer packaged goods and Logistics. LTP: ₹1,323.30 | Revenue (FY25): ₹1,60,879 Cr | PAT: ₹26,248 Cr | OPM: 23.70% | NPM: 16.38% | EPS: ₹63.02 | CEPS: ₹72.88 | ROCE: 39.68%
D15: HCL Tech | E15: HCL Technologies Ltd is a leading global IT services company. It has portfolio of services including software-led IT solutions, remote infrastructure management, engineering and R&D services and BPO..The company also in the business activities of IT services, Infrastructure Services, Business Process Outsourcing Services. LTP: ₹1,458.00 | Revenue (FY25): ₹1,16,647 Cr | PAT: ₹17,327 Cr | OPM: 21.78% | NPM: 14.85% | EPS: ₹63.94 | CEPS: ₹79.00 | ROCE: 33.22%
E20: Attribute | F20: LTP (₹) | G20: Change (%) | H20: Sales (₹ crore) | I20: PAT (₹ crore) | J20: Equity (₹ crore) | K20: Operating Profit Margin (OPM%) | L20: Net Profit Margin (NPM%) | M20: Earnings Per Share (EPS) | N20: Cash Earnings Per Share (CEPS)
E21: LTIM | F21: 5124.5 | H21: 38008 | I21: 4602 | J21: 29 | K21: 0.1708 | L21: 0.1209 | M21: 155.22 | N21: 184.49
E22: TCS | F22: 2583.6 | G22: -21.32 | H22: 255324 | I22: 48553 | J22: 362 | K22: 0.264 | L22: 0.1901 | M22: 134.13 | N22: 159.25
E23: INFOSYS | F23: 1323.3 | G23: -9.54 | H23: 160879 | I23: 26248 | J23: 2090 | K23: 0.237 | L23: 0.1638 | M23: 63.02 | N23: 72.88
E24: HCL TECH | F24: 1458 | H24: 116647 | I24: 17327 | J24: 542 | K24: 0.2178 | L24: 0.1485 | M24: 63.94 | N24: 79
E27: LTIM | L27: TCS
E28: Metric | F28: 44986 | G28: 45352 | H28: 45717 | L28: Metric | M28: 44986 | N28: 45352 | O28: 45717
E29: Debtor Days | F29: 46.5 | G29: 58.2 | H29: 55.6 | L29: Debtor Days | M29: 68 | N29: 78.5 | O29: 80.6
E30: Inventory Days | F30: 0 | G30: 0 | H30: 0 | L30: Inventory Days | M30: 0 | N30: 0 | O30: 0
E31: Days Payable | F31: 26.7 | G31: 47.4 | H31: 40.5 | L31: Days Payable | M31: 50.4 | N31: 58.5 | O31: 63.9
E32: Cash Conversion Cycle | F32: 19.8 | G32: 10.8 | H32: 15.1 | L32: Cash Conversion Cycle | M32: 17.6 | N32: 20 | O32: 16.7
E33: Working Capital Days | F33: 19.78 | G33: 10.77 | H33: 15.11 | L33: Working Capital Days | M33: 17.56 | N33: 20.04 | O33: 16.68
E34: ROCE % | F34: 0.366 | G34: 0.3203 | H34: 0.286 | L34: ROCE % | M34: 0.6379 | N34: 0.7043 | O34: 0.6978
E37: INFOSYS | L37: HCL TECH
E38: Metric | F38: 44986 | G38: 45352 | H38: 45717 | L38: Metric | M38: 44986 | N38: 45352 | O38: 45717
E39: Debtor Days | F39: 59.8 | G39: 66 | H39: 68.7 | L39: Debtor Days | M39: 83.1 | N39: 84.7 | O39: 80
E40: Inventory Days | F40: 0 | G40: 0 | H40: 0 | L40: Inventory Days | M40: 0 | N40: 0 | O40: 0
E41: Days Payable | F41: 86.8 | G41: 71.4 | H41: 57.8 | L41: Days Payable | M41: 20.3 | N41: 23.2 | O41: 27.4
E42: Cash Conversion Cycle | F42: -27 | G42: -5.4 | H42: 10.9 | L42: Cash Conversion Cycle | M42: 62.8 | N42: 61.5 | O42: 52.6
E43: Working Capital Days | F43: -27.05 | G43: -5.44 | H43: 10.95 | L43: Working Capital Days | M43: 62.78 | N43: 61.5 | O43: 52.56
E44: ROCE % | F44: 0.4509 | G44: 0.4137 | H44: 0.3968 | L44: ROCE % | M44: 0.2932 | N44: 0.3048 | O44: 0.3322

Sheet Stock Analysis
C22: Metric | D22: Value | F22: Financial Year | G22: Revenue (₹ Crore) | H22: Profit After Tax (PAT) (₹ Crore) | I22: Revenue Change (%) | J22: PAT Change (%) | K22: Nifty 50 Change (%) | L22: Nifty 50 Prices
C23: Market Cap | D23: 138154 | F23: FY 2024-25 | G23: 38008.1 | H23: 4602 | I23: =((G23-G24)/G24) -> 0.070138244 | J23: =(H23-H24)/H24 -> 0.0037953147 | K23: =(L23-L24)/L24 -> 0.076503494 | L23: 24334.2
C24: Current Price | D24: 4662.3 | F24: FY 2023-24 | G24: 35517 | H24: 4584.6 | I24: =((G24-G25)/G25) -> 0.070337221 | J24: =(H24-H25)/H25 -> 0.039521121 | K24: =(L24-L25)/L25 -> 0.25130639 | L24: 22604.85
C25: High / Low | D25: 4703.80/4630.10 | F25: FY 2022-23 | G25: 33183 | H25: 4410.3 | I25: =((G25-G26)/G26) -> 1.117789 | J25: =(H25-H26)/H26 -> 0.91877311 | K25: =(L25-L26)/L26 -> 0.056275234 | L25: 18065
C26: Stock P/E | D26: 29.04 | F26: FY 2021-22 | G26: 15668.7 | H26: 2298.5 | I26: =((G26-G27)/G27) -> 0.26668984 | J26: =(H26-H27)/H27 -> 0.18589413 | K26: =(L26-L27)/L27 -> 0.16891758 | L26: 17102.55
C27: Book Value | D27: 821.7 | F27: FY 2020-21 | G27: 12369.8 | H27: 1938.2 | L27: 14631.1
C28: Dividend Yield | D28: 1.4
C29: ROCE | D29: 0.2634
C30: ROE | D30: 0.2036 | F30: LTIM is a genuinely strong company - zero debt, ₹10,962 Cr cash, L&T backing, and solid revenue growth. But the stock got hammered 38% from its peak because margins are terrible vs peers (17% vs TCS's 26%), EPS didn't grow at all in FY25, and a ₹590 Cr one-time restructuring charge destroyed Q3 FY26 numbers. The market overreacted. The beaten-down price at ₹4,200-4,500 is where you should accumulate in tranches. If Q4 results come clean and margins start recovering toward 18%+ the stock can realistically re-rate to ₹5,200-5,800 in 12–18 months. The one thing you keep watching: margin expansion - that's the entire thesis.
C31: Face Value | D31: 1
F39: Accumulate & Hold. Don't panic sell. BUY in Tranches The stock is down 26% from its peak - mostly because of a one-time restructuring charge, not because the business is broken. Fundamentals are intact, balance sheet is rock solid, and Q4 results are out today. This is a beaten-down quality stock, not a failing one.

Sheet BETA
A1: Date | B1: Close (Nifty) | C1: Date | D1: Close(Ltim) | G1: Rm Nifty | H1: Rm LTIM | I1: Beta | J1: Covariance
A2: 43922 | B2: 8253.8 | C2: 43922 | D2: 1295.58
A3: 43924 | B3: 8083.8 | C3: 43924 | D3: 1260.13 | G3: =(B3-B2)/B2 -> -0.020596574 | H3: =(D3-D2)/D2 -> -0.027362262 | I3: =SLOPE(H3:H1482,G3:G1482) -> 0.83831404 | J3: =_xlfn.COVARIANCE.S(H3:H1482,G3:G1482)/_xlfn.VAR.S(G3:G1482) -> 0.83831404
A4: 43928 | B4: 8792.2 | C4: 43928 | D4: 1272.22 | G4: =(B4-B3)/B3 -> 0.087632054 | H4: =(D4-D3)/D3 -> 0.0095942482
A5: 43929 | B5: 8748.75 | C5: 43929 | D5: 1261.38 | G5: =(B5-B4)/B4 -> -0.0049418803 | H5: =(D5-D4)/D4 -> -0.0085205389
A6: 43930 | B6: 9111.9 | C6: 43930 | D6: 1301.54 | G6: =(B6-B5)/B5 -> 0.041508787 | H6: =(D6-D5)/D5 -> 0.031838146
A7: 43934 | B7: 8993.85 | C7: 43934 | D7: 1302.09 | G7: =(B7-B6)/B6 -> -0.012955586 | H7: =(D7-D6)/D6 -> 0.00042257633
A8: 43936 | B8: 8925.3 | C8: 43936 | D8: 1368.4 | G8: =(B8-B7)/B7 -> -0.0076218749 | H8: =(D8-D7)/D7 -> 0.050925819
A9: 43937 | B9: 8992.8 | C9: 43937 | D9: 1365.93 | G9: =(B9-B8)/B8 -> 0.007562771 | H9: =(D9-D8)/D8 -> -0.0018050278
A10: 43938 | B10: 9266.75 | C10: 43938 | D10: 1344.39 | G10: =(B10-B9)/B9 -> 0.030463259 | H10: =(D10-D9)/D9 -> -0.015769476
A11: 43941 | B11: 9261.85 | C11: 43941 | D11: 1388.5 | G11: =(B11-B10)/B10 -> -0.00052877222 | H11: =(D11-D10)/D10 -> 0.03281042
A12: 43942 | B12: 8981.45 | C12: 43942 | D12: 1349.23 | G12: =(B12-B11)/B11 -> -0.030274729 | H12: =(D12-D11)/D11 -> -0.028282319
A13: 43943 | B13: 9187.3 | C13: 43943 | D13: 1319.96 | G13: =(B13-B12)/B12 -> 0.022919462 | H13: =(D13-D12)/D12 -> -0.021693855
A14: 43944 | B14: 9313.9 | C14: 43944 | D14: 1357.84 | G14: =(B14-B13)/B13 -> 0.013779892 | H14: =(D14-D13)/D13 -> 0.028697839
A15: 43945 | B15: 9154.4 | C15: 43945 | D15: 1334.25 | G15: =(B15-B14)/B14 -> -0.017124942 | H15: =(D15-D14)/D14 -> -0.017373181
A16: 43948 | B16: 9282.3 | C16: 43948 | D16: 1349.93 | G16: =(B16-B15)/B15 -> 0.013971424 | H16: =(D16-D15)/D15 -> 0.011751921 | L16: SUMMARY OUTPUT
A17: 43949 | B17: 9380.9 | C17: 43949 | D17: 1364.07 | G17: =(B17-B16)/B16 -> 0.010622367 | H17: =(D17-D16)/D16 -> 0.010474617
A18: 43950 | B18: 9553.35 | C18: 43950 | D18: 1363.33 | G18: =(B18-B17)/B17 -> 0.018383098 | H18: =(D18-D17)/D17 -> -0.00054249415 | L18: Regression Statistics
A19: 43951 | B19: 9859.9 | C19: 43951 | D19: 1482.35 | G19: =(B19-B18)/B18 -> 0.03208822 | H19: =(D19-D18)/D18 -> 0.087300947 | L19: Multiple R | M19: 0.39971074
A20: 43955 | B20: 9293.5 | C20: 43955 | D20: 1438.05 | G20: =(B20-B19)/B19 -> -0.057444802 | H20: =(D20-D19)/D19 -> -0.02988498 | L20: R Square | M20: 0.15976867
A21: 43956 | B21: 9205.6 | C21: 43956 | D21: 1428.79 | G21: =(B21-B20)/B20 -> -0.0094582235 | H21: =(D21-D20)/D20 -> -0.0064392754 | L21: Adjusted R Square | M21: 0.15920018
A22: 43957 | B22: 9270.9 | C22: 43957 | D22: 1429.44 | G22: =(B22-B21)/B21 -> 0.0070935083 | H22: =(D22-D21)/D21 -> 0.0004549304 | L22: Standard Error | M22: 0.018849085
A23: 43958 | B23: 9199.05 | C23: 43958 | D23: 1482.62 | G23: =(B23-B22)/B22 -> -0.0077500566 | H23: =(D23-D22)/D22 -> 0.03720338 | L23: Observations | M23: 1480
A24: 43959 | B24: 9251.5 | C24: 43959 | D24: 1474.62 | G24: =(B24-B23)/B23 -> 0.0057016757 | H24: =(D24-D23)/D23 -> -0.0053958533
A25: 43962 | B25: 9239.2 | C25: 43962 | D25: 1502.12 | G25: =(B25-B24)/B24 -> -0.0013295141 | H25: =(D25-D24)/D24 -> 0.018648872 | L25: ANOVA
A26: 43963 | B26: 9196.55 | C26: 43963 | D26: 1533.9 | G26: =(B26-B25)/B25 -> -0.0046162005 | H26: =(D26-D25)/D25 -> 0.021156765 | M26: df | N26: SS | O26: MS | P26: F | Q26: Significance F
A27: 43964 | B27: 9383.55 | C27: 43964 | D27: 1541.44 | G27: =(B27-B26)/B26 -> 0.020333712 | H27: =(D27-D26)/D26 -> 0.0049155747 | L27: Regression | M27: 1 | N27: 0.099849927 | O27: 0.099849927 | P27: 281.03939 | Q27: 6.9906567e-58
A28: 43965 | B28: 9142.75 | C28: 43965 | D28: 1533.81 | G28: =(B28-B27)/B27 -> -0.02566193 | H28: =(D28-D27)/D27 -> -0.004949917 | L28: Residual | M28: 1478 | N28: 0.52511568 | O28: 0.00035528801
A29: 43966 | B29: 9136.85 | C29: 43966 | D29: 1531.53 | G29: =(B29-B28)/B28 -> -0.00064532006 | H29: =(D29-D28)/D28 -> -0.0014864944 | L29: Total | M29: 1479 | N29: 0.62496561
A30: 43969 | B30: 8823.25 | C30: 43969 | D30: 1531.39 | G30: =(B30-B29)/B29 -> -0.034322551 | H30: =(D30-D29)/D29 -> -9.1411856e-05
A31: 43970 | B31: 8879.1 | C31: 43970 | D31: 1554.19 | G31: =(B31-B30)/B30 -> 0.0063298671 | H31: =(D31-D30)/D30 -> 0.014888435 | M31: Coefficients | N31: Standard Error | O31: t Stat | P31: P-value | Q31: Lower 95% | R31: Upper 95% | S31: Lower 95.0% | T31: Upper 95.0%
A32: 43971 | B32: 9066.55 | C32: 43971 | D32: 1660.13 | G32: =(B32-B31)/B31 -> 0.021111374 | H32: =(D32-D31)/D31 -> 0.068164124 | L32: Intercept | M32: 0.00037025714 | N32: 0.00049128236 | O32: 0.75365444 | P32: 0.45117678 | Q32: -0.00059342777 | R32: 0.001333942 | S32: -0.00059342777 | T32: 0.001333942
A33: 43972 | B33: 9106.25 | C33: 43972 | D33: 1660.97 | G33: =(B33-B32)/B32 -> 0.0043787328 | H33: =(D33-D32)/D32 -> 0.00050598447 | L33: X Variable 1 | M33: 0.83831404 | N33: 0.050006118 | O33: 16.76423 | P33: 6.9906567e-58 | Q33: 0.74022352 | R33: 0.93640456 | S33: 0.74022352 | T33: 0.93640456
A34: 43973 | B34: 9039.25 | C34: 43973 | D34: 1662.6 | G34: =(B34-B33)/B33 -> -0.0073575841 | H34: =(D34-D33)/D33 -> 0.00098135427
A35: 43977 | B35: 9029.05 | C35: 43977 | D35: 1663.15 | G35: =(B35-B34)/B34 -> -0.0011284122 | H35: =(D35-D34)/D34 -> 0.00033080717
A36: 43978 | B36: 9314.95 | C36: 43978 | D36: 1669.62 | G36: =(B36-B35)/B35 -> 0.031664461 | H36: =(D36-D35)/D35 -> 0.0038902083
A37: 43979 | B37: 9490.1 | C37: 43979 | D37: 1668.88 | G37: =(B37-B36)/B36 -> 0.018803107 | H37: =(D37-D36)/D36 -> -0.00044321462
A38: 43980 | B38: 9580.3 | C38: 43980 | D38: 1673.95 | G38: =(B38-B37)/B37 -> 0.0095046417 | H38: =(D38-D37)/D37 -> 0.0030379656
A39: 43983 | B39: 9826.15 | C39: 43983 | D39: 1714.99 | G39: =(B39-B38)/B38 -> 0.025662036 | H39: =(D39-D38)/D38 -> 0.024516861
A40: 43984 | B40: 9979.1 | C40: 43984 | D40: 1729.5 | G40: =(B40-B39)/B39 -> 0.015565608 | H40: =(D40-D39)/D39 -> 0.0084606907
...

Sheet Ratio Analysis
A1: Ratio Analysis- LTIM
