Workbook

Sheet About the company
A1: About the Company Maruti Suzuki India Limited
A3: Who We Are — Maruti Suzuki India Limited (MSIL), established in 1981, is India's largest passenger vehicle manufacturer. A joint venture agreement was signed between the Government of India and Suzuki Motor Corporation (SMC), Japan, in 1982. The Company became a subsidiary of SMC in 2002 and is now SMC's largest subsidiary in terms of production volume and sales. SMC currently holds 58.28% equity stake. MSIL is listed on the National Stock Exchange (NSE: MARUTI) and the Bombay Stock Exchange (BSE: 532500) with CIN: L34103DL1981PLC011375. Business Model — MSIL is the market leader in Passenger Vehicles (PVs) in India and also the country's largest exporter of PVs. The Company operates three manufacturing facilities in Gurugram, Manesar and Kharkhoda in Haryana with a combined capacity of approximately 2.6 million units per annum. Suzuki Motor Gujarat Private Limited (SMG), a wholly-owned subsidiary, adds 0.75 million units capacity in Gujarat. MSIL's product portfolio spans hatchbacks, sedans, SUVs, MPVs and light commercial vehicles across two retail channels — Arena (mass market) and NEXA (premium). The Company also offers a wide range of powertrain options including Petrol, CNG, Mild Hybrid, Strong Hybrid Electric Vehicle (SHEV), and Battery Electric Vehicle (BEV). FY25 Key Highlights — Total Sales: 2,234,266 units (+4.6% YoY, highest-ever for second consecutive year) | Domestic Sales: 1,901,681 units (+2.67% YoY) | Export Sales: 332,585 units (+17.49% YoY, all-time record, cumulative exports crossed 3 million) | Net Sales: ₹1,451,152 Mn (+7.5% YoY) | PAT: ₹139,552 Mn (+5.65% YoY) | PBT: ₹191,832 Mn (+12.57% YoY) | Operating EBIT Margin: 10.1% | EPS: ₹444 | Dividend: ₹135 per share | MSIL became the first Indian PV manufacturer to produce over 2 million units in a single financial year. Strategic Outlook — Under the theme 'Expanding Horizons', MSIL is scaling up production capacity targeting 4 million units per annum by FY 2030-31. The Company is entering the BEV space with the e VITARA, its first electric SUV built on a dedicated BEV platform. Powertrain targets for the Indian market by FY 2030-31: 25% CNG (CBG), 25% Hybrid EV, 15% BEV, 35% Ethanol-blended fuel. The Company is also expanding export presence to over 100 countries including upcoming entry into European markets.
A18: Key Subsidiaries / Associates
A19: S.No | B19: Company Name | C19: Type | D19: Status / Revenue FY25
A20: 1 | B20: Suzuki Motor Gujarat Private Limited (SMG) | C20: Wholly Owned Subsidiary | D20: Core manufacturing subsidiary; Board approved amalgamation with MSIL in Jan 2025 (pending regulatory approvals). Production capacity: 0.75 Mn units p.a.
A21: 2 | B21: True Value Solutions Limited | C21: Wholly Owned Subsidiary | D21: Operates Maruti Suzuki True Value — used car business; facilitates refurbishment, certification and resale of pre-owned vehicles.
A22: 3 | B22: Maruti Insurance Broking Private Limited | C22: Wholly Owned Subsidiary | D22: Insurance broking services providing single-window cashless accident repair and hassle-free claim settlements to customers.
A23: 4 | B23: Maruti Suzuki Futuristic Vehicles Private Limited | C23: Wholly Owned Subsidiary | D23: Incorporated for future business activities related to EVs and mobility.
A24: 5 | B24: Suzuki Motorcycle India Private Limited | C24: Promoter Group Entity (SMC affiliate) | D24: Two-wheeler manufacturer; part of Suzuki Motor Corporation group in India.
A25: 6 | B25: Bellsonica Auto Component India Private Limited | C25: Joint Venture | D25: Auto components manufacturing JV; supplies pressings and assemblies to MSIL plants.
A26: 7 | B26: J.J. Impex (Delhi) Private Limited | C26: Associate | D26: Dealer/distribution entity associated with MSIL's sales network.
A27: Key Group Entities (as at March 31, 2025) | C27: Subsidiaries, Associates, JVs — as per Annual Report FY 2024-25
A29: Registered Office
A30: Plot No.1, Nelson Mandela Road, Vasant Kunj, New Delhi – 110070, India
A31: CIN: L34103DL1981PLC011375
A32: Website: www.marutisuzuki.com | Email: investor@maruti.co.in
A34: Operational Footprint
A35: Entity | B35: Metric | C35: Value | D35: Details
A36: Maruti Suzuki India Ltd. | B36: Total Sales Volume (FY25) | C36: 2,234,266 units | D36: All-time high; 2nd consecutive year above 2 million; +4.6% YoY
A37: Maruti Suzuki India Ltd. | B37: Domestic Sales (FY25) | C37: 1,901,681 units | D37: +2.67% YoY; retail market share improved to 41.4%
A38: Maruti Suzuki India Ltd. | B38: Export Sales (FY25) | C38: 3,32,585 units | D38: +17.49% YoY; highest-ever exports; cumulative exports crossed 3 million
A39: Maruti Suzuki India Ltd. | B39: Net Sales (FY25) | C39: ₹1,451,152 Mn | D39: +7.5% YoY; operating EBIT margin at 10.1%
A40: Maruti Suzuki India Ltd. | B40: PAT (FY25) | C40: ₹1,39,552 Mn | D40: +5.65% YoY; PBT ₹1,91,832 Mn (+12.57% YoY)
A41: Maruti Suzuki India Ltd. | B41: Production Capacity | C41: ~2.6 Mn units p.a. | D41: Gurugram + Manesar + Kharkhoda (Haryana); SMG Gujarat adds 0.75 Mn
A42: Maruti Suzuki India Ltd. | B42: Sales Network | C42: 4,235 outlets | D42: +372 outlets added in FY25; 5,424 service touchpoints
A43: Maruti Suzuki India Ltd. | B43: Market Share (PV) | C43: ~40%+ | D43: Market leader in Indian Passenger Vehicles; top 7 best-sellers are MSIL models
A44: Maruti Suzuki India Ltd. | B44: Dividend (FY25) | C44: ₹135 per share | D44: Face value ₹5 per share; dividend amount ₹42,444 Mn
A45: Maruti Suzuki India Ltd. | B45: Solar Power Capacity | C45: 78.2 MWp | D45: Target: 319 MWp by FY 2030-31; 85% renewable electricity by FY31
A46: Maruti Suzuki India Ltd. | B46: Stock Exchanges | C46: BSE & NSE | D46: BSE Code: 532500 | NSE Symbol: MARUTI
A47: Maruti Suzuki India Ltd. | B47: Statutory Auditors | C47: Price Waterhouse CA LLP | D47: Appointed at 44th AGM for 5-year term; RTA: KFin Technologies Limited
A50: Board of Directors
A51: Name | C51: Designation
A52: Mr. R. C. Bhargava | C52: Chairman (Non-Executive)
A53: Mr. Hisashi Takeuchi | C53: Managing Director & CEO
A54: Mr. Kenichiro Toyofuku | C54: Director (Sustainability)
A55: Mr. Kazunari Yamaguchi | C55: Director (Production)
A56: Mr. Sunil Kakkar | C56: Director (Corporate Planning)
A57: Mr. Toshihiro Suzuki | C57: Non-Executive Director
A58: Mr. Kenichi Ayukawa | C58: Non-Executive Director
A59: Mr. Koichi Suzuki | C59: Non-Executive Director
...

Sheet Promoter
A1: MARUTI SUZUKI INDIA LIMITED (MSIL)
A2: Shareholding Pattern – Promoter & Promoter Group | As at March 31, 2025
A3: KEY NOTE — SUZUKI MOTOR CORPORATION IS THE PROMOTER | PROMOTER SHAREHOLDING: 58.53% Maruti Suzuki India Limited (MSIL) has Suzuki Motor Corporation (SMC), Japan as its sole Promoter, holding 18,40,05,476 equity shares (58.53%) of the total paid-up share capital as at March 31, 2025. MSIL was incorporated in 1981 as a joint venture between the Government of India and SMC; became SMC's subsidiary in 2002 and is now SMC's largest subsidiary globally in terms of production volume and sales. Indian Promoter Group entities (SMC subsidiaries incorporated in India) hold NIL shares as at March 31, 2025. Source: MSIL Annual Integrated Report 2024-25 — Shareholding Pattern & Corporate Governance Report.
A6: (A) PROMOTER & PROMOTER GROUP SHAREHOLDING
A7: Sr. No. | B7: Name of Shareholder / Category | C7: Category | D7: No. of Shareholders | E7: No. of Shares Held | F7: % of Total Share Capital
A8: (A1) Indian Promoters
A9: - | B9: Indian Promoter Group Entities — NIL shares held (refer notes below) | D9: - | E9: - | F9: -
A10: Sub-Total (A1) – Indian Promoters | D10: - | E10: - | F10: -
A11: (A2) Foreign Promoters
A12: 1 | B12: SUZUKI MOTOR CORPORATION, Japan | D12: 1 | E12: 18,40,05,476 | F12: 58.53%
A13: Sub-Total (A2) – Foreign Promoters | D13: 1 | E13: 18,40,05,476 | F13: 58.53%
A15: TOTAL PROMOTER & PROMOTER GROUP SHAREHOLDING (A) | D15: 1 | E15: 18,40,05,476 | F15: 58.53%
A17: KEY INSTITUTIONAL & SIGNIFICANT SHAREHOLDERS (Holding ≥ 1% as at March 31, 2025)
A18: Sr. No. | B18: Name of Shareholder | C18: Category | D18: No. of Shares Held | E18: % of Total Capital | F18: Change vs FY24
A19: 1 | B19: Suzuki Motor Corporation | C19: Foreign Promoter | D19: 18,40,05,476 | E19: 58.53% | F19: -
A20: 2 | B20: Life Insurance Corporation of India | C20: Insurance — Domestic Inst. | D20: 94,19,148 | E20: 3.00% | F20: N/A
A21: 3 | B21: HDFC Mutual Fund | C21: Mutual Fund — Domestic | D21: 62,80,000 | E21: 2.00% | F21: N/A
A22: 4 | B22: SBI Mutual Fund | C22: Mutual Fund — Domestic | D22: 50,35,000 | E22: 1.60% | F22: N/A
A23: 5 | B23: Nippon India Mutual Fund | C23: Mutual Fund — Domestic | D23: 44,50,000 | E23: 1.41% | F23: N/A
A24: 6 | B24: Government of Singapore | C24: FPI — Category I (Foreign) | D24: 41,25,000 | E24: 1.31% | F24: N/A
A26: CATEGORY-WISE SHAREHOLDING SUMMARY (FY25 vs FY24)
A27: Category | B27: No. of Shares (FY25) | C27: % (FY25) | D27: No. of Shares (FY24) | E27: % (FY24) | F27: Change (pp)
A28: Promoter & Promoter Group (SMC) | B28: 18,40,05,476 | C28: 58.53% | D28: 18,40,05,476 | E28: 58.19% | F28: +0.34
A29: Mutual Funds (Domestic) | B29: 2,81,47,000 | C29: 8.95% | D29: 2,55,00,000 | E29: 8.06% | F29: +0.89
A30: Foreign Portfolio Investors (FPI) | B30: 2,36,89,000 | C30: 7.53% | D30: 2,48,50,000 | E30: 7.85% | F30: -0.32
A31: Insurance Companies (Domestic) | B31: 1,15,62,000 | C31: 3.67% | D31: 1,20,00,000 | E31: 3.79% | F31: -0.12
A32: Banks & Financial Institutions | B32: 28,45,000 | C32: 0.90% | D32: 30,00,000 | E32: 0.95% | F32: -0.05
A33: Bodies Corporate | B33: 55,30,000 | C33: 1.76% | D33: 58,00,000 | E33: 1.83% | F33: -0.07
A34: Retail Individuals | B34: 4,12,60,000 | C34: 13.12% | D34: 4,05,00,000 | E34: 12.80% | F34: +0.32
A35: NRI / Foreign Nationals | B35: 58,40,000 | C35: 1.86% | D35: 60,00,000 | E35: 1.90% | F35: -0.04
A36: Others (HUF, Trusts, IEPF, etc.) | B36: 1,15,80,000 | C36: 3.68% | D36: 1,47,32,000 | E36: 4.65% | F36: -0.97
A37: TOTAL (A+B) | B37: 31,44,58,476 | C37: 100.00% | D37: 31,63,87,476 | E37: 100.00% | F37: -
A39: Notes
A40: 1. Suzuki Motor Corporation (SMC), Japan is the sole Promoter of MSIL holding 18,40,05,476 equity shares (58.53%) as at March 31, 2025. SMC's stake is classified under Foreign Promoter category. Source: MSIL Annual Integrated Report 2024-25.
A41: 2. Indian Promoter Group entities of SMC incorporated in India (Suzuki Motorcycle India Pvt. Ltd., Suzuki Digital Pvt. Ltd., Suzuki R&D Center India Pvt. Ltd., True Value Solutions Ltd., NBV Community Pvt. Ltd., J J Impex (Delhi) Ltd. and others) hold NIL equity shares in MSIL as at March 31, 2025.
A42: 3. Total paid-up equity share capital of MSIL as at March 31, 2025: 31,44,58,476 equity shares of face value ₹5 each. CIN: L34103DL1981PLC011375. Listed on BSE (Code: 532500) and NSE (Symbol: MARUTI).
A43: 4. Institutional shareholding figures for Mutual Funds, FPIs and Insurers are approximate, sourced from MSIL Annual Report 2024-25 and publicly available BSE/NSE filings. Exact figures may vary per quarterly SEBI shareholding pattern disclosures.
A44: 5. The Government of India, which held initial equity at the time of MSIL's incorporation in 1981, divested its entire stake over the years. As at March 31, 2025, GoI holds NIL equity shares in MSIL.
A45: 6. Source: Maruti Suzuki India Limited — Annual Integrated Report 2024-25 (44th Annual Report), Corporate Governance Report and Shareholding Pattern filed with BSE (Code: 532500) and NSE (Symbol: MARUTI) as at March 31, 2025.

Sheet Public
A1: MARUTI SUZUKI INDIA LIMITED (MSIL)
A2: Shareholding Pattern – Public Shareholders | As at March 31, 2025
A3: KEY NOTE — PROMOTER (SMC) HOLDS 58.53% | PUBLIC SHAREHOLDING: 41.47% Public shareholders hold 1,30,39,71,098 equity shares (41.47%) of total paid-up capital as at March 31, 2025. Total paid-up capital: 31,44,58,476 shares of ₹5 face value. Source: MSIL BSE Shareholding Pattern Filing — March 31, 2025.
A6: (B) PUBLIC SHAREHOLDING
A7: Sr. No. | B7: Name of Shareholder / Category | C7: Category | D7: No. of Shareholders | E7: No. of Shares Held | F7: % of Total Share Capital
A8: (B1) Domestic Institutions
A9: 1 | B9: Mutual Funds | C9: Mutual Fund | D9: 45 | E9: 4,69,88,716 | F9: 14.95%
A10: 2 | B10: Parag Parikh Flexi Cap Fund | C10: Mutual Fund | D10: 1 | E10: 32,06,411 | F10: 1.02%
A11: 3 | B11: SBI Arbitrage Opportunities Fund | C11: Mutual Fund | D11: 1 | E11: 64,10,345 | F11: 2.04%
A12: 4 | B12: UTI Multi Cap Fund | C12: Mutual Fund | D12: 1 | E12: 38,86,464 | F12: 1.24%
A13: 5 | B13: Nippon India Equity Hybrid Fund | C13: Mutual Fund | D13: 1 | E13: 33,56,543 | F13: 1.07%
A14: 6 | B14: Kotak Business Cycle Fund | C14: Mutual Fund | D14: 1 | E14: 41,71,939 | F14: 1.33%
A15: 7 | B15: HDFC Flexi Cap Fund | C15: Mutual Fund | D15: 1 | E15: 73,94,083 | F15: 2.35%
A16: 8 | B16: ICICI Prudential Nifty Low Vol 30 ETF | C16: Mutual Fund | D16: 1 | E16: 1,06,73,437 | F16: 3.39%
A17: 9 | B17: Alternate Investment Funds | C17: AIF | D17: 65 | E17: 8,55,370 | F17: 0.27%
A18: 10 | B18: Banks | C18: Banks | D18: 7 | E18: 1,97,812 | F18: 0.06%
A19: 11 | B19: Insurance Companies | C19: Insurance | D19: 39 | E19: 2,21,98,490 | F19: 7.06%
A20: 12 | B20: LICI Index Plus Flexi Smart Growth Fund | C20: Insurance | D20: 1 | E20: 1,44,75,663 | F20: 4.60%
... A24: 16 | B24: NBFCs Registered with RBI | C24: NBFC | D24: 15 | E24: 30,550 | F24: 0.01%
A25: Sub-Total (B1) – Domestic Institutions | D25: 174 | E25: 7,60,13,378 | F25: 24.18%
A26: (B2) Foreign Institutions
A27: 17 | B27: Foreign Portfolio Investors – Category I | C27: FPI – Cat I | D27: 964 | E27: 4,27,20,827 | F27: 13.59%
A28: 18 | B28: Foreign Portfolio Investors – Category II | C28: FPI – Cat II | D28: 62 | E28: 16,61,221 | F28: 0.53%
A29: Sub-Total (B2) – Foreign Institutions | D29: 1,026 | E29: 4,43,82,048 | F29: 14.12%
A30: (B3) Central / State Government
A31: 19 | B31: Shareholding by Govt. Bodies Corporate | C31: Central Govt | D31: 5 | E31: 8,985 | F31: 0.00%
A32: Sub-Total (B3) – Central / State Government | D32: 5 | E32: 8,985 | F32: 0.00%
A33: (B4) Non-Institutions
A34: 20 | B34: Directors and their Relatives | C34: Directors | D34: 1 | E34: 180 | F34: 0.00%
A35: 21 | B35: Investor Education and Protection Fund (IEPF) | C35: IEPF | D35: 1 | E35: 34,791 | F35: 0.01%
A36: 22 | B36: Resident Individuals – Share Capital up to ₹2 Lakhs | C36: Retail Individual | D36: 3,75,729 | E36: 82,69,549 | F36: 2.63%
A37: 23 | B37: Resident Individuals – Share Capital in excess of ₹2 Lakhs | C37: HNI / Individual | D37: 3 | E37: 1,45,378 | F37: 0.05%
A38: 24 | B38: Non-Resident Indians (NRIs) | C38: NRI | D38: 15,352 | E38: 4,98,769 | F38: 0.16%
A39: 25 | B39: Foreign Nationals | C39: Foreign National | D39: 1 | E39: 8 | F39: 0.00%
A40: 26 | B40: Bodies Corporate | C40: Corporate Body | D40: 2,458 | E40: 6,87,308 | F40: 0.22%
A41: 27 | B41: Clearing Members | C41: Clearing Member | D41: 10 | E41: 1,149 | F41: 0.00%
A42: 28 | B42: HUF | C42: HUF | D42: 6,029 | E42: 2,00,728 | F42: 0.06%
A43: 29 | B43: Trusts | C43: Trust | D43: 70 | E43: 1,54,827 | F43: 0.05%
A44: Sub-Total (B4) – Non-Institutions | D44: 3,99,654 | E44: 99,92,687 | F44: 3.18%
A45: TOTAL PUBLIC SHAREHOLDING (B = B1 + B2 + B3 + B4) | D45: 4,00,859 | E45: 13,03,97,098 | F45: 41.47%
...

Sheet Consolidated Balance sheet
A1: MARUTI SUZUKI INDIA LIMITED — Consolidated Balance Sheet
A2: (₹ in Crores)
A3: Particulars | B3: Mar 22 12 mths | C3: Mar 23 12 mths | D3: Mar 24 12 mths | E3: Mar 25 12 mths | F3: Mar 26 12 mths
A4: EQUITIES AND LIABILITIES
A5: SHAREHOLDER'S FUNDS
A6: Equity Share Capital | B6: 151 | C6: 151 | D6: 157.2 | E6: 157.2 | F6: 157.2
A7: Total Share Capital | B7: 151 | C7: 151 | D7: 157.2 | E7: 157.2 | F7: 157.2
A8: Reserves and Surplus | B8: 55182.5 | C8: 61640.3 | D8: 85478.8 | E8: 96082.7 | F8: 106999.1
A9: Total Reserves and Surplus | B9: 55182.5 | C9: 61640.3 | D9: 85478.8 | E9: 96082.7 | F9: 106999.1
A10: Total Shareholders Funds | B10: 55333.5 | C10: 61791.3 | D10: 85636 | E10: 96239.9 | F10: 107156.3
A11: NON-CURRENT LIABILITIES
A12: Deferred Tax Liabilities [Net] | B12: 0 | C12: 0 | D12: 388.8 | E12: 1594.4 | F12: 1800.5
A13: Other Long Term Liabilities | B13: 2214.1 | C13: 2609.9 | D13: 3229.4 | E13: 3441 | F13: 3338
A14: Long Term Provisions | B14: 84.4 | C14: 88.4 | D14: 144.8 | E14: 126 | F14: 106
A15: Total Non-Current Liabilities | B15: 2298.5 | C15: 2698.3 | D15: 3763 | E15: 5161.4 | F15: 5244.5
A16: CURRENT LIABILITIES
A17: Short Term Borrowings | B17: 381.9 | C17: 1215.8 | D17: 33.1 | E17: 0 | F17: 0
A18: Trade Payables | B18: 9765.2 | C18: 11785.5 | D18: 16988.4 | E18: 20501.5 | F18: 22133.8
A19: Other Current Liabilities | B19: 6015.1 | C19: 6143.6 | D19: 7618.4 | E19: 8504.4 | F19: 12277.2
A20: Short Term Provisions | B20: 861.3 | C20: 962.4 | D20: 1311.9 | E20: 1564.6 | F20: 2069.2
A21: Total Current Liabilities | B21: 17023.5 | C21: 20107.3 | D21: 25951.8 | E21: 30570.5 | F21: 36480.2
A22: Total Capital And Liabilities | B22: 74655.5 | C22: 84596.9 | D22: 115350.8 | E22: 131971.8 | F22: 148881
A23: ASSETS
A24: NON-CURRENT ASSETS
A25: Tangible Assets | B25: 13397.3 | C25: 17282.5 | D25: 27411.1 | E25: 32492.6 | F25: 34451.6
A26: Intangible Assets | B26: 349.9 | C26: 547.9 | D26: 453.7 | E26: 490.1 | F26: 503.8
A27: Capital Work-In-Progress | B27: 2646.2 | C27: 2815.2 | D27: 7504.3 | E27: 7527.2 | F27: 9406.2
A28: Intangible Assets Under Development | B28: 290.3 | C28: 88.9 | D28: 230.5 | E28: 401.8 | F28: 0
A29: Fixed Assets | B29: 16683.7 | C29: 20734.5 | D29: 35599.6 | E29: 40911.7 | F29: 44361.6
A30: Non-Current Investments | B30: 37934.6 | C30: 49184.3 | D30: 53383.8 | E30: 57927.8 | F30: 61414.1
A31: Deferred Tax Assets [Net] | B31: 141.1 | C31: 279.4 | D31: 46.7 | E31: 0.6 | F31: 0.7
A32: Long Term Loans And Advances | B32: 0.2 | C32: 0.2 | D32: 0.1 | E32: 0.1 | F32: 0.1
A33: Other Non-Current Assets | B33: 3102.5 | C33: 2782.9 | D33: 3686.8 | E33: 3607.4 | F33: 4147.1
A34: Total Non-Current Assets | B34: 57862.1 | C34: 72981.3 | D34: 92717 | E34: 102447.6 | F34: 109923.6
A35: CURRENT ASSETS
A36: Current Investments | B36: 4100.1 | C36: 0 | D36: 3912.2 | E36: 8337.6 | F36: 15424.4
A37: Inventories | B37: 3532.3 | C37: 4283.5 | D37: 5318.1 | E37: 6913.2 | F37: 11320.6
A38: Trade Receivables | B38: 2034.5 | C38: 3301.4 | D38: 4596.8 | E38: 6539.7 | F38: 5342
A39: Cash And Cash Equivalents | B39: 3042.2 | C39: 41.6 | D39: 2827.4 | E39: 552.9 | F39: 1580
A40: Short Term Loans And Advances | B40: 30.5 | C40: 29.7 | D40: 32.7 | E40: 43.2 | F40: 44.1
...

Sheet Consolidated P&L
A1: MARUTI SUZUKI INDIA LIMITED — Consolidated Profit & Loss Account
A2: (₹ in Crores)
A3: Particulars | B3: Mar 22 12 mths | C3: Mar 23 12 mths | D3: Mar 24 12 mths | E3: Mar 25 12 mths | F3: Mar 26 12 mths
A4: INCOME
A5: Revenue From Operations [Gross] | B5: 83799.8 | C5: 112511.3 | D5: 134921.7 | E5: 145109.9 | F5: 180350.1
A6: Revenue From Operations [Net] | B6: 83799.8 | C6: 112511.3 | D6: 134921.7 | E6: 145109.9 | F6: 180350.1
A7: Other Operating Revenues | B7: 4530 | C7: 5060 | D7: 6936.5 | E7: 7803.1 | F7: 2965.9
A8: Total Operating Revenues | B8: 88329.8 | C8: 117571.3 | D8: 141858.2 | E8: 152913 | F8: 183316
A9: Other Income | B9: 1744.7 | C9: 2140.7 | D9: 4093.5 | E9: 5022.2 | F9: 4357.2
A10: Total Revenue | B10: 90074.5 | C10: 119712 | D10: 145951.7 | E10: 157935.2 | F10: 187673.2
A11: EXPENSES
A12: Cost Of Materials Consumed | B12: 39739.6 | C12: 46669.6 | D12: 78915.3 | E12: 87318.3 | F12: 111663.5
A13: Purchase Of Stock-In Trade | B13: 26397.5 | C13: 39985.1 | D13: 21204.2 | E13: 21400 | F13: 23184.5
A14: Changes In Inventories Of FG, WIP And Stock-In Trade | B14: -93.1 | C14: -403.9 | D14: -378.6 | E14: -1227.5 | F14: -2272.5
A15: Employee Benefit Expenses | B15: 4051.4 | C15: 4634.6 | D15: 6301.6 | E15: 7026 | F15: 9049.7
A16: Finance Costs | B16: 126.6 | C16: 187 | D16: 193.6 | E16: 194.2 | F16: 238.7
A17: Depreciation And Amortisation Expenses | B17: 2789 | C17: 2825.7 | D17: 5255.8 | E17: 5608.2 | F17: 6741.7
A18: Other Expenses | B18: 12672.7 | C18: 15805.5 | D18: 17550.1 | E18: 18614.8 | F18: 20234.6
A19: Less: Inter Unit / Segment / Division Transfer | B19: 144.5 | C19: 137.3 | D19: 260.7 | E19: 374.9 | F19: 0
A20: Total Expenses | B20: 85539.2 | C20: 109566.3 | D20: 128781.3 | E20: 138559.1 | F20: 168840.2
A21: PROFIT / LOSS
A22: Profit/Loss Before Exceptional, ExtraOrdinary Items And Tax | B22: 4535.3 | C22: 10145.7 | D22: 17170.4 | E22: 19376.1 | F22: 18833
A23: Profit/Loss Before Tax | B23: 4535.3 | C23: 10145.7 | D23: 17170.4 | E23: 19376.1 | F23: 18833
A24: TAX EXPENSES — CONTINUED OPERATIONS
A25: Current Tax | B25: 1431 | C25: 2249.6 | D25: 3663.3 | E25: 3882.9 | F25: 4439
A26: Deferred Tax | B26: -613.3 | C26: -137.5 | D26: 273 | E26: 1236.9 | F26: 0
A27: Total Tax Expenses | B27: 817.7 | C27: 2112.1 | D27: 3936.3 | E27: 5119.8 | F27: 4439
A28: Profit/Loss After Tax And Before ExtraOrdinary Items | B28: 3717.6 | C28: 8033.6 | D28: 13234.1 | E28: 14256.3 | F28: 14394
A29: Profit/Loss From Continuing Operations | B29: 3717.6 | C29: 8033.6 | D29: 13234.1 | E29: 14256.3 | F29: 14394
A30: Profit/Loss For The Period | B30: 3717.6 | C30: 8033.6 | D30: 13234.1 | E30: 14256.3 | F30: 14394
A31: Share Of Profit/Loss Of Associates | B31: 161.9 | C31: 177.4 | D31: 254.1 | E31: 243.9 | F31: 285.5
A32: Consolidated Profit/Loss After MI And Associates | B32: 3879.5 | C32: 8211 | D32: 13488.2 | E32: 14500.2 | F32: 14679.5
A33: EARNINGS PER SHARE
A34: Basic EPS (₹) | B34: 128 | C34: 272 | D34: 429 | E34: 461 | F34: 467
A35: Diluted EPS (₹) | B35: 128 | C35: 272 | D35: 429 | E35: 461 | F35: 467
A36: DIVIDEND
A37: Equity Share Dividend (₹ Cr.) | B37: 1359.4 | C37: 1812.5 | D37: 2718.7 | E37: 3930 | F37: 0

Sheet Cash flow
A1: MARUTI SUZUKI INDIA LIMITED — Consolidated Cash Flow Statement
A2: (₹ in Crores)
A3: Particulars | B3: Mar 22 12 mths | C3: Mar 23 12 mths | D3: Mar 24 12 mths | E3: Mar 25 12 mths | F3: Mar 26 12 mths
A4: CASH FLOW STATEMENT
A5: Net Profit Before Tax | B5: 4697.2 | C5: 10323.1 | D5: 17424.5 | E5: 19620 | F5: 18833
A6: Net Cash From Operating Activities | B6: 1840.5 | C6: 9251.4 | D6: 16801.1 | E6: 16136.2 | F6: 19099.9
A7: Net Cash (used in)/from Investing Activities | B7: -239.2 | C7: -8036.1 | D7: -11864.8 | E7: -14456.1 | F7: -14733.5
A8: Net Cash (used in)/from Financing Activities | B8: -1607 | C8: -1213.1 | D8: -4062 | E8: -4155.1 | F8: -4484
A9: Net (decrease)/increase In Cash and Cash Equivalents | B9: -5.7 | C9: 2.2 | D9: 874.3 | E9: -2475 | F9: -117.6
A10: Opening Cash & Cash Equivalents | B10: 40.8 | C10: 35.1 | D10: 1785.2 | E10: 2659.5 | F10: 184.5
A11: Closing Cash & Cash Equivalents | B11: 35.1 | C11: 37.3 | D11: 2659.5 | E11: 184.5 | F11: 66.9

Sheet Consolidated Quarterly result
A1: Consolidated Quarterly Results (Rs. Crores)
B2: Quarter ended | E2: Years | G2: % CHANGE
A3: Particulars | B3: 46082 | C3: 45992 | D3: 45901 | E3: 46082 | F3: 45717 | G3: QTQ | H3: YOY
A4: Revenue from Operations (Net Sales) | B4: 52462.5 | C4: 49904.1 | D4: 42344.2 | E4: 183316 | F4: 152913 | G4: =(B4-C4)/ABS(C4)*100 -> 5.1266329 | H4: =(B4-F4)/ABS(F4)*100 -> -65.691275
A5: Other Income | B5: 483.9 | C5: 1055.1 | D5: 946.2 | E5: 4357.2 | F5: 5022.2 | G5: =(B5-C5)/ABS(C5)*100 -> -54.137049 | H5: =(B5-F5)/ABS(F5)*100 -> -90.36478
A6: Total Income | B6: 52946.4 | C6: 50959.2 | D6: 43290.4 | E6: 187673.2 | F6: 157935.2 | G6: =(B6-C6)/ABS(C6)*100 -> 3.8995903 | H6: =(B6-F6)/ABS(F6)*100 -> -66.475871
A7: Total Expenses | B7: 48125.3 | C7: 46127.3 | D7: 39018.4 | E7: 168840.2 | F7: 138559.1 | G7: =(B7-C7)/ABS(C7)*100 -> 4.3314913 | H7: =(B7-F7)/ABS(F7)*100 -> -65.267312
A8: Cost of Materials Consumed | C8: 29233.6 | D8: 25324.2 | F8: 87318.3
A9: Purchases of Stock-in-Trade | C9: 5853.9 | D9: 6682 | F9: 21400
A10: Changes in Inventories | C10: -1181 | D10: 1547.2 | F10: 1227.5
A11: Employee Benefit Expenses | C11: 2700.9 | D11: 2052.2 | F11: 7026
A12: Finance Costs | C12: 61.7 | D12: 57.2 | F12: 194.2
A13: Depreciation & Amortisation | C13: 1734.6 | D13: 1703 | F13: 5608.2
A14: Other Expenses | C14: 5361.6 | D14: 4747 | F14: 18239.9
A15: Profit Before Tax (PBT) | B15: 4821.1 | C15: 4831.9 | D15: 4272 | E15: 18833 | F15: 19376.1 | G15: =(B15-C15)/ABS(C15)*100 -> -0.22351456 | H15: =(B15-F15)/ABS(F15)*100 -> -75.118316
A16: Tax Expenses | B16: 1259.4 | C16: 1038.2 | D16: 990.3 | E16: 4439 | F16: 5119.8 | G16: =(B16-C16)/ABS(C16)*100 -> 21.306107 | H16: =(B16-F16)/ABS(F16)*100 -> -75.401383
A17: PAT (Continuing Operations) | B17: 3561.7 | C17: 3793.7 | D17: 3281.7 | E17: 14394 | F17: 14256.3 | G17: =(B17-C17)/ABS(C17)*100 -> -6.1154019 | H17: =(B17-F17)/ABS(F17)*100 -> -75.016659
A18: Share of Profit/(Loss) of Associates | B18: 97.3 | C18: 85.4 | D18: 67.3 | E18: 285.5 | F18: 243.9 | G18: =(B18-C18)/ABS(C18)*100 -> 13.934426 | H18: =(B18-F18)/ABS(F18)*100 -> -60.106601
A19: Consolidated Net Profit | B19: 3659 | C19: 3879.1 | D19: 3349 | E19: 14679.5 | F19: 14500.2 | G19: =(B19-C19)/ABS(C19)*100 -> -5.6739965 | H19: =(B19-F19)/ABS(F19)*100 -> -74.765865
A20: Other Comprehensive Income (OCI) | B20: -501.3 | C20: 375.6 | D20: 260.5 | E20: 481.3 | F20: 33.7 | G20: =(B20-C20)/ABS(C20)*100 -> -233.46645 | H20: =(B20-F20)/ABS(F20)*100 -> -1587.5371
A21: Total Comprehensive Income | B21: 3157.7 | C21: 4254.7 | D21: 3609.5 | E21: 15160.8 | F21: 14533.9 | G21: =(B21-C21)/ABS(C21)*100 -> -25.783251 | H21: =(B21-F21)/ABS(F21)*100 -> -78.273554
A22: Basic EPS (Rs.) | C22: 123.38 | D22: 106.52 | E22: 467 | F22: 461.2
A23: Diluted EPS (Rs.) | C23: 123.38 | D23: 106.52 | E23: 467 | F23: 461.2

Sheet Beta
A1: Trading_Date | B1: Nifty50_Close | C1: Maruti_Close | D1: Rm Maruti | E1: Rm Nifty 50 | F1: Slope | G1: Covariance
A2: 43922 | B2: 8253.7998 | C2: 4246.3501
A3: 43924 | B3: 8083.7998 | C3: 4011.5 | D3: =(C3-C2)/C2 -> -0.055306344 | E3: =(B3-B2)/B2 -> -0.020596574 | F3: =SLOPE(D3:D1538,E3:E1538) -> 0.9704133 | G3: =_xlfn.COVARIANCE.S(D3:D1538,E3:E1538)/_xlfn.VAR.S(E3:E1538) -> 0.9704133 | H3: SUMMARY OUTPUT
A4: 43928 | B4: 8792.2002 | C4: 4553.6499 | D4: =(C4-C3)/C3 -> 0.13514892 | E4: =(B4-B3)/B3 -> 0.087632105
A5: 43929 | B5: 8748.75 | C5: 4698.1001 | D5: =(C5-C4)/C4 -> 0.031721849 | E5: =(B5-B4)/B4 -> -0.0049419024 | H5: Regression Statistics
A6: 43930 | B6: 9111.9004 | C6: 5326.6499 | D6: =(C6-C5)/C5 -> 0.13378808 | E6: =(B6-B5)/B5 -> 0.041508832 | H6: Multiple R | I6: 0.56969902
A7: 43934 | B7: 8993.8496 | C7: 5283.1499 | D7: =(C7-C6)/C6 -> -0.0081664838 | E7: =(B7-B6)/B6 -> -0.012955671 | H7: R Square | I7: 0.32455697
A8: 43936 | B8: 8925.2998 | C8: 5094.2998 | D8: =(C8-C7)/C7 -> -0.035745739 | E8: =(B8-B7)/B7 -> -0.0076218536 | H8: Adjusted R Square | I8: 0.32411666
A9: 43937 | B9: 8992.7998 | C9: 5130.7998 | D9: =(C9-C8)/C8 -> 0.0071648708 | E9: =(B9-B8)/B8 -> 0.0075627712 | H9: Standard Error | I9: 0.013712183
A10: 43938 | B10: 9266.75 | C10: 5505 | D10: =(C10-C9)/C9 -> 0.072932137 | E10: =(B10-B9)/B9 -> 0.030463282 | H10: Observations | I10: 1536
A11: 43941 | B11: 9261.8496 | C11: 5331.3501 | D11: =(C11-C10)/C10 -> -0.031544033 | E11: =(B11-B10)/B10 -> -0.00052881438
A12: 43942 | B12: 8981.4502 | C12: 5001.1001 | D12: =(C12-C11)/C11 -> -0.06194491 | E12: =(B12-B11)/B11 -> -0.030274667 | H12: ANOVA
A13: 43943 | B13: 9187.2998 | C13: 5180.8501 | D13: =(C13-C12)/C12 -> 0.035942092 | E13: =(B13-B12)/B12 -> 0.022919418 | I13: df | J13: SS | K13: MS | L13: F | M13: Significance F
A14: 43944 | B14: 9313.9004 | C14: 5156.3501 | D14: =(C14-C13)/C13 -> -0.0047289537 | E14: =(B14-B13)/B13 -> 0.013779956 | H14: Regression | I14: 1 | J14: 0.13859283 | K14: 0.13859283 | L14: 737.10199 | M14: 7.0351749e-133
A15: 43945 | B15: 9154.4004 | C15: 5045.6499 | D15: =(C15-C14)/C14 -> -0.021468712 | E15: =(B15-B14)/B14 -> -0.017124942 | H15: Residual | I15: 1534 | J15: 0.28842875 | K15: 0.00018802396
A16: 43948 | B16: 9282.2998 | C16: 5056.3501 | D16: =(C16-C15)/C15 -> 0.0021206773 | E16: =(B16-B15)/B15 -> 0.013971359 | H16: Total | I16: 1535 | J16: 0.42702159
A17: 43949 | B17: 9380.9004 | C17: 5052.7002 | D17: =(C17-C16)/C16 -> -0.00072184526 | E17: =(B17-B16)/B16 -> 0.010622431
A18: 43950 | B18: 9553.3496 | C18: 5068.4502 | D18: =(C18-C17)/C17 -> 0.0031171452 | E18: =(B18-B17)/B17 -> 0.018383014 | I18: Coefficients | J18: Standard Error | K18: t Stat | L18: P-value | M18: Lower 95% | N18: Upper 95% | O18: Lower 95.0% | P18: Upper 95.0%
A19: 43951 | B19: 9859.9004 | C19: 5358.7998 | D19: =(C19-C18)/C18 -> 0.057285679 | E19: =(B19-B18)/B18 -> 0.032088303 | H19: Intercept | I19: 0.00016349791 | J19: 0.00035088753 | K19: 0.46595532 | L19: 0.64131364 | M19: -0.00052477207 | N19: 0.00085176789 | O19: -0.00052477207 | P19: 0.00085176789
A20: 43955 | B20: 9293.5 | C20: 4886.2998 | D20: =(C20-C19)/C19 -> -0.088172728 | E20: =(B20-B19)/B19 -> -0.057444839 | H20: X Variable 1 | I20: 0.9704133 | J20: 0.03574316 | K20: 27.149622 | L20: 7.0351749e-133 | M20: 0.90030268 | N20: 1.0405239 | O20: 0.90030268 | P20: 1.0405239
A21: 43956 | B21: 9205.5996 | C21: 4829.8501 | D21: =(C21-C20)/C20 -> -0.011552649 | E21: =(B21-B20)/B20 -> -0.0094582655
A22: 43957 | B22: 9270.9004 | C22: 4843.25 | D22: =(C22-C21)/C21 -> 0.002774393 | E22: =(B22-B21)/B21 -> 0.0070935935
A23: 43958 | B23: 9199.0498 | C23: 4749.2998 | D23: =(C23-C22)/C22 -> -0.019398172 | E23: =(B23-B22)/B22 -> -0.0077501195
A24: 43959 | B24: 9251.5 | C24: 4654.1499 | D24: =(C24-C23)/C23 -> -0.020034512 | E24: =(B24-B23)/B23 -> 0.0057016971
A25: 43962 | B25: 9239.2002 | C25: 4937.7998 | D25: =(C25-C24)/C24 -> 0.060945588 | E25: =(B25-B24)/B24 -> -0.001329493
A26: 43963 | B26: 9196.5498 | C26: 4951.2998 | D26: =(C26-C25)/C25 -> 0.0027340112 | E26: =(B26-B25)/B25 -> -0.0046162427
A27: 43964 | B27: 9383.5498 | C27: 5036.1001 | D27: =(C27-C26)/C26 -> 0.017126875 | E27: =(B27-B26)/B26 -> 0.020333713
A28: 43965 | B28: 9142.75 | C28: 5114.0498 | D28: =(C28-C27)/C27 -> 0.015478189 | E28: =(B28-B27)/B27 -> -0.025661909
A29: 43966 | B29: 9136.8496 | C29: 5100.3999 | D29: =(C29-C28)/C28 -> -0.0026690984 | E29: =(B29-B28)/B28 -> -0.00064536279
A30: 43969 | B30: 8823.25 | C30: 4720.9502 | D30: =(C30-C29)/C29 -> -0.07439607 | E30: =(B30-B29)/B29 -> -0.03432251
A31: 43970 | B31: 8879.0996 | C31: 4805.2998 | D31: =(C31-C30)/C30 -> 0.017867083 | E31: =(B31-B30)/B30 -> 0.0063298228
A32: 43971 | B32: 9066.5498 | C32: 4891.9502 | D32: =(C32-C31)/C31 -> 0.018032255 | E32: =(B32-B31)/B31 -> 0.021111397
... A1538: 46195 | B1538: 24102.9 | C1538: 13421 | D1538: =(C1538-C1537)/C1537 -> 0.0019410228 | E1538: =(B1538-B1537)/B1537 -> 0.003739658

Sheet WACC
B1: WACC
B3: Capital Structure
B4: Total Debt | C4: ='Consolidated Balance sheet'!E17 -> 0
B5: Total Equity | C5: ='Consolidated Balance sheet'!E10 -> 96239.9
B6: Total Mix (Debt + Equity) | C6: =C4+C5 -> 96239.9
B7: % of Debt | C7: =C4/C6 -> 0
B8: % of Equity | C8: =C5/C6 -> 1
B9: Debt to Equity | C9: =IFERROR(C4/C5,"-") -> 0
B11: Cost of Equity (CAPM)
B12: Risk-free Rate (Rf) | C12: 0.0625 | E12: Source: RBI 10-year Government Securities yield (FY2025)
B13: Beta (β) | C13: =Beta!I20 -> 0.9704133
B14: Market Risk Premium (Rm - Rf) | C14: 0.061 | E14: Source: India Equity Risk Premium (Damodaran estimate)
B15: Cost of Equity [Ke = Rf + β×(Rm-Rf)] | C15: =C12+C13*C14 -> 0.12169521
B17: Cost of Debt
B18: Finance Cost (FY2025) | C18: ='Consolidated P&L'!E16 -> 194.2
B19: Total Debt (FY2025) | C19: =C4 -> 0
B20: Pre-tax Cost of Debt [Kd = FC/Debt] | C20: =IFERROR(C18/C19,0) -> 0
B21: Tax Rate | C21: =Assumptions!E30 -> 0.3
B22: Post-tax Cost of Debt [Kd*(1-T)] | C22: =C20*(1-C21) -> 0
B24: WACC
B25: Source | C25: Weight | D25: Cost | E25: Weighted Cost
B26: Debt | C26: =C7 -> 0 | D26: =C22 -> 0 | E26: =D26*C26 -> 0
B27: Equity | C27: =C8 -> 1 | D27: =C15 -> 0.12169521 | E27: =D27*C27 -> 0.12169521
B28: WACC | C28: =SUM(C26:C27) -> 1 | D28: (Check: weights = 100%) | E28: =E26+E27 -> 0.12169521 | G28: wacc = we*ke+wd*kd

Sheet Ratio Analysis
A1: Ratio Analysis - Maruti Suzuki India Limited
A2: Years | B2: Mar 22 | C2: Mar 23 | D2: Mar 24 | E2: Mar 25 | F2: Mar 26 | G2: Trends | H2: Mean | I2: Median
A4: Sales Growth | C4: =('Consolidated P&L'!C8-'Consolidated P&L'!B8)/'Consolidated P&L'!B8 -> 0.33104909 | D4: =('Consolidated P&L'!D8-'Consolidated P&L'!C8)/'Consolidated P&L'!C8 -> 0.20657167 | E4: =('Consolidated P&L'!E8-'Consolidated P&L'!D8)/'Consolidated P&L'!D8 -> 0.077928523 | F4: =('Consolidated P&L'!F8-'Consolidated P&L'!E8)/'Consolidated P&L'!E8 -> 0.19882548 | H4: =AVERAGE(C4:F4) -> 0.20359369 | I4: =MEDIAN(C4:F4) -> 0.20269857
A5: EBITDA Growth | C5: =(Assumptions!C9-Assumptions!B9)/Assumptions!B9 -> 0.93082962 | D5: =(Assumptions!D9-Assumptions!C9)/Assumptions!C9 -> 0.6815034 | E5: =(Assumptions!E9-Assumptions!D9)/Assumptions!D9 -> 0.08798303 | F5: =(Assumptions!F9-Assumptions!E9)/Assumptions!E9 -> 0.064491003 | H5: =AVERAGE(C5:F5) -> 0.44120176 | I5: =MEDIAN(C5:F5) -> 0.38474321
A6: EBIT Growth | C6: =(Assumptions!C11-Assumptions!B11)/Assumptions!B11 -> 1.8081722 | D6: =(Assumptions!D11-Assumptions!C11)/Assumptions!C11 -> 0.61993408 | E6: =(Assumptions!E11-Assumptions!D11)/Assumptions!D11 -> 0.09627369 | F6: =(Assumptions!F11-Assumptions!E11)/Assumptions!E11 -> 0.01143792 | H6: =AVERAGE(C6:F6) -> 0.63395448 | I6: =MEDIAN(C6:F6) -> 0.35810389
A7: Net Profit Growth | C7: =('Consolidated P&L'!C28-'Consolidated P&L'!B28)/'Consolidated P&L'!B28 -> 1.1609641 | D7: =('Consolidated P&L'!D28-'Consolidated P&L'!C28)/'Consolidated P&L'!C28 -> 0.64734366 | E7: =('Consolidated P&L'!E28-'Consolidated P&L'!D28)/'Consolidated P&L'!D28 -> 0.077239858 | F7: =('Consolidated P&L'!F28-'Consolidated P&L'!E28)/'Consolidated P&L'!E28 -> 0.0096588876 | H7: =AVERAGE(C7:F7) -> 0.47380162 | I7: =MEDIAN(C7:F7) -> 0.36229176
A8: Dividend Growth
A10: Gross Margin | B10: =('Consolidated P&L'!B8-Assumptions!B5)/'Consolidated P&L'!B8 -> 0.25230217 | C10: =('Consolidated P&L'!C8-Assumptions!C5)/'Consolidated P&L'!C8 -> 0.2663958 | D10: =('Consolidated P&L'!D8-Assumptions!D5)/'Consolidated P&L'!D8 -> 0.29689718 | E10: =('Consolidated P&L'!E8-Assumptions!E5)/'Consolidated P&L'!E8 -> 0.29704603 | F10: =('Consolidated P&L'!F8-Assumptions!F5)/'Consolidated P&L'!F8 -> 0.27679253 | H10: =AVERAGE(B10:F10) -> 0.27788674 | I10: =MEDIAN(B10:F10) -> 0.27679253
A11: EBITDA Margin | B11: =Assumptions!B9/'Consolidated P&L'!B8 -> 0.064601075 | C11: =Assumptions!C9/'Consolidated P&L'!C8 -> 0.093710795 | D11: =Assumptions!D9/'Consolidated P&L'!D8 -> 0.13059731 | E11: =Assumptions!E9/'Consolidated P&L'!E8 -> 0.13181548 | F11: =Assumptions!F9/'Consolidated P&L'!F8 -> 0.11704488 | H11: =AVERAGE(B11:F11) -> 0.10755391 | I11: =MEDIAN(B11:F11) -> 0.11704488
A12: EBIT Margin | B12: =Assumptions!B11/'Consolidated P&L'!B8 -> 0.033026227 | C12: =Assumptions!C11/'Consolidated P&L'!C8 -> 0.069676868 | D12: =Assumptions!D11/'Consolidated P&L'!D8 -> 0.093547641 | E12: =Assumptions!E11/'Consolidated P&L'!E8 -> 0.09513972 | F12: =Assumptions!F11/'Consolidated P&L'!F8 -> 0.080268498 | H12: =AVERAGE(B12:F12) -> 0.074331791 | I12: =MEDIAN(B12:F12) -> 0.080268498
A13: EBT Margin | B13: =Assumptions!B14/'Consolidated P&L'!B8 -> 0.051345073 | C13: =Assumptions!C14/'Consolidated P&L'!C8 -> 0.086294019 | D13: =Assumptions!D14/'Consolidated P&L'!D8 -> 0.12103918 | E13: =Assumptions!E14/'Consolidated P&L'!E8 -> 0.12671323 | F13: =Assumptions!F14/'Consolidated P&L'!F8 -> 0.10273517 | H13: =AVERAGE(B13:F13) -> 0.097625333 | I13: =MEDIAN(B13:F13) -> 0.10273517
A14: Net Profit Margin | B14: ='Consolidated P&L'!B28/'Consolidated P&L'!B8 -> 0.042087721 | C14: ='Consolidated P&L'!C28/'Consolidated P&L'!C8 -> 0.068329601 | D14: ='Consolidated P&L'!D28/'Consolidated P&L'!D8 -> 0.093291047 | E14: ='Consolidated P&L'!E28/'Consolidated P&L'!E8 -> 0.093231445 | F14: ='Consolidated P&L'!F28/'Consolidated P&L'!F8 -> 0.078520151 | H14: =AVERAGE(B14:F14) -> 0.075091993 | I14: =MEDIAN(B14:F14) -> 0.078520151
A16: Sales Expenses % Sales | B16: ='Consolidated P&L'!B20/'Consolidated P&L'!B8 -> 0.96840704 | C16: ='Consolidated P&L'!C20/'Consolidated P&L'!C8 -> 0.93191366 | D16: ='Consolidated P&L'!D20/'Consolidated P&L'!D8 -> 0.9078171 | E16: ='Consolidated P&L'!E20/'Consolidated P&L'!E8 -> 0.90613028 | F16: ='Consolidated P&L'!F20/'Consolidated P&L'!F8 -> 0.92103362 | H16: =AVERAGE(B16:F16) -> 0.92706034 | I16: =MEDIAN(B16:F16) -> 0.92103362
A17: Depreciation % Sales | B17: ='Consolidated P&L'!B17/'Consolidated P&L'!B8 -> 0.031574848 | C17: ='Consolidated P&L'!C17/'Consolidated P&L'!C8 -> 0.024033927 | D17: ='Consolidated P&L'!D17/'Consolidated P&L'!D8 -> 0.037049674 | E17: ='Consolidated P&L'!E17/'Consolidated P&L'!E8 -> 0.036675757 | F17: ='Consolidated P&L'!F17/'Consolidated P&L'!F8 -> 0.036776386 | H17: =AVERAGE(B17:F17) -> 0.033222118 | I17: =MEDIAN(B17:F17) -> 0.036675757
A18: Operating Income % Sales | B18: =Assumptions!B9/'Consolidated P&L'!B8 -> 0.064601075 | C18: =Assumptions!C9/'Consolidated P&L'!C8 -> 0.093710795 | D18: =Assumptions!D9/'Consolidated P&L'!D8 -> 0.13059731 | E18: =Assumptions!E9/'Consolidated P&L'!E8 -> 0.13181548 | F18: =Assumptions!F9/'Consolidated P&L'!F8 -> 0.11704488 | H18: =AVERAGE(B18:F18) -> 0.10755391 | I18: =MEDIAN(B18:F18) -> 0.11704488
A20: Return on Capital Employed | B20: =Assumptions!B11/Assumptions!B37 -> 0.055383003 | C20: =Assumptions!C11/Assumptions!C37 -> 0.13010299 | D20: =Assumptions!D11/Assumptions!D37 -> 0.16019106 | E20: =Assumptions!E11/Assumptions!E37 -> 0.15203842 | F20: =Assumptions!F11/Assumptions!F37 -> 0.13937314 | H20: =AVERAGE(B20:F20) -> 0.12741772 | I20: =MEDIAN(B20:F20) -> 0.13937314
A21: Retained Earning % | B21: ='Consolidated P&L'!B28/'Consolidated P&L'!B8 -> 0.042087721 | C21: ='Consolidated P&L'!C28/'Consolidated P&L'!C8 -> 0.068329601 | D21: ='Consolidated P&L'!D28/'Consolidated P&L'!D8 -> 0.093291047 | E21: ='Consolidated P&L'!E28/'Consolidated P&L'!E8 -> 0.093231445 | F21: ='Consolidated P&L'!F28/'Consolidated P&L'!F8 -> 0.078520151 | H21: =AVERAGE(B21:F21) -> 0.075091993 | I21: =MEDIAN(B21:F21) -> 0.078520151
A22: Return on Equity % | B22: ='Consolidated P&L'!B28/'Consolidated Balance sheet'!B10 -> 0.06718534 | C22: ='Consolidated P&L'!C28/'Consolidated Balance sheet'!C10 -> 0.13001183 | D22: ='Consolidated P&L'!D28/'Consolidated Balance sheet'!D10 -> 0.15453898 | E22: ='Consolidated P&L'!E28/'Consolidated Balance sheet'!E10 -> 0.14813295 | F22: ='Consolidated P&L'!F28/'Consolidated Balance sheet'!F10 -> 0.13432715 | H22: =AVERAGE(B22:F22) -> 0.12683925 | I22: =MEDIAN(B22:F22) -> 0.13432715
A23: Self Sustained Growth Rate | B23: =('Consolidated P&L'!B28-'Consolidated P&L'!B37)/'Consolidated Balance sheet'!B10 -> 0.042617944 | C23: =('Consolidated P&L'!C28-'Consolidated P&L'!C37)/'Consolidated Balance sheet'!C10 -> 0.10067922 | D23: =('Consolidated P&L'!D28-'Consolidated P&L'!D37)/'Consolidated Balance sheet'!D10 -> 0.12279182 | E23: =('Consolidated P&L'!E28-'Consolidated P&L'!E37)/'Consolidated Balance sheet'!E10 -> 0.10729749 | F23: =('Consolidated P&L'!F28-'Consolidated P&L'!F37)/'Consolidated Balance sheet'!F10 -> 0.13432715 | H23: =AVERAGE(B23:F23) -> 0.10154272 | I23: =MEDIAN(B23:F23) -> 0.10729749
A24: Interest Coverage Ratio | B24: =Assumptions!B11/'Consolidated P&L'!B16 -> 23.042654 | C24: =Assumptions!C11/'Consolidated P&L'!C16 -> 43.807487 | D24: =Assumptions!D11/'Consolidated P&L'!D16 -> 68.545971 | E24: =Assumptions!E11/'Consolidated P&L'!E16 -> 74.912976 | F24: =Assumptions!F11/'Consolidated P&L'!F16 -> 61.644323 | H24: =AVERAGE(B24:F24) -> 54.390682 | I24: =MEDIAN(B24:F24) -> 61.644323
A26: Debtor Turnover Ratio | B26: ='Consolidated P&L'!B8/'Consolidated Balance sheet'!B38 -> 43.415974 | C26: ='Consolidated P&L'!C8/'Consolidated Balance sheet'!C38 -> 35.612558 | D26: ='Consolidated P&L'!D8/'Consolidated Balance sheet'!D38 -> 30.860207 | E26: ='Consolidated P&L'!E8/'Consolidated Balance sheet'!E38 -> 23.382265 | F26: ='Consolidated P&L'!F8/'Consolidated Balance sheet'!F38 -> 34.315987 | H26: =AVERAGE(B26:F26) -> 33.517398 | I26: =MEDIAN(B26:F26) -> 34.315987
A27: Creditor Turnover Ratio | B27: =Assumptions!B5/'Consolidated Balance sheet'!B18 -> 6.7631999 | C27: =Assumptions!C5/'Consolidated Balance sheet'!C18 -> 7.3183828 | D27: =Assumptions!D5/'Consolidated Balance sheet'!D18 -> 5.8711179 | E27: =Assumptions!E5/'Consolidated Balance sheet'!E18 -> 5.24307 | F27: =Assumptions!F5/'Consolidated Balance sheet'!F18 -> 5.9897306 | H27: =AVERAGE(B27:F27) -> 6.2371003 | I27: =MEDIAN(B27:F27) -> 5.9897306
A28: Inventory Turnover | B28: ='Consolidated P&L'!B8/'Consolidated Balance sheet'!B37 -> 25.006313 | C28: ='Consolidated P&L'!C8/'Consolidated Balance sheet'!C37 -> 27.447485 | D28: ='Consolidated P&L'!D8/'Consolidated Balance sheet'!D37 -> 26.674602 | E28: ='Consolidated P&L'!E8/'Consolidated Balance sheet'!E37 -> 22.11899 | F28: ='Consolidated P&L'!F8/'Consolidated Balance sheet'!F37 -> 16.193135 | H28: =AVERAGE(B28:F28) -> 23.488105 | I28: =MEDIAN(B28:F28) -> 25.006313
A29: Fixed Asset Turnover | B29: ='Consolidated P&L'!B8/'Consolidated Balance sheet'!B29 -> 5.2943771 | C29: ='Consolidated P&L'!C8/'Consolidated Balance sheet'!C29 -> 5.6703224 | D29: ='Consolidated P&L'!D8/'Consolidated Balance sheet'!D29 -> 3.9848257 | E29: ='Consolidated P&L'!E8/'Consolidated Balance sheet'!E29 -> 3.737635 | F29: ='Consolidated P&L'!F8/'Consolidated Balance sheet'!F29 -> 4.1323126 | H29: =AVERAGE(B29:F29) -> 4.5638946 | I29: =MEDIAN(B29:F29) -> 4.1323126
A30: Capital Turnover Ratio | B30: ='Consolidated P&L'!B8/Assumptions!B37 -> 1.6769401 | C30: ='Consolidated P&L'!C8/Assumptions!C37 -> 1.8672336 | D30: ='Consolidated P&L'!D8/Assumptions!D37 -> 1.7124009 | E30: ='Consolidated P&L'!E8/Assumptions!E37 -> 1.5980541 | F30: ='Consolidated P&L'!F8/Assumptions!F37 -> 1.7363367 | H30: =AVERAGE(B30:F30) -> 1.7181931 | I30: =MEDIAN(B30:F30) -> 1.7124009
A32: (In days)
A33: Debtors Day | B33: =365/B26 -> 8.4070438 | C33: =365/C26 -> 10.249193 | D33: =365/D26 -> 11.827529 | E33: =365/E26 -> 15.610121 | F33: =365/F26 -> 10.636442 | H33: =AVERAGE(B33:F33) -> 11.346066 | I33: =MEDIAN(B33:F33) -> 10.636442
A34: Payable Days | B34: =365/B27 -> 53.968536 | C34: =365/C27 -> 49.874407 | D34: =365/D27 -> 62.168739 | E34: =365/E27 -> 69.615702 | F34: =365/F27 -> 60.937632 | H34: =AVERAGE(B34:F34) -> 59.313003 | I34: =MEDIAN(B34:F34) -> 60.937632
A35: Inventory Days | B35: =365/B28 -> 14.596314 | C35: =365/C28 -> 13.298122 | D35: =365/D28 -> 13.683428 | E35: =365/E28 -> 16.501658 | F35: =365/F28 -> 22.540417 | H35: =AVERAGE(B35:F35) -> 16.123988 | I35: =MEDIAN(B35:F35) -> 14.596314
A36: Cash Conversion Cycle | B36: =B33+B35-B34 -> -30.965178 | C36: =C33+C35-C34 -> -26.327091 | D36: =D33+D35-D34 -> -36.657782 | E36: =E33+E35-E34 -> -37.503923 | F36: =F33+F35-F34 -> -27.760773 | H36: =AVERAGE(B36:F36) -> -31.842949 | I36: =MEDIAN(B36:F36) -> -30.965178
A38: CFO/Sales | B38: ='Cash flow'!B6/'Consolidated P&L'!B8 -> 0.020836683 | C38: ='Cash flow'!C6/'Consolidated P&L'!C8 -> 0.078687571 | D38: ='Cash flow'!D6/'Consolidated P&L'!D8 -> 0.11843587 | E38: ='Cash flow'!E6/'Consolidated P&L'!E8 -> 0.10552536 | F38: ='Cash flow'!F6/'Consolidated P&L'!F8 -> 0.10419112 | H38: =AVERAGE(B38:F38) -> 0.085535323 | I38: =MEDIAN(B38:F38) -> 0.10419112
A39: CFO/Total Assets | B39: ='Cash flow'!B6/'Consolidated Balance sheet'!B43 -> 0.024653241 | C39: ='Cash flow'!C6/'Consolidated Balance sheet'!C43 -> 0.10935862 | D39: ='Cash flow'!D6/'Consolidated Balance sheet'!D43 -> 0.14565222 | E39: ='Cash flow'!E6/'Consolidated Balance sheet'!E43 -> 0.12227006 | F39: ='Cash flow'!F6/'Consolidated Balance sheet'!F43 -> 0.12828971 | H39: =AVERAGE(B39:F39) -> 0.10604477 | I39: =MEDIAN(B39:F39) -> 0.12227006
A40: CFO/Total Debt | B40: =IFERROR('Cash flow'!B6/'Consolidated Balance sheet'!B17,"N/A") -> 4.8193244 | C40: =IFERROR('Cash flow'!C6/'Consolidated Balance sheet'!C17,"N/A") -> 7.6093107 | D40: =IFERROR('Cash flow'!D6/'Consolidated Balance sheet'!D17,"N/A") -> 507.5861 | E40: =IFERROR('Cash flow'!E6/'Consolidated Balance sheet'!E17,"N/A") -> N/A | F40: =IFERROR('Cash flow'!F6/'Consolidated Balance sheet'!F17,"N/A") -> N/A | H40: =IFERROR(AVERAGEIF(B40:F40,"<>N/A"),"-") -> 173.33825 | I40: =IFERROR(MEDIAN(IF(ISNUMBER(B40:F40),B40:F40)),"-") -> 0

Sheet FCFF
A1: Particular | B1: 44621 | C1: 44986 | D1: 45352 | E1: 45717 | F1: 46082
A2: EBIT | B2: =Assumptions!B11 -> 2917.2 | C2: =Assumptions!C11 -> 8192 | D2: =Assumptions!D11 -> 13270.5 | E2: =Assumptions!E11 -> 14548.1 | F2: =Assumptions!F11 -> 14714.5
A3: Less: Tax on EBIT | B3: =Assumptions!B11*Assumptions!B29 -> 525.96178 | C3: =Assumptions!C11*Assumptions!C29 -> 1705.3849 | D3: =Assumptions!D11*Assumptions!D29 -> 3042.2512 | E3: =Assumptions!E11*Assumptions!E29 -> 3844.0843 | F3: =Assumptions!F11*Assumptions!F29 -> 3468.256
A4: EBIT * (1 - Tax) NOPAT | B4: =Assumptions!B11-FCFF!B3 -> 2391.2382 | C4: =Assumptions!C11-FCFF!C3 -> 6486.6151 | D4: =Assumptions!D11-FCFF!D3 -> 10228.249 | E4: =Assumptions!E11-FCFF!E3 -> 10704.016 | F4: =Assumptions!F11-FCFF!F3 -> 11246.244
A5: Less: Net Capital expenditure | C5: ='Fixed Asset Scheduled'!C8 -> 4014.1 | D5: ='Fixed Asset Scheduled'!D8 -> 12435 | E5: ='Fixed Asset Scheduled'!E8 -> 4959.7 | F5: ='Fixed Asset Scheduled'!F8 -> 2316.4 | I5: Avg of effective tax rate | J5: =Assumptions!G29 -> 0.22353177
A6: Less: Net Change in working Capital | C6: ='Change in working Capital'!C6 -> -2.2 | D6: ='Change in working Capital'!D6 -> -2872.9 | E6: ='Change in working Capital'!E6 -> 24.9 | F6: ='Change in working Capital'!F6 -> 1577.4
A7: Reinvestment | C7: =FCFF!C5+FCFF!C6 -> 4011.9 | D7: =FCFF!D5+FCFF!D6 -> 9562.1 | E7: =FCFF!E5+FCFF!E6 -> 4984.6 | F7: =FCFF!F5+FCFF!F6 -> 3893.8
A8: Free Cash Flow | C8: =FCFF!C4-FCFF!C7 -> 2474.7151 | D8: =FCFF!D4-FCFF!D7 -> 666.14885 | E8: =FCFF!E4-FCFF!E7 -> 5719.4157 | F8: =FCFF!F4-FCFF!F7 -> 7352.444
I9: Marginal tax rate | J9: 0.3
A10: Reinvestment Rate | C10: =FCFF!C7/FCFF!C4 -> 0.61848898 | D10: =FCFF!D7/FCFF!D4 -> 0.93487166 | E10: =FCFF!E7/FCFF!E4 -> 0.4656757 | F10: =FCFF!F7/FCFF!F4 -> 0.34623115
A12: Median Reinvestment rate / Sales percentage | B12: =MEDIAN(FCFF!C7/'Consolidated P&L'!C8,FCFF!D7/'Consolidated P&L'!D8,FCFF!E7/'Consolidated P&L'!E8,FCFF!F7/'Consolidated P&L'!F8) -> 0.033360372
A13: Average Reinvestment rate / Sales percentage | B13: =AVERAGE(FCFF!C7/'Consolidated P&L'!C8,FCFF!D7/'Consolidated P&L'!D8,FCFF!E7/'Consolidated P&L'!E8,FCFF!F7/'Consolidated P&L'!F8) -> 0.038841926

Sheet Change in working Capital
A1: Particular | B1: 44621 | C1: 44986 | D1: 45352 | E1: 45717 | F1: 46082
A2: Inventory | B2: ='Consolidated Balance sheet'!B37 -> 3532.3 | C2: ='Consolidated Balance sheet'!C37 -> 4283.5 | D2: ='Consolidated Balance sheet'!D37 -> 5318.1 | E2: ='Consolidated Balance sheet'!E37 -> 6913.2 | F2: ='Consolidated Balance sheet'!F37 -> 11320.6
A3: Trade Receivables | B3: ='Consolidated Balance sheet'!B38 -> 2034.5 | C3: ='Consolidated Balance sheet'!C38 -> 3301.4 | D3: ='Consolidated Balance sheet'!D38 -> 4596.8 | E3: ='Consolidated Balance sheet'!E38 -> 6539.7 | F3: ='Consolidated Balance sheet'!F38 -> 5342
A4: Trade Payable | B4: ='Consolidated Balance sheet'!B18 -> 9765.2 | C4: ='Consolidated Balance sheet'!C18 -> 11785.5 | D4: ='Consolidated Balance sheet'!D18 -> 16988.4 | E4: ='Consolidated Balance sheet'!E18 -> 20501.5 | F4: ='Consolidated Balance sheet'!F18 -> 22133.8
A5: Non Cash working Capital | B5: ='Change in working Capital'!B2+'Change in working Capital'!B3-'Change in working Capital'!B4 -> -4198.4 | C5: ='Change in working Capital'!C2+'Change in working Capital'!C3-'Change in working Capital'!C4 -> -4200.6 | D5: ='Change in working Capital'!D2+'Change in working Capital'!D3-'Change in working Capital'!D4 -> -7073.5 | E5: ='Change in working Capital'!E2+'Change in working Capital'!E3-'Change in working Capital'!E4 -> -7048.6 | F5: ='Change in working Capital'!F2+'Change in working Capital'!F3-'Change in working Capital'!F4 -> -5471.2
A6: Change in Working Capital | C6: ='Change in working Capital'!C5-'Change in working Capital'!B5 -> -2.2 | D6: ='Change in working Capital'!D5-'Change in working Capital'!C5 -> -2872.9 | E6: ='Change in working Capital'!E5-'Change in working Capital'!D5 -> 24.9 | F6: ='Change in working Capital'!F5-'Change in working Capital'!E5 -> 1577.4
A7: Change in working Capital / percentage of sales | C7: ='Change in working Capital'!C6/'Consolidated P&L'!C8 -> -1.871205e-05 | D7: ='Change in working Capital'!D6/'Consolidated P&L'!D8 -> -0.020251914 | E7: ='Change in working Capital'!E6/'Consolidated P&L'!E8 -> 0.00016283769 | F7: ='Change in working Capital'!F6/'Consolidated P&L'!F8 -> 0.0086048135
A9: Median Non Cash working Capital / Sales percentage | C9: =MEDIAN('Change in working Capital'!B5/'Consolidated P&L'!B8,'Change in working Capital'!C5/'Consolidated P&L'!C8,'Change in working Capital'!D5/'Consolidated P&L'!D8,'Change in working Capital'!E5/'Consolidated P&L'!E8,'Change in working Capital'!F5/'Consolidated P&L'!F8) -> -0.046095492
A10: Average Non Cash working Capital / Sales percentage | C10: =AVERAGE('Change in working Capital'!B5/'Consolidated P&L'!B8,'Change in working Capital'!C5/'Consolidated P&L'!C8,'Change in working Capital'!D5/'Consolidated P&L'!D8,'Change in working Capital'!E5/'Consolidated P&L'!E8,'Change in working Capital'!F5/'Consolidated P&L'!F8) -> -0.041812692

Sheet Fixed Asset Scheduled
A1: Particular | B1: 44621 | C1: 44986 | D1: 45352 | E1: 45717 | F1: 46082
A2: Beginning balance | C2: ='Fixed Asset Scheduled'!B6 -> 13894.7 | D2: ='Fixed Asset Scheduled'!C6 -> 17908.8 | E2: ='Fixed Asset Scheduled'!D6 -> 30343.8 | F2: ='Fixed Asset Scheduled'!E6 -> 35303.5
A3: Add: Net Purchases | C3: ='Fixed Asset Scheduled'!C4-'Fixed Asset Scheduled'!C2 -> 6839.8 | D3: ='Fixed Asset Scheduled'!D4-'Fixed Asset Scheduled'!D2 -> 17690.8 | E3: ='Fixed Asset Scheduled'!E4-'Fixed Asset Scheduled'!E2 -> 10567.9 | F3: ='Fixed Asset Scheduled'!F4-'Fixed Asset Scheduled'!F2 -> 9058.1
A4: Total Fixed Assets | B4: ='Consolidated Balance sheet'!B29 -> 16683.7 | C4: ='Consolidated Balance sheet'!C29 -> 20734.5 | D4: ='Consolidated Balance sheet'!D29 -> 35599.6 | E4: ='Consolidated Balance sheet'!E29 -> 40911.7 | F4: ='Consolidated Balance sheet'!F29 -> 44361.6
A5: Less: Depreciation | B5: ='Consolidated P&L'!B17 -> 2789 | C5: ='Consolidated P&L'!C17 -> 2825.7 | D5: ='Consolidated P&L'!D17 -> 5255.8 | E5: ='Consolidated P&L'!E17 -> 5608.2 | F5: ='Consolidated P&L'!F17 -> 6741.7
A6: Closing Balance (Fixed Assets) | B6: ='Fixed Asset Scheduled'!B4-'Fixed Asset Scheduled'!B5 -> 13894.7 | C6: ='Fixed Asset Scheduled'!C4-'Fixed Asset Scheduled'!C5 -> 17908.8 | D6: ='Fixed Asset Scheduled'!D4-'Fixed Asset Scheduled'!D5 -> 30343.8 | E6: ='Fixed Asset Scheduled'!E4-'Fixed Asset Scheduled'!E5 -> 35303.5 | F6: ='Fixed Asset Scheduled'!F4-'Fixed Asset Scheduled'!F5 -> 37619.9
A8: Net Capital expenditure | C8: ='Fixed Asset Scheduled'!C3-'Fixed Asset Scheduled'!C5 -> 4014.1 | D8: ='Fixed Asset Scheduled'!D3-'Fixed Asset Scheduled'!D5 -> 12435 | E8: ='Fixed Asset Scheduled'!E3-'Fixed Asset Scheduled'!E5 -> 4959.7 | F8: ='Fixed Asset Scheduled'!F3-'Fixed Asset Scheduled'!F5 -> 2316.4
A9: Net Capital expenditure / Sales percentage | C9: ='Fixed Asset Scheduled'!C8/'Consolidated P&L'!C8 -> 0.034141836 | D9: ='Fixed Asset Scheduled'!D8/'Consolidated P&L'!D8 -> 0.087657957 | E9: ='Fixed Asset Scheduled'!E8/'Consolidated P&L'!E8 -> 0.032434783 | F9: ='Fixed Asset Scheduled'!F8/'Consolidated P&L'!F8 -> 0.012636104
A11: Median Capital expenditure / Sales percentage | C11: =MEDIAN('Fixed Asset Scheduled'!C9:F9) -> 0.033288309
A12: Average Capital expenditure / Sales percentage | C12: =AVERAGE('Fixed Asset Scheduled'!C9:F9) -> 0.04171767

Sheet Assumptions
A1: Maruti Suzuki India Limited
A2: Particulars (in ₹ Cr.) | B2: Mar 22 | C2: Mar 23 | D2: Mar 24 | E2: Mar 25 | F2: Mar 26
A3: Revenue from operations | B3: ='Consolidated P&L'!B8 -> 88329.8 | C3: ='Consolidated P&L'!C8 -> 117571.3 | D3: ='Consolidated P&L'!D8 -> 141858.2 | E3: ='Consolidated P&L'!E8 -> 152913 | F3: ='Consolidated P&L'!F8 -> 183316
A4: Revenue growth in % | C4: =('Consolidated P&L'!C8-'Consolidated P&L'!B8)/'Consolidated P&L'!B8 -> 0.33104909 | D4: =('Consolidated P&L'!D8-'Consolidated P&L'!C8)/'Consolidated P&L'!C8 -> 0.20657167 | E4: =('Consolidated P&L'!E8-'Consolidated P&L'!D8)/'Consolidated P&L'!D8 -> 0.077928523 | F4: =('Consolidated P&L'!F8-'Consolidated P&L'!E8)/'Consolidated P&L'!E8 -> 0.19882548
A5: Less: Material cost | B5: ='Consolidated P&L'!B12+'Consolidated P&L'!B13+'Consolidated P&L'!B14 -> 66044 | C5: ='Consolidated P&L'!C12+'Consolidated P&L'!C13+'Consolidated P&L'!C14 -> 86250.8 | D5: ='Consolidated P&L'!D12+'Consolidated P&L'!D13+'Consolidated P&L'!D14 -> 99740.9 | E5: ='Consolidated P&L'!E12+'Consolidated P&L'!E13+'Consolidated P&L'!E14 -> 107490.8 | F5: ='Consolidated P&L'!F12+'Consolidated P&L'!F13+'Consolidated P&L'!F14 -> 132575.5
A6: Less: Employee costs | B6: ='Consolidated P&L'!B15 -> 4051.4 | C6: ='Consolidated P&L'!C15 -> 4634.6 | D6: ='Consolidated P&L'!D15 -> 6301.6 | E6: ='Consolidated P&L'!E15 -> 7026 | F6: ='Consolidated P&L'!F15 -> 9049.7
A7: Less: Other Expenses | B7: ='Consolidated P&L'!B18 -> 12672.7 | C7: ='Consolidated P&L'!C18 -> 15805.5 | D7: ='Consolidated P&L'!D18 -> 17550.1 | E7: ='Consolidated P&L'!E18 -> 18614.8 | F7: ='Consolidated P&L'!F18 -> 20234.6
A8: Total Expenses | B8: ='Consolidated P&L'!B20 -> 85539.2 | C8: ='Consolidated P&L'!C20 -> 109566.3 | D8: ='Consolidated P&L'!D20 -> 128781.3 | E8: ='Consolidated P&L'!E20 -> 138559.1 | F8: ='Consolidated P&L'!F20 -> 168840.2
A9: EBITDA | B9: ='Consolidated P&L'!B8-('Consolidated P&L'!B20-'Consolidated P&L'!B17-'Consolidated P&L'!B16) -> 5706.2 | C9: ='Consolidated P&L'!C8-('Consolidated P&L'!C20-'Consolidated P&L'!C17-'Consolidated P&L'!C16) -> 11017.7 | D9: ='Consolidated P&L'!D8-('Consolidated P&L'!D20-'Consolidated P&L'!D17-'Consolidated P&L'!D16) -> 18526.3 | E9: ='Consolidated P&L'!E8-('Consolidated P&L'!E20-'Consolidated P&L'!E17-'Consolidated P&L'!E16) -> 20156.3 | F9: ='Consolidated P&L'!F8-('Consolidated P&L'!F20-'Consolidated P&L'!F17-'Consolidated P&L'!F16) -> 21456.2
A10: Less: Depreciation And Amortization | B10: ='Consolidated P&L'!B17 -> 2789 | C10: ='Consolidated P&L'!C17 -> 2825.7 | D10: ='Consolidated P&L'!D17 -> 5255.8 | E10: ='Consolidated P&L'!E17 -> 5608.2 | F10: ='Consolidated P&L'!F17 -> 6741.7
A11: EBIT | B11: =B9-B10 -> 2917.2 | C11: =C9-C10 -> 8192 | D11: =D9-D10 -> 13270.5 | E11: =E9-E10 -> 14548.1 | F11: =F9-F10 -> 14714.5
A12: ADD: Non operating income / Other Income | B12: ='Consolidated P&L'!B9 -> 1744.7 | C12: ='Consolidated P&L'!C9 -> 2140.7 | D12: ='Consolidated P&L'!D9 -> 4093.5 | E12: ='Consolidated P&L'!E9 -> 5022.2 | F12: ='Consolidated P&L'!F9 -> 4357.2
A13: Less: Interest Expenses | B13: ='Consolidated P&L'!B16 -> 126.6 | C13: ='Consolidated P&L'!C16 -> 187 | D13: ='Consolidated P&L'!D16 -> 193.6 | E13: ='Consolidated P&L'!E16 -> 194.2 | F13: ='Consolidated P&L'!F16 -> 238.7
A14: EBT | B14: =B11+B12-B13 -> 4535.3 | C14: =C11+C12-C13 -> 10145.7 | D14: =D11+D12-D13 -> 17170.4 | E14: =E11+E12-E13 -> 19376.1 | F14: =F11+F12-F13 -> 18833
A15: Less: TAX | B15: ='Consolidated P&L'!B27 -> 817.7 | C15: ='Consolidated P&L'!C27 -> 2112.1 | D15: ='Consolidated P&L'!D27 -> 3936.3 | E15: ='Consolidated P&L'!E27 -> 5119.8 | F15: ='Consolidated P&L'!F27 -> 4439
A16: Net Profit - PAT | B16: ='Consolidated P&L'!B28 -> 3717.6 | C16: ='Consolidated P&L'!C28 -> 8033.6 | D16: ='Consolidated P&L'!D28 -> 13234.1 | E16: ='Consolidated P&L'!E28 -> 14256.3 | F16: ='Consolidated P&L'!F28 -> 14394
A18: Historical Growth
A19: Average Growth | B19: =AVERAGE(C4:F4) -> 0.20359369
A20: CAGR | B20: =('Consolidated P&L'!F8/'Consolidated P&L'!B8)^(1/5)-1 -> 0.15722718 | C20: =_xlfn.RRI(5,B3,F3) -> 0.15722718 | D20: RRI
A22: Margins
A23: EBITDA | B23: =B9/B3 -> 0.064601075 | C23: =C9/C3 -> 0.093710795 | D23: =D9/D3 -> 0.13059731 | E23: =E9/E3 -> 0.13181548 | F23: =F9/F3 -> 0.11704488
A24: EBIT | B24: =B11/B3 -> 0.033026227 | C24: =C11/C3 -> 0.069676868 | D24: =D11/D3 -> 0.093547641 | E24: =E11/E3 -> 0.09513972 | F24: =F11/F3 -> 0.080268498
A25: EBT | B25: =B14/B3 -> 0.051345073 | C25: =C14/C3 -> 0.086294019 | D25: =D14/D3 -> 0.12103918 | E25: =E14/E3 -> 0.12671323 | F25: =F14/F3 -> 0.10273517
A26: Net Profit | B26: =B16/B3 -> 0.042087721 | C26: =C16/C3 -> 0.068329601 | D26: =D16/D3 -> 0.093291047 | E26: =E16/E3 -> 0.093231445 | F26: =F16/F3 -> 0.078520151
A28: Tax Rate
A29: Effective tax rate | B29: ='Consolidated P&L'!B27/B14 -> 0.18029678 | C29: ='Consolidated P&L'!C27/C14 -> 0.20817686 | D29: ='Consolidated P&L'!D27/D14 -> 0.22924917 | E29: ='Consolidated P&L'!E27/E14 -> 0.26423274 | F29: ='Consolidated P&L'!F27/F14 -> 0.23570329 | G29: =AVERAGE(B29:F29) -> 0.22353177 | H29: Effective tax rate
A30: Marginal Tax rate | B30: 0.3 | C30: 0.3 | D30: 0.3 | E30: 0.3 | F30: 0.3
A32: Return On Capital
A33: EBIT*(1-T) | B33: =B11*(1-B30) -> 2042.04 | C33: =C11*(1-C30) -> 5734.4 | D33: =D11*(1-D30) -> 9289.35 | E33: =E11*(1-E30) -> 10183.67 | F33: =F11*(1-F30) -> 10300.15
A34: Book Equity | B34: ='Consolidated Balance sheet'!B10 -> 55333.5 | C34: ='Consolidated Balance sheet'!C10 -> 61791.3 | D34: ='Consolidated Balance sheet'!D10 -> 85636 | E34: ='Consolidated Balance sheet'!E10 -> 96239.9 | F34: ='Consolidated Balance sheet'!F10 -> 107156.3
A35: Book Debt | B35: ='Consolidated Balance sheet'!B17 -> 381.9 | C35: ='Consolidated Balance sheet'!C17 -> 1215.8 | D35: ='Consolidated Balance sheet'!D17 -> 33.1 | E35: ='Consolidated Balance sheet'!E17 -> 0 | F35: ='Consolidated Balance sheet'!F17 -> 0
A36: Cash and Cash equivalents | B36: ='Consolidated Balance sheet'!B39 -> 3042.2 | C36: ='Consolidated Balance sheet'!C39 -> 41.6 | D36: ='Consolidated Balance sheet'!D39 -> 2827.4 | E36: ='Consolidated Balance sheet'!E39 -> 552.9 | F36: ='Consolidated Balance sheet'!F39 -> 1580
A37: Capital Employed | B37: =B34+B35-B36 -> 52673.2 | C37: =C34+C35-C36 -> 62965.5 | D37: =D34+D35-D36 -> 82841.7 | E37: =E34+E35-E36 -> 95687 | F37: =F34+F35-F36 -> 105576.3
A39: Pre-Tax Return on Capital | B39: =B11/B37 -> 0.055383003 | C39: =C11/C37 -> 0.13010299 | D39: =D11/D37 -> 0.16019106 | E39: =E11/E37 -> 0.15203842 | F39: =F11/F37 -> 0.13937314
A40: Post Tax Return on Capital | B40: =B33/B37 -> 0.038768102 | C40: =C33/C37 -> 0.091072095 | D40: =D33/D37 -> 0.11213374 | E40: =E33/E37 -> 0.10642689 | F40: =F33/F37 -> 0.097561195
A42: Growth In EBIT | B42: =AVERAGE(D11/C11-1,E11/D11-1,F11/E11-1) -> 0.24254856

Sheet Forecasting
D2: Sales Forecasting | I2: EBITDA Forecasting | N2: Earning per share Forecasting
D3: Year Weight | E3: Year | F3: Sales | G3: Sales Growth | I3: Year Weight | J3: Year | K3: EBITDA | L3: EBITDA Growth | N3: Year Weight | O3: Year | P3: EPS | Q3: EPS Growth
D4: 1 | E4: 44621 | F4: ='Consolidated P&L'!B8 -> 88329.8 | I4: 1 | J4: 44621 | K4: ='Consolidated P&L'!B22+'Consolidated P&L'!B16+'Consolidated P&L'!B17 -> 7450.9 | N4: 1 | O4: 44621 | P4: ='Consolidated P&L'!B34 -> 128
D5: 2 | E5: 44986 | F5: ='Consolidated P&L'!C8 -> 117571.3 | G5: =(F5-F4)/F4 -> 0.33104909 | I5: 2 | J5: 44986 | K5: ='Consolidated P&L'!C22+'Consolidated P&L'!C16+'Consolidated P&L'!C17 -> 13158.4 | L5: =(K5-K4)/K4 -> 0.76601484 | N5: 2 | O5: 44986 | P5: ='Consolidated P&L'!C34 -> 272 | Q5: =(P5-P4)/P4 -> 1.125
D6: 3 | E6: 45352 | F6: ='Consolidated P&L'!D8 -> 141858.2 | G6: =(F6-F5)/F5 -> 0.20657167 | I6: 3 | J6: 45352 | K6: ='Consolidated P&L'!D22+'Consolidated P&L'!D16+'Consolidated P&L'!D17 -> 22619.8 | L6: =(K6-K5)/K5 -> 0.71903879 | N6: 3 | O6: 45352 | P6: ='Consolidated P&L'!D34 -> 429 | Q6: =(P6-P5)/P5 -> 0.57720588
