Workbook

Sheet About the Company
C3: About the Company (NMDC LTD)
C5: Message from CMD - "Iron ore is the lifeblood of India's infrastructure and industrial economy. Every tonne we mine contributes directly to the nation's roads, railways, ports, factories, and homes. We are committed to Responsible Mining to ensure progress is rooted in responsibility." - Shri Amitava Mukherjee, Chairman & Managing Director, NMDC Limited Who We Are - NMDC Limited is India's largest iron ore producer and a Navratna Public Sector Enterprise under the Ministry of Steel, Government of India. With over six decades of operational excellence, NMDC specialises in mechanised, cost-efficient and sustainable mining, serving markets both within India and internationally. Our operations include some of India's most advanced iron ore mines in Chhattisgarh and Karnataka, as well as South-East Asia's only mechanised diamond mine in Panna, Madhya Pradesh. Our mines have earned 5-Star ratings from the Indian Bureau of Mines. Our R&D Centre in Hyderabad is recognised as a Centre of Excellence by UNIDO. Products & Services - Iron Ore Products: Baila ROM (Fe 65.5%), DRCLO (Fe 67%), Baila Lump (Fe 65.5%), 10-20mm Baila (Fe 65.5%), Baila Fine (Fe 64%), Kumaraswamy Lump (Fe 64.5%), Kumaraswamy Fine (Fe 65%), Doni Lump (Fe 61%), Doni Fines (Fe 60%), Iron Ore Pellets (BF Grade). Also produces Rough Diamonds from Panna Mines. Industries Served - Steel manufacturing (primary), infrastructure, power, construction. Key customers include major steel producers across India. Current production ~44.07 MnT iron ore per annum; target 100 MTPA by FY30. Vision - To emerge as a global environment friendly mining organisation and also as a quality steel producer with a positive thrust on social development. Mission - To maintain its leadership as the largest iron ore producer in India, while establishing itself as a quality steel producer and expanding business by acquiring and operating iron ore, coal and other mineral assets in India and abroad, rendering optimum satisfaction to all stakeholders. FY25 Key Highlights - Revenue from Operations: Rs.23,668 Cr | PAT: Rs.6,693 Cr | PBT: Rs.9,296 Cr | Net Worth: Rs.29,579 Cr | Dividend: Rs.2,901 Cr (330%) | EPS: Rs.7.61 | ROCE: 32% | Iron Ore Production: 44.07 MnT | Iron Ore Sales: 44.40 MnT | Pellet Production: 1,70,605 T | Diamond Production: 4,602.03 Carats
C19: Subsidiaries & Joint Ventures
C20: S.No | D20: Company Name | E20: Type | F20: Country / Stake
C21: 1 | D21: Karnataka Vijaynagar Steel Ltd. | E21: Wholly Owned Subsidiary | F21: India - 100%
C22: 2 | D22: NMDC CSR Foundation | E22: Wholly Owned Subsidiary | F22: India - 100%
C23: 3 | D23: J&KMDC Ltd. | E23: Subsidiary | F23: India - 95.86%
C24: 4 | D24: Legacy Iron Ore Ltd. | E24: Subsidiary | F24: Australia - 92.84%
C25: 5 | D25: Jharkhand NMDC Ltd. | E25: Joint Venture | F25: India - 60%
C26: 6 | D26: Bastar Railway Private Ltd. | E26: Joint Venture | F26: India - 52%
C27: 7 | D27: NMDC-CMDC Ltd. | E27: Joint Venture | F27: India - 51%
C29: Total Investments in Subsidiaries, JVs & Associates | D29: Rs.1,115.34 Crore
C32: Registered Office
C33: Khanij Bhavan, 10-3-311/A, Castle Hills, Masab Tank, Hyderabad - 500028, Telangana
C34: CIN: L13100AP1958GOI001674
C35: Website: www.nmdc.co.in | Email: investors@nmdc.co.in
C38: Units & Operational Footprint
C39: Company | D39: Unit Type | E39: Number | F39: Details
C40: NMDC Limited | D40: Iron Ore Mines | E40: 3 | F40: Bailadila Complex (CG), Donimalai & Kumaraswamy (KA)
C41: NMDC Limited | D41: Diamond Mine | E41: 1 | F41: Panna Diamond Mine, Madhya Pradesh
C42: NMDC Limited | D42: Pellet Plant | E42: 1 | F42: Donimalai Pellet Plant, Karnataka
C43: NMDC Limited | D43: R&D Centre | E43: 1 | F43: Hyderabad - UNIDO Centre of Excellence
C44: NMDC Limited | D44: Iron Ore Production Capacity | E44: 44 MnT | F44: Current; target 100 MTPA by FY30
C45: NMDC Limited | D45: Total Workforce | E45: 5677 | F45: As of FY2024-25
C46: NMDC Limited | D46: Countries of Operation | E46: 3 | F46: India, Australia, Mozambique
C47: NMDC Limited | D47: Stock Exchanges | E47: 2 | F47: BSE & NSE (Nifty 50 Index)
C50: Board of Directors
C51: Name | D51: Designation
C52: Shri Amitava Mukherjee | D52: Chairman & Managing Director
C53: Shri Vishwanath Suresh | D53: Director (Commercial)
C54: Shri Joydeep Dasgupta | D54: Director (Production)
C55: Shri Vinay Kumar | D55: Director (Technical)
C56: Smt. Priyadarshini Gaddam | D56: Director (Personnel) & Director (Finance) - Addl. Charge
C57: Shri Ashish Chatterjee IAS | D57: Addl. Secretary & Financial Advisor, Ministry of Steel (Govt. Nominee)
C58: Shri Abhijit Narendra IRTS | D58: Joint Secretary, Ministry of Steel (Govt. Nominee)
C59: Shri Sanjay Tandon | D59: Independent Director
C60: Shri Mahendra Singh Rao | D60: Independent Director
C61: Shri Bharat Baburao Patil | D61: Independent Director
C62: Shri Achal Kumar Sinha | D62: Independent Director
... C65: Shri B. Vishwanath IRSS | D65: Chief Vigilance Officer

Sheet Promoter
B2: NMDC Limited — Shareholding Pattern (As of Q4 FY2024-25)
B4: PROMOTER (GoI) | D4: INSTITUTIONAL (DII + FII) | F4: RETAIL & OTHERS
B5: 60.79% | D5: 27.36% | F5: 11.85%
B6: 5,34,49,00,713 shares | D6: DII: 13.76% | FII: 13.60% | F6: Retail + NRI + Bodies Corp.
B8: (A) Promoter & Promoter Group
B9: Category | C9: No. of Shareholders | D9: Shares Held | E9: Stake % | F9: Voting Rights % | G9: Demat Shares
B10: Central Govt. / State Govt. (Indian) | C10: 1 | D10: 5,34,49,00,713 | E10: 60.79% | F10: 60.79% | G10: 5,34,49,00,713
B11: PRESIDENT OF INDIA | C11: 1 | D11: 5,34,49,00,713 | E11: 60.79% | F11: 60.79% | G11: 5,34,49,00,713
B12: Sub-Total A1 (Indian) | C12: 1 | D12: 5,34,49,00,713 | E12: 60.79% | F12: 60.79% | G12: 5,34,49,00,713
B13: A2 — Foreign | C13: - | D13: - | E13: 0.00% | F13: 0.00% | G13: -
B14: TOTAL PROMOTER (A = A1 + A2) | C14: 1 | D14: 5,34,49,00,713 | E14: 60.79% | F14: 60.79% | G14: 5,34,49,00,713
B16: (B1) Domestic Institutional Investors (DII)
B17: Investor Category | C17: No. of Shareholders | D17: Shares Held | E17: Stake % | F17: Voting Rights % | G17: Demat Shares
B18: Mutual Funds | C18: 41 | D18: 58,95,25,071 | E18: 6.71% | F18: 6.71% | G18: 58,95,25,071
B19: SBI Arbitrage Opp. Fund ★ | C19: 1 | D19: 12,02,18,423 | E19: 1.37% | F19: 1.37% | G19: —
B20: Insurance Companies | C20: 27 | D20: 60,67,99,104 | E20: 6.90% | F20: 6.90% | G20: 60,67,99,104
B21: LIC of India ★ | C21: 1 | D21: 43,02,17,392 | E21: 4.89% | F21: 4.89% | G21: —
B22: Alternate Investment Funds | C22: 17 | D22: 84,47,230 | E22: 0.10% | F22: 0.10% | G22: 84,47,230
B23: Banks | C23: 3 | D23: 82,469 | E23: 0.00% | F23: 0.00% | G23: 82,469
B24: Other Financial Institutions | C24: 1 | D24: 46,93,620 | E24: 0.05% | F24: 0.05% | G24: 46,93,620
B25: NBFCs (RBI Registered) | C25: 10 | D25: 2,61,021 | E25: 0.00% | F25: 0.00% | G25: 2,61,021
B26: Sub-Total B1 — DII | C26: 99 | D26: 1,20,98,08,515 | E26: 13.76% | F26: 13.76% | G26: 1,20,98,08,515
B28: (B2) Foreign Institutional Investors (FII)
B29: Investor Category | C29: No. of Shareholders | D29: Shares Held | E29: Stake % | F29: Voting Rights % | G29: Demat Shares
B30: Foreign Portfolio Investors — Cat I | C30: 583 | D30: 1,13,53,68,005 | E30: 12.91% | F30: 12.91% | G30: 1,13,53,68,005
B31: Foreign Portfolio Investors — Cat II | C31: 31 | D31: 6,04,21,353 | E31: 0.69% | F31: 0.69% | G31: 6,04,21,353
B32: Foreign Direct Investment | C32: 0 | D32: — | E32: 0.00% | F32: 0.00% | G32: —
B33: Sovereign Wealth Funds | C33: 0 | D33: — | E33: 0.00% | F33: 0.00% | G33: —
B34: Sub-Total B2 — FII | C34: 614 | D34: 1,19,57,89,358 | E34: 13.60% | F34: 13.60% | G34: 1,19,57,89,358
B36: (B4) Non-Institutions (Retail & Others)
B37: Category | C37: No. of Shareholders | D37: Shares Held | E37: Stake % | F37: Voting Rights % | G37: Demat Shares
B38: Resident Individuals (≤ ₹2L capital) | C38: 1112355 | D38: 75,48,95,145 | E38: 8.59% | F38: 8.59% | G38: 75,48,37,682
B39: Resident Individuals (> ₹2L capital) | C39: 160 | D39: 13,24,54,755 | E39: 1.51% | F39: 1.51% | G39: 13,24,54,755
B40: Bodies Corporate | C40: 2536 | D40: 10,93,14,096 | E40: 1.24% | F40: 1.24% | G40: 10,93,12,096
B41: Non-Resident Indians (NRIs) | C41: 14956 | D41: 3,96,00,637 | E41: 0.45% | F41: 0.45% | G41: 3,96,00,637
B42: Trusts | C42: 60 | D42: 42,20,003 | E42: 0.05% | F42: 0.05% | G42: 42,20,003
B43: Employees | C43: 114 | D43: 2,08,479 | E43: 0.00% | F43: 0.00% | G43: 2,00,989
B44: IEPF | C44: 1 | D44: 2,23,561 | E44: 0.00% | F44: 0.00% | G44: 2,23,561
B45: Others (FPI Cat III, Clearing, etc.) | C45: 10 | D45: 3,94,088 | E45: 0.00% | F45: 0.00% | G45: 3,94,088
B46: Foreign Nationals | C46: 3 | D46: 3,802 | E46: 0.00% | F46: 0.00% | G46: 3,802
...

Sheet Public
B2: NMDC Limited — Public Shareholding Detail (Q4 FY2024-25)
B4: DOMESTIC INSTITUTIONS (DII) | D4: FOREIGN INSTITUTIONS (FII) | F4: RETAIL & OTHERS
B5: 13.76% | D5: 13.60% | F5: 11.84%
B6: 99 shareholders | 1,20,98,08,515 shares | D6: 614 shareholders | 1,19,57,89,358 shares | F6: 11,30,198 shareholders | 1,04,13,14,746 shares
B9: (B1) Domestic Institutional Investors (DII)
B10: Category & Name of Shareholders | C10: No. of Shareholders | D10: Shares Held | E10: Stake % (A+B+C2) | F10: Voting Rights % | G10: Diluted Stake % | H10: Demat Shares
B11: Institutions | C11: 0 | D11: 0 | E11: - | F11: - | G11: - | H11: -
B12: B2) Institutions (Domestic) | C12: 0 | D12: 0 | E12: - | F12: - | G12: - | H12: -
B13: Mutual Funds | C13: 41 | D13: 58,95,25,071 | E13: 6.71% | F13: 6.71% | G13: 6.71% | H13: 58,95,25,071
B14: SBI Arbitrage Opportunities Fund ★ | C14: 1 | D14: 12,02,18,423 | E14: 1.37% | F14: 1.37% | G14: 1.37% | H14: —
B15: Venture Capital Funds | C15: 0 | D15: 0 | E15: — | F15: — | G15: — | H15: —
B16: Alternate Investment Funds | C16: 17 | D16: 84,47,230 | E16: 0.10% | F16: 0.10% | G16: 0.10% | H16: 84,47,230
B17: Banks | C17: 3 | D17: 82,469 | E17: 0.00% | F17: 0.00% | G17: 0.00% | H17: 82,469
B18: Insurance Companies | C18: 27 | D18: 60,67,99,104 | E18: 6.90% | F18: 6.90% | G18: 6.90% | H18: 60,67,99,104
B19: Life Insurance Corporation of India ★ | C19: 1 | D19: 43,02,17,392 | E19: 4.89% | F19: 4.89% | G19: 4.89% | H19: —
B20: Provident Funds / Pension Funds | C20: 0 | D20: 0 | E20: — | F20: — | G20: — | H20: —
B21: Asset Reconstruction Companies | C21: 0 | D21: 0 | E21: — | F21: — | G21: — | H21: —
B22: Sovereign Wealth Funds | C22: 0 | D22: 0 | E22: — | F22: — | G22: — | H22: —
B23: NBFCs Registered with RBI | C23: 10 | D23: 2,61,021 | E23: 0.00% | F23: 0.00% | G23: 0.00% | H23: 2,61,021
B24: Other Financial Institutions | C24: 1 | D24: 46,93,620 | E24: 0.05% | F24: 0.05% | G24: 0.05% | H24: 46,93,620
B25: Any Other — Institutions (Domestic) | C25: 0 | D25: 0 | E25: — | F25: — | G25: — | H25: —
B26: Sub-Total B1 — DII | C26: 99 | D26: 1,20,98,08,515 | E26: 13.76% | F26: 13.76% | G26: 13.76% | H26: 1,20,98,08,515
B28: (B2) Foreign Institutional Investors (FII)
B29: Category & Name of Shareholders | C29: No. of Shareholders | D29: Shares Held | E29: Stake % (A+B+C2) | F29: Voting Rights % | G29: Diluted Stake % | H29: Demat Shares
B30: B17) Institutions (Foreign) | C30: 0 | D30: 0 | E30: - | F30: - | G30: - | H30: -
B31: Foreign Direct Investment | C31: 0 | D31: 0 | E31: — | F31: — | G31: — | H31: —
B32: Foreign Venture Capital Investors | C32: 0 | D32: 0 | E32: — | F32: — | G32: — | H32: —
B33: Sovereign Wealth Funds | C33: 0 | D33: 0 | E33: — | F33: — | G33: — | H33: —
B34: Foreign Portfolio Investors — Category I | C34: 583 | D34: 1,13,53,68,005 | E34: 12.91% | F34: 12.91% | G34: 12.91% | H34: 1,13,53,68,005
B35: Foreign Portfolio Investors — Category II | C35: 31 | D35: 6,04,21,353 | E35: 0.69% | F35: 0.69% | G35: 0.69% | H35: 6,04,21,353
B36: Overseas Depositories (DRs) — balancing | C36: 0 | D36: 0 | E36: — | F36: — | G36: — | H36: —
B37: Any Other — Institutions (Foreign) | C37: 0 | D37: 0 | E37: — | F37: — | G37: — | H37: —
B38: Sub-Total B2 — FII | C38: 614 | D38: 1,19,57,89,358 | E38: 13.60% | F38: 13.60% | G38: 13.60% | H38: 1,19,57,89,358
B40: (B3) Central / State Government (in Public Category)
B41: Category & Name of Shareholders | C41: No. of Shareholders | D41: Shares Held | E41: Stake % (A+B+C2) | F41: Voting Rights % | G41: Diluted Stake % | H41: Demat Shares
B42: B26) Central Govt./ State Govt./ President of India | C42: 0 | D42: 0 | E42: - | F42: - | G42: - | H42: -
B43: Central Government / President of India | C43: 0 | D43: 0 | E43: — | F43: — | G43: — | H43: —
B44: State Government / Governor | C44: 0 | D44: 0 | E44: — | F44: — | G44: — | H44: —
B45: Bodies Corporate (Central/State Govt. promoter) | C45: 2 | D45: 4,218 | E45: 0.00% | F45: 0.00% | G45: 0.00% | H45: 4,218
B46: Sub-Total B3 | C46: 2 | D46: 4,218 | E46: 0.00% | F46: 0.00% | G46: 0.00% | H46: 4,218
...

Sheet Standalone Quarterly Results
D2: Standalone Quarterly Results (Rs. Crores) | K2: % CHANGE
E3: Quarter ended | G3: Half Year ended | I3: Years | K3: QTQ | L3: HY YOY | M3: YOY
D4: Particulars | E4: 45992 | F4: 45901 | G4: 45992 | H4: 45627 | I4: 45717 | J4: 45352
D5: I. REVENUE
D6: Net Sales/Income from Operations | E6: 7485 | F6: 6260 | G6: 13745 | H6: 11336 | I6: 23668.32 | J6: 21293.81 | K6: =(E6-F6)/F6 -> 0.1956869 | L6: =(G6-H6)/H6 -> 0.21250882 | M6: =(I6-J6)/J6 -> 0.11151175
D7: Other Operating Income
D8: Total Income From Operations | E8: 7485 | F8: 6260 | G8: 13745 | H8: 11336 | I8: 23668.32 | J8: 21293.81 | K8: =(E8-F8)/F8 -> 0.1956869 | L8: =(G8-H8)/H8 -> 0.21250882 | M8: =(I8-J8)/J8 -> 0.11151175
D9: II. EXPENSES
D10: Consumption of Raw Materials | E10: 0 | F10: 1 | G10: 1 | H10: 278 | I10: 12.42 | J10: 20.97 | K10: =IF(F10<>0,(E10-F10)/ABS(F10),"") -> -1 | L10: =IF(H10<>0,(G10-H10)/ABS(H10),"") -> -0.99640288 | M10: =(I10-J10)/J10 -> -0.40772532
D11: Purchase of Traded Goods | E11: 582 | F11: 430 | G11: 1012 | H11: 113 | I11: 197.09 | K11: =IF(F11<>0,(E11-F11)/ABS(F11),"") -> 0.35348837 | L11: =IF(H11<>0,(G11-H11)/ABS(H11),"") -> 7.9557522
D12: Increase / Decrease in Stocks | E12: -53 | F12: 100 | G12: 47 | H12: 140 | I12: 81.97 | J12: -66.08 | K12: =IF(F12<>0,(E12-F12)/ABS(F12),"") -> -1.53 | L12: =IF(H12<>0,(G12-H12)/ABS(H12),"") -> -0.66428571 | M12: =(I12-J12)/J12 -> -2.2404661
D13: Power & Fuel
D14: Employee Benefits Expense | E14: 442 | F14: 401 | G14: 843 | H14: 847 | I14: 1781.44 | J14: 1619.44 | K14: =(E10-F10)/F10 -> -1 | L14: =(G10-H10)/H10 -> -0.99640288 | M14: =(I14-J14)/J14 -> 0.10003458
D15: Depreciation & Amortisation | E15: 103 | F15: 106 | G15: 209 | H15: 176 | I15: 372.78 | J15: 337.05 | K15: =IF(F15<>0,(E15-F15)/ABS(F15),"") -> -0.028301887 | L15: =IF(H15<>0,(G15-H15)/ABS(H15),"") -> 0.1875 | M15: =(I15-J15)/J15 -> 0.10600801
D16: Excise Duty
D17: Admin. And Selling Expenses | E17: 0 | F17: 0 | G17: 0 | H17: 0 | J17: 329.52 | K17: =IF(F17<>0,(E17-F17)/ABS(F17),"") | L17: =IF(H17<>0,(G17-H17)/ABS(H17),"") | M17: =(I17-J17)/J17 -> -1
D18: R & D Expenses
D19: Provisions And Contingencies
D20: Exp. Capitalised
D21: Other Expenses | E21: 4365 | F21: 3322 | G21: 7687 | H21: 6106 | I21: 13337.54 | J21: 12034.76 | K21: =IF(F21<>0,(E21-F21)/ABS(F21),"") -> 0.31396749 | L21: =IF(H21<>0,(G21-H21)/ABS(H21),"") -> 0.25892565 | M21: =(I21-J21)/J21 -> 0.10825143
D22: Finance Costs | E22: 34 | F22: 7 | G22: 41 | H22: 89 | I22: 177.65 | J22: 78.24 | K22: =IF(F22<>0,(E22-F22)/ABS(F22),"") -> 3.8571429 | L22: =IF(H22<>0,(G22-H22)/ABS(H22),"") -> -0.53932584 | M22: =(I22-J22)/J22 -> 1.2705777
D23: Total Expenses | E23: 4944 | F23: 3836 | G23: 8780 | H23: 7218 | I23: 15960.89 | J23: 14353.88 | K23: =IF(F23<>0,(E23-F23)/ABS(F23),"") -> 0.28884254 | L23: =IF(H23<>0,(G23-H23)/ABS(H23),"") -> 0.21640344 | M23: =(I23-J23)/J23 -> 0.11195649
D24: III. PROFIT & LOSS
D25: EBITDA | E25: 2503 | F25: 2384 | G25: 4887 | H25: 4583 | I25: 8257.86 | J25: 7355.2 | K25: =IF(AND(F25<>0,ISNUMBER(F25)),(E25-F25)/ABS(F25),"") -> 0.049916107 | L25: =IF(AND(H25<>0,ISNUMBER(H25)),(G25-H25)/ABS(H25),"") -> 0.066332097 | M25: =(I25-J25)/J25 -> 0.12272406
D26: P/L Before Other Inc., Int., Excpt. Items & Tax | E26: 2044 | F26: 1897 | G26: 3941 | H26: 3672 | I26: 7885.08 | J26: 7018.15 | K26: =IF(F26<>0,(E26-F26)/ABS(F26),"") -> 0.077490775 | L26: =IF(H26<>0,(G26-H26)/ABS(H26),"") -> 0.073257081 | M26: =(I26-J26)/J26 -> 0.12352686
D27: Other Income | E27: 356 | F27: 381 | G27: 737 | H27: 734 | I27: 1590.24 | J27: 1355.54 | K27: =IF(F27<>0,(E27-F27)/ABS(F27),"") -> -0.065616798 | L27: =IF(H27<>0,(G27-H27)/ABS(H27),"") -> 0.0040871935 | M27: =(I27-J27)/J27 -> 0.17314133
D28: P/L Before Int., Excpt. Items & Tax (EBIT) | E28: 2400 | F28: 2278 | G28: 4678 | H28: 4407 | I28: 9475.32 | J28: 8373.69 | K28: =IF(F28<>0,(E28-F28)/ABS(F28),"") -> 0.053555751 | L28: =IF(H28<>0,(G28-H28)/ABS(H28),"") -> 0.061493079 | M28: =(I28-J28)/J28 -> 0.13155849
D29: Finance Costs (Interest) | E29: 34 | F29: 7 | G29: 41 | H29: 89 | I29: 177.65 | J29: 78.24 | K29: =IF(F29<>0,(E29-F29)/ABS(F29),"") -> 3.8571429 | L29: =IF(H29<>0,(G29-H29)/ABS(H29),"") -> -0.53932584 | M29: =(I29-J29)/J29 -> 1.2705777
D30: Profit before Exceptional Items & Tax | E30: 2365 | F30: 2270 | G30: 4635 | H30: 4317 | I30: 9297.67 | J30: 8295.45 | K30: =IF(F30<>0,(E30-F30)/ABS(F30),"") -> 0.04185022 | L30: =IF(H30<>0,(G30-H30)/ABS(H30),"") -> 0.073662265 | M30: =(I30-J30)/J30 -> 0.12081563
D31: Exceptional Items | E31: 0 | F31: 0 | G31: 0 | H31: 0 | J31: -282.15 | K31: =IF(F31<>0,(E31-F31)/ABS(F31),"") | L31: =IF(H31<>0,(G31-H31)/ABS(H31),"") | M31: =(I31-J31)/J31 -> -1
D32: Profit Before Tax | E32: 2365 | F32: 2270 | G32: 4635 | H32: 4317 | I32: 9297.67 | J32: 8013.3 | K32: =IF(F32<>0,(E32-F32)/ABS(F32),"") -> 0.04185022 | L32: =IF(H32<>0,(G32-H32)/ABS(H32),"") -> 0.073662265 | M32: =(I32-J32)/J32 -> 0.16027978
D33: Tax Expense | E33: 627 | F33: 576 | G33: 1203 | H33: 1104 | I33: 2604.14 | J33: 2380.42 | K33: =IF(F33<>0,(E33-F33)/ABS(F33),"") -> 0.088541667 | L33: =IF(H33<>0,(G33-H33)/ABS(H33),"") -> 0.089673913 | M33: =(I33-J33)/J33 -> 0.093983415
D34: P/L After Tax from Ordinary Activities | E34: 1738 | F34: 1694 | G34: 3432 | H34: 3212 | I34: 6693.53 | J34: 5632.88 | K34: =IF(F34<>0,(E34-F34)/ABS(F34),"") -> 0.025974026 | L34: =IF(H34<>0,(G34-H34)/ABS(H34),"") -> 0.068493151 | M34: =(I34-J34)/J34 -> 0.18829622
D35: Prior Year Adjustments
D36: Extra Ordinary Items | E36: 0 | F36: 0 | G36: 0 | H36: 0 | I36: -0.93 | J36: -0.99 | M36: =(I36-J36)/J36 -> -0.060606061
D37: Net Profit/(Loss) For the Period | E37: 1738 | F37: 1694 | G37: 3432 | H37: 3212 | I37: 6692.6 | J37: 5631.89 | K37: =IF(F37<>0,(E37-F37)/ABS(F37),"") -> 0.025974026 | L37: =IF(H37<>0,(G37-H37)/ABS(H37),"") -> 0.068493151 | M37: =(I37-J37)/J37 -> 0.18833997
D38: IV. EARNINGS PER SHARE (Rs.)
D39: EPS Before Extra Ordinary - Basic | E39: 1.98 | F39: 1.93 | G39: 3.9 | H39: 3.65 | I39: 7.61 | J39: 19.22 | K39: =IF(AND(F39<>0,ISNUMBER(F39)),(E39-F39)/ABS(F39),"") -> 0.025906736 | L39: =IF(AND(H39<>0,ISNUMBER(H39)),(G39-H39)/ABS(H39),"") -> 0.068493151 | M39: =(I39-J39)/J39 -> -0.60405827
D40: EPS Before Extra Ordinary - Diluted | E40: 1.98 | F40: 1.93 | G40: 3.9 | H40: 3.65 | I40: 7.61 | J40: 19.22 | K40: =IF(F40<>0,(E40-F40)/ABS(F40),"") -> 0.025906736 | L40: =IF(H40<>0,(G40-H40)/ABS(H40),"") -> 0.068493151 | M40: =(I40-J40)/J40 -> -0.60405827
D41: EPS After Extra Ordinary - Basic | E41: 1.98 | F41: 1.93 | G41: 3.9 | H41: 3.65 | I41: 7.61 | J41: 19.22 | K41: =IF(F41<>0,(E41-F41)/ABS(F41),"") -> 0.025906736 | L41: =IF(H41<>0,(G41-H41)/ABS(H41),"") -> 0.068493151 | M41: =(I41-J41)/J41 -> -0.60405827
...

Sheet Consolidated Quarterly Results
D2: Consolidated Quarterly Results (Rs. Crores) | K2: % CHANGE
E3: Quarter ended | H3: Years | K3: QTQ | L3: QOQ YOY | M3: YOY
D4: Particulars | E4: 45992 | F4: 45901 | G4: 45627 | H4: 45717 | I4: 45352
D5: I. REVENUE
D6: Net Sales/Income from Operations | E6: 7610 | F6: 6378 | G6: 6567 | H6: 23905.52 | I6: 21307.85 | K6: =(E6-F6)/F6 -> 0.193164 | L6: =IF(G6<>0,(E6-G6)/ABS(G6),"") -> 0.15882443 | M6: =(H6-I6)/I6 -> 0.12191141
D7: Other Operating Income
D8: Total Income From Operations | E8: 7610 | F8: 6378 | G8: 6567 | H8: 23905.52 | I8: 21307.85 | K8: =(E8-F8)/F8 -> 0.193164 | L8: =IF(G8<>0,(E8-G8)/ABS(G8),"") -> 0.15882443 | M8: =(H8-I8)/I8 -> 0.12191141
D9: II. EXPENSES
D10: Consumption of Raw Materials | E10: 0 | F10: 1 | G10: 192 | H10: 12.42 | I10: 20.97 | K10: =(E10-F10)/F10 -> -1 | L10: =IF(G10<>0,(E10-G10)/ABS(G10),"") -> -1 | M10: =(H10-I10)/I10 -> -0.40772532
D11: Purchase of Traded Goods | E11: 582 | F11: 430 | G11: 113 | H11: 197.09 | K11: =(E11-F11)/F11 -> 0.35348837 | L11: =IF(G11<>0,(E11-G11)/ABS(G11),"") -> 4.1504425
D12: Increase / Decrease in Stocks | E12: -52 | F12: 107 | G12: -340 | H12: 99.31 | I12: -93.36 | K12: =(E12-F12)/F12 -> -1.4859813 | L12: =IF(G12<>0,(E12-G12)/ABS(G12),"") -> 0.84705882 | M12: =(H12-I12)/I12 -> -2.0637318
D13: Power & Fuel
D14: Employee Benefits Expense | E14: 445 | F14: 402 | G14: 439 | H14: 1795.04 | I14: 1625.54 | K14: =(E14-F14)/F14 -> 0.10696517 | L14: =IF(G10<>0,(E10-G10)/ABS(G10),"") -> -1 | M14: =(H14-I14)/I14 -> 0.10427304
D15: Depreciation & Amortisation | E15: 106 | F15: 110 | G15: 102 | H15: 420.42 | I15: 350.66 | K15: =(E15-F15)/F15 -> -0.036363636 | L15: =IF(G15<>0,(E15-G15)/ABS(G15),"") -> 0.039215686 | M15: =(H15-I15)/I15 -> 0.19893914
D16: Excise Duty
D17: Admin. And Selling Expenses | E17: 0 | F17: 0 | G17: 0 | H17: 538.94 | I17: 338.47 | L17: =IF(G17<>0,(E17-G17)/ABS(G17),"") | M17: =(H17-I17)/I17 -> 0.59228292
D18: R & D Expenses
D19: Provisions And Contingencies
D20: Exp. Capitalised
D21: Other Expenses | E21: 4492 | F21: 3442 | G21: 3790 | H21: 13114.05 | I21: 12123.4 | K21: =(E21-F21)/F21 -> 0.3050552 | L21: =IF(G21<>0,(E21-G21)/ABS(G21),"") -> 0.18522427 | M21: =(H21-I21)/I21 -> 0.081713876
D22: Finance Costs | E22: 34 | F22: 7 | G22: 60 | H22: 177.68 | I22: 78.24 | K22: =(E22-F22)/F22 -> 3.8571429 | L22: =IF(G22<>0,(E22-G22)/ABS(G22),"") -> -0.43333333 | M22: =(H22-I22)/I22 -> 1.2709611
D23: Total Expenses | E23: 5077 | F23: 3961 | G23: 4391 | H23: 16354.95 | I23: 14443.92 | K23: =(E23-F23)/F23 -> 0.28174703 | L23: =IF(G23<>0,(E23-G23)/ABS(G23),"") -> 0.15622865 | M23: =(H23-I23)/I23 -> 0.13230688
D24: III. PROFIT & LOSS
D25: EBITDA | E25: 2514 | F25: 2375 | G25: 2745 | H25: 8148.67 | I25: 7292.83 | K25: =(E25-F25)/F25 -> 0.058526316 | L25: =IF(G16<>0,(E16-G16)/ABS(G16),"") | M25: =(H25-I25)/I25 -> 0.11735362
D26: P/L Before Other Inc., Int., Excpt. Items & Tax | E26: 2037 | F26: 1883 | G26: 2269 | H26: 7728.25 | I26: 6942.17 | K26: =(E26-F26)/F26 -> 0.081784387 | L26: =IF(G26<>0,(E26-G26)/ABS(G26),"") -> -0.10224769 | M26: =(H26-I26)/I26 -> 0.11323261
D27: Other Income | E27: 372 | F27: 383 | G27: 375 | H27: 1593.32 | I27: 1370.88 | K27: =(E27-F27)/F27 -> -0.028720627 | L27: =IF(G27<>0,(E27-G27)/ABS(G27),"") -> -0.008 | M27: =(H27-I27)/I27 -> 0.16226074
D28: P/L Before Int., Excpt. Items & Tax (EBIT) | E28: 2408 | F28: 2265 | G28: 2643 | H28: 9321.57 | I28: 8313.05 | K28: =(E28-F28)/F28 -> 0.063134658 | L28: =IF(G28<>0,(E28-G28)/ABS(G28),"") -> -0.088914113 | M28: =(H28-I28)/I28 -> 0.12131769
D29: Finance Costs (Interest) | E29: 34 | F29: 7 | G29: 60 | H29: 177.68 | I29: 78.24 | K29: =(E29-F29)/F29 -> 3.8571429 | L29: =IF(G29<>0,(E29-G29)/ABS(G29),"") -> -0.43333333 | M29: =(H29-I29)/I29 -> 1.2709611
D30: Profit before Exceptional Items & Tax | E30: 2374 | F30: 2258 | G30: 2583 | H30: 9143.89 | I30: 8234.81 | K30: =(E30-F30)/F30 -> 0.051372896 | L30: =IF(G30<>0,(E30-G30)/ABS(G30),"") -> -0.080913666 | M30: =(H30-I30)/I30 -> 0.11039478
D31: Exceptional Items | E31: 0 | F31: 0 | G31: 0 | I31: -282.15 | L31: =IF(G31<>0,(E31-G31)/ABS(G31),"") | M31: =(H31-I31)/I31 -> -1
D32: Profit Before Tax | E32: 2374 | F32: 2258 | G32: 2583 | H32: 9143.89 | I32: 7952.66 | K32: =(E32-F32)/F32 -> 0.051372896 | L32: =IF(G32<>0,(E32-G32)/ABS(G32),"") -> -0.080913666 | M32: =(H32-I32)/I32 -> 0.14979013
D33: Tax Expense | E33: 627 | F33: 576 | G33: 686 | H33: 2604.14 | I33: 2380.42 | K33: =(E33-F33)/F33 -> 0.088541667 | L33: =IF(G33<>0,(E33-G33)/ABS(G33),"") -> -0.086005831 | M33: =(H33-I33)/I33 -> 0.093983415
D34: P/L After Tax from Ordinary Activities | E34: 1747 | F34: 1682 | G34: 1896 | H34: 6539.75 | I34: 5572.24 | K34: =(E34-F34)/F34 -> 0.038644471 | L34: =IF(G34<>0,(E34-G34)/ABS(G34),"") -> -0.078586498 | M34: =(H34-I34)/I34 -> 0.17363035
D35: Share Of P/L Of Associates | E35: 10 | F35: 15 | G35: 1 | H35: 10.95 | I35: -0.38 | K35: =(E35-F35)/F35 -> -0.33333333 | L35: =IF(G35<>0,(E35-G35)/ABS(G35),"") -> 9 | M35: =(H35-I35)/I35 -> -29.815789
D36: Minority Interest | E36: 0 | F36: 0 | G36: -16 | H36: -7.79 | I36: 4.19 | L36: =IF(G36<>0,(E36-G36)/ABS(G36),"") -> 1 | M36: =(H36-I36)/I36 -> -2.8591885
D37: Net P/L After Minority Interest & Associates | E37: 1756 | F37: 1698 | G37: 1881 | H37: 6541.98 | I37: 5575.06 | K37: =(E37-F37)/F37 -> 0.034157833 | L37: =IF(G37<>0,(E37-G37)/ABS(G37),"") -> -0.066454014 | M37: =(H37-I37)/I37 -> 0.1734367
D38: Total Comprehensive Income | E38: 1756 | F38: 1698 | G38: 1881 | H38: 6541.98 | I38: 5575.06 | K38: =(E38-F38)/F38 -> 0.034157833 | L38: =IF(G25<>0,(E25-G25)/ABS(G25),"") -> -0.084153005 | M38: =(H38-I38)/I38 -> 0.1734367
D39: Prior Year Adjustments
D40: Extra Ordinary Items | E40: 0 | F40: 0 | G40: 0 | H40: -0.93 | I40: -0.99 | M40: =(H40-I40)/I40 -> -0.060606061
D41: Net Profit/(Loss) For the Period | E41: 1756 | F41: 1698 | G41: 1881 | H41: 6538.82 | I41: 5571.25 | K41: =(E41-F41)/F41 -> 0.034157833 | L41: =IF(G41<>0,(E41-G41)/ABS(G41),"") -> -0.066454014 | M41: =(H41-I41)/I41 -> 0.17367198
...

Sheet Standalone balance sheet
A1: NMDC - Standalone Balance Sheet (Rs. Cr.)
A2: Particulars (Rs. Cr.) | B2: Mar 25 | C2: Mar 24 | D2: Mar 23 | E2: Mar 22 | F2: Mar 21 | G2: % Chg Mar 25/Mar 24 | H2: % Chg Mar 24/Mar 23 | I2: % Chg Mar 23/Mar 22 | J2: % Chg Mar 22/Mar 21
A3: 12 Months Ended | B3: 12 mths | C3: 12 mths | D3: 12 mths | E3: 12 mths | F3: 12 mths
A4: EQUITIES AND LIABILITIES
A5: SHAREHOLDER'S FUNDS
A6: Equity Share Capital | B6: 879.18 | C6: 293.07 | D6: 293.07 | E6: 293.07 | F6: 293.07 | G6: =(B6-C6)/C6 -> 1.9998976 | H6: =(C6-D6)/D6 -> 0 | I6: =(D6-E6)/E6 -> 0 | J6: =(E6-F6)/F6 -> 0
A7: Total Share Capital | B7: 879.18 | C7: 293.07 | D7: 293.07 | E7: 293.07 | F7: 293.07 | G7: =(B7-C7)/C7 -> 1.9998976 | H7: =(C7-D7)/D7 -> 0 | I7: =(D7-E7)/E7 -> 0 | J7: =(E7-F7)/F7 -> 0
A8: Reserves and Surplus | B8: 28700 | C8: 25112.71 | D8: 22039.24 | E8: 34550.9 | F8: 29463.07 | G8: =(B8-C8)/C8 -> 0.14284759 | H8: =(C8-D8)/D8 -> 0.13945445 | I8: =(D8-E8)/E8 -> -0.36212255 | J8: =(E8-F8)/F8 -> 0.17268499
A9: Total Reserves and Surplus | B9: 28700 | C9: 25112.71 | D9: 22039.24 | E9: 34550.9 | F9: 29463.07 | G9: =(B9-C9)/C9 -> 0.14284759 | H9: =(C9-D9)/D9 -> 0.13945445 | I9: =(D9-E9)/E9 -> -0.36212255 | J9: =(E9-F9)/F9 -> 0.17268499
A10: Total Shareholders Funds | B10: 29579.18 | C10: 25405.78 | D10: 22332.31 | E10: 34843.97 | F10: 29756.14 | G10: =(B10-C10)/C10 -> 0.16426971 | H10: =(C10-D10)/D10 -> 0.13762437 | I10: =(D10-E10)/E10 -> -0.35907676 | J10: =(E10-F10)/F10 -> 0.17098421
A11: NON-CURRENT LIABILITIES
A12: Long Term Borrowings | B12: 0 | C12: 0 | D12: 0 | E12: 1668.22 | F12: 546.43 | H12: =IF(D12<>0,C12/D12-1,"") | I12: =(D12-E12)/E12 -> -1 | J12: =(E12-F12)/F12 -> 2.0529437
A13: Other Long Term Liabilities | B13: 152.25 | C13: 151.95 | D13: 155.02 | E13: 156.13 | F13: 4.57 | G13: =(B13-C13)/C13 -> 0.0019743337 | H13: =(C13-D13)/D13 -> -0.019803896 | I13: =(D13-E13)/E13 -> -0.0071094601 | J13: =(E13-F13)/F13 -> 33.164114
A14: Long Term Provisions | B14: 1453.81 | C14: 1430.75 | D14: 1255.56 | E14: 1092 | F14: 945.16 | G14: =(B14-C14)/C14 -> 0.016117421 | H14: =(C14-D14)/D14 -> 0.13953136 | I14: =(D14-E14)/E14 -> 0.14978022 | J14: =(E14-F14)/F14 -> 0.15535994
A15: Total Non-Current Liabilities | B15: 1606.06 | C15: 1582.7 | D15: 1410.58 | E15: 2916.35 | F15: 1496.16 | G15: =(B15-C15)/C15 -> 0.014759588 | H15: =(C15-D15)/D15 -> 0.12202073 | I15: =(D15-E15)/E15 -> -0.51632006 | J15: =(E15-F15)/F15 -> 0.94922335
A16: CURRENT LIABILITIES
A17: Short Term Borrowings | B17: 3770.45 | C17: 3356.54 | D17: 415.98 | E17: 1815.13 | F17: 1448.04 | G17: =(B17-C17)/C17 -> 0.12331448 | H17: =(C17-D17)/D17 -> 7.0689937 | I17: =(D17-E17)/E17 -> -0.77082633 | J17: =(E17-F17)/F17 -> 0.25350819
A18: Trade Payables | B18: 298.49 | C18: 372.52 | D18: 425.76 | E18: 967.22 | F18: 360.26 | G18: =(B18-C18)/C18 -> -0.19872759 | H18: =(C18-D18)/D18 -> -0.12504697 | I18: =(D18-E18)/E18 -> -0.55981059 | J18: =(E18-F18)/F18 -> 1.6847832
A19: Other Current Liabilities | B19: 5190.94 | C19: 4377.14 | D19: 3233.84 | E19: 4134.88 | F19: 3626.3 | G19: =(B19-C19)/C19 -> 0.18592049 | H19: =(C19-D19)/D19 -> 0.35354254 | I19: =(D19-E19)/E19 -> -0.21791201 | J19: =(E19-F19)/F19 -> 0.14024764
A20: Short Term Provisions | B20: 382.61 | C20: 254.41 | D20: 123.23 | E20: 14.39 | F20: 98 | G20: =(B20-C20)/C20 -> 0.50391101 | H20: =(C20-D20)/D20 -> 1.0645135 | I20: =(D20-E20)/E20 -> 7.5635858 | J20: =(E20-F20)/F20 -> -0.85316327
A21: Total Current Liabilities | B21: 9642.49 | C21: 8360.61 | D21: 4198.81 | E21: 6931.62 | F21: 5532.6 | G21: =(B21-C21)/C21 -> 0.15332374 | H21: =(C21-D21)/D21 -> 0.9911856 | I21: =(D21-E21)/E21 -> -0.39425271 | J21: =(E21-F21)/F21 -> 0.25286845
A22: Total Capital And Liabilities | B22: 40827.73 | C22: 35349.09 | D22: 27941.7 | E22: 44691.94 | F22: 36784.9 | G22: =(B22-C22)/C22 -> 0.15498673 | H22: =(C22-D22)/D22 -> 0.26510162 | I22: =(D22-E22)/E22 -> -0.37479331 | J22: =(E22-F22)/F22 -> 0.21495342
A23: ASSETS
A24: NON-CURRENT ASSETS
A25: Tangible Assets | B25: 4156.54 | C25: 2499.06 | D25: 2385.54 | E25: 3522.13 | F25: 2677.28 | G25: =(B25-C25)/C25 -> 0.66324138 | H25: =(C25-D25)/D25 -> 0.04758671 | I25: =(D25-E25)/E25 -> -0.32269962 | J25: =(E25-F25)/F25 -> 0.31556281
A26: Intangible Assets | B26: 645.61 | C26: 663.59 | D26: 628.33 | E26: 443.9 | F26: 441.17 | G26: =(B26-C26)/C26 -> -0.027095044 | H26: =(C26-D26)/D26 -> 0.056117009 | I26: =(D26-E26)/E26 -> 0.41547646 | J26: =(E26-F26)/F26 -> 0.0061880908
A27: Capital Work-In-Progress | B27: 4737.48 | C27: 3230.51 | D27: 1961.72 | E27: 18294.69 | F27: 17076.68 | G27: =(B27-C27)/C27 -> 0.46648052 | H27: =(C27-D27)/D27 -> 0.64677426 | I27: =(D27-E27)/E27 -> -0.89277107 | J27: =(E27-F27)/F27 -> 0.071325925
A28: Intangible Assets Under Development | B28: 0 | C28: 4.14 | D28: 6.49 | E28: 5 | F28: 51.42 | G28: =(B28-C28)/C28 -> -1 | H28: =(C28-D28)/D28 -> -0.36209553 | I28: =(D28-E28)/E28 -> 0.298 | J28: =(E28-F28)/F28 -> -0.90276157
A29: Fixed Assets | B29: 9539.63 | C29: 6397.3 | D29: 4982.08 | E29: 22265.72 | F29: 20246.55 | G29: =(B29-C29)/C29 -> 0.49119629 | H29: =(C29-D29)/D29 -> 0.28406208 | I29: =(D29-E29)/E29 -> -0.77624438 | J29: =(E29-F29)/F29 -> 0.09972909
A30: Non-Current Investments | B30: 1115.34 | C30: 991.65 | D30: 886.72 | E30: 987.43 | F30: 984.88 | G30: =(B30-C30)/C30 -> 0.12473151 | H30: =(C30-D30)/D30 -> 0.11833499 | I30: =(D30-E30)/E30 -> -0.10199204 | J30: =(E30-F30)/F30 -> 0.0025891479
A31: Deferred Tax Assets [Net] | B31: 296.25 | C31: 265.89 | D31: 297.5 | E31: 530.95 | F31: 408.28 | G31: =(B31-C31)/C31 -> 0.11418256 | H31: =(C31-D31)/D31 -> -0.1062521 | I31: =(D31-E31)/E31 -> -0.43968359 | J31: =(E31-F31)/F31 -> 0.30045557
A32: Long Term Loans And Advances | B32: 769.64 | C32: 724.43 | D32: 705.06 | E32: 682.99 | F32: 901.16 | G32: =(B32-C32)/C32 -> 0.062407686 | H32: =(C32-D32)/D32 -> 0.027472839 | I32: =(D32-E32)/E32 -> 0.032313797 | J32: =(E32-F32)/F32 -> -0.24209907
A33: Other Non-Current Assets | B33: 5816.66 | C33: 5562.82 | D33: 5309.48 | E33: 4449.79 | F33: 3695.91 | G33: =(B33-C33)/C33 -> 0.045631532 | H33: =(C33-D33)/D33 -> 0.047714654 | I33: =(D33-E33)/E33 -> 0.19319788 | J33: =(E33-F33)/F33 -> 0.20397683
A34: Total Non-Current Assets | B34: 17537.52 | C34: 13942.09 | D34: 12180.84 | E34: 28916.88 | F34: 26236.78 | G34: =(B34-C34)/C34 -> 0.25788314 | H34: =(C34-D34)/D34 -> 0.14459183 | I34: =(D34-E34)/E34 -> -0.57876368 | J34: =(E34-F34)/F34 -> 0.10215049
A35: CURRENT ASSETS
A36: Inventories | B36: 2626.89 | C36: 2738.92 | D36: 2660.58 | E36: 2164.9 | F36: 921.72 | G36: =(B36-C36)/C36 -> -0.040902984 | H36: =(C36-D36)/D36 -> 0.029444708 | I36: =(D36-E36)/E36 -> 0.22896208 | J36: =(E36-F36)/F36 -> 1.348761
A37: Trade Receivables | B37: 7734.19 | C37: 3499.21 | D37: 2656.02 | E37: 2954.3 | F37: 2139.89 | G37: =(B37-C37)/C37 -> 1.2102675 | H37: =(C37-D37)/D37 -> 0.31746372 | I37: =(D37-E37)/E37 -> -0.1009647 | J37: =(E37-F37)/F37 -> 0.38058498
A38: Cash And Cash Equivalents | B38: 10030.75 | C38: 12272.95 | D38: 7048.04 | E38: 7940.17 | F38: 5806.01 | G38: =(B38-C38)/C38 -> -0.18269446 | H38: =(C38-D38)/D38 -> 0.74132809 | I38: =(D38-E38)/E38 -> -0.11235654 | J38: =(E38-F38)/F38 -> 0.36757773
A39: Short Term Loans And Advances | B39: 51.68 | C39: 0 | D39: 0 | E39: 0 | F39: 0
A40: OtherCurrentAssets | B40: 2846.7 | C40: 2895.92 | D40: 3396.22 | E40: 2715.69 | F40: 1680.5 | G40: =(B40-C40)/C40 -> -0.016996326 | H40: =(C40-D40)/D40 -> -0.14731083 | I40: =(D40-E40)/E40 -> 0.25059193 | J40: =(E40-F40)/F40 -> 0.61600119
...

Sheet Standalone P&L 
A1: NMDC - Standalone Profit & Loss (Rs. Cr.)
A2: Particulars (Rs. Cr.) | B2: Mar 25 | C2: Mar 24 | D2: Mar 23 | E2: Mar 22 | F2: Mar 21 | G2: % Chg Mar 25/Mar 24 | H2: % Chg Mar 24/Mar 23 | I2: % Chg Mar 23/Mar 22 | J2: % Chg Mar 22/Mar 21
A3: 12 Months Ended | B3: 12 mths | C3: 12 mths | D3: 12 mths | E3: 12 mths | F3: 12 mths
A4: INCOME
A5: Revenue From Operations [Gross] | B5: 23663.58 | C5: 21289.96 | D5: 17661.1 | E5: 25881.73 | F5: 15370.05 | G5: =IF(C5=0,"",(B5-C5)/C5) -> 0.11149011 | H5: =IF(D5=0,"",(C5-D5)/D5) -> 0.20547191 | I5: =IF(E5=0,"",(D5-E5)/E5) -> -0.31762289 | J5: =IF(F5=0,"",(E5-F5)/F5) -> 0.68390669
A6: Revenue From Operations [Net] | B6: 23663.58 | C6: 21289.96 | D6: 17661.1 | E6: 25881.73 | F6: 15370.05 | G6: =IF(C6=0,"",(B6-C6)/C6) -> 0.11149011 | H6: =IF(D6=0,"",(C6-D6)/D6) -> 0.20547191 | I6: =IF(E6=0,"",(D6-E6)/E6) -> -0.31762289 | J6: =IF(F6=0,"",(E6-F6)/F6) -> 0.68390669
A7: Other Operating Revenues | B7: 4.74 | C7: 3.85 | D7: 5.78 | E7: 0 | F7: 0.01 | G7: =IF(C7=0,"",(B7-C7)/C7) -> 0.23116883 | H7: =IF(D7=0,"",(C7-D7)/D7) -> -0.33391003 | I7: =IF(E7=0,"",(D7-E7)/E7) | J7: =IF(F7=0,"",(E7-F7)/F7) -> -1
A8: Total Operating Revenues | B8: 23668.32 | C8: 21293.81 | D8: 17666.88 | E8: 25881.73 | F8: 15370.06 | G8: =IF(C8=0,"",(B8-C8)/C8) -> 0.11151175 | H8: =IF(D8=0,"",(C8-D8)/D8) -> 0.20529545 | I8: =IF(E8=0,"",(D8-E8)/E8) -> -0.31739957 | J8: =IF(F8=0,"",(E8-F8)/F8) -> 0.68390559
A9: Other Income | B9: 1590.24 | C9: 1355.54 | D9: 747.85 | E9: 718.33 | F9: 349.88 | G9: =IF(C9=0,"",(B9-C9)/C9) -> 0.17314133 | H9: =IF(D9=0,"",(C9-D9)/D9) -> 0.81258274 | I9: =IF(E9=0,"",(D9-E9)/E9) -> 0.041095318 | J9: =IF(F9=0,"",(E9-F9)/F9) -> 1.0530753
A10: Total Revenue | B10: 25258.56 | C10: 22649.35 | D10: 18414.73 | E10: 26600.06 | F10: 15719.94 | G10: =IF(C10=0,"",(B10-C10)/C10) -> 0.11520022 | H10: =IF(D10=0,"",(C10-D10)/D10) -> 0.2299583 | I10: =IF(E10=0,"",(D10-E10)/E10) -> -0.30771848 | J10: =IF(F10=0,"",(E10-F10)/F10) -> 0.69212223
A11: EXPENSES
A12: Cost Of Materials Consumed | B12: 772.11 | C12: 777.39 | D12: 771 | E12: 625.99 | F12: 410.21 | G12: =IF(C12=0,"",(B12-C12)/C12) -> -0.0067919577 | H12: =IF(D12=0,"",(C12-D12)/D12) -> 0.0082879377 | I12: =IF(E12=0,"",(D12-E12)/E12) -> 0.23164907 | J12: =IF(F12=0,"",(E12-F12)/F12) -> 0.52602326
A13: Purchase Of Stock-In Trade | B13: 197.09 | C13: 0 | D13: 0 | E13: 0 | F13: 0 | G13: =IF(C13=0,"",(B13-C13)/C13) | H13: =IF(D13=0,"",(C13-D13)/D13) | I13: =IF(E13=0,"",(D13-E13)/E13) | J13: =IF(F13=0,"",(E13-F13)/F13)
A14: Operating And Direct Expenses | B14: 10327.27 | C14: 9460.28 | D14: 7934.97 | E14: 9986.76 | F14: 2969.38 | G14: =IF(C14=0,"",(B14-C14)/C14) -> 0.091645279 | H14: =IF(D14=0,"",(C14-D14)/D14) -> 0.19222631 | I14: =IF(E14=0,"",(D14-E14)/E14) -> -0.20545102 | J14: =IF(F14=0,"",(E14-F14)/F14) -> 2.3632475
A15: Changes In Inventories Of FG,WIP And Stock-In Trade | B15: 81.97 | C15: -66.08 | D15: -496.6 | E15: -1200.5 | F15: -161.81 | G15: =IF(C15=0,"",(B15-C15)/C15) -> -2.2404661 | H15: =IF(D15=0,"",(C15-D15)/D15) -> -0.86693516 | I15: =IF(E15=0,"",(D15-E15)/E15) -> -0.58633903 | J15: =IF(F15=0,"",(E15-F15)/F15) -> 6.4191954
A16: Employee Benefit Expenses | B16: 1781.44 | C16: 1619.44 | D16: 1526.5 | E16: 1333.68 | F16: 1081.81 | G16: =IF(C16=0,"",(B16-C16)/C16) -> 0.10003458 | H16: =IF(D16=0,"",(C16-D16)/D16) -> 0.060884376 | I16: =IF(E16=0,"",(D16-E16)/E16) -> 0.14457741 | J16: =IF(F16=0,"",(E16-F16)/F16) -> 0.23282277
A17: Finance Costs | B17: 177.65 | C17: 78.24 | D17: 75.23 | E17: 39.06 | F17: 16.81 | G17: =IF(C17=0,"",(B17-C17)/C17) -> 1.2705777 | H17: =IF(D17=0,"",(C17-D17)/D17) -> 0.040010634 | I17: =IF(E17=0,"",(D17-E17)/E17) -> 0.92601126 | J17: =IF(F17=0,"",(E17-F17)/F17) -> 1.3236169
A18: Depreciation And Amortisation Expenses | B18: 372.78 | C18: 337.05 | D18: 335.41 | E18: 286.85 | F18: 227.83 | G18: =IF(C18=0,"",(B18-C18)/C18) -> 0.10600801 | H18: =IF(D18=0,"",(C18-D18)/D18) -> 0.0048895382 | I18: =IF(E18=0,"",(D18-E18)/E18) -> 0.16928708 | J18: =IF(F18=0,"",(E18-F18)/F18) -> 0.2590528
A19: Other Expenses | B19: 2250.58 | C19: 2147.56 | D19: 1867.97 | E19: 2546.81 | F19: 2274.61 | G19: =IF(C19=0,"",(B19-C19)/C19) -> 0.04797072 | H19: =IF(D19=0,"",(C19-D19)/D19) -> 0.14967585 | I19: =IF(E19=0,"",(D19-E19)/E19) -> -0.26654521 | J19: =IF(F19=0,"",(E19-F19)/F19) -> 0.11966887
A20: Total Expenses | B20: 15960.89 | C20: 14353.88 | D20: 12014.48 | E20: 13618.65 | F20: 6818.84 | G20: =IF(C20=0,"",(B20-C20)/C20) -> 0.11195649 | H20: =IF(D20=0,"",(C20-D20)/D20) -> 0.19471504 | I20: =IF(E20=0,"",(D20-E20)/E20) -> -0.11779215 | J20: =IF(F20=0,"",(E20-F20)/F20) -> 0.9972092
A21: Profit/Loss Before Exceptional, ExtraOrdinary Items And Tax | B21: 9297.67 | C21: 8295.47 | D21: 6400.25 | E21: 12981.41 | F21: 8901.1 | G21: =IF(C21=0,"",(B21-C21)/C21) -> 0.12081293 | H21: =IF(D21=0,"",(C21-D21)/D21) -> 0.29611656 | I21: =IF(E21=0,"",(D21-E21)/E21) -> -0.50696804 | J21: =IF(F21=0,"",(E21-F21)/F21) -> 0.45840514
A22: Exceptional Items | B22: 0 | C22: -282.15 | D22: 1237.27 | E22: 0 | F22: 0 | G22: =IF(C22=0,"",(B22-C22)/C22) -> -1 | H22: =IF(D22=0,"",(C22-D22)/D22) -> -1.2280424 | I22: =IF(E22=0,"",(D22-E22)/E22) | J22: =IF(F22=0,"",(E22-F22)/F22)
A23: Profit/Loss Before Tax | B23: 9297.67 | C23: 8013.32 | D23: 7637.52 | E23: 12981.41 | F23: 8901.1 | G23: =IF(C23=0,"",(B23-C23)/C23) -> 0.16027689 | H23: =IF(D23=0,"",(C23-D23)/D23) -> 0.049204454 | I23: =IF(E23=0,"",(D23-E23)/E23) -> -0.41165713 | J23: =IF(F23=0,"",(E23-F23)/F23) -> 0.45840514
A24: Tax Expenses-Continued Operations
A25: Current Tax | B25: 2410.81 | C25: 2117.62 | D25: 1664.65 | E25: 3444.39 | F25: 2316.46 | G25: =IF(C25=0,"",(B25-C25)/C25) -> 0.1384526 | H25: =IF(D25=0,"",(C25-D25)/D25) -> 0.27211125 | I25: =IF(E25=0,"",(D25-E25)/E25) -> -0.51670688 | J25: =IF(F25=0,"",(E25-F25)/F25) -> 0.4869197
A26: Deferred Tax | B26: -30.36 | C26: 31.62 | D26: 271.43 | E26: -122.67 | F26: -11.21 | G26: =IF(C26=0,"",(B26-C26)/C26) -> -1.9601518 | H26: =IF(D26=0,"",(C26-D26)/D26) -> -0.88350588 | I26: =IF(E26=0,"",(D26-E26)/E26) -> -3.2126844 | J26: =IF(F26=0,"",(E26-F26)/F26) -> 9.9429081
A27: Tax For Earlier Years | B27: 223.69 | C27: 231.18 | D27: 172.13 | E27: 260.53 | F27: 343.2 | G27: =IF(C27=0,"",(B27-C27)/C27) -> -0.032398996 | H27: =IF(D27=0,"",(C27-D27)/D27) -> 0.34305467 | I27: =IF(E27=0,"",(D27-E27)/E27) -> -0.33930833 | J27: =IF(F27=0,"",(E27-F27)/F27) -> -0.24087995
A28: Total Tax Expenses | B28: 2604.14 | C28: 2380.42 | D28: 2108.21 | E28: 3582.25 | F28: 2648.45 | G28: =IF(C28=0,"",(B28-C28)/C28) -> 0.093983415 | H28: =IF(D28=0,"",(C28-D28)/D28) -> 0.12911902 | I28: =IF(E28=0,"",(D28-E28)/E28) -> -0.4114844 | J28: =IF(F28=0,"",(E28-F28)/F28) -> 0.35258359
A29: Profit/Loss After Tax And Before ExtraOrdinary Items | B29: 6693.53 | C29: 5632.9 | D29: 5529.31 | E29: 9399.16 | F29: 6252.65 | G29: =IF(C29=0,"",(B29-C29)/C29) -> 0.188292 | H29: =IF(D29=0,"",(C29-D29)/D29) -> 0.018734707 | I29: =IF(E29=0,"",(D29-E29)/E29) -> -0.41172296 | J29: =IF(F29=0,"",(E29-F29)/F29) -> 0.50322823
A30: Profit/Loss From Continuing Operations | B30: 6693.53 | C30: 5632.9 | D30: 5529.31 | E30: 9399.16 | F30: 6252.65 | G30: =IF(C30=0,"",(B30-C30)/C30) -> 0.188292 | H30: =IF(D30=0,"",(C30-D30)/D30) -> 0.018734707 | I30: =IF(E30=0,"",(D30-E30)/E30) -> -0.41172296 | J30: =IF(F30=0,"",(E30-F30)/F30) -> 0.50322823
A31: Profit Loss From Discontinuing Operations | B31: -1.24 | C31: -1.32 | D31: -0.91 | E31: -0.91 | F31: 0.53 | G31: =IF(C31=0,"",(B31-C31)/C31) -> -0.060606061 | H31: =IF(D31=0,"",(C31-D31)/D31) -> 0.45054945 | I31: =IF(E31=0,"",(D31-E31)/E31) -> 0 | J31: =IF(F31=0,"",(E31-F31)/F31) -> -2.7169811
A32: Total Tax Expenses Discontinuing Operations | B32: -0.31 | C32: -0.33 | D32: -0.23 | E32: -0.23 | F32: 0.13 | G32: =IF(C32=0,"",(B32-C32)/C32) -> -0.060606061 | H32: =IF(D32=0,"",(C32-D32)/D32) -> 0.43478261 | I32: =IF(E32=0,"",(D32-E32)/E32) -> 0 | J32: =IF(F32=0,"",(E32-F32)/F32) -> -2.7692308
A33: Net Profit Loss From Discontinuing Operations | B33: -0.93 | C33: -0.99 | D33: -0.68 | E33: -0.68 | F33: 0.4 | G33: =IF(C33=0,"",(B33-C33)/C33) -> -0.060606061 | H33: =IF(D33=0,"",(C33-D33)/D33) -> 0.45588235 | I33: =IF(E33=0,"",(D33-E33)/E33) -> 0 | J33: =IF(F33=0,"",(E33-F33)/F33) -> -2.7
A34: Profit/Loss For The Period | B34: 6692.6 | C34: 5631.91 | D34: 5528.63 | E34: 9398.48 | F34: 6253.05 | G34: =IF(C34=0,"",(B34-C34)/C34) -> 0.18833575 | H34: =IF(D34=0,"",(C34-D34)/D34) -> 0.018680939 | I34: =IF(E34=0,"",(D34-E34)/E34) -> -0.41175275 | J34: =IF(F34=0,"",(E34-F34)/F34) -> 0.50302332
A36: OTHER ADDITIONAL INFORMATION
A37: EARNINGS PER SHARE
A38: Basic EPS (Rs.) | B38: 7.61 | C38: 19.22 | D38: 18.86 | E38: 32.07 | F38: 20.62 | G38: =IF(C38=0,"",(B38-C38)/C38) -> -0.60405827 | H38: =IF(D38=0,"",(C38-D38)/D38) -> 0.019088017 | I38: =IF(E38=0,"",(D38-E38)/E38) -> -0.41191144 | J38: =IF(F38=0,"",(E38-F38)/F38) -> 0.55528613
A39: Diluted EPS (Rs.) | B39: 7.61 | C39: 19.22 | D39: 18.86 | E39: 32.07 | F39: 20.62 | G39: =IF(C39=0,"",(B39-C39)/C39) -> -0.60405827 | H39: =IF(D39=0,"",(C39-D39)/D39) -> 0.019088017 | I39: =IF(E39=0,"",(D39-E39)/E39) -> -0.41191144 | J39: =IF(F39=0,"",(E39-F39)/F39) -> 0.55528613
A40: Indigenous Raw Materials | B40: 12.42 | C40: 20.97 | D40: 70.59 | E40: 106.95 | F40: 42.01 | G40: =IF(C40=0,"",(B40-C40)/C40) -> -0.40772532 | H40: =IF(D40=0,"",(C40-D40)/D40) -> -0.70293243 | I40: =IF(E40=0,"",(D40-E40)/E40) -> -0.33997195 | J40: =IF(F40=0,"",(E40-F40)/F40) -> 1.5458224
A41: Imported Stores And Spares | B41: 1.12 | C41: 1.85 | D41: 1.69 | E41: 2.07 | F41: 6.01 | G41: =IF(C41=0,"",(B41-C41)/C41) -> -0.39459459 | H41: =IF(D41=0,"",(C41-D41)/D41) -> 0.094674556 | I41: =IF(E41=0,"",(D41-E41)/E41) -> -0.18357488 | J41: =IF(F41=0,"",(E41-F41)/F41) -> -0.65557404
...

Sheet Consolidated Balance sheet
A1: NMDC - Consolidated Balance Sheet (Rs. Cr.)
A2: Particulars (Rs. Cr.) | B2: Mar 21 | C2: Mar 22 | D2: Mar 23 | E2: Mar 24 | F2: Mar 25 | G2: % Chg Mar 22/Mar 21 | H2: % Chg Mar 23/Mar 22 | I2: % Chg Mar 24/Mar 23 | J2: % Chg Mar 25/Mar 24 | K2: % Chg Mar 25/Mar 25
A3: 12 Months Ended | B3: 12 mths | C3: 12 mths | D3: 12 mths | E3: 12 mths | F3: 12 mths
A4: EQUITIES AND LIABILITIES
A5: SHAREHOLDER'S FUNDS
A6: Equity Share Capital | B6: 293.07 | C6: 293.07 | D6: 293.07 | E6: 293.07 | F6: 879.18 | H6: =(C6-B6)/B6 -> 0 | I6: =(D6-C6)/C6 -> 0 | J6: =(E6-D6)/D6 -> 0 | K6: =(F6-E6)/E6 -> 1.9998976
A7: Total Share Capital | B7: 293.07 | C7: 293.07 | D7: 293.07 | E7: 293.07 | F7: 879.18 | H7: =(C7-B7)/B7 -> 0 | I7: =(D7-C7)/C7 -> 0 | J7: =(E7-D7)/D7 -> 0 | K7: =(F7-E7)/E7 -> 1.9998976
A8: Reserves and Surplus | B8: 29590.98 | C8: 34693.83 | D8: 22327.76 | E8: 25362.83 | F8: 28816.59 | H8: =(C8-B8)/B8 -> 0.17244613 | I8: =(D8-C8)/C8 -> -0.35643427 | J8: =(E8-D8)/D8 -> 0.13593258 | K8: =(F8-E8)/E8 -> 0.13617408
A9: Total Reserves and Surplus | B9: 29590.98 | C9: 34693.83 | D9: 22327.76 | E9: 25362.83 | F9: 28816.59 | H9: =(C9-B9)/B9 -> 0.17244613 | I9: =(D9-C9)/C9 -> -0.35643427 | J9: =(E9-D9)/D9 -> 0.13593258 | K9: =(F9-E9)/E9 -> 0.13617408
A10: Minority Interest | B10: 13.54 | C10: 13.45 | D10: 14.23 | E10: 17.01 | F10: 11.41 | H10: =(C10-B10)/B10 -> -0.0066469719 | I10: =(D10-C10)/C10 -> 0.057992565 | J10: =(E10-D10)/D10 -> 0.19536191 | K10: =(F10-E10)/E10 -> -0.32921811
A11: Total Shareholders Funds | B11: 29884.05 | C11: 34986.9 | D11: 22620.83 | E11: 25655.9 | F11: 29695.77 | H11: =(C11-B11)/B11 -> 0.17075497 | I11: =(D11-C11)/C11 -> -0.35344858 | J11: =(E11-D11)/D11 -> 0.13417147 | K11: =(F11-E11)/E11 -> 0.15746359
A12: NON-CURRENT LIABILITIES
A13: Long Term Borrowings | B13: 546.43 | C13: 1668.22 | D13: 0 | E13: 0 | F13: 0 | H13: =(C13-B13)/B13 -> 2.0529437 | I13: =(D13-C13)/C13 -> -1
A14: Other Long Term Liabilities | B14: 4.7 | C14: 156.13 | D14: 155.3 | E14: 152.04 | F14: 152.25 | H14: =(C14-B14)/B14 -> 32.219149 | I14: =(D14-C14)/C14 -> -0.0053160828 | J14: =(E14-D14)/D14 -> -0.020991629 | K14: =(F14-E14)/E14 -> 0.0013812155
A15: Long Term Provisions | B15: 945.41 | C15: 1092.46 | D15: 1255.99 | E15: 1431.26 | F15: 1479.09 | H15: =(C15-B15)/B15 -> 0.15554098 | I15: =(D15-C15)/C15 -> 0.14968969 | J15: =(E15-D15)/D15 -> 0.13954729 | K15: =(F15-E15)/E15 -> 0.033418107
A16: Total Non-Current Liabilities | B16: 1496.54 | C16: 2916.81 | D16: 1411.29 | E16: 1583.3 | F16: 1631.34 | H16: =(C16-B16)/B16 -> 0.94903578 | I16: =(D16-C16)/C16 -> -0.51615292 | J16: =(E16-D16)/D16 -> 0.1218814 | K16: =(F16-E16)/E16 -> 0.030341691
A17: CURRENT LIABILITIES
A18: Short Term Borrowings | B18: 1448.04 | C18: 1815.13 | D18: 415.98 | E18: 3356.54 | F18: 3770.45 | H18: =(C18-B18)/B18 -> 0.25350819 | I18: =(D18-C18)/C18 -> -0.77082633 | J18: =(E18-D18)/D18 -> 7.0689937 | K18: =(F18-E18)/E18 -> 0.12331448
A19: Trade Payables | B19: 360.78 | C19: 967.53 | D19: 425.91 | E19: 412.55 | F19: 321.46 | H19: =(C19-B19)/B19 -> 1.6817728 | I19: =(D19-C19)/C19 -> -0.5597966 | J19: =(E19-D19)/D19 -> -0.031368129 | K19: =(F19-E19)/E19 -> -0.22079748
A20: Other Current Liabilities | B20: 3628.29 | C20: 4136.62 | D20: 3235.61 | E20: 4380.44 | F20: 5192.7 | H20: =(C20-B20)/B20 -> 0.14010181 | I20: =(D20-C20)/C20 -> -0.21781309 | J20: =(E20-D20)/D20 -> 0.353822 | K20: =(F20-E20)/E20 -> 0.18542886
A21: Short Term Provisions | B21: 98.56 | C21: 15.13 | D21: 123.86 | E21: 255.29 | F21: 383.75 | H21: =(C21-B21)/B21 -> -0.84648945 | I21: =(D21-C21)/C21 -> 7.1863847 | J21: =(E21-D21)/D21 -> 1.0611174 | K21: =(F21-E21)/E21 -> 0.50319245
A22: Total Current Liabilities | B22: 5535.67 | C22: 6934.41 | D22: 4201.36 | E22: 8404.82 | F22: 9668.36 | H22: =(C22-B22)/B22 -> 0.25267763 | I22: =(D22-C22)/C22 -> -0.3941287 | J22: =(E22-D22)/D22 -> 1.0004998 | K22: =(F22-E22)/E22 -> 0.15033516
A23: Total Capital And Liabilities | B23: 36929.8 | C23: 44851.57 | D23: 28247.71 | E23: 35661.03 | F23: 41006.88 | H23: =(C23-B23)/B23 -> 0.21450888 | I23: =(D23-C23)/C23 -> -0.37019574 | J23: =(E23-D23)/D23 -> 0.26243968 | K23: =(F23-E23)/E23 -> 0.14990734
A24: ASSETS
A25: NON-CURRENT ASSETS
A26: Tangible Assets | B26: 3320.95 | C26: 4165.13 | D26: 2388.75 | E26: 2520.49 | F26: 4177.3 | H26: =(C26-B26)/B26 -> 0.25419835 | I26: =(D26-C26)/C26 -> -0.42648849 | J26: =(E26-D26)/D26 -> 0.055150183 | K26: =(F26-E26)/E26 -> 0.65733647
A27: Intangible Assets | B27: 518.57 | C27: 535.73 | D27: 715.93 | E27: 762.24 | F27: 767.27 | H27: =(C27-B27)/B27 -> 0.033091 | I27: =(D27-C27)/C27 -> 0.33636347 | J27: =(E27-D27)/D27 -> 0.064685095 | K27: =(F27-E27)/E27 -> 0.0065989715
A28: Capital Work-In-Progress | B28: 17106.51 | C28: 18324.52 | D28: 1991.55 | E28: 3230.51 | F28: 4737.48 | H28: =(C28-B28)/B28 -> 0.071201548 | I28: =(D28-C28)/C28 -> -0.89131775 | J28: =(E28-D28)/D28 -> 0.62210841 | K28: =(F28-E28)/E28 -> 0.46648052
A29: Intangible Assets Under Development | B29: 51.42 | C29: 5 | D29: 6.49 | E29: 4.14 | F29: 0 | H29: =(C29-B29)/B29 -> -0.90276157 | I29: =(D29-C29)/C29 -> 0.298 | J29: =(E29-D29)/D29 -> -0.36209553 | K29: =(F29-E29)/E29 -> -1
A30: Fixed Assets | B30: 20997.45 | C30: 23030.38 | D30: 5102.72 | E30: 6517.38 | F30: 9682.05 | H30: =(C30-B30)/B30 -> 0.096817947 | I30: =(D30-C30)/C30 -> -0.77843527 | J30: =(E30-D30)/D30 -> 0.27723645 | K30: =(F30-E30)/E30 -> 0.48557396
A31: Non-Current Investments | B31: 874.9 | C31: 894.95 | D31: 934.68 | E31: 951.17 | F31: 974.53 | H31: =(C31-B31)/B31 -> 0.022916905 | I31: =(D31-C31)/C31 -> 0.044393542 | J31: =(E31-D31)/D31 -> 0.017642402 | K31: =(F31-E31)/E31 -> 0.024559227
A32: Deferred Tax Assets [Net] | B32: 408.28 | C32: 530.95 | D32: 297.5 | E32: 265.89 | F32: 296.25 | H32: =(C32-B32)/B32 -> 0.30045557 | I32: =(D32-C32)/C32 -> -0.43968359 | J32: =(E32-D32)/D32 -> -0.1062521 | K32: =(F32-E32)/E32 -> 0.11418256
A33: Long Term Loans And Advances | B33: 259.17 | C33: 40.77 | D33: 62.62 | E33: 81.74 | F33: 126.72 | H33: =(C33-B33)/B33 -> -0.84269013 | I33: =(D33-C33)/C33 -> 0.53593328 | J33: =(E33-D33)/D33 -> 0.30533376 | K33: =(F33-E33)/E33 -> 0.55028138
A34: Other Non-Current Assets | B34: 3695.91 | C34: 4449.8 | D34: 5949.09 | E34: 6202.43 | F34: 6456.76 | H34: =(C34-B34)/B34 -> 0.20397953 | I34: =(D34-C34)/C34 -> 0.33693424 | J34: =(E34-D34)/D34 -> 0.042584664 | K34: =(F34-E34)/E34 -> 0.041004896
A35: Total Non-Current Assets | B35: 26329.6 | C35: 29040.74 | D35: 12440.5 | E35: 14112.5 | F35: 17630.2 | H35: =(C35-B35)/B35 -> 0.10296928 | I35: =(D35-C35)/C35 -> -0.57161904 | J35: =(E35-D35)/D35 -> 0.13439974 | K35: =(F35-E35)/E35 -> 0.24926129
A36: CURRENT ASSETS
A37: Current Investments | B37: 0 | C37: 0 | D37: 0 | E37: 4.89 | F37: 3.6 | K37: =(F37-E37)/E37 -> -0.26380368
A38: Inventories | B38: 921.72 | C38: 2164.9 | D38: 2660.58 | E38: 2766.95 | F38: 2637.72 | H38: =(C38-B38)/B38 -> 1.348761 | I38: =(D38-C38)/C38 -> 0.22896208 | J38: =(E38-D38)/D38 -> 0.039980004 | K38: =(F38-E38)/E38 -> -0.046704856
A39: Trade Receivables | B39: 2139.89 | C39: 2954.3 | D39: 2656.02 | E39: 3508.93 | F39: 7744.61 | H39: =(C39-B39)/B39 -> 0.38058498 | I39: =(D39-C39)/C39 -> -0.1009647 | J39: =(E39-D39)/D39 -> 0.32112333 | K39: =(F39-E39)/E39 -> 1.2071144
A40: Cash And Cash Equivalents | B40: 5861.82 | C40: 7978.29 | D40: 7097.75 | E40: 12363.65 | F40: 10088.55 | H40: =(C40-B40)/B40 -> 0.36106022 | I40: =(D40-C40)/C40 -> -0.11036701 | J40: =(E40-D40)/D40 -> 0.74191117 | K40: =(F40-E40)/E40 -> -0.18401524
...

Sheet Consolidated P&L
A1: NMDC - Consolidated Profit & Loss (Rs. Cr.)
A2: Particulars (Rs. Cr.) | B2: Mar 21 | C2: Mar 22 | D2: Mar 23 | E2: Mar 24 | F2: Mar 25 | G2: % Chg Mar 22/Mar 21 | H2: % Chg Mar 23/Mar 22 | I2: % Chg Mar 24/Mar 23 | J2: % Chg Mar 25/Mar 24 | K2: % Chg Mar 25/Mar 24
A3: 12 Months Ended | B3: 12 mths | C3: 12 mths | D3: 12 mths | E3: 12 mths | F3: 12 mths
A4: INCOME
A5: Revenue From Operations [Gross] | B5: 15370.05 | C5: 25881.73 | D5: 17661.1 | E5: 21301.23 | F5: 23900.78 | H5: =(C5-B5)/B5 -> 0.68390669 | I5: =(D5-C5)/C5 -> -0.31762289 | J5: =(E5-D5)/D5 -> 0.20611004 | K5: =(F5-E5)/E5 -> 0.12203755
A6: Revenue From Operations [Net] | B6: 15370.05 | C6: 25881.73 | D6: 17661.1 | E6: 21301.23 | F6: 23900.78 | H6: =(C6-B6)/B6 -> 0.68390669 | I6: =(D6-C6)/C6 -> -0.31762289 | J6: =(E6-D6)/D6 -> 0.20611004 | K6: =(F6-E6)/E6 -> 0.12203755
A7: Other Operating Revenues | B7: 0.01 | C7: 0 | D7: 5.78 | E7: 6.62 | F7: 4.74 | H7: =(C7-B7)/B7 -> -1 | J7: =(E7-D7)/D7 -> 0.14532872 | K7: =(F7-E7)/E7 -> -0.28398792
A8: Total Operating Revenues | B8: 15370.06 | C8: 25881.73 | D8: 17666.88 | E8: 21307.85 | F8: 23905.52 | H8: =(C8-B8)/B8 -> 0.68390559 | I8: =(D8-C8)/C8 -> -0.31739957 | J8: =(E8-D8)/D8 -> 0.20609015 | K8: =(F8-E8)/E8 -> 0.12191141
A9: Other Income | B9: 351.6 | C9: 718.52 | D9: 768.22 | E9: 1370.88 | F9: 1593.32 | H9: =(C9-B9)/B9 -> 1.0435722 | I9: =(D9-C9)/C9 -> 0.06916996 | J9: =(E9-D9)/D9 -> 0.78448882 | K9: =(F9-E9)/E9 -> 0.16226074
A10: Total Revenue | B10: 15721.66 | C10: 26600.25 | D10: 18435.1 | E10: 22678.73 | F10: 25498.84 | H10: =(C10-B10)/B10 -> 0.6919492 | I10: =(D10-C10)/C10 -> -0.30695764 | J10: =(E10-D10)/D10 -> 0.23019295 | K10: =(F10-E10)/E10 -> 0.12435044
A11: EXPENSES
A12: Cost Of Materials Consumed | B12: 410.24 | C12: 626.02 | D12: 771.03 | E12: 841.79 | F12: 896.39 | H12: =(C12-B12)/B12 -> 0.52598479 | I12: =(D12-C12)/C12 -> 0.23163797 | J12: =(E12-D12)/D12 -> 0.091773342 | K12: =(F12-E12)/E12 -> 0.064861783
A13: Purchase Of Stock-In Trade | B13: 0 | C13: 0 | D13: 0 | E13: 0 | F13: 197.09
A14: Operating And Direct Expenses | B14: 2969.38 | C14: 10178.99 | D14: 7935.05 | E14: 9460.47 | F14: 10502.91 | H14: =(C14-B14)/B14 -> 2.427985 | I14: =(D14-C14)/C14 -> -0.2204482 | J14: =(E14-D14)/D14 -> 0.19223823 | K14: =(F14-E14)/E14 -> 0.11018903
A15: Changes In Inventories Of FG,WIP And Stock-In Trade | B15: -161.81 | C15: -1200.5 | D15: -496.6 | E15: -93.36 | F15: 99.31 | H15: =(C15-B15)/B15 -> 6.4191954 | I15: =(D15-C15)/C15 -> -0.58633903 | J15: =(E15-D15)/D15 -> -0.81200161 | K15: =(F15-E15)/E15 -> -2.0637318
A16: Employee Benefit Expenses | B16: 1085.24 | C16: 1337.07 | D16: 1530.57 | E16: 1625.54 | F16: 1795.04 | H16: =(C16-B16)/B16 -> 0.23205005 | I16: =(D16-C16)/C16 -> 0.14471942 | J16: =(E16-D16)/D16 -> 0.062048779 | K16: =(F16-E16)/E16 -> 0.10427304
A17: Finance Costs | B17: 16.81 | C17: 39.06 | D17: 75.23 | E17: 78.24 | F17: 177.68 | H17: =(C17-B17)/B17 -> 1.3236169 | I17: =(D17-C17)/C17 -> 0.92601126 | J17: =(E17-D17)/D17 -> 0.040010634 | K17: =(F17-E17)/E17 -> 1.2709611
A18: Depreciation And Amortisation Expenses | B18: 228.54 | C18: 287.74 | D18: 336.18 | E18: 350.66 | F18: 420.42 | H18: =(C18-B18)/B18 -> 0.25903562 | I18: =(D18-C18)/C18 -> 0.16834642 | J18: =(E18-D18)/D18 -> 0.043072164 | K18: =(F18-E18)/E18 -> 0.19893914
A19: Other Expenses | B19: 2277.74 | C19: 2357.63 | D19: 1874.3 | E19: 2180.58 | F19: 2266.11 | H19: =(C19-B19)/B19 -> 0.03507424 | I19: =(D19-C19)/C19 -> -0.20500672 | J19: =(E19-D19)/D19 -> 0.16341034 | K19: =(F19-E19)/E19 -> 0.039223509
A20: Total Expenses | B20: 6826.14 | C20: 13626.01 | D20: 12025.76 | E20: 14443.92 | F20: 16354.95 | H20: =(C20-B20)/B20 -> 0.99615156 | I20: =(D20-C20)/C20 -> -0.11744084 | J20: =(E20-D20)/D20 -> 0.20108168 | K20: =(F20-E20)/E20 -> 0.13230688
A21: Profit/Loss Before Exceptional, ExtraOrdinary Items And Tax | B21: 8895.52 | C21: 12974.24 | D21: 6409.34 | E21: 8234.81 | F21: 9143.89 | H21: =(C21-B21)/B21 -> 0.45851395 | I21: =(D21-C21)/C21 -> -0.50599496 | J21: =(E21-D21)/D21 -> 0.28481404 | K21: =(F21-E21)/E21 -> 0.11039478
A22: Exceptional Items | B22: 0 | C22: 0 | D22: 1237.27 | E22: -282.15 | F22: 0 | J22: =(E22-D22)/D22 -> -1.2280424 | K22: =(F22-E22)/E22 -> -1
A23: Profit/Loss Before Tax | B23: 8895.52 | C23: 12974.24 | D23: 7646.61 | E23: 7952.66 | F23: 9143.89 | H23: =(C23-B23)/B23 -> 0.45851395 | I23: =(D23-C23)/C23 -> -0.41063137 | J23: =(E23-D23)/D23 -> 0.040024272 | K23: =(F23-E23)/E23 -> 0.14979013
A24: Tax Expenses-Continued Operations
A25: Current Tax | B25: 2316.46 | C25: 3444.39 | D25: 1664.65 | E25: 2117.62 | F25: 2410.81 | H25: =(C25-B25)/B25 -> 0.4869197 | I25: =(D25-C25)/C25 -> -0.51670688 | J25: =(E25-D25)/D25 -> 0.27211125 | K25: =(F25-E25)/E25 -> 0.1384526
A26: Deferred Tax | B26: -11.21 | C26: -122.67 | D26: 271.43 | E26: 31.62 | F26: -30.36 | H26: =(C26-B26)/B26 -> 9.9429081 | I26: =(D26-C26)/C26 -> -3.2126844 | J26: =(E26-D26)/D26 -> -0.88350588 | K26: =(F26-E26)/E26 -> -1.9601518
A27: Tax For Earlier Years | B27: 343.2 | C27: 260.53 | D27: 172.13 | E27: 231.18 | F27: 223.69 | H27: =(C27-B27)/B27 -> -0.24087995 | I27: =(D27-C27)/C27 -> -0.33930833 | J27: =(E27-D27)/D27 -> 0.34305467 | K27: =(F27-E27)/E27 -> -0.032398996
A28: Total Tax Expenses | B28: 2648.45 | C28: 3582.25 | D28: 2108.21 | E28: 2380.42 | F28: 2604.14 | H28: =(C28-B28)/B28 -> 0.35258359 | I28: =(D28-C28)/C28 -> -0.4114844 | J28: =(E28-D28)/D28 -> 0.12911902 | K28: =(F28-E28)/E28 -> 0.093983415
A29: Profit/Loss After Tax And Before ExtraOrdinary Items | B29: 6247.07 | C29: 9391.99 | D29: 5538.4 | E29: 5572.24 | F29: 6539.75 | H29: =(C29-B29)/B29 -> 0.5034232 | I29: =(D29-C29)/C29 -> -0.41030602 | J29: =(E29-D29)/D29 -> 0.0061100679 | K29: =(F29-E29)/E29 -> 0.17363035
A30: Profit/Loss From Continuing Operations | B30: 6247.07 | C30: 9391.99 | D30: 5538.4 | E30: 5572.24 | F30: 6539.75 | H30: =(C30-B30)/B30 -> 0.5034232 | I30: =(D30-C30)/C30 -> -0.41030602 | J30: =(E30-D30)/D30 -> 0.0061100679 | K30: =(F30-E30)/E30 -> 0.17363035
A31: Profit Loss From Discontinuing Operations | B31: 0.53 | C31: -0.91 | D31: -0.91 | E31: -1.32 | F31: -1.24 | H31: =(C31-B31)/B31 -> -2.7169811 | I31: =(D31-C31)/C31 -> 0 | J31: =(E31-D31)/D31 -> 0.45054945 | K31: =(F31-E31)/E31 -> -0.060606061
A32: Total Tax Expenses Discontinuing Operations | B32: 0.13 | C32: -0.23 | D32: -0.23 | E32: -0.33 | F32: -0.31 | H32: =(C32-B32)/B32 -> -2.7692308 | I32: =(D32-C32)/C32 -> 0 | J32: =(E32-D32)/D32 -> 0.43478261 | K32: =(F32-E32)/E32 -> -0.060606061
A33: Net Profit Loss From Discontinuing Operations | B33: 0.4 | C33: -0.68 | D33: -0.68 | E33: -0.99 | F33: -0.93 | H33: =(C33-B33)/B33 -> -2.7 | I33: =(D33-C33)/C33 -> 0 | J33: =(E33-D33)/D33 -> 0.45588235 | K33: =(F33-E33)/E33 -> -0.060606061
A34: Profit/Loss For The Period | B34: 6247.47 | C34: 9391.31 | D34: 5537.72 | E34: 5571.25 | F34: 6538.82 | H34: =(C34-B34)/B34 -> 0.5032181 | I34: =(D34-C34)/C34 -> -0.41033573 | J34: =(E34-D34)/D34 -> 0.0060548385 | K34: =(F34-E34)/E34 -> 0.17367198
A35: Minority Interest | B35: 0.37 | C35: 0.55 | D35: -1.1 | E35: 4.19 | F35: 10.95 | H35: =(C35-B35)/B35 -> 0.48648649 | I35: =(D35-C35)/C35 -> -3 | J35: =(E35-D35)/D35 -> -4.8090909 | K35: =(F35-E35)/E35 -> 1.6133652
A36: Share Of Profit/Loss Of Associates | B36: 29.17 | C36: -12.26 | D36: 64.84 | E36: -0.38 | F36: -7.79 | H36: =(C36-B36)/B36 -> -1.4202948 | I36: =(D36-C36)/C36 -> -6.2887439 | J36: =(E36-D36)/D36 -> -1.0058606 | K36: =(F36-E36)/E36 -> 19.5
A37: Consolidated Profit/Loss After MI And Associates | B37: 6277.01 | C37: 9379.6 | D37: 5601.46 | E37: 5575.06 | F37: 6541.98 | H37: =(C37-B37)/B37 -> 0.49427833 | I37: =(D37-C37)/C37 -> -0.40280396 | J37: =(E37-D37)/D37 -> -0.004713057 | K37: =(F37-E37)/E37 -> 0.1734367
A39: OTHER ADDITIONAL INFORMATION
A40: EARNINGS PER SHARE
A41: Basic EPS (Rs.) | B41: 21 | C41: 32 | D41: 19 | E41: 19 | F41: 7 | H41: =(C41-B41)/B41 -> 0.52380952 | I41: =(D41-C41)/C41 -> -0.40625 | J41: =(E41-D41)/D41 -> 0 | K41: =(F41-E41)/E41 -> -0.63157895
...

Sheet Peers
F2: Attribute | G2: LTP (₹) | H2: Sales (₹ crore) | I2: PAT (₹ crore) | J2: Equity (₹ crore) | K2: Operating Profit Margin (OPM%) | L2: Net Profit Margin (NPM%) | M2: Earnings Per Share (EPS) | N2: Cash Earnings Per Share (CEPS)
F3: NMDC | G3: 90.66 | H3: 23905.52 | I3: 6538.82 | J3: 879.18 | K3: 34.08 | L3: 27.36 | M3: 7 | N3: 7.92
F4: JSW Steel | G4: 1265 | H4: 168824 | I4: 3802 | J4: 271.57 | K4: 13.56 | L4: 2.07 | M4: 14 | N4: 48.28
F5: TATA Steel | G5: 211.39 | H5: 218542.51 | I5: 2982.97 | J5: 994.32 | K5: 11.57 | L5: 1.56 | M5: 3 | N5: 13.48
F6: Hindalco | G6: 1039.3 | H6: 238496 | I6: 15999 | J6: 222.21 | K6: 13.33 | L6: 6.7 | M6: 72 | N6: 107.47
F8: NMDC | L8: JSW Steel
F9: Metric | G9: 44986 | H9: 45352 | I9: 45717 | L9: Metric | M9: 44986 | N9: 45352 | O9: 45717
F10: Debtor Days | G10: 57.9 | H10: 52.8 | I10: 85.9 | L10: Debtor Days | M10: 16 | N10: 15.3 | O10: 17.3
F11: Inventory Days | G11: 55 | H11: 47.4 | I11: 40.3 | L11: Inventory Days | M11: 72.9 | N11: 78.8 | O11: 75.6
F12: Days Payable | G12: -37.5 | H12: -106.9 | I12: -74.1 | L12: Days Payable | M12: 78.9 | N12: 84.4 | O12: 86.2
F13: Cash Conversion Cycle | G13: 150.4 | H13: 207.1 | I13: 200.3 | L13: Cash Conversion Cycle | M13: 10 | N13: 9.7 | O13: 6.7
F14: Working Capital Days | G14: 150.4 | H14: 207.1 | I14: 200.3 | L14: Working Capital Days | M14: 10 | N14: 9.7 | O14: 6.7
F15: ROCE % | G15: 28.14 | H15: 28.65 | I15: 27.85 | L15: ROCE % | M15: 8.37 | N15: 12.9 | O15: 8.14
